Workbook

Sheet README
A1: Hoja | B1: Descripción
A2: EFACT_CNE | B2: Información de facturación definitiva proveniente de los archivos EFACT publicados por la CNE en los Decretos de Precio de Nudo
A3: FACT_EMITIDA | B3: Información de facturación real desde PDFs y sistema SIGGE (gestión facturación electrónica)
A4: SIGGE_E | B4: Información de facturación real de Energía desde PDFs y sistema SIGGE (gestión facturación electrónica)
A5: SIGGE_P | B5: Información de facturación real de Potencia desde PDFs y sistema SIGGE (gestión facturación electrónica)
A6: FACT_EST_EFACT | B6: Estimación de facturación emitida en base a información de los EFACT Decretos Precios de Nudo
A7: FACT_EST_CEN | B7: Estimación de la facturación emitida en base a los balances mensuales publicados por el Coordinador

Sheet MAPA_DATA
A1: Num | B1: Anho | C1: Mes | D1: Fecha | E1: FACT_EMITIDA | F1: FACT_EST_EFACT | G1: FACT_EST_CEN | H1: EFACT_CNE | I1: EFACT_EST_CEN | J1: OrigenData1 | K1: OrigenData2
A2: 1 | B2: 2020 | C2: 10 | D2: 44105 | E2: 1 | F2: 0 | G2: 0 | H2: 1 | I2: 0 | J2: FACT_EMITIDA | K2: EFACT_CNE
A3: 2 | B3: 2020 | C3: 11 | D3: 44136 | E3: 1 | F3: 0 | G3: 0 | H3: 1 | I3: 0 | J3: FACT_EMITIDA | K3: EFACT_CNE
A4: 3 | B4: 2020 | C4: 12 | D4: 44166 | E4: 1 | F4: 0 | G4: 0 | H4: 1 | I4: 0 | J4: FACT_EMITIDA | K4: EFACT_CNE
A5: 4 | B5: 2021 | C5: 1 | D5: 44197 | E5: 1 | F5: 0 | G5: 0 | H5: 1 | I5: 0 | J5: FACT_EMITIDA | K5: EFACT_CNE
A6: 5 | B6: 2021 | C6: 2 | D6: 44228 | E6: 1 | F6: 0 | G6: 0 | H6: 1 | I6: 0 | J6: FACT_EMITIDA | K6: EFACT_CNE
A7: 6 | B7: 2021 | C7: 3 | D7: 44256 | E7: 1 | F7: 0 | G7: 0 | H7: 1 | I7: 0 | J7: FACT_EMITIDA | K7: EFACT_CNE

Sheet ReliquidacionEFACT
A2: Generador | B2: [GX]
A3: Distribuidor | B3: [EEDD]
A4: Licitacion | B4: 2013/03-2° Llamado
A5: Bloque | B5: [BLOQUE]
C7: LO QUE SE FACTURÓ | L7: LO QUE SE DEBIÓ HABER FACTURADO | U7: RELQUIDACIÓN Y CÁLCULO INTERESES
A8: ID | B8: MES | C8: ORIGEN DATA | D8: Energía (kWh) | E8: Monto Energía ($) | F8: $/kWh | G8: Potencia (kW) | H8: Monto Potencia ($) | I8: $/kW-mes | J8: Monto Total ($) | L8: ORIGEN DATA | M8: Energía (kWh) | N8: Monto Energía ($) | O8: $/kWh | P8: Potencia (kW) | Q8: Monto Potencia ($) | R8: $/kW-mes | S8: Monto Total ($) | U8: Mes | V8: Reliquidación mensual ($) | W8: Decreto PNP Reliquidación | X8: Fecha publicación Diario Oficial | Y8: Interés Anual | Z8: Fecha Facturación | AA8: Fecha Reliquidación | AB8: N° de días de intereses | AC8: Interés total según n° de días | AD8: Intereses ($) | AE8: Reliquidación Total ($)
A9: 9 | B9: 44105 | C9: FACT_EMITIDA | D9: =CONCATENATE("SUMIF(",IF(C9="FACT_EMITIDA","SIGGE_E",C9),"!B:B,ReliquidacionEFACT!B",A9,",",IF(C9="FACT_EMITIDA","SIGGE_E",C9),"!S:S)") -> SUMIF(SIGGE_E!B:B,ReliquidacionEFACT!B9,SIGGE_E!S:S) | E9: =CONCATENATE("SUMIF(",IF(C9="FACT_EMITIDA","SIGGE_E",C9),"!B:B,ReliquidacionEFACT!B",A9,",",IF(C9="FACT_EMITIDA","SIGGE_E",C9),"!T:T)") -> SUMIF(SIGGE_E!B:B,ReliquidacionEFACT!B9,SIGGE_E!T:T) | F9: =CONCATENATE("IFERROR((E",A9,"/D",A9,"),0)") -> IFERROR((E9/D9),0) | G9: =CONCATENATE("SUMIF(",IF(C9="FACT_EMITIDA","SIGGE_P",C9),"!B:B,ReliquidacionEFACT!B",A9,",",IF(C9="FACT_EMITIDA","SIGGE_P",C9),"!U:U)") -> SUMIF(SIGGE_P!B:B,ReliquidacionEFACT!B9,SIGGE_P!U:U) | H9: =CONCATENATE("SUMIF(",IF(C9="FACT_EMITIDA","SIGGE_P",C9),"!B:B,ReliquidacionEFACT!B",A9,",",IF(C9="FACT_EMITIDA","SIGGE_P",C9),"!V:V)") -> SUMIF(SIGGE_P!B:B,ReliquidacionEFACT!B9,SIGGE_P!V:V) | I9: =CONCATENATE("IFERROR((H",A9,"/G",A9,"),0)") -> IFERROR((H9/G9),0) | J9: =CONCATENATE("(E",A9,"+H",A9,")") -> (E9+H9) | L9: =(MAPA_DATA!K2) -> EFACT_CNE | M9: =CONCATENATE("SUMIF(",L9,"!B:B,ReliquidacionEFACT!B",A9,",",L9,"!S:S)") -> SUMIF(EFACT_CNE!B:B,ReliquidacionEFACT!B9,EFACT_CNE!S:S) | N9: =CONCATENATE("SUMIF(",L9,"!B:B,ReliquidacionEFACT!B",A9,",",L9,"!T:T)") -> SUMIF(EFACT_CNE!B:B,ReliquidacionEFACT!B9,EFACT_CNE!T:T) | O9: =CONCATENATE("IFERROR((N",A9,"/M",A9,"),0)") -> IFERROR((N9/M9),0) | P9: =CONCATENATE("SUMIF(",L9,"!B:B,ReliquidacionEFACT!B",A9,",",L9,"!U:U)") -> SUMIF(EFACT_CNE!B:B,ReliquidacionEFACT!B9,EFACT_CNE!U:U) | Q9: =CONCATENATE("SUMIF(",L9,"!B:B,ReliquidacionEFACT!B",A9,",",L9,"!V:V)") -> SUMIF(EFACT_CNE!B:B,ReliquidacionEFACT!B9,EFACT_CNE!V:V) | R9: =CONCATENATE("IFERROR((Q",A9,"/P",A9,"),0)") -> IFERROR((Q9/P9),0) | S9: =CONCATENATE("(N",A9,"+Q",A9,")") -> (N9+Q9) | U9: 44105 | V9: =CONCATENATE("(S",A9,"-J",A9,")") -> (S9-J9) | W9: PNP_8T | X9: 44600 | Y9: 0.0328 | Z9: 44129 | AA9: 44651 | AB9: =CONCATENATE("(AA",A9,"-Z",A9,")") -> (AA9-Z9) | AC9: =CONCATENATE("(1+Y",A9,")^(AB",A9,"/360)-1") -> (1+Y9)^(AB9/360)-1 | AD9: =CONCATENATE("(AC",A9,"*V",A9,")") -> (AC9*V9) | AE9: =CONCATENATE("(V",A9,"+AD",A9,")") -> (V9+AD9)
A10: =A9+1 -> 10 | B10: 44136 | C10: FACT_EMITIDA | D10: =CONCATENATE("SUMIF(",IF(C10="FACT_EMITIDA","SIGGE_E",C10),"!B:B,ReliquidacionEFACT!B",A10,",",IF(C10="FACT_EMITIDA","SIGGE_E",C10),"!S:S)") -> SUMIF(SIGGE_E!B:B,ReliquidacionEFACT!B10,SIGGE_E!S:S) | E10: =CONCATENATE("SUMIF(",IF(C10="FACT_EMITIDA","SIGGE_E",C10),"!B:B,ReliquidacionEFACT!B",A10,",",IF(C10="FACT_EMITIDA","SIGGE_E",C10),"!T:T)") -> SUMIF(SIGGE_E!B:B,ReliquidacionEFACT!B10,SIGGE_E!T:T) | F10: =CONCATENATE("IFERROR((E",A10,"/D",A10,"),0)") -> IFERROR((E10/D10),0) | G10: =CONCATENATE("SUMIF(",IF(C10="FACT_EMITIDA","SIGGE_P",C10),"!B:B,ReliquidacionEFACT!B",A10,",",IF(C10="FACT_EMITIDA","SIGGE_P",C10),"!U:U)") -> SUMIF(SIGGE_P!B:B,ReliquidacionEFACT!B10,SIGGE_P!U:U) | H10: =CONCATENATE("SUMIF(",IF(C10="FACT_EMITIDA","SIGGE_P",C10),"!B:B,ReliquidacionEFACT!B",A10,",",IF(C10="FACT_EMITIDA","SIGGE_P",C10),"!V:V)") -> SUMIF(SIGGE_P!B:B,ReliquidacionEFACT!B10,SIGGE_P!V:V) | I10: =CONCATENATE("IFERROR((H",A10,"/G",A10,"),0)") -> IFERROR((H10/G10),0) | J10: =CONCATENATE("(E",A10,"+H",A10,")") -> (E10+H10) | L10: =(MAPA_DATA!K3) -> EFACT_CNE | M10: =CONCATENATE("SUMIF(",L10,"!B:B,ReliquidacionEFACT!B",A10,",",L10,"!S:S)") -> SUMIF(EFACT_CNE!B:B,ReliquidacionEFACT!B10,EFACT_CNE!S:S) | N10: =CONCATENATE("SUMIF(",L10,"!B:B,ReliquidacionEFACT!B",A10,",",L10,"!T:T)") -> SUMIF(EFACT_CNE!B:B,ReliquidacionEFACT!B10,EFACT_CNE!T:T) | O10: =CONCATENATE("IFERROR((N",A10,"/M",A10,"),0)") -> IFERROR((N10/M10),0) | P10: =CONCATENATE("SUMIF(",L10,"!B:B,ReliquidacionEFACT!B",A10,",",L10,"!U:U)") -> SUMIF(EFACT_CNE!B:B,ReliquidacionEFACT!B10,EFACT_CNE!U:U) | Q10: =CONCATENATE("SUMIF(",L10,"!B:B,ReliquidacionEFACT!B",A10,",",L10,"!V:V)") -> SUMIF(EFACT_CNE!B:B,ReliquidacionEFACT!B10,EFACT_CNE!V:V) | R10: =CONCATENATE("IFERROR((Q",A10,"/P",A10,"),0)") -> IFERROR((Q10/P10),0) | S10: =CONCATENATE("(N",A10,"+Q",A10,")") -> (N10+Q10) | U10: 44136 | V10: =CONCATENATE("(S",A10,"-J",A10,")") -> (S10-J10) | W10: PNP_8T | X10: 44600 | Y10: 0.0328 | Z10: 44160 | AA10: =AA9 -> 44651 | AB10: =CONCATENATE("(AA",A10,"-Z",A10,")") -> (AA10-Z10) | AC10: =CONCATENATE("(1+Y",A10,")^(AB",A10,"/360)-1") -> (1+Y10)^(AB10/360)-1 | AD10: =CONCATENATE("(AC",A10,"*V",A10,")") -> (AC10*V10) | AE10: =CONCATENATE("(V",A10,"+AD",A10,")") -> (V10+AD10)
A11: =A10+1 -> 11 | B11: 44166 | C11: FACT_EMITIDA | D11: =CONCATENATE("SUMIF(",IF(C11="FACT_EMITIDA","SIGGE_E",C11),"!B:B,ReliquidacionEFACT!B",A11,",",IF(C11="FACT_EMITIDA","SIGGE_E",C11),"!S:S)") -> SUMIF(SIGGE_E!B:B,ReliquidacionEFACT!B11,SIGGE_E!S:S) | E11: =CONCATENATE("SUMIF(",IF(C11="FACT_EMITIDA","SIGGE_E",C11),"!B:B,ReliquidacionEFACT!B",A11,",",IF(C11="FACT_EMITIDA","SIGGE_E",C11),"!T:T)") -> SUMIF(SIGGE_E!B:B,ReliquidacionEFACT!B11,SIGGE_E!T:T) | F11: =CONCATENATE("IFERROR((E",A11,"/D",A11,"),0)") -> IFERROR((E11/D11),0) | G11: =CONCATENATE("SUMIF(",IF(C11="FACT_EMITIDA","SIGGE_P",C11),"!B:B,ReliquidacionEFACT!B",A11,",",IF(C11="FACT_EMITIDA","SIGGE_P",C11),"!U:U)") -> SUMIF(SIGGE_P!B:B,ReliquidacionEFACT!B11,SIGGE_P!U:U) | H11: =CONCATENATE("SUMIF(",IF(C11="FACT_EMITIDA","SIGGE_P",C11),"!B:B,ReliquidacionEFACT!B",A11,",",IF(C11="FACT_EMITIDA","SIGGE_P",C11),"!V:V)") -> SUMIF(SIGGE_P!B:B,ReliquidacionEFACT!B11,SIGGE_P!V:V) | I11: =CONCATENATE("IFERROR((H",A11,"/G",A11,"),0)") -> IFERROR((H11/G11),0) | J11: =CONCATENATE("(E",A11,"+H",A11,")") -> (E11+H11) | L11: =(MAPA_DATA!K4) -> EFACT_CNE | M11: =CONCATENATE("SUMIF(",L11,"!B:B,ReliquidacionEFACT!B",A11,",",L11,"!S:S)") -> SUMIF(EFACT_CNE!B:B,ReliquidacionEFACT!B11,EFACT_CNE!S:S) | N11: =CONCATENATE("SUMIF(",L11,"!B:B,ReliquidacionEFACT!B",A11,",",L11,"!T:T)") -> SUMIF(EFACT_CNE!B:B,ReliquidacionEFACT!B11,EFACT_CNE!T:T) | O11: =CONCATENATE("IFERROR((N",A11,"/M",A11,"),0)") -> IFERROR((N11/M11),0) | P11: =CONCATENATE("SUMIF(",L11,"!B:B,ReliquidacionEFACT!B",A11,",",L11,"!U:U)") -> SUMIF(EFACT_CNE!B:B,ReliquidacionEFACT!B11,EFACT_CNE!U:U) | Q11: =CONCATENATE("SUMIF(",L11,"!B:B,ReliquidacionEFACT!B",A11,",",L11,"!V:V)") -> SUMIF(EFACT_CNE!B:B,ReliquidacionEFACT!B11,EFACT_CNE!V:V) | R11: =CONCATENATE("IFERROR((Q",A11,"/P",A11,"),0)") -> IFERROR((Q11/P11),0) | S11: =CONCATENATE("(N",A11,"+Q",A11,")") -> (N11+Q11) | U11: 44166 | V11: =CONCATENATE("(S",A11,"-J",A11,")") -> (S11-J11) | W11: PNP_8T | X11: 44600 | Y11: 0.0328 | Z11: 44190 | AA11: =AA10 -> 44651 | AB11: =CONCATENATE("(AA",A11,"-Z",A11,")") -> (AA11-Z11) | AC11: =CONCATENATE("(1+Y",A11,")^(AB",A11,"/360)-1") -> (1+Y11)^(AB11/360)-1 | AD11: =CONCATENATE("(AC",A11,"*V",A11,")") -> (AC11*V11) | AE11: =CONCATENATE("(V",A11,"+AD",A11,")") -> (V11+AD11)
A12: =A11+1 -> 12 | B12: 44197 | C12: FACT_EMITIDA | D12: =CONCATENATE("SUMIF(",IF(C12="FACT_EMITIDA","SIGGE_E",C12),"!B:B,ReliquidacionEFACT!B",A12,",",IF(C12="FACT_EMITIDA","SIGGE_E",C12),"!S:S)") -> SUMIF(SIGGE_E!B:B,ReliquidacionEFACT!B12,SIGGE_E!S:S) | E12: =CONCATENATE("SUMIF(",IF(C12="FACT_EMITIDA","SIGGE_E",C12),"!B:B,ReliquidacionEFACT!B",A12,",",IF(C12="FACT_EMITIDA","SIGGE_E",C12),"!T:T)") -> SUMIF(SIGGE_E!B:B,ReliquidacionEFACT!B12,SIGGE_E!T:T) | F12: =CONCATENATE("IFERROR((E",A12,"/D",A12,"),0)") -> IFERROR((E12/D12),0) | G12: =CONCATENATE("SUMIF(",IF(C12="FACT_EMITIDA","SIGGE_P",C12),"!B:B,ReliquidacionEFACT!B",A12,",",IF(C12="FACT_EMITIDA","SIGGE_P",C12),"!U:U)") -> SUMIF(SIGGE_P!B:B,ReliquidacionEFACT!B12,SIGGE_P!U:U) | H12: =CONCATENATE("SUMIF(",IF(C12="FACT_EMITIDA","SIGGE_P",C12),"!B:B,ReliquidacionEFACT!B",A12,",",IF(C12="FACT_EMITIDA","SIGGE_P",C12),"!V:V)") -> SUMIF(SIGGE_P!B:B,ReliquidacionEFACT!B12,SIGGE_P!V:V) | I12: =CONCATENATE("IFERROR((H",A12,"/G",A12,"),0)") -> IFERROR((H12/G12),0) | J12: =CONCATENATE("(E",A12,"+H",A12,")") -> (E12+H12) | L12: =(MAPA_DATA!K5) -> EFACT_CNE | M12: =CONCATENATE("SUMIF(",L12,"!B:B,ReliquidacionEFACT!B",A12,",",L12,"!S:S)") -> SUMIF(EFACT_CNE!B:B,ReliquidacionEFACT!B12,EFACT_CNE!S:S) | N12: =CONCATENATE("SUMIF(",L12,"!B:B,ReliquidacionEFACT!B",A12,",",L12,"!T:T)") -> SUMIF(EFACT_CNE!B:B,ReliquidacionEFACT!B12,EFACT_CNE!T:T) | O12: =CONCATENATE("IFERROR((N",A12,"/M",A12,"),0)") -> IFERROR((N12/M12),0) | P12: =CONCATENATE("SUMIF(",L12,"!B:B,ReliquidacionEFACT!B",A12,",",L12,"!U:U)") -> SUMIF(EFACT_CNE!B:B,ReliquidacionEFACT!B12,EFACT_CNE!U:U) | Q12: =CONCATENATE("SUMIF(",L12,"!B:B,ReliquidacionEFACT!B",A12,",",L12,"!V:V)") -> SUMIF(EFACT_CNE!B:B,ReliquidacionEFACT!B12,EFACT_CNE!V:V) | R12: =CONCATENATE("IFERROR((Q",A12,"/P",A12,"),0)") -> IFERROR((Q12/P12),0) | S12: =CONCATENATE("(N",A12,"+Q",A12,")") -> (N12+Q12) | U12: 44197 | V12: =CONCATENATE("(S",A12,"-J",A12,")") -> (S12-J12) | W12: PNP_8T | X12: 44600 | Y12: 0.0328 | Z12: 44221 | AA12: =AA11 -> 44651 | AB12: =CONCATENATE("(AA",A12,"-Z",A12,")") -> (AA12-Z12) | AC12: =CONCATENATE("(1+Y",A12,")^(AB",A12,"/360)-1") -> (1+Y12)^(AB12/360)-1 | AD12: =CONCATENATE("(AC",A12,"*V",A12,")") -> (AC12*V12) | AE12: =CONCATENATE("(V",A12,"+AD",A12,")") -> (V12+AD12)
A13: =A12+1 -> 13 | B13: 44228 | C13: FACT_EMITIDA | D13: =CONCATENATE("SUMIF(",IF(C13="FACT_EMITIDA","SIGGE_E",C13),"!B:B,ReliquidacionEFACT!B",A13,",",IF(C13="FACT_EMITIDA","SIGGE_E",C13),"!S:S)") -> SUMIF(SIGGE_E!B:B,ReliquidacionEFACT!B13,SIGGE_E!S:S) | E13: =CONCATENATE("SUMIF(",IF(C13="FACT_EMITIDA","SIGGE_E",C13),"!B:B,ReliquidacionEFACT!B",A13,",",IF(C13="FACT_EMITIDA","SIGGE_E",C13),"!T:T)") -> SUMIF(SIGGE_E!B:B,ReliquidacionEFACT!B13,SIGGE_E!T:T) | F13: =CONCATENATE("IFERROR((E",A13,"/D",A13,"),0)") -> IFERROR((E13/D13),0) | G13: =CONCATENATE("SUMIF(",IF(C13="FACT_EMITIDA","SIGGE_P",C13),"!B:B,ReliquidacionEFACT!B",A13,",",IF(C13="FACT_EMITIDA","SIGGE_P",C13),"!U:U)") -> SUMIF(SIGGE_P!B:B,ReliquidacionEFACT!B13,SIGGE_P!U:U) | H13: =CONCATENATE("SUMIF(",IF(C13="FACT_EMITIDA","SIGGE_P",C13),"!B:B,ReliquidacionEFACT!B",A13,",",IF(C13="FACT_EMITIDA","SIGGE_P",C13),"!V:V)") -> SUMIF(SIGGE_P!B:B,ReliquidacionEFACT!B13,SIGGE_P!V:V) | I13: =CONCATENATE("IFERROR((H",A13,"/G",A13,"),0)") -> IFERROR((H13/G13),0) | J13: =CONCATENATE("(E",A13,"+H",A13,")") -> (E13+H13) | L13: =(MAPA_DATA!K6) -> EFACT_CNE | M13: =CONCATENATE("SUMIF(",L13,"!B:B,ReliquidacionEFACT!B",A13,",",L13,"!S:S)") -> SUMIF(EFACT_CNE!B:B,ReliquidacionEFACT!B13,EFACT_CNE!S:S) | N13: =CONCATENATE("SUMIF(",L13,"!B:B,ReliquidacionEFACT!B",A13,",",L13,"!T:T)") -> SUMIF(EFACT_CNE!B:B,ReliquidacionEFACT!B13,EFACT_CNE!T:T) | O13: =CONCATENATE("IFERROR((N",A13,"/M",A13,"),0)") -> IFERROR((N13/M13),0) | P13: =CONCATENATE("SUMIF(",L13,"!B:B,ReliquidacionEFACT!B",A13,",",L13,"!U:U)") -> SUMIF(EFACT_CNE!B:B,ReliquidacionEFACT!B13,EFACT_CNE!U:U) | Q13: =CONCATENATE("SUMIF(",L13,"!B:B,ReliquidacionEFACT!B",A13,",",L13,"!V:V)") -> SUMIF(EFACT_CNE!B:B,ReliquidacionEFACT!B13,EFACT_CNE!V:V) | R13: =CONCATENATE("IFERROR((Q",A13,"/P",A13,"),0)") -> IFERROR((Q13/P13),0) | S13: =CONCATENATE("(N",A13,"+Q",A13,")") -> (N13+Q13) | U13: 44228 | V13: =CONCATENATE("(S",A13,"-J",A13,")") -> (S13-J13) | W13: PNP_8T | X13: 44600 | Y13: 0.0328 | Z13: 44252 | AA13: =AA12 -> 44651 | AB13: =CONCATENATE("(AA",A13,"-Z",A13,")") -> (AA13-Z13) | AC13: =CONCATENATE("(1+Y",A13,")^(AB",A13,"/360)-1") -> (1+Y13)^(AB13/360)-1 | AD13: =CONCATENATE("(AC",A13,"*V",A13,")") -> (AC13*V13) | AE13: =CONCATENATE("(V",A13,"+AD",A13,")") -> (V13+AD13)
A14: =A13+1 -> 14 | B14: 44256 | C14: FACT_EMITIDA | D14: =CONCATENATE("SUMIF(",IF(C14="FACT_EMITIDA","SIGGE_E",C14),"!B:B,ReliquidacionEFACT!B",A14,",",IF(C14="FACT_EMITIDA","SIGGE_E",C14),"!S:S)") -> SUMIF(SIGGE_E!B:B,ReliquidacionEFACT!B14,SIGGE_E!S:S) | E14: =CONCATENATE("SUMIF(",IF(C14="FACT_EMITIDA","SIGGE_E",C14),"!B:B,ReliquidacionEFACT!B",A14,",",IF(C14="FACT_EMITIDA","SIGGE_E",C14),"!T:T)") -> SUMIF(SIGGE_E!B:B,ReliquidacionEFACT!B14,SIGGE_E!T:T) | F14: =CONCATENATE("IFERROR((E",A14,"/D",A14,"),0)") -> IFERROR((E14/D14),0) | G14: =CONCATENATE("SUMIF(",IF(C14="FACT_EMITIDA","SIGGE_P",C14),"!B:B,ReliquidacionEFACT!B",A14,",",IF(C14="FACT_EMITIDA","SIGGE_P",C14),"!U:U)") -> SUMIF(SIGGE_P!B:B,ReliquidacionEFACT!B14,SIGGE_P!U:U) | H14: =CONCATENATE("SUMIF(",IF(C14="FACT_EMITIDA","SIGGE_P",C14),"!B:B,ReliquidacionEFACT!B",A14,",",IF(C14="FACT_EMITIDA","SIGGE_P",C14),"!V:V)") -> SUMIF(SIGGE_P!B:B,ReliquidacionEFACT!B14,SIGGE_P!V:V) | I14: =CONCATENATE("IFERROR((H",A14,"/G",A14,"),0)") -> IFERROR((H14/G14),0) | J14: =CONCATENATE("(E",A14,"+H",A14,")") -> (E14+H14) | L14: =(MAPA_DATA!K7) -> EFACT_CNE | M14: =CONCATENATE("SUMIF(",L14,"!B:B,ReliquidacionEFACT!B",A14,",",L14,"!S:S)") -> SUMIF(EFACT_CNE!B:B,ReliquidacionEFACT!B14,EFACT_CNE!S:S) | N14: =CONCATENATE("SUMIF(",L14,"!B:B,ReliquidacionEFACT!B",A14,",",L14,"!T:T)") -> SUMIF(EFACT_CNE!B:B,ReliquidacionEFACT!B14,EFACT_CNE!T:T) | O14: =CONCATENATE("IFERROR((N",A14,"/M",A14,"),0)") -> IFERROR((N14/M14),0) | P14: =CONCATENATE("SUMIF(",L14,"!B:B,ReliquidacionEFACT!B",A14,",",L14,"!U:U)") -> SUMIF(EFACT_CNE!B:B,ReliquidacionEFACT!B14,EFACT_CNE!U:U) | Q14: =CONCATENATE("SUMIF(",L14,"!B:B,ReliquidacionEFACT!B",A14,",",L14,"!V:V)") -> SUMIF(EFACT_CNE!B:B,ReliquidacionEFACT!B14,EFACT_CNE!V:V) | R14: =CONCATENATE("IFERROR((Q",A14,"/P",A14,"),0)") -> IFERROR((Q14/P14),0) | S14: =CONCATENATE("(N",A14,"+Q",A14,")") -> (N14+Q14) | U14: 44256 | V14: =CONCATENATE("(S",A14,"-J",A14,")") -> (S14-J14) | W14: PNP_8T | X14: 44600 | Y14: 0.0328 | Z14: 44280 | AA14: =AA13 -> 44651 | AB14: =CONCATENATE("(AA",A14,"-Z",A14,")") -> (AA14-Z14) | AC14: =CONCATENATE("(1+Y",A14,")^(AB",A14,"/360)-1") -> (1+Y14)^(AB14/360)-1 | AD14: =CONCATENATE("(AC",A14,"*V",A14,")") -> (AC14*V14) | AE14: =CONCATENATE("(V",A14,"+AD",A14,")") -> (V14+AD14)
AD15: Reliquidación | AE15: =CONCATENATE("SUM(AE9:AE14)") -> SUM(AE9:AE14)
AC17: Montos a favor | AD17: LAP emite factura
AC18: Montos en contra | AD18: LAP emite nota de crédito

Sheet ReliquidacionCEN
A2: Generador | B2: [GX]
A3: Distribuidor | B3: [EEDD]
A4: Licitacion | B4: 2013/03-2° Llamado
A5: Bloque | B5: [BLOQUE]
C7: LO QUE SE FACTURÓ (VIGENTE) | L7: LO QUE SE DEBIÓ HABER FACTURADO (RELIQUIDADO) | U7: RELQUIDACIÓN Y CÁLCULO INTERESES
A8: ID | B8: MES | C8: ORIGEN DATA | D8: Energía (kWh) | E8: Monto Energía ($) | F8: $/kWh | G8: Potencia (kW) | H8: Monto Potencia ($) | I8: $/kW-mes | J8: Monto Total ($) | L8: ORIGEN DATA | M8: Energía (kWh) | N8: Monto Energía ($) | O8: $/kWh | P8: Potencia (kW) | Q8: Monto Potencia ($) | R8: $/kW-mes | S8: Monto Total ($) | U8: Mes | V8: Reliquidación mensual ($) | W8: Decreto PNP Reliquidación | X8: Fecha publicación Diario Oficial | Y8: Interés Anual | Z8: Fecha Facturación | AA8: Fecha Reliquidación | AB8: N° de días de intereses | AC8: Interés total según n° de días | AD8: Intereses ($) | AE8: Reliquidación Total ($)
A9: 9 | B9: 44105 | C9: FACT_EMITIDA | D9: =CONCATENATE("SUMIF(",IF(C9="FACT_EMITIDA","SIGGE_E",C9),"!B:B,ReliquidacionCEN!B",A9,",",IF(C9="FACT_EMITIDA","SIGGE_E",C9),"!S:S)") -> SUMIF(SIGGE_E!B:B,ReliquidacionCEN!B9,SIGGE_E!S:S) | E9: =CONCATENATE("SUMIF(",IF(C9="FACT_EMITIDA","SIGGE_E",C9),"!B:B,ReliquidacionCEN!B",A9,",",IF(C9="FACT_EMITIDA","SIGGE_E",C9),"!T:T)") -> SUMIF(SIGGE_E!B:B,ReliquidacionCEN!B9,SIGGE_E!T:T) | F9: =CONCATENATE("IFERROR((E",A9,"/D",A9,"),0)") -> IFERROR((E9/D9),0) | G9: =CONCATENATE("SUMIF(",IF(C9="FACT_EMITIDA","SIGGE_P",C9),"!B:B,ReliquidacionCEN!B",A9,",",IF(C9="FACT_EMITIDA","SIGGE_P",C9),"!U:U)") -> SUMIF(SIGGE_P!B:B,ReliquidacionCEN!B9,SIGGE_P!U:U) | H9: =CONCATENATE("SUMIF(",IF(C9="FACT_EMITIDA","SIGGE_P",C9),"!B:B,ReliquidacionCEN!B",A9,",",IF(C9="FACT_EMITIDA","SIGGE_P",C9),"!V:V)") -> SUMIF(SIGGE_P!B:B,ReliquidacionCEN!B9,SIGGE_P!V:V) | I9: =CONCATENATE("IFERROR((H",A9,"/G",A9,"),0)") -> IFERROR((H9/G9),0) | J9: =CONCATENATE("(E",A9,"+H",A9,")") -> (E9+H9) | L9: FACT_EST_CEN | M9: =CONCATENATE("SUMIF(",IF(L9="FACT_EST_CEN","CEN_Energia",L9),"!B:B,ReliquidacionCEN!B",A9,",",IF(L9="FACT_EST_CEN","CEN_Energia",L9),"!Z:Z)") -> SUMIF(CEN_Energia!B:B,ReliquidacionCEN!B9,CEN_Energia!Z:Z) | N9: =CONCATENATE("SUMIF(",IF(L9="FACT_EST_CEN","CEN_Energia",L9),"!B:B,ReliquidacionCEN!B",A9,",",IF(L9="FACT_EST_CEN","CEN_Energia",L9),"!BK:BK)") -> SUMIF(CEN_Energia!B:B,ReliquidacionCEN!B9,CEN_Energia!BK:BK) | O9: =CONCATENATE("IFERROR((N",A9,"/M",A9,"),0)") -> IFERROR((N9/M9),0) | P9: =CONCATENATE("SUMIF(",IF(L9="FACT_EST_CEN","CEN_Potencia",L9),"!B:B,ReliquidacionCEN!B",A9,",",IF(L9="FACT_EST_CEN","CEN_Potencia",L9),"!R:R)") -> SUMIF(CEN_Potencia!B:B,ReliquidacionCEN!B9,CEN_Potencia!R:R) | Q9: =CONCATENATE("SUMIF(",IF(L9="FACT_EST_CEN","CEN_Potencia",L9),"!B:B,ReliquidacionCEN!B",A9,",",IF(L9="FACT_EST_CEN","CEN_Potencia",L9),"!BC:BC)") -> SUMIF(CEN_Potencia!B:B,ReliquidacionCEN!B9,CEN_Potencia!BC:BC) | R9: =CONCATENATE("IFERROR((Q",A9,"/P",A9,"),0)") -> IFERROR((Q9/P9),0) | S9: =CONCATENATE("(N",A9,"+Q",A9,")") -> (N9+Q9) | U9: 44105 | V9: =CONCATENATE("(S",A9,"-J",A9,")") -> (S9-J9) | W9: PNP_8T | X9: 44600 | Y9: 0.0328 | Z9: 44129 | AA9: 44651 | AB9: =CONCATENATE("(AA",A9,"-Z",A9,")") -> (AA9-Z9) | AC9: =CONCATENATE("(1+Y",A9,")^(AB",A9,"/360)-1") -> (1+Y9)^(AB9/360)-1 | AD9: =CONCATENATE("(AC",A9,"*V",A9,")") -> (AC9*V9) | AE9: =CONCATENATE("(V",A9,"+AD",A9,")") -> (V9+AD9)
A10: =A9+1 -> 10 | B10: 44136 | C10: FACT_EMITIDA | D10: =CONCATENATE("SUMIF(",IF(C10="FACT_EMITIDA","SIGGE_E",C10),"!B:B,ReliquidacionCEN!B",A10,",",IF(C10="FACT_EMITIDA","SIGGE_E",C10),"!S:S)") -> SUMIF(SIGGE_E!B:B,ReliquidacionCEN!B10,SIGGE_E!S:S) | E10: =CONCATENATE("SUMIF(",IF(C10="FACT_EMITIDA","SIGGE_E",C10),"!B:B,ReliquidacionCEN!B",A10,",",IF(C10="FACT_EMITIDA","SIGGE_E",C10),"!T:T)") -> SUMIF(SIGGE_E!B:B,ReliquidacionCEN!B10,SIGGE_E!T:T) | F10: =CONCATENATE("IFERROR((E",A10,"/D",A10,"),0)") -> IFERROR((E10/D10),0) | G10: =CONCATENATE("SUMIF(",IF(C10="FACT_EMITIDA","SIGGE_P",C10),"!B:B,ReliquidacionCEN!B",A10,",",IF(C10="FACT_EMITIDA","SIGGE_P",C10),"!U:U)") -> SUMIF(SIGGE_P!B:B,ReliquidacionCEN!B10,SIGGE_P!U:U) | H10: =CONCATENATE("SUMIF(",IF(C10="FACT_EMITIDA","SIGGE_P",C10),"!B:B,ReliquidacionCEN!B",A10,",",IF(C10="FACT_EMITIDA","SIGGE_P",C10),"!V:V)") -> SUMIF(SIGGE_P!B:B,ReliquidacionCEN!B10,SIGGE_P!V:V) | I10: =CONCATENATE("IFERROR((H",A10,"/G",A10,"),0)") -> IFERROR((H10/G10),0) | J10: =CONCATENATE("(E",A10,"+H",A10,")") -> (E10+H10) | L10: FACT_EST_CEN | M10: =CONCATENATE("SUMIF(",IF(L10="FACT_EST_CEN","CEN_Energia",L10),"!B:B,ReliquidacionCEN!B",A10,",",IF(L10="FACT_EST_CEN","CEN_Energia",L10),"!Z:Z)") -> SUMIF(CEN_Energia!B:B,ReliquidacionCEN!B10,CEN_Energia!Z:Z) | N10: =CONCATENATE("SUMIF(",IF(L10="FACT_EST_CEN","CEN_Energia",L10),"!B:B,ReliquidacionCEN!B",A10,",",IF(L10="FACT_EST_CEN","CEN_Energia",L10),"!BK:BK)") -> SUMIF(CEN_Energia!B:B,ReliquidacionCEN!B10,CEN_Energia!BK:BK) | O10: =CONCATENATE("IFERROR((N",A10,"/M",A10,"),0)") -> IFERROR((N10/M10),0) | P10: =CONCATENATE("SUMIF(",IF(L10="FACT_EST_CEN","CEN_Potencia",L10),"!B:B,ReliquidacionCEN!B",A10,",",IF(L10="FACT_EST_CEN","CEN_Potencia",L10),"!R:R)") -> SUMIF(CEN_Potencia!B:B,ReliquidacionCEN!B10,CEN_Potencia!R:R) | Q10: =CONCATENATE("SUMIF(",IF(L10="FACT_EST_CEN","CEN_Potencia",L10),"!B:B,ReliquidacionCEN!B",A10,",",IF(L10="FACT_EST_CEN","CEN_Potencia",L10),"!BC:BC)") -> SUMIF(CEN_Potencia!B:B,ReliquidacionCEN!B10,CEN_Potencia!BC:BC) | R10: =CONCATENATE("IFERROR((Q",A10,"/P",A10,"),0)") -> IFERROR((Q10/P10),0) | S10: =CONCATENATE("(N",A10,"+Q",A10,")") -> (N10+Q10) | U10: 44136 | V10: =CONCATENATE("(S",A10,"-J",A10,")") -> (S10-J10) | W10: PNP_8T | X10: 44600 | Y10: 0.0328 | Z10: 44160 | AA10: =AA9 -> 44651 | AB10: =CONCATENATE("(AA",A10,"-Z",A10,")") -> (AA10-Z10) | AC10: =CONCATENATE("(1+Y",A10,")^(AB",A10,"/360)-1") -> (1+Y10)^(AB10/360)-1 | AD10: =CONCATENATE("(AC",A10,"*V",A10,")") -> (AC10*V10) | AE10: =CONCATENATE("(V",A10,"+AD",A10,")") -> (V10+AD10)
A11: =A10+1 -> 11 | B11: 44166 | C11: FACT_EMITIDA | D11: =CONCATENATE("SUMIF(",IF(C11="FACT_EMITIDA","SIGGE_E",C11),"!B:B,ReliquidacionCEN!B",A11,",",IF(C11="FACT_EMITIDA","SIGGE_E",C11),"!S:S)") -> SUMIF(SIGGE_E!B:B,ReliquidacionCEN!B11,SIGGE_E!S:S) | E11: =CONCATENATE("SUMIF(",IF(C11="FACT_EMITIDA","SIGGE_E",C11),"!B:B,ReliquidacionCEN!B",A11,",",IF(C11="FACT_EMITIDA","SIGGE_E",C11),"!T:T)") -> SUMIF(SIGGE_E!B:B,ReliquidacionCEN!B11,SIGGE_E!T:T) | F11: =CONCATENATE("IFERROR((E",A11,"/D",A11,"),0)") -> IFERROR((E11/D11),0) | G11: =CONCATENATE("SUMIF(",IF(C11="FACT_EMITIDA","SIGGE_P",C11),"!B:B,ReliquidacionCEN!B",A11,",",IF(C11="FACT_EMITIDA","SIGGE_P",C11),"!U:U)") -> SUMIF(SIGGE_P!B:B,ReliquidacionCEN!B11,SIGGE_P!U:U) | H11: =CONCATENATE("SUMIF(",IF(C11="FACT_EMITIDA","SIGGE_P",C11),"!B:B,ReliquidacionCEN!B",A11,",",IF(C11="FACT_EMITIDA","SIGGE_P",C11),"!V:V)") -> SUMIF(SIGGE_P!B:B,ReliquidacionCEN!B11,SIGGE_P!V:V) | I11: =CONCATENATE("IFERROR((H",A11,"/G",A11,"),0)") -> IFERROR((H11/G11),0) | J11: =CONCATENATE("(E",A11,"+H",A11,")") -> (E11+H11) | L11: FACT_EST_CEN | M11: =CONCATENATE("SUMIF(",IF(L11="FACT_EST_CEN","CEN_Energia",L11),"!B:B,ReliquidacionCEN!B",A11,",",IF(L11="FACT_EST_CEN","CEN_Energia",L11),"!Z:Z)") -> SUMIF(CEN_Energia!B:B,ReliquidacionCEN!B11,CEN_Energia!Z:Z) | N11: =CONCATENATE("SUMIF(",IF(L11="FACT_EST_CEN","CEN_Energia",L11),"!B:B,ReliquidacionCEN!B",A11,",",IF(L11="FACT_EST_CEN","CEN_Energia",L11),"!BK:BK)") -> SUMIF(CEN_Energia!B:B,ReliquidacionCEN!B11,CEN_Energia!BK:BK) | O11: =CONCATENATE("IFERROR((N",A11,"/M",A11,"),0)") -> IFERROR((N11/M11),0) | P11: =CONCATENATE("SUMIF(",IF(L11="FACT_EST_CEN","CEN_Potencia",L11),"!B:B,ReliquidacionCEN!B",A11,",",IF(L11="FACT_EST_CEN","CEN_Potencia",L11),"!R:R)") -> SUMIF(CEN_Potencia!B:B,ReliquidacionCEN!B11,CEN_Potencia!R:R) | Q11: =CONCATENATE("SUMIF(",IF(L11="FACT_EST_CEN","CEN_Potencia",L11),"!B:B,ReliquidacionCEN!B",A11,",",IF(L11="FACT_EST_CEN","CEN_Potencia",L11),"!BC:BC)") -> SUMIF(CEN_Potencia!B:B,ReliquidacionCEN!B11,CEN_Potencia!BC:BC) | R11: =CONCATENATE("IFERROR((Q",A11,"/P",A11,"),0)") -> IFERROR((Q11/P11),0) | S11: =CONCATENATE("(N",A11,"+Q",A11,")") -> (N11+Q11) | U11: 44166 | V11: =CONCATENATE("(S",A11,"-J",A11,")") -> (S11-J11) | W11: PNP_8T | X11: 44600 | Y11: 0.0328 | Z11: 44190 | AA11: =AA10 -> 44651 | AB11: =CONCATENATE("(AA",A11,"-Z",A11,")") -> (AA11-Z11) | AC11: =CONCATENATE("(1+Y",A11,")^(AB",A11,"/360)-1") -> (1+Y11)^(AB11/360)-1 | AD11: =CONCATENATE("(AC",A11,"*V",A11,")") -> (AC11*V11) | AE11: =CONCATENATE("(V",A11,"+AD",A11,")") -> (V11+AD11)
A12: =A11+1 -> 12 | B12: 44197 | C12: FACT_EMITIDA | D12: =CONCATENATE("SUMIF(",IF(C12="FACT_EMITIDA","SIGGE_E",C12),"!B:B,ReliquidacionCEN!B",A12,",",IF(C12="FACT_EMITIDA","SIGGE_E",C12),"!S:S)") -> SUMIF(SIGGE_E!B:B,ReliquidacionCEN!B12,SIGGE_E!S:S) | E12: =CONCATENATE("SUMIF(",IF(C12="FACT_EMITIDA","SIGGE_E",C12),"!B:B,ReliquidacionCEN!B",A12,",",IF(C12="FACT_EMITIDA","SIGGE_E",C12),"!T:T)") -> SUMIF(SIGGE_E!B:B,ReliquidacionCEN!B12,SIGGE_E!T:T) | F12: =CONCATENATE("IFERROR((E",A12,"/D",A12,"),0)") -> IFERROR((E12/D12),0) | G12: =CONCATENATE("SUMIF(",IF(C12="FACT_EMITIDA","SIGGE_P",C12),"!B:B,ReliquidacionCEN!B",A12,",",IF(C12="FACT_EMITIDA","SIGGE_P",C12),"!U:U)") -> SUMIF(SIGGE_P!B:B,ReliquidacionCEN!B12,SIGGE_P!U:U) | H12: =CONCATENATE("SUMIF(",IF(C12="FACT_EMITIDA","SIGGE_P",C12),"!B:B,ReliquidacionCEN!B",A12,",",IF(C12="FACT_EMITIDA","SIGGE_P",C12),"!V:V)") -> SUMIF(SIGGE_P!B:B,ReliquidacionCEN!B12,SIGGE_P!V:V) | I12: =CONCATENATE("IFERROR((H",A12,"/G",A12,"),0)") -> IFERROR((H12/G12),0) | J12: =CONCATENATE("(E",A12,"+H",A12,")") -> (E12+H12) | L12: FACT_EST_CEN | M12: =CONCATENATE("SUMIF(",IF(L12="FACT_EST_CEN","CEN_Energia",L12),"!B:B,ReliquidacionCEN!B",A12,",",IF(L12="FACT_EST_CEN","CEN_Energia",L12),"!Z:Z)") -> SUMIF(CEN_Energia!B:B,ReliquidacionCEN!B12,CEN_Energia!Z:Z) | N12: =CONCATENATE("SUMIF(",IF(L12="FACT_EST_CEN","CEN_Energia",L12),"!B:B,ReliquidacionCEN!B",A12,",",IF(L12="FACT_EST_CEN","CEN_Energia",L12),"!BK:BK)") -> SUMIF(CEN_Energia!B:B,ReliquidacionCEN!B12,CEN_Energia!BK:BK) | O12: =CONCATENATE("IFERROR((N",A12,"/M",A12,"),0)") -> IFERROR((N12/M12),0) | P12: =CONCATENATE("SUMIF(",IF(L12="FACT_EST_CEN","CEN_Potencia",L12),"!B:B,ReliquidacionCEN!B",A12,",",IF(L12="FACT_EST_CEN","CEN_Potencia",L12),"!R:R)") -> SUMIF(CEN_Potencia!B:B,ReliquidacionCEN!B12,CEN_Potencia!R:R) | Q12: =CONCATENATE("SUMIF(",IF(L12="FACT_EST_CEN","CEN_Potencia",L12),"!B:B,ReliquidacionCEN!B",A12,",",IF(L12="FACT_EST_CEN","CEN_Potencia",L12),"!BC:BC)") -> SUMIF(CEN_Potencia!B:B,ReliquidacionCEN!B12,CEN_Potencia!BC:BC) | R12: =CONCATENATE("IFERROR((Q",A12,"/P",A12,"),0)") -> IFERROR((Q12/P12),0) | S12: =CONCATENATE("(N",A12,"+Q",A12,")") -> (N12+Q12) | U12: 44197 | V12: =CONCATENATE("(S",A12,"-J",A12,")") -> (S12-J12) | W12: PNP_8T | X12: 44600 | Y12: 0.0328 | Z12: 44221 | AA12: =AA11 -> 44651 | AB12: =CONCATENATE("(AA",A12,"-Z",A12,")") -> (AA12-Z12) | AC12: =CONCATENATE("(1+Y",A12,")^(AB",A12,"/360)-1") -> (1+Y12)^(AB12/360)-1 | AD12: =CONCATENATE("(AC",A12,"*V",A12,")") -> (AC12*V12) | AE12: =CONCATENATE("(V",A12,"+AD",A12,")") -> (V12+AD12)
A13: =A12+1 -> 13 | B13: 44228 | C13: FACT_EMITIDA | D13: =CONCATENATE("SUMIF(",IF(C13="FACT_EMITIDA","SIGGE_E",C13),"!B:B,ReliquidacionCEN!B",A13,",",IF(C13="FACT_EMITIDA","SIGGE_E",C13),"!S:S)") -> SUMIF(SIGGE_E!B:B,ReliquidacionCEN!B13,SIGGE_E!S:S) | E13: =CONCATENATE("SUMIF(",IF(C13="FACT_EMITIDA","SIGGE_E",C13),"!B:B,ReliquidacionCEN!B",A13,",",IF(C13="FACT_EMITIDA","SIGGE_E",C13),"!T:T)") -> SUMIF(SIGGE_E!B:B,ReliquidacionCEN!B13,SIGGE_E!T:T) | F13: =CONCATENATE("IFERROR((E",A13,"/D",A13,"),0)") -> IFERROR((E13/D13),0) | G13: =CONCATENATE("SUMIF(",IF(C13="FACT_EMITIDA","SIGGE_P",C13),"!B:B,ReliquidacionCEN!B",A13,",",IF(C13="FACT_EMITIDA","SIGGE_P",C13),"!U:U)") -> SUMIF(SIGGE_P!B:B,ReliquidacionCEN!B13,SIGGE_P!U:U) | H13: =CONCATENATE("SUMIF(",IF(C13="FACT_EMITIDA","SIGGE_P",C13),"!B:B,ReliquidacionCEN!B",A13,",",IF(C13="FACT_EMITIDA","SIGGE_P",C13),"!V:V)") -> SUMIF(SIGGE_P!B:B,ReliquidacionCEN!B13,SIGGE_P!V:V) | I13: =CONCATENATE("IFERROR((H",A13,"/G",A13,"),0)") -> IFERROR((H13/G13),0) | J13: =CONCATENATE("(E",A13,"+H",A13,")") -> (E13+H13) | L13: FACT_EST_CEN | M13: =CONCATENATE("SUMIF(",IF(L13="FACT_EST_CEN","CEN_Energia",L13),"!B:B,ReliquidacionCEN!B",A13,",",IF(L13="FACT_EST_CEN","CEN_Energia",L13),"!Z:Z)") -> SUMIF(CEN_Energia!B:B,ReliquidacionCEN!B13,CEN_Energia!Z:Z) | N13: =CONCATENATE("SUMIF(",IF(L13="FACT_EST_CEN","CEN_Energia",L13),"!B:B,ReliquidacionCEN!B",A13,",",IF(L13="FACT_EST_CEN","CEN_Energia",L13),"!BK:BK)") -> SUMIF(CEN_Energia!B:B,ReliquidacionCEN!B13,CEN_Energia!BK:BK) | O13: =CONCATENATE("IFERROR((N",A13,"/M",A13,"),0)") -> IFERROR((N13/M13),0) | P13: =CONCATENATE("SUMIF(",IF(L13="FACT_EST_CEN","CEN_Potencia",L13),"!B:B,ReliquidacionCEN!B",A13,",",IF(L13="FACT_EST_CEN","CEN_Potencia",L13),"!R:R)") -> SUMIF(CEN_Potencia!B:B,ReliquidacionCEN!B13,CEN_Potencia!R:R) | Q13: =CONCATENATE("SUMIF(",IF(L13="FACT_EST_CEN","CEN_Potencia",L13),"!B:B,ReliquidacionCEN!B",A13,",",IF(L13="FACT_EST_CEN","CEN_Potencia",L13),"!BC:BC)") -> SUMIF(CEN_Potencia!B:B,ReliquidacionCEN!B13,CEN_Potencia!BC:BC) | R13: =CONCATENATE("IFERROR((Q",A13,"/P",A13,"),0)") -> IFERROR((Q13/P13),0) | S13: =CONCATENATE("(N",A13,"+Q",A13,")") -> (N13+Q13) | U13: 44228 | V13: =CONCATENATE("(S",A13,"-J",A13,")") -> (S13-J13) | W13: PNP_8T | X13: 44600 | Y13: 0.0328 | Z13: 44252 | AA13: =AA12 -> 44651 | AB13: =CONCATENATE("(AA",A13,"-Z",A13,")") -> (AA13-Z13) | AC13: =CONCATENATE("(1+Y",A13,")^(AB",A13,"/360)-1") -> (1+Y13)^(AB13/360)-1 | AD13: =CONCATENATE("(AC",A13,"*V",A13,")") -> (AC13*V13) | AE13: =CONCATENATE("(V",A13,"+AD",A13,")") -> (V13+AD13)
A14: =A13+1 -> 14 | B14: 44256 | C14: FACT_EMITIDA | D14: =CONCATENATE("SUMIF(",IF(C14="FACT_EMITIDA","SIGGE_E",C14),"!B:B,ReliquidacionCEN!B",A14,",",IF(C14="FACT_EMITIDA","SIGGE_E",C14),"!S:S)") -> SUMIF(SIGGE_E!B:B,ReliquidacionCEN!B14,SIGGE_E!S:S) | E14: =CONCATENATE("SUMIF(",IF(C14="FACT_EMITIDA","SIGGE_E",C14),"!B:B,ReliquidacionCEN!B",A14,",",IF(C14="FACT_EMITIDA","SIGGE_E",C14),"!T:T)") -> SUMIF(SIGGE_E!B:B,ReliquidacionCEN!B14,SIGGE_E!T:T) | F14: =CONCATENATE("IFERROR((E",A14,"/D",A14,"),0)") -> IFERROR((E14/D14),0) | G14: =CONCATENATE("SUMIF(",IF(C14="FACT_EMITIDA","SIGGE_P",C14),"!B:B,ReliquidacionCEN!B",A14,",",IF(C14="FACT_EMITIDA","SIGGE_P",C14),"!U:U)") -> SUMIF(SIGGE_P!B:B,ReliquidacionCEN!B14,SIGGE_P!U:U) | H14: =CONCATENATE("SUMIF(",IF(C14="FACT_EMITIDA","SIGGE_P",C14),"!B:B,ReliquidacionCEN!B",A14,",",IF(C14="FACT_EMITIDA","SIGGE_P",C14),"!V:V)") -> SUMIF(SIGGE_P!B:B,ReliquidacionCEN!B14,SIGGE_P!V:V) | I14: =CONCATENATE("IFERROR((H",A14,"/G",A14,"),0)") -> IFERROR((H14/G14),0) | J14: =CONCATENATE("(E",A14,"+H",A14,")") -> (E14+H14) | L14: FACT_EST_CEN | M14: =CONCATENATE("SUMIF(",IF(L14="FACT_EST_CEN","CEN_Energia",L14),"!B:B,ReliquidacionCEN!B",A14,",",IF(L14="FACT_EST_CEN","CEN_Energia",L14),"!Z:Z)") -> SUMIF(CEN_Energia!B:B,ReliquidacionCEN!B14,CEN_Energia!Z:Z) | N14: =CONCATENATE("SUMIF(",IF(L14="FACT_EST_CEN","CEN_Energia",L14),"!B:B,ReliquidacionCEN!B",A14,",",IF(L14="FACT_EST_CEN","CEN_Energia",L14),"!BK:BK)") -> SUMIF(CEN_Energia!B:B,ReliquidacionCEN!B14,CEN_Energia!BK:BK) | O14: =CONCATENATE("IFERROR((N",A14,"/M",A14,"),0)") -> IFERROR((N14/M14),0) | P14: =CONCATENATE("SUMIF(",IF(L14="FACT_EST_CEN","CEN_Potencia",L14),"!B:B,ReliquidacionCEN!B",A14,",",IF(L14="FACT_EST_CEN","CEN_Potencia",L14),"!R:R)") -> SUMIF(CEN_Potencia!B:B,ReliquidacionCEN!B14,CEN_Potencia!R:R) | Q14: =CONCATENATE("SUMIF(",IF(L14="FACT_EST_CEN","CEN_Potencia",L14),"!B:B,ReliquidacionCEN!B",A14,",",IF(L14="FACT_EST_CEN","CEN_Potencia",L14),"!BC:BC)") -> SUMIF(CEN_Potencia!B:B,ReliquidacionCEN!B14,CEN_Potencia!BC:BC) | R14: =CONCATENATE("IFERROR((Q",A14,"/P",A14,"),0)") -> IFERROR((Q14/P14),0) | S14: =CONCATENATE("(N",A14,"+Q",A14,")") -> (N14+Q14) | U14: 44256 | V14: =CONCATENATE("(S",A14,"-J",A14,")") -> (S14-J14) | W14: PNP_8T | X14: 44600 | Y14: 0.0328 | Z14: 44280 | AA14: =AA13 -> 44651 | AB14: =CONCATENATE("(AA",A14,"-Z",A14,")") -> (AA14-Z14) | AC14: =CONCATENATE("(1+Y",A14,")^(AB",A14,"/360)-1") -> (1+Y14)^(AB14/360)-1 | AD14: =CONCATENATE("(AC",A14,"*V",A14,")") -> (AC14*V14) | AE14: =CONCATENATE("(V",A14,"+AD",A14,")") -> (V14+AD14)
AD15: Reliquidación | AE15: =CONCATENATE("SUM(AE9:AE14)") -> SUM(AE9:AE14)
AC17: Montos a favor | AD17: LAP emite factura
AC18: Montos en contra | AD18: LAP emite nota de crédito

Sheet ResumenRetiros
A2: Generador | B2: [GX]
A3: Distribuidor | B3: [EEDD]
A4: Licitacion | B4: 2013/03-2° Llamado
A5: Bloque | B5: [BLOQUE]
A8: ID | B8: MES | C8: ORIGEN DATA | D8: Energía SIGGE (kWh) | E8: Energía EFACT AT (kWh) | F8: Energía EFACT BT (kWh) | G8: Energía Coordinador AT (kWh) | H8: Energía Coordinador BT (kWh)
A9: 9 | B9: 44105 | C9: FACT_EMITIDA | D9: =CONCATENATE("SUMIF(","SIGGE_E!B:B,ResumenRetiros!B",A9,",","SIGGE_E","!S:S)") -> SUMIF(SIGGE_E!B:B,ResumenRetiros!B9,SIGGE_E!S:S) | E9: =CONCATENATE("SUMIF(","EFACT_CNE","!B:B,ResumenRetiros!B",A9,",","EFACT_CNE","!S:S)") -> SUMIF(EFACT_CNE!B:B,ResumenRetiros!B9,EFACT_CNE!S:S) | F9: =CONCATENATE("SUMIF(","EfactCNE_BT","!B:B,ResumenRetiros!B",A9,",","EfactCNE_BT","!M:M)") -> SUMIF(EfactCNE_BT!B:B,ResumenRetiros!B9,EfactCNE_BT!M:M) | G9: =CONCATENATE("SUMIF(CEN_Energia!B:B,ResumenRetiros!B",A9,",CEN_Energia!Z:Z)") -> SUMIF(CEN_Energia!B:B,ResumenRetiros!B9,CEN_Energia!Z:Z) | H9: =CONCATENATE("SUMIF(CEN_EnergiaBT!B:B,ResumenRetiros!B",A9,",CEN_EnergiaBT!K:K)") -> SUMIF(CEN_EnergiaBT!B:B,ResumenRetiros!B9,CEN_EnergiaBT!K:K)
A10: =A9+1 -> 10 | B10: 44136 | C10: FACT_EMITIDA | D10: =CONCATENATE("SUMIF(","SIGGE_E!B:B,ResumenRetiros!B",A10,",","SIGGE_E","!S:S)") -> SUMIF(SIGGE_E!B:B,ResumenRetiros!B10,SIGGE_E!S:S) | E10: =CONCATENATE("SUMIF(","EFACT_CNE","!B:B,ResumenRetiros!B",A10,",","EFACT_CNE","!S:S)") -> SUMIF(EFACT_CNE!B:B,ResumenRetiros!B10,EFACT_CNE!S:S) | F10: =CONCATENATE("SUMIF(","EfactCNE_BT","!B:B,ResumenRetiros!B",A10,",","EfactCNE_BT","!M:M)") -> SUMIF(EfactCNE_BT!B:B,ResumenRetiros!B10,EfactCNE_BT!M:M) | G10: =CONCATENATE("SUMIF(CEN_Energia!B:B,ResumenRetiros!B",A10,",CEN_Energia!Z:Z)") -> SUMIF(CEN_Energia!B:B,ResumenRetiros!B10,CEN_Energia!Z:Z) | H10: =CONCATENATE("SUMIF(CEN_EnergiaBT!B:B,ResumenRetiros!B",A10,",CEN_EnergiaBT!K:K)") -> SUMIF(CEN_EnergiaBT!B:B,ResumenRetiros!B10,CEN_EnergiaBT!K:K)
A11: =A10+1 -> 11 | B11: 44166 | C11: FACT_EMITIDA | D11: =CONCATENATE("SUMIF(","SIGGE_E!B:B,ResumenRetiros!B",A11,",","SIGGE_E","!S:S)") -> SUMIF(SIGGE_E!B:B,ResumenRetiros!B11,SIGGE_E!S:S) | E11: =CONCATENATE("SUMIF(","EFACT_CNE","!B:B,ResumenRetiros!B",A11,",","EFACT_CNE","!S:S)") -> SUMIF(EFACT_CNE!B:B,ResumenRetiros!B11,EFACT_CNE!S:S) | F11: =CONCATENATE("SUMIF(","EfactCNE_BT","!B:B,ResumenRetiros!B",A11,",","EfactCNE_BT","!M:M)") -> SUMIF(EfactCNE_BT!B:B,ResumenRetiros!B11,EfactCNE_BT!M:M) | G11: =CONCATENATE("SUMIF(CEN_Energia!B:B,ResumenRetiros!B",A11,",CEN_Energia!Z:Z)") -> SUMIF(CEN_Energia!B:B,ResumenRetiros!B11,CEN_Energia!Z:Z) | H11: =CONCATENATE("SUMIF(CEN_EnergiaBT!B:B,ResumenRetiros!B",A11,",CEN_EnergiaBT!K:K)") -> SUMIF(CEN_EnergiaBT!B:B,ResumenRetiros!B11,CEN_EnergiaBT!K:K)
A12: =A11+1 -> 12 | B12: 44197 | C12: FACT_EMITIDA | D12: =CONCATENATE("SUMIF(","SIGGE_E!B:B,ResumenRetiros!B",A12,",","SIGGE_E","!S:S)") -> SUMIF(SIGGE_E!B:B,ResumenRetiros!B12,SIGGE_E!S:S) | E12: =CONCATENATE("SUMIF(","EFACT_CNE","!B:B,ResumenRetiros!B",A12,",","EFACT_CNE","!S:S)") -> SUMIF(EFACT_CNE!B:B,ResumenRetiros!B12,EFACT_CNE!S:S) | F12: =CONCATENATE("SUMIF(","EfactCNE_BT","!B:B,ResumenRetiros!B",A12,",","EfactCNE_BT","!M:M)") -> SUMIF(EfactCNE_BT!B:B,ResumenRetiros!B12,EfactCNE_BT!M:M) | G12: =CONCATENATE("SUMIF(CEN_Energia!B:B,ResumenRetiros!B",A12,",CEN_Energia!Z:Z)") -> SUMIF(CEN_Energia!B:B,ResumenRetiros!B12,CEN_Energia!Z:Z) | H12: =CONCATENATE("SUMIF(CEN_EnergiaBT!B:B,ResumenRetiros!B",A12,",CEN_EnergiaBT!K:K)") -> SUMIF(CEN_EnergiaBT!B:B,ResumenRetiros!B12,CEN_EnergiaBT!K:K)
A13: =A12+1 -> 13 | B13: 44228 | C13: FACT_EMITIDA | D13: =CONCATENATE("SUMIF(","SIGGE_E!B:B,ResumenRetiros!B",A13,",","SIGGE_E","!S:S)") -> SUMIF(SIGGE_E!B:B,ResumenRetiros!B13,SIGGE_E!S:S) | E13: =CONCATENATE("SUMIF(","EFACT_CNE","!B:B,ResumenRetiros!B",A13,",","EFACT_CNE","!S:S)") -> SUMIF(EFACT_CNE!B:B,ResumenRetiros!B13,EFACT_CNE!S:S) | F13: =CONCATENATE("SUMIF(","EfactCNE_BT","!B:B,ResumenRetiros!B",A13,",","EfactCNE_BT","!M:M)") -> SUMIF(EfactCNE_BT!B:B,ResumenRetiros!B13,EfactCNE_BT!M:M) | G13: =CONCATENATE("SUMIF(CEN_Energia!B:B,ResumenRetiros!B",A13,",CEN_Energia!Z:Z)") -> SUMIF(CEN_Energia!B:B,ResumenRetiros!B13,CEN_Energia!Z:Z) | H13: =CONCATENATE("SUMIF(CEN_EnergiaBT!B:B,ResumenRetiros!B",A13,",CEN_EnergiaBT!K:K)") -> SUMIF(CEN_EnergiaBT!B:B,ResumenRetiros!B13,CEN_EnergiaBT!K:K)
A14: =A13+1 -> 14 | B14: 44256 | C14: FACT_EMITIDA | D14: =CONCATENATE("SUMIF(","SIGGE_E!B:B,ResumenRetiros!B",A14,",","SIGGE_E","!S:S)") -> SUMIF(SIGGE_E!B:B,ResumenRetiros!B14,SIGGE_E!S:S) | E14: =CONCATENATE("SUMIF(","EFACT_CNE","!B:B,ResumenRetiros!B",A14,",","EFACT_CNE","!S:S)") -> SUMIF(EFACT_CNE!B:B,ResumenRetiros!B14,EFACT_CNE!S:S) | F14: =CONCATENATE("SUMIF(","EfactCNE_BT","!B:B,ResumenRetiros!B",A14,",","EfactCNE_BT","!M:M)") -> SUMIF(EfactCNE_BT!B:B,ResumenRetiros!B14,EfactCNE_BT!M:M) | G14: =CONCATENATE("SUMIF(CEN_Energia!B:B,ResumenRetiros!B",A14,",CEN_Energia!Z:Z)") -> SUMIF(CEN_Energia!B:B,ResumenRetiros!B14,CEN_Energia!Z:Z) | H14: =CONCATENATE("SUMIF(CEN_EnergiaBT!B:B,ResumenRetiros!B",A14,",CEN_EnergiaBT!K:K)") -> SUMIF(CEN_EnergiaBT!B:B,ResumenRetiros!B14,CEN_EnergiaBT!K:K)
D15: =CONCATENATE("SUM(D9:D14)") -> SUM(D9:D14) | E15: =CONCATENATE("SUM(E9:E14)") -> SUM(E9:E14) | F15: =CONCATENATE("SUM(F9:F14)") -> SUM(F9:F14) | G15: =CONCATENATE("SUM(G9:G14)") -> SUM(G9:G14) | H15: =CONCATENATE("SUM(H9:H14)") -> SUM(H9:H14)

Sheet FACT_EMITIDA
A1: Periodo | B1: MesDevengado | C1: Nombre | D1: Concepto | E1: Agrupacion | F1: Glosa | G1: FechaCarga | H1: TipoDocumento | I1: Folio | J1: Vendedor | K1: Comprador | L1: Bloque | M1: Empresa | N1: ClaveEEDD | O1: Licitacion | P1: NomAgrupacion | Q1: Num | R1: Barra | S1: Energia | T1: PrecioEnergia | U1: Potencia | V1: PrecioPotencia | W1: Monto
A2: 43344 | B2: 43344 | C2: Licitación Caren y Cec (SIC 2013/03-2) BS1A | D2: Energia Licitaciones | E2: Energía | F2: Lic. SIC 2013/03-2 bloques BS1A: Energía sep 2018 | G2: 43392 | H2: 33 | I2: 6305 | J2: s | K2: s | L2: BS1A | M2: Caren | N2: Cec | O2: 41335 | P2: CEC | Q2: 1 | R2: TotalBarras | S2: 3000 | T2: 58.085 | U2: NULL | V2: NULL | W2: 174255
A3: 43374 | B3: 43374 | C3: Licitación Caren y Cec (SIC 2013/03-2) BS1A | D3: Energia Licitaciones | E3: Energía | F3: Lic. SIC 2013/03-2 bloques BS1A: Energía oct 2018 | G3: 43431 | H3: 33 | I3: 6796 | J3: s | K3: s | L3: BS1A | M3: Caren | N3: Cec | O3: 41335 | P3: CEC | Q3: 1 | R3: TotalBarras | S3: 3000 | T3: 59.678 | U3: NULL | V3: NULL | W3: 179035
A4: 43405 | B4: 43405 | C4: Licitación Caren y Cec (SIC 2013/03-2) BS1A | D4: Energia Licitaciones | E4: Energía | F4: Lic. SIC 2013/03-2 bloques BS1A: Energía nov 2018 | G4: 43448 | H4: 33 | I4: 6939 | J4: s | K4: s | L4: BS1A | M4: Caren | N4: Cec | O4: 41335 | P4: CEC | Q4: 1 | R4: TotalBarras | S4: 4000 | T4: 59.635 | U4: NULL | V4: NULL | W4: 238540
A5: 43435 | B5: 43435 | C5: Licitación Caren y Cec (SIC 2013/03-2) BS1A | D5: Energia Licitaciones | E5: Energía | F5: Lic. SIC 2013/03-2 bloques BS1A: Energía dic 2018 | G5: 43486 | H5: 33 | I5: 7194 | J5: s | K5: s | L5: BS1A | M5: Caren | N5: Cec | O5: 41335 | P5: CEC | Q5: 1 | R5: TotalBarras | S5: 5000 | T5: 67.951 | U5: NULL | V5: NULL | W5: 339757
A6: 43466 | B6: 43466 | C6: Licitación Caren y Cec (SIC 2013/03-2) BS1A | D6: Reliq. Energia Licitaciones | E6: Energía | F6: Lic. SIC 2013/03-2 bloques BS1A: Reliq. Energía ene 2019 | G6: 43539 | H6: 33 | I6: NULL | J6: s | K6: s | L6: BS1A | M6: Caren | N6: Cec | O6: 41335 | P6: CEC | Q6: 1 | R6: A.JAHUEL 220 | S6: 1.46188 | T6: 66.9 | U6: NULL | V6: NULL | W6: 98
A7: 43466 | B7: 43466 | C7: Licitación Caren y Cec (SIC 2013/03-2) BS1A | D7: Energia Licitaciones | E7: Energía | F7: Lic. SIC 2013/03-2 bloques BS1A: Energía ene 2019 | G7: 43504 | H7: 33 | I7: 7513 | J7: s | K7: s | L7: BS1A | M7: Caren | N7: Cec | O7: 41335 | P7: CEC | Q7: 1 | R7: A.JAHUEL 220 | S7: 1371.306 | T7: 66.9 | U7: NULL | V7: NULL | W7: 91740
A8: 43466 | B8: 43466 | C8: Licitación Caren y Cec (SIC 2013/03-2) BS1A | D8: Reliq. Energia Licitaciones | E8: Energía | F8: Lic. SIC 2013/03-2 bloques BS1A: Reliq. Energía ene 2019 | G8: 43539 | H8: 33 | I8: NULL | J8: s | K8: s | L8: BS1A | M8: Caren | N8: Cec | O8: 41335 | P8: CEC | Q8: 2 | R8: A.MELIP 220 | S8: 0.009388 | T8: 69.014 | U8: NULL | V8: NULL | W8: 1
A9: 43466 | B9: 43466 | C9: Licitación Caren y Cec (SIC 2013/03-2) BS1A | D9: Energia Licitaciones | E9: Energía | F9: Lic. SIC 2013/03-2 bloques BS1A: Energía ene 2019 | G9: 43504 | H9: 33 | I9: 7513 | J9: s | K9: s | L9: BS1A | M9: Caren | N9: Cec | O9: 41335 | P9: CEC | Q9: 2 | R9: A.MELIP 220 | S9: 8.806166 | T9: 69.014 | U9: NULL | V9: NULL | W9: 608
A10: 43466 | B10: 43466 | C10: Licitación Caren y Cec (SIC 2013/03-2) BS1A | D10: Reliq. Energia Licitaciones | E10: Energía | F10: Lic. SIC 2013/03-2 bloques BS1A: Reliq. Energía ene 2019 | G10: 43539 | H10: 33 | I10: NULL | J10: s | K10: s | L10: BS1A | M10: Caren | N10: Cec | O10: 41335 | P10: CEC | Q10: 3 | R10: CHARRUA 220 | S10: 0.453721 | T10: 63.27 | U10: NULL | V10: NULL | W10: 29
A11: 43466 | B11: 43466 | C11: Licitación Caren y Cec (SIC 2013/03-2) BS1A | D11: Energia Licitaciones | E11: Energía | F11: Lic. SIC 2013/03-2 bloques BS1A: Energía ene 2019 | G11: 43504 | H11: 33 | I11: 7513 | J11: s | K11: s | L11: BS1A | M11: Caren | N11: Cec | O11: 41335 | P11: CEC | Q11: 3 | R11: CHARRUA 220 | S11: 425.60961 | T11: 63.27 | U11: NULL | V11: NULL | W11: 26928
A12: 43466 | B12: 43466 | C12: Licitación Caren y Cec (SIC 2013/03-2) BS1A | D12: Reliq. Energia Licitaciones | E12: Energía | F12: Lic. SIC 2013/03-2 bloques BS1A: Reliq. Energía ene 2019 | G12: 43539 | H12: 33 | I12: NULL | J12: s | K12: s | L12: BS1A | M12: Caren | N12: Cec | O12: 41335 | P12: CEC | Q12: 4 | R12: ITAHUE 220 | S12: 2.212452 | T12: 65.349 | U12: NULL | V12: NULL | W12: 145
A13: 43466 | B13: 43466 | C13: Licitación Caren y Cec (SIC 2013/03-2) BS1A | D13: Energia Licitaciones | E13: Energía | F13: Lic. SIC 2013/03-2 bloques BS1A: Energía ene 2019 | G13: 43504 | H13: 33 | I13: 7513 | J13: s | K13: s | L13: BS1A | M13: Caren | N13: Cec | O13: 41335 | P13: CEC | Q13: 4 | R13: ITAHUE 220 | S13: 2075.374 | T13: 65.349 | U13: NULL | V13: NULL | W13: 135624
A14: 43466 | B14: 43466 | C14: Licitación Caren y Cec (SIC 2013/03-2) BS1A | D14: Reliq. Energia Licitaciones | E14: Energía | F14: Lic. SIC 2013/03-2 bloques BS1A: Reliq. Energía ene 2019 | G14: 43539 | H14: 33 | I14: NULL | J14: s | K14: s | L14: BS1A | M14: Caren | N14: Cec | O14: 41335 | P14: CEC | Q14: 5 | R14: RAPEL 220 | S14: 0.008637 | T14: 69.368 | U14: NULL | V14: NULL | W14: 1
A15: 43466 | B15: 43466 | C15: Licitación Caren y Cec (SIC 2013/03-2) BS1A | D15: Energia Licitaciones | E15: Energía | F15: Lic. SIC 2013/03-2 bloques BS1A: Energía ene 2019 | G15: 43504 | H15: 33 | I15: 7513 | J15: s | K15: s | L15: BS1A | M15: Caren | N15: Cec | O15: 41335 | P15: CEC | Q15: 5 | R15: RAPEL 220 | S15: 8.102057 | T15: 69.368 | U15: NULL | V15: NULL | W15: 562
A16: 43497 | B16: 43497 | C16: Licitación Caren y Cec (SIC 2013/03-2) BS1A | D16: Reliq. Energia Licitaciones | E16: Energía | F16: Lic. SIC 2013/03-2 bloques BS1A: Reliq. Energía feb 2019 | G16: 43564 | H16: 61 | I16: NULL | J16: s | K16: s | L16: BS1A | M16: Caren | N16: Cec | O16: 41335 | P16: CEC | Q16: 1 | R16: A.JAHUEL 220 | S16: 0.23349 | T16: 66.9 | U16: NULL | V16: NULL | W16: 16
A17: 43497 | B17: 43497 | C17: Licitación Caren y Cec (SIC 2013/03-2) BS1A | D17: Energia Licitaciones | E17: Energía | F17: Lic. SIC 2013/03-2 bloques BS1A: Energía feb 2019 | G17: 43532 | H17: 33 | I17: 7798 | J17: s | K17: s | L17: BS1A | M17: Caren | N17: Cec | O17: 41335 | P17: CEC | Q17: 1 | R17: A.JAHUEL 220 | S17: 1368.5299 | T17: 66.9 | U17: NULL | V17: NULL | W17: 91555
A18: 43497 | B18: 43497 | C18: Licitación Caren y Cec (SIC 2013/03-2) BS1A | D18: Energia Licitaciones | E18: Energía | F18: Lic. SIC 2013/03-2 bloques BS1A: Energía feb 2019 | G18: 43532 | H18: 33 | I18: 7798 | J18: s | K18: s | L18: BS1A | M18: Caren | N18: Cec | O18: 41335 | P18: CEC | Q18: 2 | R18: A.MELIP 220 | S18: 8.816632 | T18: 69.014 | U18: NULL | V18: NULL | W18: 608
A19: 43497 | B19: 43497 | C19: Licitación Caren y Cec (SIC 2013/03-2) BS1A | D19: Reliq. Energia Licitaciones | E19: Energía | F19: Lic. SIC 2013/03-2 bloques BS1A: Reliq. Energía feb 2019 | G19: 43564 | H19: 61 | I19: NULL | J19: s | K19: s | L19: BS1A | M19: Caren | N19: Cec | O19: 41335 | P19: CEC | Q19: 3 | R19: CHARRUA 220 | S19: 0.072089 | T19: 63.27 | U19: NULL | V19: NULL | W19: 5
A20: 43497 | B20: 43497 | C20: Licitación Caren y Cec (SIC 2013/03-2) BS1A | D20: Energia Licitaciones | E20: Energía | F20: Lic. SIC 2013/03-2 bloques BS1A: Energía feb 2019 | G20: 43532 | H20: 33 | I20: 7798 | J20: s | K20: s | L20: BS1A | M20: Caren | N20: Cec | O20: 41335 | P20: CEC | Q20: 3 | R20: CHARRUA 220 | S20: 422.52678 | T20: 63.27 | U20: NULL | V20: NULL | W20: 26733
A21: 43497 | B21: 43497 | C21: Licitación Caren y Cec (SIC 2013/03-2) BS1A | D21: Reliq. Energia Licitaciones | E21: Energía | F21: Lic. SIC 2013/03-2 bloques BS1A: Reliq. Energía feb 2019 | G21: 43564 | H21: 61 | I21: NULL | J21: s | K21: s | L21: BS1A | M21: Caren | N21: Cec | O21: 41335 | P21: CEC | Q21: 4 | R21: ITAHUE 220 | S21: 0.353269 | T21: 65.349 | U21: NULL | V21: NULL | W21: 23
A22: 43497 | B22: 43497 | C22: Licitación Caren y Cec (SIC 2013/03-2) BS1A | D22: Energia Licitaciones | E22: Energía | F22: Lic. SIC 2013/03-2 bloques BS1A: Energía feb 2019 | G22: 43532 | H22: 33 | I22: 7798 | J22: s | K22: s | L22: BS1A | M22: Caren | N22: Cec | O22: 41335 | P22: CEC | Q22: 4 | R22: ITAHUE 220 | S22: 2070.5801 | T22: 65.349 | U22: NULL | V22: NULL | W22: 135310
A23: 43497 | B23: 43497 | C23: Licitación Caren y Cec (SIC 2013/03-2) BS1A | D23: Energia Licitaciones | E23: Energía | F23: Lic. SIC 2013/03-2 bloques BS1A: Energía feb 2019 | G23: 43532 | H23: 33 | I23: 7798 | J23: s | K23: s | L23: BS1A | M23: Caren | N23: Cec | O23: 41335 | P23: CEC | Q23: 5 | R23: RAPEL 220 | S23: 8.102328 | T23: 69.368 | U23: NULL | V23: NULL | W23: 562
A24: 43525 | B24: 43525 | C24: Licitación Caren y Cec (SIC 2013/03-2) BS1A | D24: Reliq. Energia Licitaciones | E24: Energía | F24: Lic. SIC 2013/03-2 bloques BS1A: Reliq. Energía mar 2019 | G24: 43598 | H24: 33 | I24: NULL | J24: s | K24: s | L24: BS1A | M24: Caren | N24: Cec | O24: 41335 | P24: CEC | Q24: 1 | R24: A.JAHUEL 220 | S24: 0.580609 | T24: 66.9 | U24: NULL | V24: NULL | W24: 39
A25: 43525 | B25: 43525 | C25: Licitación Caren y Cec (SIC 2013/03-2) BS1A | D25: Energia Licitaciones | E25: Energía | F25: Lic. SIC 2013/03-2 bloques BS1A: Energía mar 2019 | G25: 43563 | H25: 33 | I25: 8389 | J25: s | K25: s | L25: BS1A | M25: Caren | N25: Cec | O25: 41335 | P25: CEC | Q25: 1 | R25: A.JAHUEL 220 | S25: 1311.6233 | T25: 66.9 | U25: NULL | V25: NULL | W25: 87748
A26: 43525 | B26: 43525 | C26: Licitación Caren y Cec (SIC 2013/03-2) BS1A | D26: Energia Licitaciones | E26: Energía | F26: Lic. SIC 2013/03-2 bloques BS1A: Energía mar 2019 | G26: 43563 | H26: 33 | I26: 8389 | J26: s | K26: s | L26: BS1A | M26: Caren | N26: Cec | O26: 41335 | P26: CEC | Q26: 2 | R26: A.MELIP 220 | S26: 8.173697 | T26: 69.014 | U26: NULL | V26: NULL | W26: 564
A27: 43525 | B27: 43525 | C27: Licitación Caren y Cec (SIC 2013/03-2) BS1A | D27: Reliq. Energia Licitaciones | E27: Energía | F27: Lic. SIC 2013/03-2 bloques BS1A: Reliq. Energía mar 2019 | G27: 43598 | H27: 33 | I27: NULL | J27: s | K27: s | L27: BS1A | M27: Caren | N27: Cec | O27: 41335 | P27: CEC | Q27: 3 | R27: CHARRUA 220 | S27: 0.178218 | T27: 63.27 | U27: NULL | V27: NULL | W27: 11
A28: 43525 | B28: 43525 | C28: Licitación Caren y Cec (SIC 2013/03-2) BS1A | D28: Energia Licitaciones | E28: Energía | F28: Lic. SIC 2013/03-2 bloques BS1A: Energía mar 2019 | G28: 43563 | H28: 33 | I28: 8389 | J28: s | K28: s | L28: BS1A | M28: Caren | N28: Cec | O28: 41335 | P28: CEC | Q28: 3 | R28: CHARRUA 220 | S28: 402.60399 | T28: 63.27 | U28: NULL | V28: NULL | W28: 25473
A29: 43525 | B29: 43525 | C29: Licitación Caren y Cec (SIC 2013/03-2) BS1A | D29: Reliq. Energia Licitaciones | E29: Energía | F29: Lic. SIC 2013/03-2 bloques BS1A: Reliq. Energía mar 2019 | G29: 43598 | H29: 33 | I29: NULL | J29: s | K29: s | L29: BS1A | M29: Caren | N29: Cec | O29: 41335 | P29: CEC | Q29: 4 | R29: ITAHUE 220 | S29: 0.87116 | T29: 65.349 | U29: NULL | V29: NULL | W29: 57
A30: 43525 | B30: 43525 | C30: Licitación Caren y Cec (SIC 2013/03-2) BS1A | D30: Energia Licitaciones | E30: Energía | F30: Lic. SIC 2013/03-2 bloques BS1A: Energía mar 2019 | G30: 43563 | H30: 33 | I30: 8389 | J30: s | K30: s | L30: BS1A | M30: Caren | N30: Cec | O30: 41335 | P30: CEC | Q30: 4 | R30: ITAHUE 220 | S30: 1967.9945 | T30: 65.349 | U30: NULL | V30: NULL | W30: 128606
A31: 43525 | B31: 43525 | C31: Licitación Caren y Cec (SIC 2013/03-2) BS1A | D31: Energia Licitaciones | E31: Energía | F31: Lic. SIC 2013/03-2 bloques BS1A: Energía mar 2019 | G31: 43563 | H31: 33 | I31: 8389 | J31: s | K31: s | L31: BS1A | M31: Caren | N31: Cec | O31: 41335 | P31: CEC | Q31: 5 | R31: RAPEL 220 | S31: 7.514895 | T31: 69.368 | U31: NULL | V31: NULL | W31: 521
A32: 43556 | B32: 43556 | C32: Licitación Caren y Cec (SIC 2013/03-2) BS1A | D32: Potencia Licitaciones | E32: Potencia | F32: Lic. SIC 2013/03-2 bloques BS1A: Potencia abr 2019 | G32: 43598 | H32: 33 | I32: 8451 | J32: s | K32: s | L32: BS1A | M32: Caren | N32: Cec | O32: 41335 | P32: CEC | Q32: 1 | R32: A.JAHUEL 220 | S32: NULL | T32: NULL | U32: 0 | V32: 0 | W32: 0
A33: 43556 | B33: 43556 | C33: Licitación Caren y Cec (SIC 2013/03-2) BS1A | D33: Reliq. Energia Licitaciones | E33: Energía | F33: Lic. SIC 2013/03-2 bloques BS1A: Reliq. Energía abr 2019 | G33: 43913.498 | H33: 61 | I33: NULL | J33: s | K33: s | L33: BS1A | M33: Caren | N33: Cec | O33: 41335 | P33: CEC | Q33: 1 | R33: A.JAHUEL 220 | S33: 1 | T33: -1091 | U33: NULL | V33: NULL | W33: -1091
A34: 43556 | B34: 43556 | C34: Licitación Caren y Cec (SIC 2013/03-2) BS1A | D34: Energia Licitaciones | E34: Energía | F34: Lic. SIC 2013/03-2 bloques BS1A: Energía abr 2019 | G34: 43598 | H34: 33 | I34: 8451 | J34: s | K34: s | L34: BS1A | M34: Caren | N34: Cec | O34: 41335 | P34: CEC | Q34: 1 | R34: A.JAHUEL 220 | S34: 897.9651 | T34: 66.9 | U34: NULL | V34: NULL | W34: 60074
A35: 43556 | B35: 43556 | C35: Licitación Caren y Cec (SIC 2013/03-2) BS1A | D35: Potencia Licitaciones | E35: Potencia | F35: Lic. SIC 2013/03-2 bloques BS1A: Potencia abr 2019 | G35: 43598 | H35: 33 | I35: 8451 | J35: s | K35: s | L35: BS1A | M35: Caren | N35: Cec | O35: 41335 | P35: CEC | Q35: 2 | R35: A.MELIP 220 | S35: NULL | T35: NULL | U35: 0 | V35: 0 | W35: 0
A36: 43556 | B36: 43556 | C36: Licitación Caren y Cec (SIC 2013/03-2) BS1A | D36: Reliq. Energia Licitaciones | E36: Energía | F36: Lic. SIC 2013/03-2 bloques BS1A: Reliq. Energía abr 2019 | G36: 43913.498 | H36: 61 | I36: NULL | J36: s | K36: s | L36: BS1A | M36: Caren | N36: Cec | O36: 41335 | P36: CEC | Q36: 2 | R36: A.MELIP 220 | S36: 1 | T36: -8 | U36: NULL | V36: NULL | W36: -8
A37: 43556 | B37: 43556 | C37: Licitación Caren y Cec (SIC 2013/03-2) BS1A | D37: Energia Licitaciones | E37: Energía | F37: Lic. SIC 2013/03-2 bloques BS1A: Energía abr 2019 | G37: 43598 | H37: 33 | I37: 8451 | J37: s | K37: s | L37: BS1A | M37: Caren | N37: Cec | O37: 41335 | P37: CEC | Q37: 2 | R37: A.MELIP 220 | S37: 5.912451 | T37: 69.014 | U37: NULL | V37: NULL | W37: 408
A38: 43556 | B38: 43556 | C38: Licitación Caren y Cec (SIC 2013/03-2) BS1A | D38: Potencia Licitaciones | E38: Potencia | F38: Lic. SIC 2013/03-2 bloques BS1A: Potencia abr 2019 | G38: 43598 | H38: 33 | I38: 8451 | J38: s | K38: s | L38: BS1A | M38: Caren | N38: Cec | O38: 41335 | P38: CEC | Q38: 3 | R38: CHARRUA 220 | S38: NULL | T38: NULL | U38: 0 | V38: 0 | W38: 0
A39: 43556 | B39: 43556 | C39: Licitación Caren y Cec (SIC 2013/03-2) BS1A | D39: Reliq. Energia Licitaciones | E39: Energía | F39: Lic. SIC 2013/03-2 bloques BS1A: Reliq. Energía abr 2019 | G39: 43913.498 | H39: 61 | I39: NULL | J39: s | K39: s | L39: BS1A | M39: Caren | N39: Cec | O39: 41335 | P39: CEC | Q39: 3 | R39: CHARRUA 220 | S39: 1 | T39: -327 | U39: NULL | V39: NULL | W39: -327
A40: 43556 | B40: 43556 | C40: Licitación Caren y Cec (SIC 2013/03-2) BS1A | D40: Energia Licitaciones | E40: Energía | F40: Lic. SIC 2013/03-2 bloques BS1A: Energía abr 2019 | G40: 43598 | H40: 33 | I40: 8451 | J40: s | K40: s | L40: BS1A | M40: Caren | N40: Cec | O40: 41335 | P40: CEC | Q40: 3 | R40: CHARRUA 220 | S40: 278.37089 | T40: 63.27 | U40: NULL | V40: NULL | W40: 17613
...

Sheet SIGGE_E
A1: Periodo | B1: MesDevengado | C1: Nombre | D1: Concepto | E1: Agrupacion | F1: Glosa | G1: FechaCarga | H1: TipoDocumento | I1: Folio | J1: Vendedor | K1: Comprador | L1: Bloque | M1: Empresa | N1: ClaveEEDD | O1: Licitacion | P1: NomAgrupacion | Q1: Num | R1: Barra | S1: Energia | T1: PrecioEnergia | U1: Potencia | V1: PrecioPotencia | W1: Monto
A2: 43344 | B2: 43344 | C2: Licitación Caren y Cec (SIC 2013/03-2) BS1A | D2: Energia Licitaciones | E2: Energía | F2: Lic. SIC 2013/03-2 bloques BS1A: Energía sep 2018 | G2: 43392 | H2: 33 | I2: 6305 | J2: s | K2: s | L2: BS1A | M2: Caren | N2: Cec | O2: 41335 | P2: CEC | Q2: 1 | R2: TotalBarras | S2: 3000 | T2: 58.085 | U2: NULL | V2: NULL | W2: 174255
A3: 43374 | B3: 43374 | C3: Licitación Caren y Cec (SIC 2013/03-2) BS1A | D3: Energia Licitaciones | E3: Energía | F3: Lic. SIC 2013/03-2 bloques BS1A: Energía oct 2018 | G3: 43431 | H3: 33 | I3: 6796 | J3: s | K3: s | L3: BS1A | M3: Caren | N3: Cec | O3: 41335 | P3: CEC | Q3: 1 | R3: TotalBarras | S3: 3000 | T3: 59.678 | U3: NULL | V3: NULL | W3: 179035
A4: 43405 | B4: 43405 | C4: Licitación Caren y Cec (SIC 2013/03-2) BS1A | D4: Energia Licitaciones | E4: Energía | F4: Lic. SIC 2013/03-2 bloques BS1A: Energía nov 2018 | G4: 43448 | H4: 33 | I4: 6939 | J4: s | K4: s | L4: BS1A | M4: Caren | N4: Cec | O4: 41335 | P4: CEC | Q4: 1 | R4: TotalBarras | S4: 4000 | T4: 59.635 | U4: NULL | V4: NULL | W4: 238540
A5: 43435 | B5: 43435 | C5: Licitación Caren y Cec (SIC 2013/03-2) BS1A | D5: Energia Licitaciones | E5: Energía | F5: Lic. SIC 2013/03-2 bloques BS1A: Energía dic 2018 | G5: 43486 | H5: 33 | I5: 7194 | J5: s | K5: s | L5: BS1A | M5: Caren | N5: Cec | O5: 41335 | P5: CEC | Q5: 1 | R5: TotalBarras | S5: 5000 | T5: 67.951 | U5: NULL | V5: NULL | W5: 339757
A6: 43466 | B6: 43466 | C6: Licitación Caren y Cec (SIC 2013/03-2) BS1A | D6: Reliq. Energia Licitaciones | E6: Energía | F6: Lic. SIC 2013/03-2 bloques BS1A: Reliq. Energía ene 2019 | G6: 43539 | H6: 33 | I6: NULL | J6: s | K6: s | L6: BS1A | M6: Caren | N6: Cec | O6: 41335 | P6: CEC | Q6: 1 | R6: A.JAHUEL 220 | S6: 1.46188 | T6: 66.9 | U6: NULL | V6: NULL | W6: 98
A7: 43466 | B7: 43466 | C7: Licitación Caren y Cec (SIC 2013/03-2) BS1A | D7: Energia Licitaciones | E7: Energía | F7: Lic. SIC 2013/03-2 bloques BS1A: Energía ene 2019 | G7: 43504 | H7: 33 | I7: 7513 | J7: s | K7: s | L7: BS1A | M7: Caren | N7: Cec | O7: 41335 | P7: CEC | Q7: 1 | R7: A.JAHUEL 220 | S7: 1371.306 | T7: 66.9 | U7: NULL | V7: NULL | W7: 91740
A8: 43466 | B8: 43466 | C8: Licitación Caren y Cec (SIC 2013/03-2) BS1A | D8: Reliq. Energia Licitaciones | E8: Energía | F8: Lic. SIC 2013/03-2 bloques BS1A: Reliq. Energía ene 2019 | G8: 43539 | H8: 33 | I8: NULL | J8: s | K8: s | L8: BS1A | M8: Caren | N8: Cec | O8: 41335 | P8: CEC | Q8: 2 | R8: A.MELIP 220 | S8: 0.009388 | T8: 69.014 | U8: NULL | V8: NULL | W8: 1
A9: 43466 | B9: 43466 | C9: Licitación Caren y Cec (SIC 2013/03-2) BS1A | D9: Energia Licitaciones | E9: Energía | F9: Lic. SIC 2013/03-2 bloques BS1A: Energía ene 2019 | G9: 43504 | H9: 33 | I9: 7513 | J9: s | K9: s | L9: BS1A | M9: Caren | N9: Cec | O9: 41335 | P9: CEC | Q9: 2 | R9: A.MELIP 220 | S9: 8.806166 | T9: 69.014 | U9: NULL | V9: NULL | W9: 608
A10: 43466 | B10: 43466 | C10: Licitación Caren y Cec (SIC 2013/03-2) BS1A | D10: Reliq. Energia Licitaciones | E10: Energía | F10: Lic. SIC 2013/03-2 bloques BS1A: Reliq. Energía ene 2019 | G10: 43539 | H10: 33 | I10: NULL | J10: s | K10: s | L10: BS1A | M10: Caren | N10: Cec | O10: 41335 | P10: CEC | Q10: 3 | R10: CHARRUA 220 | S10: 0.453721 | T10: 63.27 | U10: NULL | V10: NULL | W10: 29
A11: 43466 | B11: 43466 | C11: Licitación Caren y Cec (SIC 2013/03-2) BS1A | D11: Energia Licitaciones | E11: Energía | F11: Lic. SIC 2013/03-2 bloques BS1A: Energía ene 2019 | G11: 43504 | H11: 33 | I11: 7513 | J11: s | K11: s | L11: BS1A | M11: Caren | N11: Cec | O11: 41335 | P11: CEC | Q11: 3 | R11: CHARRUA 220 | S11: 425.60961 | T11: 63.27 | U11: NULL | V11: NULL | W11: 26928
A12: 43466 | B12: 43466 | C12: Licitación Caren y Cec (SIC 2013/03-2) BS1A | D12: Reliq. Energia Licitaciones | E12: Energía | F12: Lic. SIC 2013/03-2 bloques BS1A: Reliq. Energía ene 2019 | G12: 43539 | H12: 33 | I12: NULL | J12: s | K12: s | L12: BS1A | M12: Caren | N12: Cec | O12: 41335 | P12: CEC | Q12: 4 | R12: ITAHUE 220 | S12: 2.212452 | T12: 65.349 | U12: NULL | V12: NULL | W12: 145
A13: 43466 | B13: 43466 | C13: Licitación Caren y Cec (SIC 2013/03-2) BS1A | D13: Energia Licitaciones | E13: Energía | F13: Lic. SIC 2013/03-2 bloques BS1A: Energía ene 2019 | G13: 43504 | H13: 33 | I13: 7513 | J13: s | K13: s | L13: BS1A | M13: Caren | N13: Cec | O13: 41335 | P13: CEC | Q13: 4 | R13: ITAHUE 220 | S13: 2075.374 | T13: 65.349 | U13: NULL | V13: NULL | W13: 135624
A14: 43466 | B14: 43466 | C14: Licitación Caren y Cec (SIC 2013/03-2) BS1A | D14: Reliq. Energia Licitaciones | E14: Energía | F14: Lic. SIC 2013/03-2 bloques BS1A: Reliq. Energía ene 2019 | G14: 43539 | H14: 33 | I14: NULL | J14: s | K14: s | L14: BS1A | M14: Caren | N14: Cec | O14: 41335 | P14: CEC | Q14: 5 | R14: RAPEL 220 | S14: 0.008637 | T14: 69.368 | U14: NULL | V14: NULL | W14: 1
A15: 43466 | B15: 43466 | C15: Licitación Caren y Cec (SIC 2013/03-2) BS1A | D15: Energia Licitaciones | E15: Energía | F15: Lic. SIC 2013/03-2 bloques BS1A: Energía ene 2019 | G15: 43504 | H15: 33 | I15: 7513 | J15: s | K15: s | L15: BS1A | M15: Caren | N15: Cec | O15: 41335 | P15: CEC | Q15: 5 | R15: RAPEL 220 | S15: 8.102057 | T15: 69.368 | U15: NULL | V15: NULL | W15: 562
A16: 43497 | B16: 43497 | C16: Licitación Caren y Cec (SIC 2013/03-2) BS1A | D16: Reliq. Energia Licitaciones | E16: Energía | F16: Lic. SIC 2013/03-2 bloques BS1A: Reliq. Energía feb 2019 | G16: 43564 | H16: 61 | I16: NULL | J16: s | K16: s | L16: BS1A | M16: Caren | N16: Cec | O16: 41335 | P16: CEC | Q16: 1 | R16: A.JAHUEL 220 | S16: 0.23349 | T16: 66.9 | U16: NULL | V16: NULL | W16: 16
A17: 43497 | B17: 43497 | C17: Licitación Caren y Cec (SIC 2013/03-2) BS1A | D17: Energia Licitaciones | E17: Energía | F17: Lic. SIC 2013/03-2 bloques BS1A: Energía feb 2019 | G17: 43532 | H17: 33 | I17: 7798 | J17: s | K17: s | L17: BS1A | M17: Caren | N17: Cec | O17: 41335 | P17: CEC | Q17: 1 | R17: A.JAHUEL 220 | S17: 1368.5299 | T17: 66.9 | U17: NULL | V17: NULL | W17: 91555
