Workbook

Sheet README
A1: Hoja | B1: Descripción
A2: EFACT_CNE | B2: Información de facturación definitiva proveniente de los archivos EFACT publicados por la CNE en los Decretos de Precio de Nudo
A3: FACT_EMITIDA | B3: Información de facturación real desde PDFs y sistema SIGGE (gestión facturación electrónica)
A4: SIGGE_E | B4: Información de facturación real de Energía desde PDFs y sistema SIGGE (gestión facturación electrónica)
A5: SIGGE_P | B5: Información de facturación real de Potencia desde PDFs y sistema SIGGE (gestión facturación electrónica)
A6: FACT_EST_EFACT | B6: Estimación de facturación emitida en base a información de los EFACT Decretos Precios de Nudo
A7: FACT_EST_CEN | B7: Estimación de la facturación emitida en base a los balances mensuales publicados por el Coordinador

Sheet ReliquidacionEFACT
A1: =0 / 0 | B1: =0 / 1 | C1: =0 / 2 | D1: =0 / 3 | E1: =0 / 4 | F1: =0 / 5 | G1: =0 / 6 | H1: =0 / 7 | I1: =0 / 8 | J1: =0 / 9 | K1: =0 / 10 | L1: =0 / 11 | M1: =0 / 12 | N1: =0 / 13 | O1: =0 / 14 | P1: =0 / 15 | Q1: =0 / 16 | R1: =0 / 17 | S1: =0 / 18 | T1: =0 / 19 | U1: =0 / 20 | V1: =0 / 21 | W1: =0 / 22 | X1: =0 / 23 | Y1: =0 / 24 | Z1: =0 / 25 | AA1: =0 / 26 | AB1: =0 / 27 | AC1: =0 / 28 | AD1: =0 / 29 | AE1: =0 / 30
A2: Generador | B2: San Juan
A3: Distribuidor | B3: CEC
A4: Licitacion | B4: 2013/03-2° Llamado
A5: Bloque | B5: BS2A
C7: LO QUE SE FACTURÓ | L7: LO QUE SE DEBIÓ HABER FACTURADO | U7: RELQUIDACIÓN Y CÁLCULO INTERESES
A8: ID | B8: MES | C8: ORIGEN DATA | D8: Energía (kWh) | E8: Monto Energía ($) | F8: $/kWh | G8: Potencia (kW) | H8: Monto Potencia ($) | I8: $/kW-mes | J8: Monto Total ($) | L8: ORIGEN DATA | M8: Energía (kWh) | N8: Monto Energía ($) | O8: $/kWh | P8: Potencia (kW) | Q8: Monto Potencia ($) | R8: $/kW-mes | S8: Monto Total ($) | U8: Mes | V8: Reliquidación mensual ($) | W8: Decreto PNP Reliquidación | X8: Fecha publicación Diario Oficial | Y8: Interés Anual | Z8: Fecha Facturación | AA8: Fecha Reliquidación | AB8: N° de días de intereses | AC8: Interés total según n° de días | AD8: Intereses ($) | AE8: Reliquidación Total ($)
A9: 9 | B9: 44105 | C9: FACT_EMITIDA | D9: =SUMIF(SIGGE_E!B:B,ReliquidacionEFACT!B9,SIGGE_E!S:S) | E9: =SUMIF(SIGGE_E!B:B,ReliquidacionEFACT!B9,SIGGE_E!T:T) | F9: =IFERROR((E9/D9),0) | G9: =SUMIF(SIGGE_P!B:B,ReliquidacionEFACT!B9,SIGGE_P!U:U) | H9: =SUMIF(SIGGE_P!B:B,ReliquidacionEFACT!B9,SIGGE_P!V:V) | I9: =IFERROR((H9/G9),0) | J9: =(E9+H9) | L9: EFACT_CNE | M9: =SUMIF(EFACT_CNE!B:B,ReliquidacionEFACT!B9,EFACT_CNE!S:S) | N9: =SUMIF(EFACT_CNE!B:B,ReliquidacionEFACT!B9,EFACT_CNE!T:T) | O9: =IFERROR((N9/M9),0) | P9: =SUMIF(EFACT_CNE!B:B,ReliquidacionEFACT!B9,EFACT_CNE!U:U) | Q9: =SUMIF(EFACT_CNE!B:B,ReliquidacionEFACT!B9,EFACT_CNE!V:V) | R9: =IFERROR((Q9/P9),0) | S9: =(N9+Q9) | U9: 44105 | V9: =(S9-J9) | W9: PNP_8T | X9: 44600 | Y9: 0.0648 | Z9: 44160 | AA9: 44651 | AB9: =(AA9-Z9) | AC9: =(1+Y9)^(AB9/360)-1 | AD9: =(AC9*V9) | AE9: =(V9+AD9)
A10: 10 | B10: 44136 | C10: FACT_EMITIDA | D10: =SUMIF(SIGGE_E!B:B,ReliquidacionEFACT!B10,SIGGE_E!S:S) | E10: =SUMIF(SIGGE_E!B:B,ReliquidacionEFACT!B10,SIGGE_E!T:T) | F10: =IFERROR((E10/D10),0) | G10: =SUMIF(SIGGE_P!B:B,ReliquidacionEFACT!B10,SIGGE_P!U:U) | H10: =SUMIF(SIGGE_P!B:B,ReliquidacionEFACT!B10,SIGGE_P!V:V) | I10: =IFERROR((H10/G10),0) | J10: =(E10+H10) | L10: EFACT_CNE | M10: =SUMIF(EFACT_CNE!B:B,ReliquidacionEFACT!B10,EFACT_CNE!S:S) | N10: =SUMIF(EFACT_CNE!B:B,ReliquidacionEFACT!B10,EFACT_CNE!T:T) | O10: =IFERROR((N10/M10),0) | P10: =SUMIF(EFACT_CNE!B:B,ReliquidacionEFACT!B10,EFACT_CNE!U:U) | Q10: =SUMIF(EFACT_CNE!B:B,ReliquidacionEFACT!B10,EFACT_CNE!V:V) | R10: =IFERROR((Q10/P10),0) | S10: =(N10+Q10) | U10: 44136 | V10: =(S10-J10) | W10: PNP_8T | X10: 44600 | Y10: 0.0648 | Z10: 44190 | AA10: 44651 | AB10: =(AA10-Z10) | AC10: =(1+Y10)^(AB10/360)-1 | AD10: =(AC10*V10) | AE10: =(V10+AD10)
A11: 11 | B11: 44166 | C11: FACT_EMITIDA | D11: =SUMIF(SIGGE_E!B:B,ReliquidacionEFACT!B11,SIGGE_E!S:S) | E11: =SUMIF(SIGGE_E!B:B,ReliquidacionEFACT!B11,SIGGE_E!T:T) | F11: =IFERROR((E11/D11),0) | G11: =SUMIF(SIGGE_P!B:B,ReliquidacionEFACT!B11,SIGGE_P!U:U) | H11: =SUMIF(SIGGE_P!B:B,ReliquidacionEFACT!B11,SIGGE_P!V:V) | I11: =IFERROR((H11/G11),0) | J11: =(E11+H11) | L11: EFACT_CNE | M11: =SUMIF(EFACT_CNE!B:B,ReliquidacionEFACT!B11,EFACT_CNE!S:S) | N11: =SUMIF(EFACT_CNE!B:B,ReliquidacionEFACT!B11,EFACT_CNE!T:T) | O11: =IFERROR((N11/M11),0) | P11: =SUMIF(EFACT_CNE!B:B,ReliquidacionEFACT!B11,EFACT_CNE!U:U) | Q11: =SUMIF(EFACT_CNE!B:B,ReliquidacionEFACT!B11,EFACT_CNE!V:V) | R11: =IFERROR((Q11/P11),0) | S11: =(N11+Q11) | U11: 44166 | V11: =(S11-J11) | W11: PNP_8T | X11: 44600 | Y11: 0.0648 | Z11: 44221 | AA11: 44651 | AB11: =(AA11-Z11) | AC11: =(1+Y11)^(AB11/360)-1 | AD11: =(AC11*V11) | AE11: =(V11+AD11)
A12: 12 | B12: 44197 | C12: FACT_EMITIDA | D12: =SUMIF(SIGGE_E!B:B,ReliquidacionEFACT!B12,SIGGE_E!S:S) | E12: =SUMIF(SIGGE_E!B:B,ReliquidacionEFACT!B12,SIGGE_E!T:T) | F12: =IFERROR((E12/D12),0) | G12: =SUMIF(SIGGE_P!B:B,ReliquidacionEFACT!B12,SIGGE_P!U:U) | H12: =SUMIF(SIGGE_P!B:B,ReliquidacionEFACT!B12,SIGGE_P!V:V) | I12: =IFERROR((H12/G12),0) | J12: =(E12+H12) | L12: EFACT_CNE | M12: =SUMIF(EFACT_CNE!B:B,ReliquidacionEFACT!B12,EFACT_CNE!S:S) | N12: =SUMIF(EFACT_CNE!B:B,ReliquidacionEFACT!B12,EFACT_CNE!T:T) | O12: =IFERROR((N12/M12),0) | P12: =SUMIF(EFACT_CNE!B:B,ReliquidacionEFACT!B12,EFACT_CNE!U:U) | Q12: =SUMIF(EFACT_CNE!B:B,ReliquidacionEFACT!B12,EFACT_CNE!V:V) | R12: =IFERROR((Q12/P12),0) | S12: =(N12+Q12) | U12: 44197 | V12: =(S12-J12) | W12: PNP_8T | X12: 44600 | Y12: 0.0648 | Z12: 44252 | AA12: 44651 | AB12: =(AA12-Z12) | AC12: =(1+Y12)^(AB12/360)-1 | AD12: =(AC12*V12) | AE12: =(V12+AD12)
A13: 13 | B13: 44228 | C13: FACT_EMITIDA | D13: =SUMIF(SIGGE_E!B:B,ReliquidacionEFACT!B13,SIGGE_E!S:S) | E13: =SUMIF(SIGGE_E!B:B,ReliquidacionEFACT!B13,SIGGE_E!T:T) | F13: =IFERROR((E13/D13),0) | G13: =SUMIF(SIGGE_P!B:B,ReliquidacionEFACT!B13,SIGGE_P!U:U) | H13: =SUMIF(SIGGE_P!B:B,ReliquidacionEFACT!B13,SIGGE_P!V:V) | I13: =IFERROR((H13/G13),0) | J13: =(E13+H13) | L13: EFACT_CNE | M13: =SUMIF(EFACT_CNE!B:B,ReliquidacionEFACT!B13,EFACT_CNE!S:S) | N13: =SUMIF(EFACT_CNE!B:B,ReliquidacionEFACT!B13,EFACT_CNE!T:T) | O13: =IFERROR((N13/M13),0) | P13: =SUMIF(EFACT_CNE!B:B,ReliquidacionEFACT!B13,EFACT_CNE!U:U) | Q13: =SUMIF(EFACT_CNE!B:B,ReliquidacionEFACT!B13,EFACT_CNE!V:V) | R13: =IFERROR((Q13/P13),0) | S13: =(N13+Q13) | U13: 44228 | V13: =(S13-J13) | W13: PNP_8T | X13: 44600 | Y13: 0.0648 | Z13: 44280 | AA13: 44651 | AB13: =(AA13-Z13) | AC13: =(1+Y13)^(AB13/360)-1 | AD13: =(AC13*V13) | AE13: =(V13+AD13)
A14: 14 | B14: 44256 | C14: FACT_EMITIDA | D14: =SUMIF(SIGGE_E!B:B,ReliquidacionEFACT!B14,SIGGE_E!S:S) | E14: =SUMIF(SIGGE_E!B:B,ReliquidacionEFACT!B14,SIGGE_E!T:T) | F14: =IFERROR((E14/D14),0) | G14: =SUMIF(SIGGE_P!B:B,ReliquidacionEFACT!B14,SIGGE_P!U:U) | H14: =SUMIF(SIGGE_P!B:B,ReliquidacionEFACT!B14,SIGGE_P!V:V) | I14: =IFERROR((H14/G14),0) | J14: =(E14+H14) | L14: EFACT_CNE | M14: =SUMIF(EFACT_CNE!B:B,ReliquidacionEFACT!B14,EFACT_CNE!S:S) | N14: =SUMIF(EFACT_CNE!B:B,ReliquidacionEFACT!B14,EFACT_CNE!T:T) | O14: =IFERROR((N14/M14),0) | P14: =SUMIF(EFACT_CNE!B:B,ReliquidacionEFACT!B14,EFACT_CNE!U:U) | Q14: =SUMIF(EFACT_CNE!B:B,ReliquidacionEFACT!B14,EFACT_CNE!V:V) | R14: =IFERROR((Q14/P14),0) | S14: =(N14+Q14) | U14: 44256 | V14: =(S14-J14) | W14: PNP_8T | X14: 44600 | Y14: 0.0648 | Z14: 44311 | AA14: 44651 | AB14: =(AA14-Z14) | AC14: =(1+Y14)^(AB14/360)-1 | AD14: =(AC14*V14) | AE14: =(V14+AD14)
AD15: Reliquidación | AE15: =SUM(AE9:AE14)
AC17: Montos a favor | AD17: LAP emite factura
AC18: Montos en contra | AD18: LAP emite nota de crédito

Sheet ResumenRetiros
A2: Generador | B2: San Juan
A3: Distribuidor | B3: CEC
A4: Licitacion | B4: 2013/03-2° Llamado
A5: Bloque | B5: BS2A
A8: ID | B8: MES | C8: ORIGEN DATA | D8: Energía SIGGE (kWh) | E8: Energía EFACT AT (kWh) | F8: Energía EFACT BT (kWh) | G8: Energía Coordinador AT (kWh) | H8: Energía Coordinador BT (kWh)
A9: 9 | B9: 44105 | C9: FACT_EMITIDA | D9: =SUMIF(SIGGE_E!B:B,ResumenRetiros!B9,SIGGE_E!S:S) | E9: =SUMIF(EFACT_CNE!B:B,ResumenRetiros!B9,EFACT_CNE!S:S) | F9: =SUMIF(EfactCNE_BT!B:B,ResumenRetiros!B9,EfactCNE_BT!M:M) | G9: =SUMIF(CEN_Energia!B:B,ResumenRetiros!B9,CEN_Energia!Z:Z) | H9: =SUMIF(CEN_EnergiaBT!B:B,ResumenRetiros!B9,CEN_EnergiaBT!K:K)
A10: 10 | B10: 44136 | C10: FACT_EMITIDA | D10: =SUMIF(SIGGE_E!B:B,ResumenRetiros!B10,SIGGE_E!S:S) | E10: =SUMIF(EFACT_CNE!B:B,ResumenRetiros!B10,EFACT_CNE!S:S) | F10: =SUMIF(EfactCNE_BT!B:B,ResumenRetiros!B10,EfactCNE_BT!M:M) | G10: =SUMIF(CEN_Energia!B:B,ResumenRetiros!B10,CEN_Energia!Z:Z) | H10: =SUMIF(CEN_EnergiaBT!B:B,ResumenRetiros!B10,CEN_EnergiaBT!K:K)
A11: 11 | B11: 44166 | C11: FACT_EMITIDA | D11: =SUMIF(SIGGE_E!B:B,ResumenRetiros!B11,SIGGE_E!S:S) | E11: =SUMIF(EFACT_CNE!B:B,ResumenRetiros!B11,EFACT_CNE!S:S) | F11: =SUMIF(EfactCNE_BT!B:B,ResumenRetiros!B11,EfactCNE_BT!M:M) | G11: =SUMIF(CEN_Energia!B:B,ResumenRetiros!B11,CEN_Energia!Z:Z) | H11: =SUMIF(CEN_EnergiaBT!B:B,ResumenRetiros!B11,CEN_EnergiaBT!K:K)
A12: 12 | B12: 44197 | C12: FACT_EMITIDA | D12: =SUMIF(SIGGE_E!B:B,ResumenRetiros!B12,SIGGE_E!S:S) | E12: =SUMIF(EFACT_CNE!B:B,ResumenRetiros!B12,EFACT_CNE!S:S) | F12: =SUMIF(EfactCNE_BT!B:B,ResumenRetiros!B12,EfactCNE_BT!M:M) | G12: =SUMIF(CEN_Energia!B:B,ResumenRetiros!B12,CEN_Energia!Z:Z) | H12: =SUMIF(CEN_EnergiaBT!B:B,ResumenRetiros!B12,CEN_EnergiaBT!K:K)
A13: 13 | B13: 44228 | C13: FACT_EMITIDA | D13: =SUMIF(SIGGE_E!B:B,ResumenRetiros!B13,SIGGE_E!S:S) | E13: =SUMIF(EFACT_CNE!B:B,ResumenRetiros!B13,EFACT_CNE!S:S) | F13: =SUMIF(EfactCNE_BT!B:B,ResumenRetiros!B13,EfactCNE_BT!M:M) | G13: =SUMIF(CEN_Energia!B:B,ResumenRetiros!B13,CEN_Energia!Z:Z) | H13: =SUMIF(CEN_EnergiaBT!B:B,ResumenRetiros!B13,CEN_EnergiaBT!K:K)
A14: 14 | B14: 44256 | C14: FACT_EMITIDA | D14: =SUMIF(SIGGE_E!B:B,ResumenRetiros!B14,SIGGE_E!S:S) | E14: =SUMIF(EFACT_CNE!B:B,ResumenRetiros!B14,EFACT_CNE!S:S) | F14: =SUMIF(EfactCNE_BT!B:B,ResumenRetiros!B14,EfactCNE_BT!M:M) | G14: =SUMIF(CEN_Energia!B:B,ResumenRetiros!B14,CEN_Energia!Z:Z) | H14: =SUMIF(CEN_EnergiaBT!B:B,ResumenRetiros!B14,CEN_EnergiaBT!K:K)
D15: =SUM(D9:D14) | E15: =SUM(E9:E14) | F15: =SUM(F9:F14) | G15: =SUM(G9:G14) | H15: =SUM(H9:H14)

Sheet FactRealE
A1: Empresa | B1: MesDevengado | C1: IdAgrupacion | D1: NomAgrupacion | E1: Bloque | F1: NombreCliente | G1: FechaDeContabilizacion | H1: PrefijoFolio | I1: CuentaDeMayor | J1: CodigoDeArticulo | K1: NumDeFolio | L1: MontoCLP | M1: TotalUSD

Sheet FactRealP
A1: Empresa | B1: MesDevengado | C1: IdAgrupacion | D1: NomAgrupacion | E1: Bloque | F1: NombreCliente | G1: FechaDeContabilizacion | H1: PrefijoFolio | I1: CuentaDeMayor | J1: CodigoDeArticulo | K1: NumDeFolio | L1: MontoCLP | M1: TotalUSD

Sheet FACT_EMITIDA
A1: Periodo | B1: MesDevengado | C1: Nombre | D1: Concepto | E1: Agrupacion | F1: Glosa | G1: FechaCarga | H1: TipoDocumento | I1: Folio | J1: Vendedor | K1: Comprador | L1: Bloque | M1: Empresa | N1: ClaveEEDD | O1: Licitacion | P1: NomAgrupacion | Q1: Num | R1: Barra | S1: Energia | T1: MontoEnergia | U1: Potencia | V1: MontoPotencia | W1: Precio
A2: 01-10-2020 | B2: 01-10-2020 | C2: Licitación Eolica San Juan y Cec (SIC 2013/03-2) BS2A | D2: Potencia Licitaciones | E2: Potencia | F2: Lic. SIC 2013/03-2 bloques BS2A: Potencia oct 2020 | G2: 2020-11-06 19:47:10 | H2: 33 | I2: 15439 | J2: s | K2: s | L2: BS2A | M2: SAN_JUAN_LAP | N2: Cec | O2: 2013/03-2 | P2: CEC | Q2: 1 | R2: A.JAHUEL 220 | U2: 0 | V2: 0 | W2: 6059.26
A3: 01-10-2020 | B3: 01-10-2020 | C3: Licitación Eolica San Juan y Cec (SIC 2013/03-2) BS2A | D3: Energia Licitaciones | E3: Energía | F3: Lic. SIC 2013/03-2 bloques BS2A: Energía oct 2020 | G3: 2020-11-06 19:47:10 | H3: 33 | I3: 15439 | J3: s | K3: s | L3: BS2A | M3: SAN_JUAN_LAP | N3: Cec | O3: 2013/03-2 | P3: CEC | Q3: 1 | R3: A.JAHUEL 220 | S3: 18230.56 | T3: 1326510 | W3: 72.763
A4: 01-10-2020 | B4: 01-10-2020 | C4: Licitación Eolica San Juan y Cec (SIC 2013/03-2) BS2A | D4: Potencia Licitaciones | E4: Potencia | F4: Lic. SIC 2013/03-2 bloques BS2A: Potencia oct 2020 | G4: 2020-11-06 19:47:10 | H4: 33 | I4: 15439 | J4: s | K4: s | L4: BS2A | M4: SAN_JUAN_LAP | N4: Cec | O4: 2013/03-2 | P4: CEC | Q4: 2 | R4: A.MELIP 220 | U4: 0 | V4: 0 | W4: 6135.33
A5: 01-10-2020 | B5: 01-10-2020 | C5: Licitación Eolica San Juan y Cec (SIC 2013/03-2) BS2A | D5: Energia Licitaciones | E5: Energía | F5: Lic. SIC 2013/03-2 bloques BS2A: Energía oct 2020 | G5: 2020-11-06 19:47:10 | H5: 33 | I5: 15439 | J5: s | K5: s | L5: BS2A | M5: SAN_JUAN_LAP | N5: Cec | O5: 2013/03-2 | P5: CEC | Q5: 2 | R5: A.MELIP 220 | S5: 79.411571 | T5: 5861 | W5: 73.8
A6: 01-10-2020 | B6: 01-10-2020 | C6: Licitación Eolica San Juan y Cec (SIC 2013/03-2) BS2A | D6: Potencia Licitaciones | E6: Potencia | F6: Lic. SIC 2013/03-2 bloques BS2A: Potencia oct 2020 | G6: 2020-11-06 19:47:10 | H6: 33 | I6: 15439 | J6: s | K6: s | L6: BS2A | M6: SAN_JUAN_LAP | N6: Cec | O6: 2013/03-2 | P6: CEC | Q6: 3 | R6: CHARRUA 220 | U6: 0 | V6: 0 | W6: 5857.6
A7: 01-10-2020 | B7: 01-10-2020 | C7: Licitación Eolica San Juan y Cec (SIC 2013/03-2) BS2A | D7: Energia Licitaciones | E7: Energía | F7: Lic. SIC 2013/03-2 bloques BS2A: Energía oct 2020 | G7: 2020-11-06 19:47:10 | H7: 33 | I7: 15439 | J7: s | K7: s | L7: BS2A | M7: SAN_JUAN_LAP | N7: Cec | O7: 2013/03-2 | P7: CEC | Q7: 3 | R7: CHARRUA 220 | S7: 2695.4699 | T7: 187128 | W7: 69.423
A8: 01-10-2020 | B8: 01-10-2020 | C8: Licitación Eolica San Juan y Cec (SIC 2013/03-2) BS2A | D8: Potencia Licitaciones | E8: Potencia | F8: Lic. SIC 2013/03-2 bloques BS2A: Potencia oct 2020 | G8: 2020-11-06 19:47:10 | H8: 33 | I8: 15439 | J8: s | K8: s | L8: BS2A | M8: SAN_JUAN_LAP | N8: Cec | O8: 2013/03-2 | P8: CEC | Q8: 4 | R8: ITAHUE 220 | U8: 0 | V8: 0 | W8: 5984.39
A9: 01-10-2020 | B9: 01-10-2020 | C9: Licitación Eolica San Juan y Cec (SIC 2013/03-2) BS2A | D9: Energia Licitaciones | E9: Energía | F9: Lic. SIC 2013/03-2 bloques BS2A: Energía oct 2020 | G9: 2020-11-06 19:47:10 | H9: 33 | I9: 15439 | J9: s | K9: s | L9: BS2A | M9: SAN_JUAN_LAP | N9: Cec | O9: 2013/03-2 | P9: CEC | Q9: 4 | R9: ITAHUE 220 | S9: 23046.249 | T9: 1602521 | W9: 69.535
A10: 01-10-2020 | B10: 01-10-2020 | C10: Licitación Eolica San Juan y Cec (SIC 2013/03-2) BS2A | D10: Potencia Licitaciones | E10: Potencia | F10: Lic. SIC 2013/03-2 bloques BS2A: Potencia oct 2020 | G10: 2020-11-06 19:47:10 | H10: 33 | I10: 15439 | J10: s | K10: s | L10: BS2A | M10: SAN_JUAN_LAP | N10: Cec | O10: 2013/03-2 | P10: CEC | Q10: 5 | R10: RAPEL 220 | U10: 0 | V10: 0 | W10: 5746.51
A11: 01-10-2020 | B11: 01-10-2020 | C11: Licitación Eolica San Juan y Cec (SIC 2013/03-2) BS2A | D11: Energia Licitaciones | E11: Energía | F11: Lic. SIC 2013/03-2 bloques BS2A: Energía oct 2020 | G11: 2020-11-06 19:47:10 | H11: 33 | I11: 15439 | J11: s | K11: s | L11: BS2A | M11: SAN_JUAN_LAP | N11: Cec | O11: 2013/03-2 | P11: CEC | Q11: 5 | R11: RAPEL 220 | S11: 95.14513 | T11: 6837 | W11: 71.854
A12: 01-11-2020 | B12: 01-11-2020 | C12: Licitación Eolica San Juan y Cec (SIC 2013/03-2) BS2A | D12: Potencia Licitaciones | E12: Potencia | F12: Lic. SIC 2013/03-2 bloques BS2A: Potencia nov 2020 | G12: 2020-12-04 16:22:38 | H12: 33 | I12: 16398 | J12: s | K12: s | L12: BS2A | M12: SAN_JUAN_LAP | N12: Cec | O12: 2013/03-2 | P12: CEC | Q12: 1 | R12: A.JAHUEL 220 | U12: 0 | V12: 0 | W12: 6059.26
A13: 01-11-2020 | B13: 01-11-2020 | C13: Licitación Eolica San Juan y Cec (SIC 2013/03-2) BS2A | D13: Energia Licitaciones | E13: Energía | F13: Lic. SIC 2013/03-2 bloques BS2A: Energía nov 2020 | G13: 2020-12-04 16:22:38 | H13: 33 | I13: 16398 | J13: s | K13: s | L13: BS2A | M13: SAN_JUAN_LAP | N13: Cec | O13: 2013/03-2 | P13: CEC | Q13: 1 | R13: A.JAHUEL 220 | S13: 21276.417 | T13: 1548136 | W13: 72.763
A14: 01-11-2020 | B14: 01-11-2020 | C14: Licitación Eolica San Juan y Cec (SIC 2013/03-2) BS2A | D14: Potencia Licitaciones | E14: Potencia | F14: Lic. SIC 2013/03-2 bloques BS2A: Potencia nov 2020 | G14: 2020-12-04 16:22:38 | H14: 33 | I14: 16398 | J14: s | K14: s | L14: BS2A | M14: SAN_JUAN_LAP | N14: Cec | O14: 2013/03-2 | P14: CEC | Q14: 2 | R14: A.MELIP 220 | U14: 0 | V14: 0 | W14: 6135.33
A15: 01-11-2020 | B15: 01-11-2020 | C15: Licitación Eolica San Juan y Cec (SIC 2013/03-2) BS2A | D15: Energia Licitaciones | E15: Energía | F15: Lic. SIC 2013/03-2 bloques BS2A: Energía nov 2020 | G15: 2020-12-04 16:22:38 | H15: 33 | I15: 16398 | J15: s | K15: s | L15: BS2A | M15: SAN_JUAN_LAP | N15: Cec | O15: 2013/03-2 | P15: CEC | Q15: 2 | R15: A.MELIP 220 | S15: 89.365117 | T15: 6595 | W15: 73.8
A16: 01-11-2020 | B16: 01-11-2020 | C16: Licitación Eolica San Juan y Cec (SIC 2013/03-2) BS2A | D16: Potencia Licitaciones | E16: Potencia | F16: Lic. SIC 2013/03-2 bloques BS2A: Potencia nov 2020 | G16: 2020-12-04 16:22:38 | H16: 33 | I16: 16398 | J16: s | K16: s | L16: BS2A | M16: SAN_JUAN_LAP | N16: Cec | O16: 2013/03-2 | P16: CEC | Q16: 3 | R16: CHARRUA 220 | U16: 0 | V16: 0 | W16: 5857.6
A17: 01-11-2020 | B17: 01-11-2020 | C17: Licitación Eolica San Juan y Cec (SIC 2013/03-2) BS2A | D17: Energia Licitaciones | E17: Energía | F17: Lic. SIC 2013/03-2 bloques BS2A: Energía nov 2020 | G17: 2020-12-04 16:22:38 | H17: 33 | I17: 16398 | J17: s | K17: s | L17: BS2A | M17: SAN_JUAN_LAP | N17: Cec | O17: 2013/03-2 | P17: CEC | Q17: 3 | R17: CHARRUA 220 | S17: 3208.0461 | T17: 222712 | W17: 69.423
A18: 01-11-2020 | B18: 01-11-2020 | C18: Licitación Eolica San Juan y Cec (SIC 2013/03-2) BS2A | D18: Potencia Licitaciones | E18: Potencia | F18: Lic. SIC 2013/03-2 bloques BS2A: Potencia nov 2020 | G18: 2020-12-04 16:22:38 | H18: 33 | I18: 16398 | J18: s | K18: s | L18: BS2A | M18: SAN_JUAN_LAP | N18: Cec | O18: 2013/03-2 | P18: CEC | Q18: 4 | R18: ITAHUE 220 | U18: 0 | V18: 0 | W18: 5984.39
A19: 01-11-2020 | B19: 01-11-2020 | C19: Licitación Eolica San Juan y Cec (SIC 2013/03-2) BS2A | D19: Energia Licitaciones | E19: Energía | F19: Lic. SIC 2013/03-2 bloques BS2A: Energía nov 2020 | G19: 2020-12-04 16:22:38 | H19: 33 | I19: 16398 | J19: s | K19: s | L19: BS2A | M19: SAN_JUAN_LAP | N19: Cec | O19: 2013/03-2 | P19: CEC | Q19: 4 | R19: ITAHUE 220 | S19: 26768.591 | T19: 1861354 | W19: 69.535
A20: 01-11-2020 | B20: 01-11-2020 | C20: Licitación Eolica San Juan y Cec (SIC 2013/03-2) BS2A | D20: Potencia Licitaciones | E20: Potencia | F20: Lic. SIC 2013/03-2 bloques BS2A: Potencia nov 2020 | G20: 2020-12-04 16:22:38 | H20: 33 | I20: 16398 | J20: s | K20: s | L20: BS2A | M20: SAN_JUAN_LAP | N20: Cec | O20: 2013/03-2 | P20: CEC | Q20: 5 | R20: RAPEL 220 | U20: 0 | V20: 0 | W20: 5746.51
A21: 01-11-2020 | B21: 01-11-2020 | C21: Licitación Eolica San Juan y Cec (SIC 2013/03-2) BS2A | D21: Energia Licitaciones | E21: Energía | F21: Lic. SIC 2013/03-2 bloques BS2A: Energía nov 2020 | G21: 2020-12-04 16:22:38 | H21: 33 | I21: 16398 | J21: s | K21: s | L21: BS2A | M21: SAN_JUAN_LAP | N21: Cec | O21: 2013/03-2 | P21: CEC | Q21: 5 | R21: RAPEL 220 | S21: 109.99316 | T21: 7903 | W21: 71.854
A22: 01-12-2020 | B22: 01-12-2020 | C22: Licitación Eolica San Juan y Cec (SIC 2013/03-2) BS2A | D22: Potencia Licitaciones | E22: Potencia | F22: Lic. SIC 2013/03-2 bloques BS2A: Potencia dic 2020 | G22: 2021-01-07 17:06:30 | H22: 33 | I22: 16766 | J22: s | K22: s | L22: BS2A | M22: SAN_JUAN_LAP | N22: Cec | O22: 2013/03-2 | P22: CEC | Q22: 1 | R22: A.JAHUEL 220 | U22: 0 | V22: 0 | W22: 6059.26
A23: 01-12-2020 | B23: 01-12-2020 | C23: Licitación Eolica San Juan y Cec (SIC 2013/03-2) BS2A | D23: Energia Licitaciones | E23: Energía | F23: Lic. SIC 2013/03-2 bloques BS2A: Energía dic 2020 | G23: 2021-01-07 17:06:30 | H23: 33 | I23: 16766 | J23: s | K23: s | L23: BS2A | M23: SAN_JUAN_LAP | N23: Cec | O23: 2013/03-2 | P23: CEC | Q23: 1 | R23: A.JAHUEL 220 | S23: 27412.592 | T23: 1994622 | W23: 72.763
A24: 01-12-2020 | B24: 01-12-2020 | C24: Licitación Eolica San Juan y Cec (SIC 2013/03-2) BS2A | D24: Potencia Licitaciones | E24: Potencia | F24: Lic. SIC 2013/03-2 bloques BS2A: Potencia dic 2020 | G24: 2021-01-07 17:06:30 | H24: 33 | I24: 16766 | J24: s | K24: s | L24: BS2A | M24: SAN_JUAN_LAP | N24: Cec | O24: 2013/03-2 | P24: CEC | Q24: 2 | R24: A.MELIP 220 | U24: 0 | V24: 0 | W24: 6135.33
A25: 01-12-2020 | B25: 01-12-2020 | C25: Licitación Eolica San Juan y Cec (SIC 2013/03-2) BS2A | D25: Energia Licitaciones | E25: Energía | F25: Lic. SIC 2013/03-2 bloques BS2A: Energía dic 2020 | G25: 2021-01-07 17:06:30 | H25: 33 | I25: 16766 | J25: s | K25: s | L25: BS2A | M25: SAN_JUAN_LAP | N25: Cec | O25: 2013/03-2 | P25: CEC | Q25: 2 | R25: A.MELIP 220 | S25: 111.38554 | T25: 8220 | W25: 73.8
A26: 01-12-2020 | B26: 01-12-2020 | C26: Licitación Eolica San Juan y Cec (SIC 2013/03-2) BS2A | D26: Potencia Licitaciones | E26: Potencia | F26: Lic. SIC 2013/03-2 bloques BS2A: Potencia dic 2020 | G26: 2021-01-07 17:06:30 | H26: 33 | I26: 16766 | J26: s | K26: s | L26: BS2A | M26: SAN_JUAN_LAP | N26: Cec | O26: 2013/03-2 | P26: CEC | Q26: 3 | R26: CHARRUA 220 | U26: 0 | V26: 0 | W26: 5857.6
A27: 01-12-2020 | B27: 01-12-2020 | C27: Licitación Eolica San Juan y Cec (SIC 2013/03-2) BS2A | D27: Energia Licitaciones | E27: Energía | F27: Lic. SIC 2013/03-2 bloques BS2A: Energía dic 2020 | G27: 2021-01-07 17:06:30 | H27: 33 | I27: 16766 | J27: s | K27: s | L27: BS2A | M27: SAN_JUAN_LAP | N27: Cec | O27: 2013/03-2 | P27: CEC | Q27: 3 | R27: CHARRUA 220 | S27: 4163.1976 | T27: 289022 | W27: 69.423
A28: 01-12-2020 | B28: 01-12-2020 | C28: Licitación Eolica San Juan y Cec (SIC 2013/03-2) BS2A | D28: Potencia Licitaciones | E28: Potencia | F28: Lic. SIC 2013/03-2 bloques BS2A: Potencia dic 2020 | G28: 2021-01-07 17:06:30 | H28: 33 | I28: 16766 | J28: s | K28: s | L28: BS2A | M28: SAN_JUAN_LAP | N28: Cec | O28: 2013/03-2 | P28: CEC | Q28: 4 | R28: ITAHUE 220 | U28: 0 | V28: 0 | W28: 5984.39
A29: 01-12-2020 | B29: 01-12-2020 | C29: Licitación Eolica San Juan y Cec (SIC 2013/03-2) BS2A | D29: Energia Licitaciones | E29: Energía | F29: Lic. SIC 2013/03-2 bloques BS2A: Energía dic 2020 | G29: 2021-01-07 17:06:30 | H29: 33 | I29: 16766 | J29: s | K29: s | L29: BS2A | M29: SAN_JUAN_LAP | N29: Cec | O29: 2013/03-2 | P29: CEC | Q29: 4 | R29: ITAHUE 220 | S29: 34307.345 | T29: 2385561 | W29: 69.535
A30: 01-12-2020 | B30: 01-12-2020 | C30: Licitación Eolica San Juan y Cec (SIC 2013/03-2) BS2A | D30: Potencia Licitaciones | E30: Potencia | F30: Lic. SIC 2013/03-2 bloques BS2A: Potencia dic 2020 | G30: 2021-01-07 17:06:30 | H30: 33 | I30: 16766 | J30: s | K30: s | L30: BS2A | M30: SAN_JUAN_LAP | N30: Cec | O30: 2013/03-2 | P30: CEC | Q30: 5 | R30: RAPEL 220 | U30: 0 | V30: 0 | W30: 5746.51
A31: 01-12-2020 | B31: 01-12-2020 | C31: Licitación Eolica San Juan y Cec (SIC 2013/03-2) BS2A | D31: Energia Licitaciones | E31: Energía | F31: Lic. SIC 2013/03-2 bloques BS2A: Energía dic 2020 | G31: 2021-01-07 17:06:30 | H31: 33 | I31: 16766 | J31: s | K31: s | L31: BS2A | M31: SAN_JUAN_LAP | N31: Cec | O31: 2013/03-2 | P31: CEC | Q31: 5 | R31: RAPEL 220 | S31: 140.14268 | T31: 10070 | W31: 71.854
A32: 01-01-2021 | B32: 01-01-2021 | C32: Licitación Eolica San Juan y Cec (SIC 2013/03-2) BS2A | D32: Potencia Licitaciones | E32: Potencia | F32: Lic. SIC 2013/03-2 bloques BS2A: Potencia ene 2021 | G32: 2021-02-09 11:19:03 | H32: 33 | I32: 17142 | J32: s | K32: s | L32: BS2A | M32: SAN_JUAN_LAP | N32: Cec | O32: 2013/03-2 | P32: CEC | Q32: 1 | R32: A.JAHUEL 220 | U32: 0 | V32: 0 | W32: 5914.42
A33: 01-01-2021 | B33: 01-01-2021 | C33: Licitación Eolica San Juan y Cec (SIC 2013/03-2) BS2A | D33: Energia Licitaciones | E33: Energía | F33: Lic. SIC 2013/03-2 bloques BS2A: Energía ene 2021 | G33: 2021-02-09 11:19:03 | H33: 33 | I33: 17142 | J33: s | K33: s | L33: BS2A | M33: SAN_JUAN_LAP | N33: Cec | O33: 2013/03-2 | P33: CEC | Q33: 1 | R33: A.JAHUEL 220 | S33: 22217.748 | T33: 1714366 | W33: 77.162
A34: 01-01-2021 | B34: 01-01-2021 | C34: Licitación Eolica San Juan y Cec (SIC 2013/03-2) BS2A | D34: Potencia Licitaciones | E34: Potencia | F34: Lic. SIC 2013/03-2 bloques BS2A: Potencia ene 2021 | G34: 2021-02-09 11:19:03 | H34: 33 | I34: 17142 | J34: s | K34: s | L34: BS2A | M34: SAN_JUAN_LAP | N34: Cec | O34: 2013/03-2 | P34: CEC | Q34: 2 | R34: A.MELIP 220 | U34: 0 | V34: 0 | W34: 6007.37
A35: 01-01-2021 | B35: 01-01-2021 | C35: Licitación Eolica San Juan y Cec (SIC 2013/03-2) BS2A | D35: Energia Licitaciones | E35: Energía | F35: Lic. SIC 2013/03-2 bloques BS2A: Energía ene 2021 | G35: 2021-02-09 11:19:03 | H35: 33 | I35: 17142 | J35: s | K35: s | L35: BS2A | M35: SAN_JUAN_LAP | N35: Cec | O35: 2013/03-2 | P35: CEC | Q35: 2 | R35: A.MELIP 220 | S35: 72.195624 | T35: 5676 | W35: 78.626
A36: 01-01-2021 | B36: 01-01-2021 | C36: Licitación Eolica San Juan y Cec (SIC 2013/03-2) BS2A | D36: Potencia Licitaciones | E36: Potencia | F36: Lic. SIC 2013/03-2 bloques BS2A: Potencia ene 2021 | G36: 2021-02-09 11:19:03 | H36: 33 | I36: 17142 | J36: s | K36: s | L36: BS2A | M36: SAN_JUAN_LAP | N36: Cec | O36: 2013/03-2 | P36: CEC | Q36: 3 | R36: CHARRUA 220 | U36: 0 | V36: 0 | W36: 5302.48
A37: 01-01-2021 | B37: 01-01-2021 | C37: Licitación Eolica San Juan y Cec (SIC 2013/03-2) BS2A | D37: Energia Licitaciones | E37: Energía | F37: Lic. SIC 2013/03-2 bloques BS2A: Energía ene 2021 | G37: 2021-02-09 11:19:03 | H37: 33 | I37: 17142 | J37: s | K37: s | L37: BS2A | M37: SAN_JUAN_LAP | N37: Cec | O37: 2013/03-2 | P37: CEC | Q37: 3 | R37: CHARRUA 220 | S37: 2402.761 | T37: 171031 | W37: 71.181
A38: 01-01-2021 | B38: 01-01-2021 | C38: Licitación Eolica San Juan y Cec (SIC 2013/03-2) BS2A | D38: Potencia Licitaciones | E38: Potencia | F38: Lic. SIC 2013/03-2 bloques BS2A: Potencia ene 2021 | G38: 2021-02-09 11:19:03 | H38: 33 | I38: 17142 | J38: s | K38: s | L38: BS2A | M38: SAN_JUAN_LAP | N38: Cec | O38: 2013/03-2 | P38: CEC | Q38: 4 | R38: ITAHUE 220 | U38: 0 | V38: 0 | W38: 5512.82
A39: 01-01-2021 | B39: 01-01-2021 | C39: Licitación Eolica San Juan y Cec (SIC 2013/03-2) BS2A | D39: Energia Licitaciones | E39: Energía | F39: Lic. SIC 2013/03-2 bloques BS2A: Energía ene 2021 | G39: 2021-02-09 11:19:03 | H39: 33 | I39: 17142 | J39: s | K39: s | L39: BS2A | M39: SAN_JUAN_LAP | N39: Cec | O39: 2013/03-2 | P39: CEC | Q39: 4 | R39: ITAHUE 220 | S39: 27471.494 | T39: 1995667 | W39: 72.645
A40: 01-01-2021 | B40: 01-01-2021 | C40: Licitación Eolica San Juan y Cec (SIC 2013/03-2) BS2A | D40: Potencia Licitaciones | E40: Potencia | F40: Lic. SIC 2013/03-2 bloques BS2A: Potencia ene 2021 | G40: 2021-02-09 11:19:03 | H40: 33 | I40: 17142 | J40: s | K40: s | L40: BS2A | M40: SAN_JUAN_LAP | N40: Cec | O40: 2013/03-2 | P40: CEC | Q40: 5 | R40: RAPEL 220 | U40: 0 | V40: 0 | W40: 5963.28
...

Sheet SIGGE_E
A1: Periodo | B1: MesDevengado | C1: Nombre | D1: Concepto | E1: Agrupacion | F1: Glosa | G1: FechaCarga | H1: TipoDocumento | I1: Folio | J1: Vendedor | K1: Comprador | L1: Bloque | M1: Empresa | N1: ClaveEEDD | O1: Licitacion | P1: NomAgrupacion | Q1: Num | R1: Barra | S1: Energia | T1: MontoEnergia | U1: Potencia | V1: MontoPotencia | W1: Precio
A2: 01-10-2020 | B2: 01-10-2020 | C2: Licitación Eolica San Juan y Cec (SIC 2013/03-2) BS2A | D2: Energia Licitaciones | E2: Energía | F2: Lic. SIC 2013/03-2 bloques BS2A: Energía oct 2020 | G2: 2020-11-06 19:47:10 | H2: 33 | I2: 15439 | J2: s | K2: s | L2: BS2A | M2: SAN_JUAN_LAP | N2: Cec | O2: 2013/03-2 | P2: CEC | Q2: 1 | R2: A.JAHUEL 220 | S2: 18230.56 | T2: 1326510 | W2: 72.763
A3: 01-10-2020 | B3: 01-10-2020 | C3: Licitación Eolica San Juan y Cec (SIC 2013/03-2) BS2A | D3: Energia Licitaciones | E3: Energía | F3: Lic. SIC 2013/03-2 bloques BS2A: Energía oct 2020 | G3: 2020-11-06 19:47:10 | H3: 33 | I3: 15439 | J3: s | K3: s | L3: BS2A | M3: SAN_JUAN_LAP | N3: Cec | O3: 2013/03-2 | P3: CEC | Q3: 2 | R3: A.MELIP 220 | S3: 79.411571 | T3: 5861 | W3: 73.8
A4: 01-10-2020 | B4: 01-10-2020 | C4: Licitación Eolica San Juan y Cec (SIC 2013/03-2) BS2A | D4: Energia Licitaciones | E4: Energía | F4: Lic. SIC 2013/03-2 bloques BS2A: Energía oct 2020 | G4: 2020-11-06 19:47:10 | H4: 33 | I4: 15439 | J4: s | K4: s | L4: BS2A | M4: SAN_JUAN_LAP | N4: Cec | O4: 2013/03-2 | P4: CEC | Q4: 3 | R4: CHARRUA 220 | S4: 2695.4699 | T4: 187128 | W4: 69.423
A5: 01-10-2020 | B5: 01-10-2020 | C5: Licitación Eolica San Juan y Cec (SIC 2013/03-2) BS2A | D5: Energia Licitaciones | E5: Energía | F5: Lic. SIC 2013/03-2 bloques BS2A: Energía oct 2020 | G5: 2020-11-06 19:47:10 | H5: 33 | I5: 15439 | J5: s | K5: s | L5: BS2A | M5: SAN_JUAN_LAP | N5: Cec | O5: 2013/03-2 | P5: CEC | Q5: 4 | R5: ITAHUE 220 | S5: 23046.249 | T5: 1602521 | W5: 69.535
A6: 01-10-2020 | B6: 01-10-2020 | C6: Licitación Eolica San Juan y Cec (SIC 2013/03-2) BS2A | D6: Energia Licitaciones | E6: Energía | F6: Lic. SIC 2013/03-2 bloques BS2A: Energía oct 2020 | G6: 2020-11-06 19:47:10 | H6: 33 | I6: 15439 | J6: s | K6: s | L6: BS2A | M6: SAN_JUAN_LAP | N6: Cec | O6: 2013/03-2 | P6: CEC | Q6: 5 | R6: RAPEL 220 | S6: 95.14513 | T6: 6837 | W6: 71.854
A7: 01-11-2020 | B7: 01-11-2020 | C7: Licitación Eolica San Juan y Cec (SIC 2013/03-2) BS2A | D7: Energia Licitaciones | E7: Energía | F7: Lic. SIC 2013/03-2 bloques BS2A: Energía nov 2020 | G7: 2020-12-04 16:22:38 | H7: 33 | I7: 16398 | J7: s | K7: s | L7: BS2A | M7: SAN_JUAN_LAP | N7: Cec | O7: 2013/03-2 | P7: CEC | Q7: 1 | R7: A.JAHUEL 220 | S7: 21276.417 | T7: 1548136 | W7: 72.763
A8: 01-11-2020 | B8: 01-11-2020 | C8: Licitación Eolica San Juan y Cec (SIC 2013/03-2) BS2A | D8: Energia Licitaciones | E8: Energía | F8: Lic. SIC 2013/03-2 bloques BS2A: Energía nov 2020 | G8: 2020-12-04 16:22:38 | H8: 33 | I8: 16398 | J8: s | K8: s | L8: BS2A | M8: SAN_JUAN_LAP | N8: Cec | O8: 2013/03-2 | P8: CEC | Q8: 2 | R8: A.MELIP 220 | S8: 89.365117 | T8: 6595 | W8: 73.8
A9: 01-11-2020 | B9: 01-11-2020 | C9: Licitación Eolica San Juan y Cec (SIC 2013/03-2) BS2A | D9: Energia Licitaciones | E9: Energía | F9: Lic. SIC 2013/03-2 bloques BS2A: Energía nov 2020 | G9: 2020-12-04 16:22:38 | H9: 33 | I9: 16398 | J9: s | K9: s | L9: BS2A | M9: SAN_JUAN_LAP | N9: Cec | O9: 2013/03-2 | P9: CEC | Q9: 3 | R9: CHARRUA 220 | S9: 3208.0461 | T9: 222712 | W9: 69.423
A10: 01-11-2020 | B10: 01-11-2020 | C10: Licitación Eolica San Juan y Cec (SIC 2013/03-2) BS2A | D10: Energia Licitaciones | E10: Energía | F10: Lic. SIC 2013/03-2 bloques BS2A: Energía nov 2020 | G10: 2020-12-04 16:22:38 | H10: 33 | I10: 16398 | J10: s | K10: s | L10: BS2A | M10: SAN_JUAN_LAP | N10: Cec | O10: 2013/03-2 | P10: CEC | Q10: 4 | R10: ITAHUE 220 | S10: 26768.591 | T10: 1861354 | W10: 69.535
A11: 01-11-2020 | B11: 01-11-2020 | C11: Licitación Eolica San Juan y Cec (SIC 2013/03-2) BS2A | D11: Energia Licitaciones | E11: Energía | F11: Lic. SIC 2013/03-2 bloques BS2A: Energía nov 2020 | G11: 2020-12-04 16:22:38 | H11: 33 | I11: 16398 | J11: s | K11: s | L11: BS2A | M11: SAN_JUAN_LAP | N11: Cec | O11: 2013/03-2 | P11: CEC | Q11: 5 | R11: RAPEL 220 | S11: 109.99316 | T11: 7903 | W11: 71.854
A12: 01-12-2020 | B12: 01-12-2020 | C12: Licitación Eolica San Juan y Cec (SIC 2013/03-2) BS2A | D12: Energia Licitaciones | E12: Energía | F12: Lic. SIC 2013/03-2 bloques BS2A: Energía dic 2020 | G12: 2021-01-07 17:06:30 | H12: 33 | I12: 16766 | J12: s | K12: s | L12: BS2A | M12: SAN_JUAN_LAP | N12: Cec | O12: 2013/03-2 | P12: CEC | Q12: 1 | R12: A.JAHUEL 220 | S12: 27412.592 | T12: 1994622 | W12: 72.763
A13: 01-12-2020 | B13: 01-12-2020 | C13: Licitación Eolica San Juan y Cec (SIC 2013/03-2) BS2A | D13: Energia Licitaciones | E13: Energía | F13: Lic. SIC 2013/03-2 bloques BS2A: Energía dic 2020 | G13: 2021-01-07 17:06:30 | H13: 33 | I13: 16766 | J13: s | K13: s | L13: BS2A | M13: SAN_JUAN_LAP | N13: Cec | O13: 2013/03-2 | P13: CEC | Q13: 2 | R13: A.MELIP 220 | S13: 111.38554 | T13: 8220 | W13: 73.8
... A31: 01-03-2021 | B31: 01-03-2021 | C31: Licitación Eolica San Juan y Cec (SIC 2013/03-2) BS2A | D31: Energia Licitaciones | E31: Energía | F31: Lic. SIC 2013/03-2 bloques BS2A: Energía mar 2021 | G31: 2021-04-08 11:44:36 | H31: 33 | I31: 18244 | J31: s | K31: s | L31: BS2A | M31: SAN_JUAN_LAP | N31: Cec | O31: 2013/03-2 | P31: CEC | Q31: 5 | R31: RAPEL 220 | S31: 66.575164 | T31: 5222 | W31: 78.444

Sheet SIGGE_P
A1: Periodo | B1: MesDevengado | C1: Nombre | D1: Concepto | E1: Agrupacion | F1: Glosa | G1: FechaCarga | H1: TipoDocumento | I1: Folio | J1: Vendedor | K1: Comprador | L1: Bloque | M1: Empresa | N1: ClaveEEDD | O1: Licitacion | P1: NomAgrupacion | Q1: Num | R1: Barra | S1: Energia | T1: MontoEnergia | U1: Potencia | V1: MontoPotencia | W1: Precio
A2: 01-10-2020 | B2: 01-10-2020 | C2: Licitación Eolica San Juan y Cec (SIC 2013/03-2) BS2A | D2: Potencia Licitaciones | E2: Potencia | F2: Lic. SIC 2013/03-2 bloques BS2A: Potencia oct 2020 | G2: 2020-11-06 19:47:10 | H2: 33 | I2: 15439 | J2: s | K2: s | L2: BS2A | M2: SAN_JUAN_LAP | N2: Cec | O2: 2013/03-2 | P2: CEC | Q2: 1 | R2: A.JAHUEL 220 | U2: 0 | V2: 0 | W2: 6059.26
A3: 01-10-2020 | B3: 01-10-2020 | C3: Licitación Eolica San Juan y Cec (SIC 2013/03-2) BS2A | D3: Potencia Licitaciones | E3: Potencia | F3: Lic. SIC 2013/03-2 bloques BS2A: Potencia oct 2020 | G3: 2020-11-06 19:47:10 | H3: 33 | I3: 15439 | J3: s | K3: s | L3: BS2A | M3: SAN_JUAN_LAP | N3: Cec | O3: 2013/03-2 | P3: CEC | Q3: 2 | R3: A.MELIP 220 | U3: 0 | V3: 0 | W3: 6135.33
A4: 01-10-2020 | B4: 01-10-2020 | C4: Licitación Eolica San Juan y Cec (SIC 2013/03-2) BS2A | D4: Potencia Licitaciones | E4: Potencia | F4: Lic. SIC 2013/03-2 bloques BS2A: Potencia oct 2020 | G4: 2020-11-06 19:47:10 | H4: 33 | I4: 15439 | J4: s | K4: s | L4: BS2A | M4: SAN_JUAN_LAP | N4: Cec | O4: 2013/03-2 | P4: CEC | Q4: 3 | R4: CHARRUA 220 | U4: 0 | V4: 0 | W4: 5857.6
A5: 01-10-2020 | B5: 01-10-2020 | C5: Licitación Eolica San Juan y Cec (SIC 2013/03-2) BS2A | D5: Potencia Licitaciones | E5: Potencia | F5: Lic. SIC 2013/03-2 bloques BS2A: Potencia oct 2020 | G5: 2020-11-06 19:47:10 | H5: 33 | I5: 15439 | J5: s | K5: s | L5: BS2A | M5: SAN_JUAN_LAP | N5: Cec | O5: 2013/03-2 | P5: CEC | Q5: 4 | R5: ITAHUE 220 | U5: 0 | V5: 0 | W5: 5984.39
A6: 01-10-2020 | B6: 01-10-2020 | C6: Licitación Eolica San Juan y Cec (SIC 2013/03-2) BS2A | D6: Potencia Licitaciones | E6: Potencia | F6: Lic. SIC 2013/03-2 bloques BS2A: Potencia oct 2020 | G6: 2020-11-06 19:47:10 | H6: 33 | I6: 15439 | J6: s | K6: s | L6: BS2A | M6: SAN_JUAN_LAP | N6: Cec | O6: 2013/03-2 | P6: CEC | Q6: 5 | R6: RAPEL 220 | U6: 0 | V6: 0 | W6: 5746.51
A7: 01-11-2020 | B7: 01-11-2020 | C7: Licitación Eolica San Juan y Cec (SIC 2013/03-2) BS2A | D7: Potencia Licitaciones | E7: Potencia | F7: Lic. SIC 2013/03-2 bloques BS2A: Potencia nov 2020 | G7: 2020-12-04 16:22:38 | H7: 33 | I7: 16398 | J7: s | K7: s | L7: BS2A | M7: SAN_JUAN_LAP | N7: Cec | O7: 2013/03-2 | P7: CEC | Q7: 1 | R7: A.JAHUEL 220 | U7: 0 | V7: 0 | W7: 6059.26
A8: 01-11-2020 | B8: 01-11-2020 | C8: Licitación Eolica San Juan y Cec (SIC 2013/03-2) BS2A | D8: Potencia Licitaciones | E8: Potencia | F8: Lic. SIC 2013/03-2 bloques BS2A: Potencia nov 2020 | G8: 2020-12-04 16:22:38 | H8: 33 | I8: 16398 | J8: s | K8: s | L8: BS2A | M8: SAN_JUAN_LAP | N8: Cec | O8: 2013/03-2 | P8: CEC | Q8: 2 | R8: A.MELIP 220 | U8: 0 | V8: 0 | W8: 6135.33
A9: 01-11-2020 | B9: 01-11-2020 | C9: Licitación Eolica San Juan y Cec (SIC 2013/03-2) BS2A | D9: Potencia Licitaciones | E9: Potencia | F9: Lic. SIC 2013/03-2 bloques BS2A: Potencia nov 2020 | G9: 2020-12-04 16:22:38 | H9: 33 | I9: 16398 | J9: s | K9: s | L9: BS2A | M9: SAN_JUAN_LAP | N9: Cec | O9: 2013/03-2 | P9: CEC | Q9: 3 | R9: CHARRUA 220 | U9: 0 | V9: 0 | W9: 5857.6
A10: 01-11-2020 | B10: 01-11-2020 | C10: Licitación Eolica San Juan y Cec (SIC 2013/03-2) BS2A | D10: Potencia Licitaciones | E10: Potencia | F10: Lic. SIC 2013/03-2 bloques BS2A: Potencia nov 2020 | G10: 2020-12-04 16:22:38 | H10: 33 | I10: 16398 | J10: s | K10: s | L10: BS2A | M10: SAN_JUAN_LAP | N10: Cec | O10: 2013/03-2 | P10: CEC | Q10: 4 | R10: ITAHUE 220 | U10: 0 | V10: 0 | W10: 5984.39
A11: 01-11-2020 | B11: 01-11-2020 | C11: Licitación Eolica San Juan y Cec (SIC 2013/03-2) BS2A | D11: Potencia Licitaciones | E11: Potencia | F11: Lic. SIC 2013/03-2 bloques BS2A: Potencia nov 2020 | G11: 2020-12-04 16:22:38 | H11: 33 | I11: 16398 | J11: s | K11: s | L11: BS2A | M11: SAN_JUAN_LAP | N11: Cec | O11: 2013/03-2 | P11: CEC | Q11: 5 | R11: RAPEL 220 | U11: 0 | V11: 0 | W11: 5746.51
A12: 01-12-2020 | B12: 01-12-2020 | C12: Licitación Eolica San Juan y Cec (SIC 2013/03-2) BS2A | D12: Potencia Licitaciones | E12: Potencia | F12: Lic. SIC 2013/03-2 bloques BS2A: Potencia dic 2020 | G12: 2021-01-07 17:06:30 | H12: 33 | I12: 16766 | J12: s | K12: s | L12: BS2A | M12: SAN_JUAN_LAP | N12: Cec | O12: 2013/03-2 | P12: CEC | Q12: 1 | R12: A.JAHUEL 220 | U12: 0 | V12: 0 | W12: 6059.26
A13: 01-12-2020 | B13: 01-12-2020 | C13: Licitación Eolica San Juan y Cec (SIC 2013/03-2) BS2A | D13: Potencia Licitaciones | E13: Potencia | F13: Lic. SIC 2013/03-2 bloques BS2A: Potencia dic 2020 | G13: 2021-01-07 17:06:30 | H13: 33 | I13: 16766 | J13: s | K13: s | L13: BS2A | M13: SAN_JUAN_LAP | N13: Cec | O13: 2013/03-2 | P13: CEC | Q13: 2 | R13: A.MELIP 220 | U13: 0 | V13: 0 | W13: 6135.33
... A31: 01-03-2021 | B31: 01-03-2021 | C31: Licitación Eolica San Juan y Cec (SIC 2013/03-2) BS2A | D31: Potencia Licitaciones | E31: Potencia | F31: Lic. SIC 2013/03-2 bloques BS2A: Potencia mar 2021 | G31: 2021-04-08 11:44:36 | H31: 33 | I31: 18244 | J31: s | K31: s | L31: BS2A | M31: SAN_JUAN_LAP | N31: Cec | O31: 2013/03-2 | P31: CEC | Q31: 5 | R31: RAPEL 220 | U31: 0 | V31: 0 | W31: 5963.281

Sheet EFACT_CNE
A1: IdContrato | B1: MesDevengado | C1: Anho | D1: Mes | E1: Codigo | F1: DX | G1: NomEmpresaDistribuidora | H1: GX | I1: NomSuministrador | J1: CodigoContrato | K1: PuntoRetiro | L1: Contrato | M1: Energia_kWh | N1: Potencia_kW | O1: Sistema | P1: DataCreated | Q1: IdBarra | R1: NomBarra | S1: Energia | T1: TotalEnergiaAjustado | U1: Potencia | V1: TotalPotenciaAjustado | W1: EmpresaDistribuidora | X1: PrecioEnergia | Y1: PrecioEnergiaAjustado | Z1: TotalEnergia | AA1: PrecioPotencia | AB1: PrecioPotenciaAjustado | AC1: TotalPotencia | AD1: Fecha
A2: -1 | B2: 01-10-2020 | C2: 2020 | D2: 10 | E2: Curico 13.2 | F2: CEC | G2: CEC | H2: San Juan SpA. | I2: San Juan SpA. | J2: SIC 2013/03_2_BS2A_BB_CEC_San Juan SpA. | K2: Curico 13.2 | L2: -1 | M2: 23564.346 | N2: 0 | O2: 5 | P2: 44676.579 | Q2: 8 | R2: ALTO JAHUEL 220 | S2: 9529.2322 | T2: 693038.26 | U2: 0 | V2: 0 | W2: CEC | X2: 82.73903 | Y2: 693.03826 | Z2: 788439.43 | AA2: 0 | AB2: 0 | AC2: 0 | AD2: 44105
A3: -1 | B3: 01-10-2020 | C3: 2020 | D3: 10 | E3: Curico 13.2 | F3: CEC | G3: CEC | H3: San Juan SpA. | I3: San Juan SpA. | J3: SIC 2013/03_2_BS2A_BB_CEC_San Juan SpA. | K3: Curico 13.2 | L3: -1 | M3: 23564.346 | N3: 0 | O3: 5 | P3: 44676.579 | Q3: 34 | R3: CHARRUA 220 | S3: 1924.9767 | T3: 133572.77 | U3: 0 | V3: 0 | W3: CEC | X3: 78.941173 | Y3: 133.57277 | Z3: 151959.92 | AA3: 0 | AB3: 0 | AC3: 0 | AD3: 44105
A4: -1 | B4: 01-10-2020 | C4: 2020 | D4: 10 | E4: Curico 13.2 | F4: CEC | G4: CEC | H4: San Juan SpA. | I4: San Juan SpA. | J4: SIC 2013/03_2_BS2A_BB_CEC_San Juan SpA. | K4: Curico 13.2 | L4: -1 | M4: 23564.346 | N4: 0 | O4: 5 | P4: 44676.579 | Q4: 23 | R4: ITAHUE 220 | S4: 12591.197 | T4: 875101.6 | U4: 0 | V4: 0 | W4: CEC | X4: 79.068333 | Y4: 875.1016 | Z4: 995564.96 | AA4: 0 | AB4: 0 | AC4: 0 | AD4: 44105
A5: -1 | B5: 01-10-2020 | C5: 2020 | D5: 10 | E5: Curico 13.2 | F5: CEC | G5: CEC | H5: San Juan SpA. | I5: San Juan SpA. | J5: SIC 2013/03_2_BS2A_BB_CEC_San Juan SpA. | K5: Curico 13.2 | L5: -1 | M5: 23564.346 | N5: 0 | O5: 5 | P5: 44676.579 | Q5: 13 | R5: MELIPILLA 220 | S5: 42.985882 | T5: 3170.784 | U5: 0 | V5: 0 | W5: CEC | X5: 83.917383 | Y5: 3.170784 | Z5: 3607.2628 | AA5: 0 | AB5: 0 | AC5: 0 | AD5: 44105
A6: -1 | B6: 01-10-2020 | C6: 2020 | D6: 10 | E6: Curico 13.2 | F6: CEC | G6: CEC | H6: San Juan SpA. | I6: San Juan SpA. | J6: SIC 2013/03_2_BS2A_BB_CEC_San Juan SpA. | K6: Curico 13.2 | L6: -1 | M6: 23564.346 | N6: 0 | O6: 5 | P6: 44676.579 | Q6: 22 | R6: RAPEL 220 | S6: 55.376932 | T6: 3977.0888 | U6: 0 | V6: 0 | W6: CEC | X6: 81.704792 | Y6: 3.9770888 | Z6: 4524.5607 | AA6: 0 | AB6: 0 | AC6: 0 | AD6: 44105
A7: -1 | B7: 01-10-2020 | C7: 2020 | D7: 10 | E7: Quinta 13.8 | F7: CEC | G7: CEC | H7: San Juan SpA. | I7: San Juan SpA. | J7: SIC 2013/03_2_BS2A_BB_CEC_San Juan SpA. | K7: Quinta 13.8 | L7: -1 | M7: 5360.0959 | N7: 0 | O7: 5 | P7: 44676.579 | Q7: 8 | R7: ALTO JAHUEL 220 | S7: 2621.6114 | T7: 190663.53 | U7: 0 | V7: 0 | W7: CEC | X7: 82.73903 | Y7: 190.66353 | Z7: 216909.59 | AA7: 0 | AB7: 0 | AC7: 0 | AD7: 44105
A8: -1 | B8: 01-10-2020 | C8: 2020 | D8: 10 | E8: Quinta 13.8 | F8: CEC | G8: CEC | H8: San Juan SpA. | I8: San Juan SpA. | J8: SIC 2013/03_2_BS2A_BB_CEC_San Juan SpA. | K8: Quinta 13.8 | L8: -1 | M8: 5360.0959 | N8: 0 | O8: 5 | P8: 44676.579 | Q8: 34 | R8: CHARRUA 220 | S8: 279.65327 | T8: 19404.942 | U8: 0 | V8: 0 | W8: CEC | X8: 78.941173 | Y8: 19.404942 | Z8: 22076.157 | AA8: 0 | AB8: 0 | AC8: 0 | AD8: 44105
A9: -1 | B9: 01-10-2020 | C9: 2020 | D9: 10 | E9: Quinta 13.8 | F9: CEC | G9: CEC | H9: San Juan SpA. | I9: San Juan SpA. | J9: SIC 2013/03_2_BS2A_BB_CEC_San Juan SpA. | K9: Quinta 13.8 | L9: -1 | M9: 5360.0959 | N9: 0 | O9: 5 | P9: 44676.579 | Q9: 23 | R9: ITAHUE 220 | S9: 2583.6296 | T9: 179565.01 | U9: 0 | V9: 0 | W9: CEC | X9: 79.068333 | Y9: 179.56501 | Z9: 204283.29 | AA9: 0 | AB9: 0 | AC9: 0 | AD9: 44105
A10: -1 | B10: 01-10-2020 | C10: 2020 | D10: 10 | E10: Quinta 13.8 | F10: CEC | G10: CEC | H10: San Juan SpA. | I10: San Juan SpA. | J10: SIC 2013/03_2_BS2A_BB_CEC_San Juan SpA. | K10: Quinta 13.8 | L10: -1 | M10: 5360.0959 | N10: 0 | O10: 5 | P10: 44676.579 | Q10: 22 | R10: RAPEL 220 | S10: 7.000787 | T10: 502.7861 | U10: 0 | V10: 0 | W10: CEC | X10: 81.704792 | Y10: 0.5027861 | Z10: 571.99784 | AA10: 0 | AB10: 0 | AC10: 0 | AD10: 44105
A11: -1 | B11: 01-10-2020 | C11: 2020 | D11: 10 | E11: Teno 13.2 | F11: CEC | G11: CEC | H11: San Juan SpA. | I11: San Juan SpA. | J11: SIC 2013/03_2_BS2A_BB_CEC_San Juan SpA. | K11: Teno 13.2 | L11: -1 | M11: 13778.674 | N11: 0 | O11: 5 | P11: 44676.579 | Q11: 8 | R11: ALTO JAHUEL 220 | S11: 5917.1469 | T11: 430339.94 | U11: 0 | V11: 0 | W11: CEC | X11: 82.73903 | Y11: 430.33994 | Z11: 489578.99 | AA11: 0 | AB11: 0 | AC11: 0 | AD11: 44105
A12: -1 | B12: 01-10-2020 | C12: 2020 | D12: 10 | E12: Teno 13.2 | F12: CEC | G12: CEC | H12: San Juan SpA. | I12: San Juan SpA. | J12: SIC 2013/03_2_BS2A_BB_CEC_San Juan SpA. | K12: Teno 13.2 | L12: -1 | M12: 13778.674 | N12: 0 | O12: 5 | P12: 44676.579 | Q12: 34 | R12: CHARRUA 220 | S12: 466.80138 | T12: 32391.017 | U12: 0 | V12: 0 | W12: CEC | X12: 78.941173 | Y12: 32.391017 | Z12: 36849.848 | AA12: 0 | AB12: 0 | AC12: 0 | AD12: 44105
A13: -1 | B13: 01-10-2020 | C13: 2020 | D13: 10 | E13: Teno 13.2 | F13: CEC | G13: CEC | H13: San Juan SpA. | I13: San Juan SpA. | J13: SIC 2013/03_2_BS2A_BB_CEC_San Juan SpA. | K13: Teno 13.2 | L13: -1 | M13: 13778.674 | N13: 0 | O13: 5 | P13: 44676.579 | Q13: 23 | R13: ITAHUE 220 | S13: 7665.8924 | T13: 532787.69 | U13: 0 | V13: 0 | W13: CEC | X13: 79.068333 | Y13: 532.78769 | Z13: 606129.33 | AA13: 0 | AB13: 0 | AC13: 0 | AD13: 44105
... A85: -1 | B85: 01-03-2021 | C85: 2021 | D85: 3 | E85: Teno 13.2 | F85: CEC | G85: CEC | H85: San Juan SpA. | I85: San Juan SpA. | J85: SIC 2013/03_2_BS2A_BB_CEC_San Juan SpA. | K85: Teno 13.2 | L85: -1 | M85: 9360.9751 | N85: 0 | O85: 5 | P85: 44676.579 | Q85: 22 | R85: RAPEL 220 | S85: 18.343627 | T85: 1438.4806 | U85: 0 | V85: 0 | W85: CEC | X85: 86.650333 | Y85: 1.4384806 | Z85: 1589.4814 | AA85: 0 | AB85: 0 | AC85: 0 | AD85: 44256

Sheet EfactCNE_BT
A1: IdContrato | B1: MesDevengado | C1: Anho | D1: Mes | E1: Codigo | F1: DX | G1: NomEmpresaDistribuidora | H1: GX | I1: NomSuministrador | J1: CodigoContrato | K1: PuntoRetiro | L1: Contrato | M1: Energia_kWh | N1: Potencia_kW | O1: Sistema | P1: Fecha

Sheet CEN_Energia
A1: Num | B1: MesDevengado | C1: Anho | D1: Mes | E1: Empresa | F1: Propietario | G1: Turno | H1: Distribuidora | I1: Clave | J1: PuntoRetiro | K1: Medida_kWh | L1: PuntoRetiroBT | M1: BarraEnAT | N1: FactorRef_BT_AT | O1: ValorAT | P1: Bloque | Q1: Incremento | R1: kWhAnho | S1: PorcenEnergiaAnho | T1: kWh_AnhoMes | U1: PorcenBarraAnho | V1: EnergiaBloqueAnhoMesBarra_kWh | W1: Amplificacion24h | X1: Denominador | Y1: Prorrata | Z1: EnergiaBloqueTurnoAnhoMesBarra_kWh | AA1: V_DecretoPNPVigente | AB1: V_DecretoPNCPAsociado | AC1: V_DecretoPNCPLicitacion | AD1: V_Barra | AE1: V_PrecioOferta_EnergiaPolpaico220 | AF1: V_Indexacion | AG1: V_PrecioEnergiaIndexado_USDMWh | AH1: V_DolarPNPVigente | AI1: V_FactorAjusteEnergia | AJ1: V_PrecioEnergiaAjustado_CLP_kWh_Polpaico220 | AK1: V_FPEnergia | AL1: V_PrecioEnergiaAjustado_CLP_kWh | AM1: V_PrecioPotenciaUSD_kW_Mes | AN1: V_PrecioPotenciaIndexadoUSD_kW_Mes | AO1: V_FactorAjustePotencia | AP1: V_PrecioPotenciaAjustado_CLP_kW_Mes_Polpaico220 | AQ1: V_FPPotencia | AR1: V_PrecioPotenciaAjustado_CLP_kW_Mes | AS1: V_TotalEnergiaMesBarraGxDxBloque_CLP_kW_Mes | AT1: R_DecretoPNPReliquidacion | AU1: R_DecretoPNCPAsociado | AV1: R_DecretoPNCPLicitacion | AW1: R_Barra | AX1: R_PrecioOfertaEnergiaPolpaico220 | AY1: R_Indexacion | AZ1: R_PrecioEnergiaIndexado_USDMWh | BA1: R_DolarPNPReliquidacion | BB1: R_FactorAjusteEnergia | BC1: R_PrecioEnergiaAjustado_CLP_kWh_Polpaico220 | BD1: R_FPEnergia | BE1: R_PrecioEnergiaAjustado_CLP_kWh | BF1: R_PrecioPotenciaUSD_kW_Mes | BG1: R_FactorAjustePotencia | BH1: R_PrecioPotenciaAjustado_CLP_kW_Mes_Polpaico220 | BI1: R_FPPotencia | BJ1: R_PrecioPotenciaAjustado_CLP_kW_Mes | BK1: R_TotalEnergiaMesBarraGxDxBloque_CLP_kW_Mes
A2: 3226 | B2: 01-01-2021 | C2: 2021 | D2: 1 | E2: SAN_JUAN_LAP | F2: SUM_CEC_A | G2: A | H2: CEC | I2: CCURCURIBLOQA | J2: CURICO | K2: -61394.961 | L2: CURICO | M2: ALTO JAHUEL | N2: 0.24824931 | O2: 15241.257 | P2: BS2A | Q2: 2 | W2: 2 | X2: 0 | AA2: PNP_6T_08-05-2020 | AB2: PNCP_9T_12-08-2019 | AC2: PNCP_4T_30-04-2013 | AD2: ALTO JAHUEL 220 | AE2: 100.646 | AF2: 1.072776 | AG2: 107.97062 | AH2: 694.38 | AI2: 0.875 | AJ2: 65.601057 | AK2: 0.9827 | AL2: 64.466 | AM2: 8.9176 | AN2: 9.5665875 | AO2: 0.913 | AP2: 6064.9194 | AQ2: 0.99365142 | AR2: 6026.4158 | AT2: PNP_19T_30-12-2020 | AU2: PNCP_12T_10-08-2020 | AV2: PNCP_4T_30-04-2013 | AW2: ALTO JAHUEL 220 | AX2: 100.646 | AY2: 1.0833852 | AZ2: 109.03838 | BA2: 801.49 | BB2: 0.905 | BC2: 79.090823 | BD2: 0.9753 | BE2: 77.137 | BF2: 8.9176 | BG2: 0.77 | BH2: 5962.3808 | BI2: 0.98462454 | BJ2: 5870.7065
A3: 3228 | B3: 01-01-2021 | C3: 2021 | D3: 1 | E3: SAN_JUAN_LAP | F3: SUM_CEC_A | G3: A | H3: CEC | I3: CCURCURIBLOQA | J3: CURICO | K3: -61394.961 | L3: CURICO | M3: CHARRUA | N3: 0.077540048 | O3: 4760.5682 | P3: BS2A | Q3: 2 | W3: 2 | X3: 0 | AA3: PNP_6T_08-05-2020 | AB3: PNCP_9T_12-08-2019 | AC3: PNCP_4T_30-04-2013 | AD3: CHARRUA 220 | AE3: 100.646 | AF3: 1.072776 | AG3: 107.97062 | AH3: 694.38 | AI3: 0.875 | AJ3: 65.601057 | AK3: 0.935 | AL3: 61.337 | AM3: 8.9176 | AN3: 9.5665875 | AO3: 0.913 | AP3: 6064.9194 | AQ3: 1.0961716 | AR3: 6648.1923 | AT3: PNP_19T_30-12-2020 | AU3: PNCP_12T_10-08-2020 | AV3: PNCP_4T_30-04-2013 | AW3: CHARRUA 220 | AX3: 100.646 | AY3: 1.0833852 | AZ3: 109.03838 | BA3: 801.49 | BB3: 0.905 | BC3: 79.090823 | BD3: 0.8997 | BE3: 71.158 | BF3: 8.9176 | BG3: 0.77 | BH3: 5962.3808 | BI3: 1.0261762 | BJ3: 6118.4533
A4: 3230 | B4: 01-01-2021 | C4: 2021 | D4: 1 | E4: SAN_JUAN_LAP | F4: SUM_CEC_A | G4: A | H4: CEC | I4: CCURCURIBLOQA | J4: CURICO | K4: -61394.961 | L4: CURICO | M4: ITAHUE | N4: 0.73979704 | O4: 45419.81 | P4: BS2A | Q4: 2 | W4: 2 | X4: 0 | AA4: PNP_6T_08-05-2020 | AB4: PNCP_9T_12-08-2019 | AC4: PNCP_4T_30-04-2013 | AD4: ITAHUE 220 | AE4: 100.646 | AF4: 1.072776 | AG4: 107.97062 | AH4: 694.38 | AI4: 0.875 | AJ4: 65.601057 | AK4: 0.9537 | AL4: 62.564 | AM4: 8.9176 | AN4: 9.5665875 | AO4: 0.913 | AP4: 6064.9194 | AQ4: 1.0078958 | AR4: 6112.8068 | AT4: PNP_19T_30-12-2020 | AU4: PNCP_12T_10-08-2020 | AV4: PNCP_4T_30-04-2013 | AW4: ITAHUE 220 | AX4: 100.646 | AY4: 1.0833852 | AZ4: 109.03838 | BA4: 801.49 | BB4: 0.905 | BC4: 79.090823 | BD4: 0.9182 | BE4: 72.621 | BF4: 8.9176 | BG4: 0.77 | BH4: 5962.3808 | BI4: 0.94872847 | BJ4: 5656.6804
A5: 3232 | B5: 01-01-2021 | C5: 2021 | D5: 1 | E5: SAN_JUAN_LAP | F5: SUM_CEC_A | G5: A | H5: CEC | I5: CCURCURIBLOQA | J5: CURICO | K5: -61394.961 | L5: CURICO | M5: MELIPILLA | N5: 0.0029085776 | O5: 178.572 | P5: BS2A | Q5: 2 | W5: 2 | X5: 0 | AA5: PNP_6T_08-05-2020 | AB5: PNCP_9T_12-08-2019 | AC5: PNCP_4T_30-04-2013 | AD5: MELIPILLA 220 | AE5: 100.646 | AF5: 1.072776 | AG5: 107.97062 | AH5: 694.38 | AI5: 0.875 | AJ5: 65.601057 | AK5: 1.0179 | AL5: 66.775 | AM5: 8.9176 | AN5: 9.5665875 | AO5: 0.913 | AP5: 6064.9194 | AQ5: 0.9897501 | AR5: 6002.7545 | AT5: PNP_19T_30-12-2020 | AU5: PNCP_12T_10-08-2020 | AV5: PNCP_4T_30-04-2013 | AW5: MELIPILLA 220 | AX5: 100.646 | AY5: 1.0833852 | AZ5: 109.03838 | BA5: 801.49 | BB5: 0.905 | BC5: 79.090823 | BD5: 0.9938 | BE5: 78.6 | BF5: 8.9176 | BG5: 0.77 | BH5: 5962.3808 | BI5: 0.98418586 | BJ5: 5868.0909
A6: 3234 | B6: 01-01-2021 | C6: 2021 | D6: 1 | E6: SAN_JUAN_LAP | F6: SUM_CEC_A | G6: A | H6: CEC | I6: CCURCURIBLOQA | J6: CURICO | K6: -61394.961 | L6: CURICO | M6: RAPEL | N6: 0.0026170695 | O6: 160.67488 | P6: BS2A | Q6: 2 | W6: 2 | X6: 0 | AA6: PNP_6T_08-05-2020 | AB6: PNCP_9T_12-08-2019 | AC6: PNCP_4T_30-04-2013 | AD6: RAPEL 220 | AE6: 100.646 | AF6: 1.072776 | AG6: 107.97062 | AH6: 694.38 | AI6: 0.875 | AJ6: 65.601057 | AK6: 0.9925 | AL6: 65.109 | AM6: 8.9176 | AN6: 9.5665875 | AO6: 0.913 | AP6: 6064.9194 | AQ6: 0.93847214 | AR6: 5691.7579 | AT6: PNP_19T_30-12-2020 | AU6: PNCP_12T_10-08-2020 | AV6: PNCP_4T_30-04-2013 | AW6: RAPEL 220 | AX6: 100.646 | AY6: 1.0833852 | AZ6: 109.03838 | BA6: 801.49 | BB6: 0.905 | BC6: 79.090823 | BD6: 0.9915 | BE6: 78.419 | BF6: 8.9176 | BG6: 0.77 | BH6: 5962.3808 | BI6: 0.98523331 | BJ6: 5874.3362
A7: 2581 | B7: 01-01-2021 | C7: 2021 | D7: 1 | E7: SAN_JUAN_LAP | F7: SUM_CEC_A | G7: A | H7: CEC | I7: CCURQUINBLOQA | J7: QUINTA | K7: -18253.107 | L7: QUINTA | M7: ALTO JAHUEL | N7: 0.45523814 | O7: 8309.5104 | P7: BS2A | Q7: 2 | W7: 2 | X7: 0 | AA7: PNP_6T_08-05-2020 | AB7: PNCP_9T_12-08-2019 | AC7: PNCP_4T_30-04-2013 | AD7: ALTO JAHUEL 220 | AE7: 100.646 | AF7: 1.072776 | AG7: 107.97062 | AH7: 694.38 | AI7: 0.875 | AJ7: 65.601057 | AK7: 0.9827 | AL7: 64.466 | AM7: 8.9176 | AN7: 9.5665875 | AO7: 0.913 | AP7: 6064.9194 | AQ7: 0.99365142 | AR7: 6026.4158 | AT7: PNP_19T_30-12-2020 | AU7: PNCP_12T_10-08-2020 | AV7: PNCP_4T_30-04-2013 | AW7: ALTO JAHUEL 220 | AX7: 100.646 | AY7: 1.0833852 | AZ7: 109.03838 | BA7: 801.49 | BB7: 0.905 | BC7: 79.090823 | BD7: 0.9753 | BE7: 77.137 | BF7: 8.9176 | BG7: 0.77 | BH7: 5962.3808 | BI7: 0.98462454 | BJ7: 5870.7065
A8: 2583 | B8: 01-01-2021 | C8: 2021 | D8: 1 | E8: SAN_JUAN_LAP | F8: SUM_CEC_A | G8: A | H8: CEC | I8: CCURQUINBLOQA | J8: QUINTA | K8: -18253.107 | L8: QUINTA | M8: CHARRUA | N8: 0.068896616 | O8: 1257.5773 | P8: BS2A | Q8: 2 | W8: 2 | X8: 0 | AA8: PNP_6T_08-05-2020 | AB8: PNCP_9T_12-08-2019 | AC8: PNCP_4T_30-04-2013 | AD8: CHARRUA 220 | AE8: 100.646 | AF8: 1.072776 | AG8: 107.97062 | AH8: 694.38 | AI8: 0.875 | AJ8: 65.601057 | AK8: 0.935 | AL8: 61.337 | AM8: 8.9176 | AN8: 9.5665875 | AO8: 0.913 | AP8: 6064.9194 | AQ8: 1.0961716 | AR8: 6648.1923 | AT8: PNP_19T_30-12-2020 | AU8: PNCP_12T_10-08-2020 | AV8: PNCP_4T_30-04-2013 | AW8: CHARRUA 220 | AX8: 100.646 | AY8: 1.0833852 | AZ8: 109.03838 | BA8: 801.49 | BB8: 0.905 | BC8: 79.090823 | BD8: 0.8997 | BE8: 71.158 | BF8: 8.9176 | BG8: 0.77 | BH8: 5962.3808 | BI8: 1.0261762 | BJ8: 6118.4533
A9: 2585 | B9: 01-01-2021 | C9: 2021 | D9: 1 | E9: SAN_JUAN_LAP | F9: SUM_CEC_A | G9: A | H9: CEC | I9: CCURQUINBLOQA | J9: QUINTA | K9: -18253.107 | L9: QUINTA | M9: ITAHUE | N9: 0.7098692 | O9: 12957.318 | P9: BS2A | Q9: 2 | W9: 2 | X9: 0 | AA9: PNP_6T_08-05-2020 | AB9: PNCP_9T_12-08-2019 | AC9: PNCP_4T_30-04-2013 | AD9: ITAHUE 220 | AE9: 100.646 | AF9: 1.072776 | AG9: 107.97062 | AH9: 694.38 | AI9: 0.875 | AJ9: 65.601057 | AK9: 0.9537 | AL9: 62.564 | AM9: 8.9176 | AN9: 9.5665875 | AO9: 0.913 | AP9: 6064.9194 | AQ9: 1.0078958 | AR9: 6112.8068 | AT9: PNP_19T_30-12-2020 | AU9: PNCP_12T_10-08-2020 | AV9: PNCP_4T_30-04-2013 | AW9: ITAHUE 220 | AX9: 100.646 | AY9: 1.0833852 | AZ9: 109.03838 | BA9: 801.49 | BB9: 0.905 | BC9: 79.090823 | BD9: 0.9182 | BE9: 72.621 | BF9: 8.9176 | BG9: 0.77 | BH9: 5962.3808 | BI9: 0.94872847 | BJ9: 5656.6804
A10: 2587 | B10: 01-01-2021 | C10: 2021 | D10: 1 | E10: SAN_JUAN_LAP | F10: SUM_CEC_A | G10: A | H10: CEC | I10: CCURQUINBLOQA | J10: QUINTA | K10: -18253.107 | L10: QUINTA | M10: RAPEL | N10: 0.0014965643 | O10: 27.316948 | P10: BS2A | Q10: 2 | W10: 2 | X10: 0 | AA10: PNP_6T_08-05-2020 | AB10: PNCP_9T_12-08-2019 | AC10: PNCP_4T_30-04-2013 | AD10: RAPEL 220 | AE10: 100.646 | AF10: 1.072776 | AG10: 107.97062 | AH10: 694.38 | AI10: 0.875 | AJ10: 65.601057 | AK10: 0.9925 | AL10: 65.109 | AM10: 8.9176 | AN10: 9.5665875 | AO10: 0.913 | AP10: 6064.9194 | AQ10: 0.93847214 | AR10: 5691.7579 | AT10: PNP_19T_30-12-2020 | AU10: PNCP_12T_10-08-2020 | AV10: PNCP_4T_30-04-2013 | AW10: RAPEL 220 | AX10: 100.646 | AY10: 1.0833852 | AZ10: 109.03838 | BA10: 801.49 | BB10: 0.905 | BC10: 79.090823 | BD10: 0.9915 | BE10: 78.419 | BF10: 8.9176 | BG10: 0.77 | BH10: 5962.3808 | BI10: 0.98523331 | BJ10: 5874.3362
A11: 5401 | B11: 01-01-2021 | C11: 2021 | D11: 1 | E11: SAN_JUAN_LAP | F11: SUM_CEC_A | G11: A | H11: CEC | I11: CCURTENOBLOQA | J11: TENO | K11: -15402.649 | L11: TENO | M11: ALTO JAHUEL | N11: 0.26343871 | O11: 4057.654 | P11: BS2A | Q11: 2 | W11: 2 | X11: 0 | AA11: PNP_6T_08-05-2020 | AB11: PNCP_9T_12-08-2019 | AC11: PNCP_4T_30-04-2013 | AD11: ALTO JAHUEL 220 | AE11: 100.646 | AF11: 1.072776 | AG11: 107.97062 | AH11: 694.38 | AI11: 0.875 | AJ11: 65.601057 | AK11: 0.9827 | AL11: 64.466 | AM11: 8.9176 | AN11: 9.5665875 | AO11: 0.913 | AP11: 6064.9194 | AQ11: 0.99365142 | AR11: 6026.4158 | AT11: PNP_19T_30-12-2020 | AU11: PNCP_12T_10-08-2020 | AV11: PNCP_4T_30-04-2013 | AW11: ALTO JAHUEL 220 | AX11: 100.646 | AY11: 1.0833852 | AZ11: 109.03838 | BA11: 801.49 | BB11: 0.905 | BC11: 79.090823 | BD11: 0.9753 | BE11: 77.137 | BF11: 8.9176 | BG11: 0.77 | BH11: 5962.3808 | BI11: 0.98462454 | BJ11: 5870.7065
A12: 5403 | B12: 01-01-2021 | C12: 2021 | D12: 1 | E12: SAN_JUAN_LAP | F12: SUM_CEC_A | G12: A | H12: CEC | I12: CCURTENOBLOQA | J12: TENO | K12: -15402.649 | L12: TENO | M12: CHARRUA | N12: 0.07126243 | O12: 1097.6302 | P12: BS2A | Q12: 2 | W12: 2 | X12: 0 | AA12: PNP_6T_08-05-2020 | AB12: PNCP_9T_12-08-2019 | AC12: PNCP_4T_30-04-2013 | AD12: CHARRUA 220 | AE12: 100.646 | AF12: 1.072776 | AG12: 107.97062 | AH12: 694.38 | AI12: 0.875 | AJ12: 65.601057 | AK12: 0.935 | AL12: 61.337 | AM12: 8.9176 | AN12: 9.5665875 | AO12: 0.913 | AP12: 6064.9194 | AQ12: 1.0961716 | AR12: 6648.1923 | AT12: PNP_19T_30-12-2020 | AU12: PNCP_12T_10-08-2020 | AV12: PNCP_4T_30-04-2013 | AW12: CHARRUA 220 | AX12: 100.646 | AY12: 1.0833852 | AZ12: 109.03838 | BA12: 801.49 | BB12: 0.905 | BC12: 79.090823 | BD12: 0.8997 | BE12: 71.158 | BF12: 8.9176 | BG12: 0.77 | BH12: 5962.3808 | BI12: 1.0261762 | BJ12: 6118.4533
A13: 5405 | B13: 01-01-2021 | C13: 2021 | D13: 1 | E13: SAN_JUAN_LAP | F13: SUM_CEC_A | G13: A | H13: CEC | I13: CCURTENOBLOQA | J13: TENO | K13: -15402.649 | L13: TENO | M13: ITAHUE | N13: 0.74738784 | O13: 11511.753 | P13: BS2A | Q13: 2 | W13: 2 | X13: 0 | AA13: PNP_6T_08-05-2020 | AB13: PNCP_9T_12-08-2019 | AC13: PNCP_4T_30-04-2013 | AD13: ITAHUE 220 | AE13: 100.646 | AF13: 1.072776 | AG13: 107.97062 | AH13: 694.38 | AI13: 0.875 | AJ13: 65.601057 | AK13: 0.9537 | AL13: 62.564 | AM13: 8.9176 | AN13: 9.5665875 | AO13: 0.913 | AP13: 6064.9194 | AQ13: 1.0078958 | AR13: 6112.8068 | AT13: PNP_19T_30-12-2020 | AU13: PNCP_12T_10-08-2020 | AV13: PNCP_4T_30-04-2013 | AW13: ITAHUE 220 | AX13: 100.646 | AY13: 1.0833852 | AZ13: 109.03838 | BA13: 801.49 | BB13: 0.905 | BC13: 79.090823 | BD13: 0.9182 | BE13: 72.621 | BF13: 8.9176 | BG13: 0.77 | BH13: 5962.3808 | BI13: 0.94872847 | BJ13: 5656.6804
... A43: 5689 | B43: 01-03-2021 | C43: 2021 | D43: 1 | E43: SAN_JUAN_LAP | F43: SUM_CEC_A | G43: A | H43: CEC | I43: CCURTENOBLOQA | J43: TENO | K43: -18721.95 | L43: TENO | M43: RAPEL | N43: 0.0025360776 | O43: 47.480317 | P43: BS2A | Q43: 2 | W43: 2 | X43: 0 | AA43: PNP_16T_02-11-2020 | AB43: PNCP_2T_10-02-2020 | AC43: PNCP_4T_30-04-2013 | AD43: RAPEL 220 | AE43: 100.646 | AF43: 1.0808212 | AG43: 108.78033 | AH43: 779.31 | AI43: 0.879 | AJ43: 74.515991 | AK43: 0.9638 | AL43: 71.819 | AM43: 8.9176 | AN43: 9.6383308 | AO43: 0.804 | AP43: 6039.043 | AQ43: 0.93699547 | AR43: 5658.556 | AT43: PNP_19T_30-12-2020 | AU43: PNCP_12T_10-08-2020 | AV43: PNCP_4T_30-04-2013 | AW43: RAPEL 220 | AX43: 100.646 | AY43: 1.0833852 | AZ43: 109.03838 | BA43: 801.49 | BB43: 0.905 | BC43: 79.090823 | BD43: 0.9915 | BE43: 78.419 | BF43: 8.9176 | BG43: 0.77 | BH43: 5962.3808 | BI43: 0.98523331 | BJ43: 5874.3362
A44: 3016 | B44: 01-10-2020 | C44: 2020 | D44: 1 | E44: SAN_JUAN_LAP | F44: SUM_CEC_A | G44: A | H44: CEC | I44: CCURCURIBLOQA | J44: CURICO | K44: -47128.691 | L44: CURICO | M44: ALTO JAHUEL | N44: 0.24824931 | O44: 11699.665 | P44: BS2A | Q44: 2 | V44: 713834.32 | W44: 2 | X44: 2.33481e-07 | Y44: 0.333334 | Z44: 3899.8962 | AA44: PNP_6T_08-05-2020 | AB44: PNCP_9T_12-08-2019 | AC44: PNCP_4T_30-04-2013 | AD44: ALTO JAHUEL 220 | AE44: 100.646 | AF44: 1.072776 | AG44: 107.97062 | AH44: 694.38 | AI44: 0.875 | AJ44: 65.601057 | AK44: 0.9827 | AL44: 64.466 | AM44: 8.9176 | AN44: 9.5665875 | AO44: 0.913 | AP44: 6064.9194 | AQ44: 0.99365142 | AR44: 6026.4158 | AS44: 251410.71 | AT44: PNP_16T_02-11-2020 | AU44: PNCP_2T_10-02-2020 | AV44: PNCP_4T_30-04-2013 | AW44: ALTO JAHUEL 220 | AX44: 100.646 | AY44: 1.0808212 | AZ44: 108.78033 | BA44: 779.31 | BB44: 0.879 | BC44: 74.515991 | BD44: 0.976 | BE44: 72.728 | BF44: 8.9176 | BG44: 0.804 | BH44: 6039.043 | BI44: 0.99553616 | BJ44: 6012.0857 | BK44: 283631.65
A45: 3018 | B45: 01-10-2020 | C45: 2020 | D45: 1 | E45: SAN_JUAN_LAP | F45: SUM_CEC_A | G45: A | H45: CEC | I45: CCURCURIBLOQA | J45: CURICO | K45: -47128.691 | L45: CURICO | M45: CHARRUA | N45: 0.077540048 | O45: 3654.361 | P45: BS2A | Q45: 2 | V45: 713834.32 | W45: 2 | X45: 2.33481e-07 | Y45: 0.333334 | Z45: 1218.1228 | AA45: PNP_6T_08-05-2020 | AB45: PNCP_9T_12-08-2019 | AC45: PNCP_4T_30-04-2013 | AD45: CHARRUA 220 | AE45: 100.646 | AF45: 1.072776 | AG45: 107.97062 | AH45: 694.38 | AI45: 0.875 | AJ45: 65.601057 | AK45: 0.935 | AL45: 61.337 | AM45: 8.9176 | AN45: 9.5665875 | AO45: 0.913 | AP45: 6064.9194 | AQ45: 1.0961716 | AR45: 6648.1923 | AS45: 74715.996 | AT45: PNP_16T_02-11-2020 | AU45: PNCP_2T_10-02-2020 | AV45: PNCP_4T_30-04-2013 | AW45: CHARRUA 220 | AX45: 100.646 | AY45: 1.0808212 | AZ45: 108.78033 | BA45: 779.31 | BB45: 0.879 | BC45: 74.515991 | BD45: 0.9312 | BE45: 69.389 | BF45: 8.9176 | BG45: 0.804 | BH45: 6039.043 | BI45: 1.1187731 | BJ45: 6756.3187 | BK45: 84524.321
A46: 3020 | B46: 01-10-2020 | C46: 2020 | D46: 1 | E46: SAN_JUAN_LAP | F46: SUM_CEC_A | G46: A | H46: CEC | I46: CCURCURIBLOQA | J46: CURICO | K46: -47128.691 | L46: CURICO | M46: ITAHUE | N46: 0.73979704 | O46: 34865.666 | P46: BS2A | Q46: 2 | V46: 713834.32 | W46: 2 | X46: 2.33481e-07 | Y46: 0.333334 | Z46: 11621.912 | AA46: PNP_6T_08-05-2020 | AB46: PNCP_9T_12-08-2019 | AC46: PNCP_4T_30-04-2013 | AD46: ITAHUE 220 | AE46: 100.646 | AF46: 1.072776 | AG46: 107.97062 | AH46: 694.38 | AI46: 0.875 | AJ46: 65.601057 | AK46: 0.9537 | AL46: 62.564 | AM46: 8.9176 | AN46: 9.5665875 | AO46: 0.913 | AP46: 6064.9194 | AQ46: 1.0078958 | AR46: 6112.8068 | AS46: 727113.3 | AT46: PNP_16T_02-11-2020 | AU46: PNCP_2T_10-02-2020 | AV46: PNCP_4T_30-04-2013 | AW46: ITAHUE 220 | AX46: 100.646 | AY46: 1.0808212 | AZ46: 108.78033 | BA46: 779.31 | BB46: 0.879 | BC46: 74.515991 | BD46: 0.9327 | BE46: 69.501 | BF46: 8.9176 | BG46: 0.804 | BH46: 6039.043 | BI46: 1.0164069 | BJ46: 6138.1249 | BK46: 807734.51
