Workbook

Sheet Reliquidacion
A2: Generador | B2: [GX]
A3: Distribuidor | B3: [EEDD]
A4: Licitacion | B4: 2013/03-2° Llamado
A5: Bloque | B5: [BLOQUE]
U6: RELQUIDACIÓN Y CÁLCULO INTERESES
C7: LO QUE SE FACTURÓ | L7: LO QUE SE DEBIÓ HABER FACTURADO | U7: Reliquidación mensual | V7: Decreto PNP | W7: Fecha publicación | X7: Interes | Y7: Fecha | Z7: Fecha | AA7: N° de días | AB7: Interés total | AC7: Intereses | AD7: Reliquidación
A8: ID | B8: MES | C8: ORIGEN DATA | D8: Energía (kWh) | E8: $/kWh | F8: Monto Energía ($) | G8: Potencia (kW) | H8: $/kW-mes | I8: Monto Potencia ($) | J8: Monto Total ($) | L8: ORIGEN DATA | M8: Energía (kWh) | N8: $/kWh | O8: Monto Energía ($) | P8: Potencia (kW) | Q8: $/kW-mes | R8: Monto Potencia ($) | S8: Monto Total ($) | V8: Reliquidación | W8: Diario Oficial | X8: Anual | Y8: Facturación | Z8: Reliquidación | AA8: de intereses | AB8: según n° de días | AD8: Total
A9: 9 | B9: 42370 | C9: =IF(VLOOKUP(B9,'MAPA DATA'!C:F,2,0)=1,"FACT_EMITIDA",IF(VLOOKUP(B9,'MAPA DATA'!C:F,3,0)=1,"FACT_EST_EFACT",(IF(VLOOKUP(B9,'MAPA DATA'!C:F,4,0)=1,"FACT_EST_CEN","SIN DATA")))) -> SIN DATA | D9: =CONCATENATE("=SUMAR.SI(",IF(C9="FACT_EMITIDA","SIGGE_E",C9),"!B:B;Reliquidacion!B",A9,";",IF(C9="FACT_EMITIDA","SIGGE_E",C9),"!F:F)") -> =SUMAR.SI(SIN DATA!B:B;Reliquidacion!B9;SIN DATA!F:F) | E9: =CONCATENATE("=(F",A9,"/D",A9,")") -> =(F9/D9) | F9: =CONCATENATE("=SUMAR.SI(",IF(C9="FACT_EMITIDA","SIGGE_E",C9),"!B:B;Reliquidacion!B",A9,";",IF(C9="FACT_EMITIDA","SIGGE_E",C9),"!H:H)") -> =SUMAR.SI(SIN DATA!B:B;Reliquidacion!B9;SIN DATA!H:H) | G9: =CONCATENATE("=SUMAR.SI(",IF(C9="FACT_EMITIDA","SIGGE_P",C9),"!B:B;Reliquidacion!B",A9,";",IF(C9="FACT_EMITIDA","SIGGE_P",C9),"!F:F)") -> =SUMAR.SI(SIN DATA!B:B;Reliquidacion!B9;SIN DATA!F:F) | H9: =CONCATENATE("=(I",A9,"/G",A9,")") -> =(I9/G9) | I9: =CONCATENATE("=SUMAR.SI(",IF(C9="FACT_EMITIDA","SIGGE_P",C9),"!B:B;Reliquidacion!B",A9,";",IF(C9="FACT_EMITIDA","SIGGE_P",C9),"!H:H)") -> =SUMAR.SI(SIN DATA!B:B;Reliquidacion!B9;SIN DATA!H:H) | J9: =CONCATENATE("=(F",A9,"+I",A9,")") -> =(F9+I9) | L9: =IF(VLOOKUP(B9,'MAPA DATA'!C:H,5,0)=1,"EFACT_CNE",IF(VLOOKUP(B9,'MAPA DATA'!C:H,6,0)=1,"EFACT_EST_CNE","SIN DATA")) -> EFACT_CNE | M9: =CONCATENATE("=SUMAR.SI(",L9,"!B:B;Reliquidacion!B",A9,";",L9,"!S:S)") -> =SUMAR.SI(EFACT_CNE!B:B;Reliquidacion!B9;EFACT_CNE!S:S) | N9: =CONCATENATE("=(O",A9,"/M",A9,")") -> =(O9/M9) | O9: =CONCATENATE("=SUMAR.SI(",L9,"!B:B;Reliquidacion!B",A9,";",L9,"!W:W)") -> =SUMAR.SI(EFACT_CNE!B:B;Reliquidacion!B9;EFACT_CNE!W:W) | P9: =CONCATENATE("=SUMAR.SI(",L9,"!B:B;Reliquidacion!B",A9,";",L9,"!X:X)") -> =SUMAR.SI(EFACT_CNE!B:B;Reliquidacion!B9;EFACT_CNE!X:X) | Q9: =CONCATENATE("=(R",A9,"/P",A9,")") -> =(R9/P9) | R9: =CONCATENATE("=SUMAR.SI(",L9,"!B:B;Reliquidacion!B",A9,";",L9,"!AB:AB)") -> =SUMAR.SI(EFACT_CNE!B:B;Reliquidacion!B9;EFACT_CNE!AB:AB) | S9: =CONCATENATE("=(O",A9,"+R",A9,")") -> =(O9+R9) | U9: =CONCATENATE("=(S",A9,"-J",A9,")") -> =(S9-J9) | V9: PNP 7T/2018 | W9: =VLOOKUP(V9,#REF!,2,0) -> #REF! | X9: =VLOOKUP(V9,#REF!,6,0) -> #REF! | Y9: 43156 | Z9: 44377 | AA9: =Z9-Y9 -> 1221 | AB9: =+(1+X9)^(AA9/360)-1 -> #REF! | AC9: =AB9*U9 -> #REF! | AD9: =+U9+AC9 -> #VALUE!
A10: =A9+1 -> 10 | B10: 42401 | C10: =IF(VLOOKUP(B10,'MAPA DATA'!C:F,2,0)=1,"FACT_EMITIDA",IF(VLOOKUP(B10,'MAPA DATA'!C:F,3,0)=1,"FACT_EST_EFACT",(IF(VLOOKUP(B10,'MAPA DATA'!C:F,4,0)=1,"FACT_EST_CEN","SIN DATA")))) -> SIN DATA | D10: =CONCATENATE("=SUMAR.SI(",IF(C10="FACT_EMITIDA","SIGGE_E",C10),"!B:B;Reliquidacion!B",A10,";",IF(C10="FACT_EMITIDA","SIGGE_E",C10),"!F:F)") -> =SUMAR.SI(SIN DATA!B:B;Reliquidacion!B10;SIN DATA!F:F) | E10: =CONCATENATE("=(F",A10,"/D",A10,")") -> =(F10/D10) | F10: =CONCATENATE("=SUMAR.SI(",IF(C10="FACT_EMITIDA","SIGGE_E",C10),"!B:B;Reliquidacion!B",A10,";",IF(C10="FACT_EMITIDA","SIGGE_E",C10),"!H:H)") -> =SUMAR.SI(SIN DATA!B:B;Reliquidacion!B10;SIN DATA!H:H) | G10: =CONCATENATE("=SUMAR.SI(",IF(C10="FACT_EMITIDA","SIGGE_P",C10),"!B:B;Reliquidacion!B",A10,";",IF(C10="FACT_EMITIDA","SIGGE_P",C10),"!F:F)") -> =SUMAR.SI(SIN DATA!B:B;Reliquidacion!B10;SIN DATA!F:F) | H10: =CONCATENATE("=(I",A10,"/G",A10,")") -> =(I10/G10) | I10: =CONCATENATE("=SUMAR.SI(",IF(C10="FACT_EMITIDA","SIGGE_P",C10),"!B:B;Reliquidacion!B",A10,";",IF(C10="FACT_EMITIDA","SIGGE_P",C10),"!H:H)") -> =SUMAR.SI(SIN DATA!B:B;Reliquidacion!B10;SIN DATA!H:H) | J10: =CONCATENATE("=(F",A10,"+I",A10,")") -> =(F10+I10) | L10: =IF(VLOOKUP(B10,'MAPA DATA'!C:H,5,0)=1,"EFACT_CNE",IF(VLOOKUP(B10,'MAPA DATA'!C:H,6,0)=1,"EFACT_EST_CNE","SIN DATA")) -> EFACT_CNE | M10: =CONCATENATE("=SUMAR.SI(",L10,"!B:B;Reliquidacion!B",A10,";",L10,"!S:S)") -> =SUMAR.SI(EFACT_CNE!B:B;Reliquidacion!B10;EFACT_CNE!S:S) | N10: =CONCATENATE("=(O",A10,"/M",A10,")") -> =(O10/M10) | O10: =CONCATENATE("=SUMAR.SI(",L10,"!B:B;Reliquidacion!B",A10,";",L10,"!W:W)") -> =SUMAR.SI(EFACT_CNE!B:B;Reliquidacion!B10;EFACT_CNE!W:W) | P10: =CONCATENATE("=SUMAR.SI(",L10,"!B:B;Reliquidacion!B",A10,";",L10,"!X:X)") -> =SUMAR.SI(EFACT_CNE!B:B;Reliquidacion!B10;EFACT_CNE!X:X) | Q10: =CONCATENATE("=(R",A10,"/P",A10,")") -> =(R10/P10) | R10: =CONCATENATE("=SUMAR.SI(",L10,"!B:B;Reliquidacion!B",A10,";",L10,"!AB:AB)") -> =SUMAR.SI(EFACT_CNE!B:B;Reliquidacion!B10;EFACT_CNE!AB:AB) | S10: =CONCATENATE("=(O",A10,"+R",A10,")") -> =(O10+R10) | U10: =CONCATENATE("=(S",A10,"-J",A10,")") -> =(S10-J10) | V10: PNP 7T/2019 | W10: =VLOOKUP(V10,#REF!,2,0) -> #REF! | X10: =VLOOKUP(V10,#REF!,6,0) -> #REF! | Y10: 43156 | Z10: 44377 | AA10: =Z10-Y10 -> 1221 | AB10: =+(1+X10)^(AA10/360)-1 -> #REF! | AC10: =AB10*U10 -> #REF! | AD10: =+U10+AC10 -> #VALUE!
A11: =A10+1 -> 11 | B11: 42430 | C11: =IF(VLOOKUP(B11,'MAPA DATA'!C:F,2,0)=1,"FACT_EMITIDA",IF(VLOOKUP(B11,'MAPA DATA'!C:F,3,0)=1,"FACT_EST_EFACT",(IF(VLOOKUP(B11,'MAPA DATA'!C:F,4,0)=1,"FACT_EST_CEN","SIN DATA")))) -> FACT_EST_EFACT | D11: =CONCATENATE("=SUMAR.SI(",IF(C11="FACT_EMITIDA","SIGGE_E",C11),"!B:B;Reliquidacion!B",A11,";",IF(C11="FACT_EMITIDA","SIGGE_E",C11),"!F:F)") -> =SUMAR.SI(FACT_EST_EFACT!B:B;Reliquidacion!B11;FACT_EST_EFACT!F:F) | E11: =CONCATENATE("=(F",A11,"/D",A11,")") -> =(F11/D11) | F11: =CONCATENATE("=SUMAR.SI(",IF(C11="FACT_EMITIDA","SIGGE_E",C11),"!B:B;Reliquidacion!B",A11,";",IF(C11="FACT_EMITIDA","SIGGE_E",C11),"!H:H)") -> =SUMAR.SI(FACT_EST_EFACT!B:B;Reliquidacion!B11;FACT_EST_EFACT!H:H) | G11: =CONCATENATE("=SUMAR.SI(",IF(C11="FACT_EMITIDA","SIGGE_P",C11),"!B:B;Reliquidacion!B",A11,";",IF(C11="FACT_EMITIDA","SIGGE_P",C11),"!F:F)") -> =SUMAR.SI(FACT_EST_EFACT!B:B;Reliquidacion!B11;FACT_EST_EFACT!F:F) | H11: =CONCATENATE("=(I",A11,"/G",A11,")") -> =(I11/G11) | I11: =CONCATENATE("=SUMAR.SI(",IF(C11="FACT_EMITIDA","SIGGE_P",C11),"!B:B;Reliquidacion!B",A11,";",IF(C11="FACT_EMITIDA","SIGGE_P",C11),"!H:H)") -> =SUMAR.SI(FACT_EST_EFACT!B:B;Reliquidacion!B11;FACT_EST_EFACT!H:H) | J11: =CONCATENATE("=(F",A11,"+I",A11,")") -> =(F11+I11) | L11: =IF(VLOOKUP(B11,'MAPA DATA'!C:H,5,0)=1,"EFACT_CNE",IF(VLOOKUP(B11,'MAPA DATA'!C:H,6,0)=1,"EFACT_EST_CNE","SIN DATA")) -> EFACT_CNE | M11: =CONCATENATE("=SUMAR.SI(",L11,"!B:B;Reliquidacion!B",A11,";",L11,"!S:S)") -> =SUMAR.SI(EFACT_CNE!B:B;Reliquidacion!B11;EFACT_CNE!S:S) | N11: =CONCATENATE("=(O",A11,"/M",A11,")") -> =(O11/M11) | O11: =CONCATENATE("=SUMAR.SI(",L11,"!B:B;Reliquidacion!B",A11,";",L11,"!W:W)") -> =SUMAR.SI(EFACT_CNE!B:B;Reliquidacion!B11;EFACT_CNE!W:W) | P11: =CONCATENATE("=SUMAR.SI(",L11,"!B:B;Reliquidacion!B",A11,";",L11,"!X:X)") -> =SUMAR.SI(EFACT_CNE!B:B;Reliquidacion!B11;EFACT_CNE!X:X) | Q11: =CONCATENATE("=(R",A11,"/P",A11,")") -> =(R11/P11) | R11: =CONCATENATE("=SUMAR.SI(",L11,"!B:B;Reliquidacion!B",A11,";",L11,"!AB:AB)") -> =SUMAR.SI(EFACT_CNE!B:B;Reliquidacion!B11;EFACT_CNE!AB:AB) | S11: =CONCATENATE("=(O",A11,"+R",A11,")") -> =(O11+R11) | U11: =CONCATENATE("=(S",A11,"-J",A11,")") -> =(S11-J11) | V11: PNP 7T/2020 | W11: =VLOOKUP(V11,#REF!,2,0) -> #REF! | X11: =VLOOKUP(V11,#REF!,6,0) -> #REF! | Y11: 43156 | Z11: 44377 | AA11: =Z11-Y11 -> 1221 | AB11: =+(1+X11)^(AA11/360)-1 -> #REF! | AC11: =AB11*U11 -> #REF! | AD11: =+U11+AC11 -> #VALUE!
A12: =A11+1 -> 12 | B12: 42461 | C12: =IF(VLOOKUP(B12,'MAPA DATA'!C:F,2,0)=1,"FACT_EMITIDA",IF(VLOOKUP(B12,'MAPA DATA'!C:F,3,0)=1,"FACT_EST_EFACT",(IF(VLOOKUP(B12,'MAPA DATA'!C:F,4,0)=1,"FACT_EST_CEN","SIN DATA")))) -> FACT_EST_EFACT | D12: =CONCATENATE("=SUMAR.SI(",IF(C12="FACT_EMITIDA","SIGGE_E",C12),"!B:B;Reliquidacion!B",A12,";",IF(C12="FACT_EMITIDA","SIGGE_E",C12),"!F:F)") -> =SUMAR.SI(FACT_EST_EFACT!B:B;Reliquidacion!B12;FACT_EST_EFACT!F:F) | E12: =CONCATENATE("=(F",A12,"/D",A12,")") -> =(F12/D12) | F12: =CONCATENATE("=SUMAR.SI(",IF(C12="FACT_EMITIDA","SIGGE_E",C12),"!B:B;Reliquidacion!B",A12,";",IF(C12="FACT_EMITIDA","SIGGE_E",C12),"!H:H)") -> =SUMAR.SI(FACT_EST_EFACT!B:B;Reliquidacion!B12;FACT_EST_EFACT!H:H) | G12: =CONCATENATE("=SUMAR.SI(",IF(C12="FACT_EMITIDA","SIGGE_P",C12),"!B:B;Reliquidacion!B",A12,";",IF(C12="FACT_EMITIDA","SIGGE_P",C12),"!F:F)") -> =SUMAR.SI(FACT_EST_EFACT!B:B;Reliquidacion!B12;FACT_EST_EFACT!F:F) | H12: =CONCATENATE("=(I",A12,"/G",A12,")") -> =(I12/G12) | I12: =CONCATENATE("=SUMAR.SI(",IF(C12="FACT_EMITIDA","SIGGE_P",C12),"!B:B;Reliquidacion!B",A12,";",IF(C12="FACT_EMITIDA","SIGGE_P",C12),"!H:H)") -> =SUMAR.SI(FACT_EST_EFACT!B:B;Reliquidacion!B12;FACT_EST_EFACT!H:H) | J12: =CONCATENATE("=(F",A12,"+I",A12,")") -> =(F12+I12) | L12: =IF(VLOOKUP(B12,'MAPA DATA'!C:H,5,0)=1,"EFACT_CNE",IF(VLOOKUP(B12,'MAPA DATA'!C:H,6,0)=1,"EFACT_EST_CNE","SIN DATA")) -> EFACT_CNE | M12: =CONCATENATE("=SUMAR.SI(",L12,"!B:B;Reliquidacion!B",A12,";",L12,"!S:S)") -> =SUMAR.SI(EFACT_CNE!B:B;Reliquidacion!B12;EFACT_CNE!S:S) | N12: =CONCATENATE("=(O",A12,"/M",A12,")") -> =(O12/M12) | O12: =CONCATENATE("=SUMAR.SI(",L12,"!B:B;Reliquidacion!B",A12,";",L12,"!W:W)") -> =SUMAR.SI(EFACT_CNE!B:B;Reliquidacion!B12;EFACT_CNE!W:W) | P12: =CONCATENATE("=SUMAR.SI(",L12,"!B:B;Reliquidacion!B",A12,";",L12,"!X:X)") -> =SUMAR.SI(EFACT_CNE!B:B;Reliquidacion!B12;EFACT_CNE!X:X) | Q12: =CONCATENATE("=(R",A12,"/P",A12,")") -> =(R12/P12) | R12: =CONCATENATE("=SUMAR.SI(",L12,"!B:B;Reliquidacion!B",A12,";",L12,"!AB:AB)") -> =SUMAR.SI(EFACT_CNE!B:B;Reliquidacion!B12;EFACT_CNE!AB:AB) | S12: =CONCATENATE("=(O",A12,"+R",A12,")") -> =(O12+R12) | U12: =CONCATENATE("=(S",A12,"-J",A12,")") -> =(S12-J12) | V12: PNP 7T/2021 | W12: =VLOOKUP(V12,#REF!,2,0) -> #REF! | X12: =VLOOKUP(V12,#REF!,6,0) -> #REF! | Y12: 43156 | Z12: 44377 | AA12: =Z12-Y12 -> 1221 | AB12: =+(1+X12)^(AA12/360)-1 -> #REF! | AC12: =AB12*U12 -> #REF! | AD12: =+U12+AC12 -> #VALUE!
A13: =A12+1 -> 13 | B13: 42491 | C13: =IF(VLOOKUP(B13,'MAPA DATA'!C:F,2,0)=1,"FACT_EMITIDA",IF(VLOOKUP(B13,'MAPA DATA'!C:F,3,0)=1,"FACT_EST_EFACT",(IF(VLOOKUP(B13,'MAPA DATA'!C:F,4,0)=1,"FACT_EST_CEN","SIN DATA")))) -> FACT_EST_EFACT | D13: =CONCATENATE("=SUMAR.SI(",IF(C13="FACT_EMITIDA","SIGGE_E",C13),"!B:B;Reliquidacion!B",A13,";",IF(C13="FACT_EMITIDA","SIGGE_E",C13),"!F:F)") -> =SUMAR.SI(FACT_EST_EFACT!B:B;Reliquidacion!B13;FACT_EST_EFACT!F:F) | E13: =CONCATENATE("=(F",A13,"/D",A13,")") -> =(F13/D13) | F13: =CONCATENATE("=SUMAR.SI(",IF(C13="FACT_EMITIDA","SIGGE_E",C13),"!B:B;Reliquidacion!B",A13,";",IF(C13="FACT_EMITIDA","SIGGE_E",C13),"!H:H)") -> =SUMAR.SI(FACT_EST_EFACT!B:B;Reliquidacion!B13;FACT_EST_EFACT!H:H) | G13: =CONCATENATE("=SUMAR.SI(",IF(C13="FACT_EMITIDA","SIGGE_P",C13),"!B:B;Reliquidacion!B",A13,";",IF(C13="FACT_EMITIDA","SIGGE_P",C13),"!F:F)") -> =SUMAR.SI(FACT_EST_EFACT!B:B;Reliquidacion!B13;FACT_EST_EFACT!F:F) | H13: =CONCATENATE("=(I",A13,"/G",A13,")") -> =(I13/G13) | I13: =CONCATENATE("=SUMAR.SI(",IF(C13="FACT_EMITIDA","SIGGE_P",C13),"!B:B;Reliquidacion!B",A13,";",IF(C13="FACT_EMITIDA","SIGGE_P",C13),"!H:H)") -> =SUMAR.SI(FACT_EST_EFACT!B:B;Reliquidacion!B13;FACT_EST_EFACT!H:H) | J13: =CONCATENATE("=(F",A13,"+I",A13,")") -> =(F13+I13) | L13: =IF(VLOOKUP(B13,'MAPA DATA'!C:H,5,0)=1,"EFACT_CNE",IF(VLOOKUP(B13,'MAPA DATA'!C:H,6,0)=1,"EFACT_EST_CNE","SIN DATA")) -> EFACT_CNE | M13: =CONCATENATE("=SUMAR.SI(",L13,"!B:B;Reliquidacion!B",A13,";",L13,"!S:S)") -> =SUMAR.SI(EFACT_CNE!B:B;Reliquidacion!B13;EFACT_CNE!S:S) | N13: =CONCATENATE("=(O",A13,"/M",A13,")") -> =(O13/M13) | O13: =CONCATENATE("=SUMAR.SI(",L13,"!B:B;Reliquidacion!B",A13,";",L13,"!W:W)") -> =SUMAR.SI(EFACT_CNE!B:B;Reliquidacion!B13;EFACT_CNE!W:W) | P13: =CONCATENATE("=SUMAR.SI(",L13,"!B:B;Reliquidacion!B",A13,";",L13,"!X:X)") -> =SUMAR.SI(EFACT_CNE!B:B;Reliquidacion!B13;EFACT_CNE!X:X) | Q13: =CONCATENATE("=(R",A13,"/P",A13,")") -> =(R13/P13) | R13: =CONCATENATE("=SUMAR.SI(",L13,"!B:B;Reliquidacion!B",A13,";",L13,"!AB:AB)") -> =SUMAR.SI(EFACT_CNE!B:B;Reliquidacion!B13;EFACT_CNE!AB:AB) | S13: =CONCATENATE("=(O",A13,"+R",A13,")") -> =(O13+R13) | U13: =CONCATENATE("=(S",A13,"-J",A13,")") -> =(S13-J13) | V13: PNP 7T/2022 | W13: =VLOOKUP(V13,#REF!,2,0) -> #REF! | X13: =VLOOKUP(V13,#REF!,6,0) -> #REF! | Y13: 43156 | Z13: 44377 | AA13: =Z13-Y13 -> 1221 | AB13: =+(1+X13)^(AA13/360)-1 -> #REF! | AC13: =AB13*U13 -> #REF! | AD13: =+U13+AC13 -> #VALUE!
A14: =A13+1 -> 14 | B14: 42522 | C14: =IF(VLOOKUP(B14,'MAPA DATA'!C:F,2,0)=1,"FACT_EMITIDA",IF(VLOOKUP(B14,'MAPA DATA'!C:F,3,0)=1,"FACT_EST_EFACT",(IF(VLOOKUP(B14,'MAPA DATA'!C:F,4,0)=1,"FACT_EST_CEN","SIN DATA")))) -> FACT_EST_EFACT | D14: =CONCATENATE("=SUMAR.SI(",IF(C14="FACT_EMITIDA","SIGGE_E",C14),"!B:B;Reliquidacion!B",A14,";",IF(C14="FACT_EMITIDA","SIGGE_E",C14),"!F:F)") -> =SUMAR.SI(FACT_EST_EFACT!B:B;Reliquidacion!B14;FACT_EST_EFACT!F:F) | E14: =CONCATENATE("=(F",A14,"/D",A14,")") -> =(F14/D14) | F14: =CONCATENATE("=SUMAR.SI(",IF(C14="FACT_EMITIDA","SIGGE_E",C14),"!B:B;Reliquidacion!B",A14,";",IF(C14="FACT_EMITIDA","SIGGE_E",C14),"!H:H)") -> =SUMAR.SI(FACT_EST_EFACT!B:B;Reliquidacion!B14;FACT_EST_EFACT!H:H) | G14: =CONCATENATE("=SUMAR.SI(",IF(C14="FACT_EMITIDA","SIGGE_P",C14),"!B:B;Reliquidacion!B",A14,";",IF(C14="FACT_EMITIDA","SIGGE_P",C14),"!F:F)") -> =SUMAR.SI(FACT_EST_EFACT!B:B;Reliquidacion!B14;FACT_EST_EFACT!F:F) | H14: =CONCATENATE("=(I",A14,"/G",A14,")") -> =(I14/G14) | I14: =CONCATENATE("=SUMAR.SI(",IF(C14="FACT_EMITIDA","SIGGE_P",C14),"!B:B;Reliquidacion!B",A14,";",IF(C14="FACT_EMITIDA","SIGGE_P",C14),"!H:H)") -> =SUMAR.SI(FACT_EST_EFACT!B:B;Reliquidacion!B14;FACT_EST_EFACT!H:H) | J14: =CONCATENATE("=(F",A14,"+I",A14,")") -> =(F14+I14) | L14: =IF(VLOOKUP(B14,'MAPA DATA'!C:H,5,0)=1,"EFACT_CNE",IF(VLOOKUP(B14,'MAPA DATA'!C:H,6,0)=1,"EFACT_EST_CNE","SIN DATA")) -> EFACT_CNE | M14: =CONCATENATE("=SUMAR.SI(",L14,"!B:B;Reliquidacion!B",A14,";",L14,"!S:S)") -> =SUMAR.SI(EFACT_CNE!B:B;Reliquidacion!B14;EFACT_CNE!S:S) | N14: =CONCATENATE("=(O",A14,"/M",A14,")") -> =(O14/M14) | O14: =CONCATENATE("=SUMAR.SI(",L14,"!B:B;Reliquidacion!B",A14,";",L14,"!W:W)") -> =SUMAR.SI(EFACT_CNE!B:B;Reliquidacion!B14;EFACT_CNE!W:W) | P14: =CONCATENATE("=SUMAR.SI(",L14,"!B:B;Reliquidacion!B",A14,";",L14,"!X:X)") -> =SUMAR.SI(EFACT_CNE!B:B;Reliquidacion!B14;EFACT_CNE!X:X) | Q14: =CONCATENATE("=(R",A14,"/P",A14,")") -> =(R14/P14) | R14: =CONCATENATE("=SUMAR.SI(",L14,"!B:B;Reliquidacion!B",A14,";",L14,"!AB:AB)") -> =SUMAR.SI(EFACT_CNE!B:B;Reliquidacion!B14;EFACT_CNE!AB:AB) | S14: =CONCATENATE("=(O",A14,"+R",A14,")") -> =(O14+R14) | U14: =CONCATENATE("=(S",A14,"-J",A14,")") -> =(S14-J14) | V14: PNP 7T/2023 | W14: =VLOOKUP(V14,#REF!,2,0) -> #REF! | X14: =VLOOKUP(V14,#REF!,6,0) -> #REF! | Y14: 43156 | Z14: 44377 | AA14: =Z14-Y14 -> 1221 | AB14: =+(1+X14)^(AA14/360)-1 -> #REF! | AC14: =AB14*U14 -> #REF! | AD14: =+U14+AC14 -> #VALUE!
A15: =A14+1 -> 15 | B15: 42552 | C15: =IF(VLOOKUP(B15,'MAPA DATA'!C:F,2,0)=1,"FACT_EMITIDA",IF(VLOOKUP(B15,'MAPA DATA'!C:F,3,0)=1,"FACT_EST_EFACT",(IF(VLOOKUP(B15,'MAPA DATA'!C:F,4,0)=1,"FACT_EST_CEN","SIN DATA")))) -> FACT_EST_EFACT | D15: =CONCATENATE("=SUMAR.SI(",IF(C15="FACT_EMITIDA","SIGGE_E",C15),"!B:B;Reliquidacion!B",A15,";",IF(C15="FACT_EMITIDA","SIGGE_E",C15),"!F:F)") -> =SUMAR.SI(FACT_EST_EFACT!B:B;Reliquidacion!B15;FACT_EST_EFACT!F:F) | E15: =CONCATENATE("=(F",A15,"/D",A15,")") -> =(F15/D15) | F15: =CONCATENATE("=SUMAR.SI(",IF(C15="FACT_EMITIDA","SIGGE_E",C15),"!B:B;Reliquidacion!B",A15,";",IF(C15="FACT_EMITIDA","SIGGE_E",C15),"!H:H)") -> =SUMAR.SI(FACT_EST_EFACT!B:B;Reliquidacion!B15;FACT_EST_EFACT!H:H) | G15: =CONCATENATE("=SUMAR.SI(",IF(C15="FACT_EMITIDA","SIGGE_P",C15),"!B:B;Reliquidacion!B",A15,";",IF(C15="FACT_EMITIDA","SIGGE_P",C15),"!F:F)") -> =SUMAR.SI(FACT_EST_EFACT!B:B;Reliquidacion!B15;FACT_EST_EFACT!F:F) | H15: =CONCATENATE("=(I",A15,"/G",A15,")") -> =(I15/G15) | I15: =CONCATENATE("=SUMAR.SI(",IF(C15="FACT_EMITIDA","SIGGE_P",C15),"!B:B;Reliquidacion!B",A15,";",IF(C15="FACT_EMITIDA","SIGGE_P",C15),"!H:H)") -> =SUMAR.SI(FACT_EST_EFACT!B:B;Reliquidacion!B15;FACT_EST_EFACT!H:H) | J15: =CONCATENATE("=(F",A15,"+I",A15,")") -> =(F15+I15) | L15: =IF(VLOOKUP(B15,'MAPA DATA'!C:H,5,0)=1,"EFACT_CNE",IF(VLOOKUP(B15,'MAPA DATA'!C:H,6,0)=1,"EFACT_EST_CNE","SIN DATA")) -> EFACT_CNE | M15: =CONCATENATE("=SUMAR.SI(",L15,"!B:B;Reliquidacion!B",A15,";",L15,"!S:S)") -> =SUMAR.SI(EFACT_CNE!B:B;Reliquidacion!B15;EFACT_CNE!S:S) | N15: =CONCATENATE("=(O",A15,"/M",A15,")") -> =(O15/M15) | O15: =CONCATENATE("=SUMAR.SI(",L15,"!B:B;Reliquidacion!B",A15,";",L15,"!W:W)") -> =SUMAR.SI(EFACT_CNE!B:B;Reliquidacion!B15;EFACT_CNE!W:W) | P15: =CONCATENATE("=SUMAR.SI(",L15,"!B:B;Reliquidacion!B",A15,";",L15,"!X:X)") -> =SUMAR.SI(EFACT_CNE!B:B;Reliquidacion!B15;EFACT_CNE!X:X) | Q15: =CONCATENATE("=(R",A15,"/P",A15,")") -> =(R15/P15) | R15: =CONCATENATE("=SUMAR.SI(",L15,"!B:B;Reliquidacion!B",A15,";",L15,"!AB:AB)") -> =SUMAR.SI(EFACT_CNE!B:B;Reliquidacion!B15;EFACT_CNE!AB:AB) | S15: =CONCATENATE("=(O",A15,"+R",A15,")") -> =(O15+R15) | U15: =CONCATENATE("=(S",A15,"-J",A15,")") -> =(S15-J15) | V15: PNP 7T/2024 | W15: =VLOOKUP(V15,#REF!,2,0) -> #REF! | X15: =VLOOKUP(V15,#REF!,6,0) -> #REF! | Y15: 43156 | Z15: 44377 | AA15: =Z15-Y15 -> 1221 | AB15: =+(1+X15)^(AA15/360)-1 -> #REF! | AC15: =AB15*U15 -> #REF! | AD15: =+U15+AC15 -> #VALUE!
A16: =A15+1 -> 16 | B16: 42583 | C16: =IF(VLOOKUP(B16,'MAPA DATA'!C:F,2,0)=1,"FACT_EMITIDA",IF(VLOOKUP(B16,'MAPA DATA'!C:F,3,0)=1,"FACT_EST_EFACT",(IF(VLOOKUP(B16,'MAPA DATA'!C:F,4,0)=1,"FACT_EST_CEN","SIN DATA")))) -> SIN DATA | D16: =CONCATENATE("=SUMAR.SI(",IF(C16="FACT_EMITIDA","SIGGE_E",C16),"!B:B;Reliquidacion!B",A16,";",IF(C16="FACT_EMITIDA","SIGGE_E",C16),"!F:F)") -> =SUMAR.SI(SIN DATA!B:B;Reliquidacion!B16;SIN DATA!F:F) | E16: =CONCATENATE("=(F",A16,"/D",A16,")") -> =(F16/D16) | F16: =CONCATENATE("=SUMAR.SI(",IF(C16="FACT_EMITIDA","SIGGE_E",C16),"!B:B;Reliquidacion!B",A16,";",IF(C16="FACT_EMITIDA","SIGGE_E",C16),"!H:H)") -> =SUMAR.SI(SIN DATA!B:B;Reliquidacion!B16;SIN DATA!H:H) | G16: =CONCATENATE("=SUMAR.SI(",IF(C16="FACT_EMITIDA","SIGGE_P",C16),"!B:B;Reliquidacion!B",A16,";",IF(C16="FACT_EMITIDA","SIGGE_P",C16),"!F:F)") -> =SUMAR.SI(SIN DATA!B:B;Reliquidacion!B16;SIN DATA!F:F) | H16: =CONCATENATE("=(I",A16,"/G",A16,")") -> =(I16/G16) | I16: =CONCATENATE("=SUMAR.SI(",IF(C16="FACT_EMITIDA","SIGGE_P",C16),"!B:B;Reliquidacion!B",A16,";",IF(C16="FACT_EMITIDA","SIGGE_P",C16),"!H:H)") -> =SUMAR.SI(SIN DATA!B:B;Reliquidacion!B16;SIN DATA!H:H) | J16: =CONCATENATE("=(F",A16,"+I",A16,")") -> =(F16+I16) | L16: =IF(VLOOKUP(B16,'MAPA DATA'!C:H,5,0)=1,"EFACT_CNE",IF(VLOOKUP(B16,'MAPA DATA'!C:H,6,0)=1,"EFACT_EST_CNE","SIN DATA")) -> EFACT_CNE | M16: =CONCATENATE("=SUMAR.SI(",L16,"!B:B;Reliquidacion!B",A16,";",L16,"!S:S)") -> =SUMAR.SI(EFACT_CNE!B:B;Reliquidacion!B16;EFACT_CNE!S:S) | N16: =CONCATENATE("=(O",A16,"/M",A16,")") -> =(O16/M16) | O16: =CONCATENATE("=SUMAR.SI(",L16,"!B:B;Reliquidacion!B",A16,";",L16,"!W:W)") -> =SUMAR.SI(EFACT_CNE!B:B;Reliquidacion!B16;EFACT_CNE!W:W) | P16: =CONCATENATE("=SUMAR.SI(",L16,"!B:B;Reliquidacion!B",A16,";",L16,"!X:X)") -> =SUMAR.SI(EFACT_CNE!B:B;Reliquidacion!B16;EFACT_CNE!X:X) | Q16: =CONCATENATE("=(R",A16,"/P",A16,")") -> =(R16/P16) | R16: =CONCATENATE("=SUMAR.SI(",L16,"!B:B;Reliquidacion!B",A16,";",L16,"!AB:AB)") -> =SUMAR.SI(EFACT_CNE!B:B;Reliquidacion!B16;EFACT_CNE!AB:AB) | S16: =CONCATENATE("=(O",A16,"+R",A16,")") -> =(O16+R16) | U16: =CONCATENATE("=(S",A16,"-J",A16,")") -> =(S16-J16) | V16: PNP 7T/2025 | W16: =VLOOKUP(V16,#REF!,2,0) -> #REF! | X16: =VLOOKUP(V16,#REF!,6,0) -> #REF! | Y16: 43156 | Z16: 44377 | AA16: =Z16-Y16 -> 1221 | AB16: =+(1+X16)^(AA16/360)-1 -> #REF! | AC16: =AB16*U16 -> #REF! | AD16: =+U16+AC16 -> #VALUE!
A17: =A16+1 -> 17 | B17: 42614 | C17: =IF(VLOOKUP(B17,'MAPA DATA'!C:F,2,0)=1,"FACT_EMITIDA",IF(VLOOKUP(B17,'MAPA DATA'!C:F,3,0)=1,"FACT_EST_EFACT",(IF(VLOOKUP(B17,'MAPA DATA'!C:F,4,0)=1,"FACT_EST_CEN","SIN DATA")))) -> FACT_EST_EFACT | D17: =CONCATENATE("=SUMAR.SI(",IF(C17="FACT_EMITIDA","SIGGE_E",C17),"!B:B;Reliquidacion!B",A17,";",IF(C17="FACT_EMITIDA","SIGGE_E",C17),"!F:F)") -> =SUMAR.SI(FACT_EST_EFACT!B:B;Reliquidacion!B17;FACT_EST_EFACT!F:F) | E17: =CONCATENATE("=(F",A17,"/D",A17,")") -> =(F17/D17) | F17: =CONCATENATE("=SUMAR.SI(",IF(C17="FACT_EMITIDA","SIGGE_E",C17),"!B:B;Reliquidacion!B",A17,";",IF(C17="FACT_EMITIDA","SIGGE_E",C17),"!H:H)") -> =SUMAR.SI(FACT_EST_EFACT!B:B;Reliquidacion!B17;FACT_EST_EFACT!H:H) | G17: =CONCATENATE("=SUMAR.SI(",IF(C17="FACT_EMITIDA","SIGGE_P",C17),"!B:B;Reliquidacion!B",A17,";",IF(C17="FACT_EMITIDA","SIGGE_P",C17),"!F:F)") -> =SUMAR.SI(FACT_EST_EFACT!B:B;Reliquidacion!B17;FACT_EST_EFACT!F:F) | H17: =CONCATENATE("=(I",A17,"/G",A17,")") -> =(I17/G17) | I17: =CONCATENATE("=SUMAR.SI(",IF(C17="FACT_EMITIDA","SIGGE_P",C17),"!B:B;Reliquidacion!B",A17,";",IF(C17="FACT_EMITIDA","SIGGE_P",C17),"!H:H)") -> =SUMAR.SI(FACT_EST_EFACT!B:B;Reliquidacion!B17;FACT_EST_EFACT!H:H) | J17: =CONCATENATE("=(F",A17,"+I",A17,")") -> =(F17+I17) | L17: =IF(VLOOKUP(B17,'MAPA DATA'!C:H,5,0)=1,"EFACT_CNE",IF(VLOOKUP(B17,'MAPA DATA'!C:H,6,0)=1,"EFACT_EST_CNE","SIN DATA")) -> EFACT_CNE | M17: =CONCATENATE("=SUMAR.SI(",L17,"!B:B;Reliquidacion!B",A17,";",L17,"!S:S)") -> =SUMAR.SI(EFACT_CNE!B:B;Reliquidacion!B17;EFACT_CNE!S:S) | N17: =CONCATENATE("=(O",A17,"/M",A17,")") -> =(O17/M17) | O17: =CONCATENATE("=SUMAR.SI(",L17,"!B:B;Reliquidacion!B",A17,";",L17,"!W:W)") -> =SUMAR.SI(EFACT_CNE!B:B;Reliquidacion!B17;EFACT_CNE!W:W) | P17: =CONCATENATE("=SUMAR.SI(",L17,"!B:B;Reliquidacion!B",A17,";",L17,"!X:X)") -> =SUMAR.SI(EFACT_CNE!B:B;Reliquidacion!B17;EFACT_CNE!X:X) | Q17: =CONCATENATE("=(R",A17,"/P",A17,")") -> =(R17/P17) | R17: =CONCATENATE("=SUMAR.SI(",L17,"!B:B;Reliquidacion!B",A17,";",L17,"!AB:AB)") -> =SUMAR.SI(EFACT_CNE!B:B;Reliquidacion!B17;EFACT_CNE!AB:AB) | S17: =CONCATENATE("=(O",A17,"+R",A17,")") -> =(O17+R17) | U17: =CONCATENATE("=(S",A17,"-J",A17,")") -> =(S17-J17) | V17: PNP 7T/2026 | W17: =VLOOKUP(V17,#REF!,2,0) -> #REF! | X17: =VLOOKUP(V17,#REF!,6,0) -> #REF! | Y17: 43156 | Z17: 44377 | AA17: =Z17-Y17 -> 1221 | AB17: =+(1+X17)^(AA17/360)-1 -> #REF! | AC17: =AB17*U17 -> #REF! | AD17: =+U17+AC17 -> #VALUE!
A18: =A17+1 -> 18 | B18: 42644 | C18: =IF(VLOOKUP(B18,'MAPA DATA'!C:F,2,0)=1,"FACT_EMITIDA",IF(VLOOKUP(B18,'MAPA DATA'!C:F,3,0)=1,"FACT_EST_EFACT",(IF(VLOOKUP(B18,'MAPA DATA'!C:F,4,0)=1,"FACT_EST_CEN","SIN DATA")))) -> FACT_EST_EFACT | D18: =CONCATENATE("=SUMAR.SI(",IF(C18="FACT_EMITIDA","SIGGE_E",C18),"!B:B;Reliquidacion!B",A18,";",IF(C18="FACT_EMITIDA","SIGGE_E",C18),"!F:F)") -> =SUMAR.SI(FACT_EST_EFACT!B:B;Reliquidacion!B18;FACT_EST_EFACT!F:F) | E18: =CONCATENATE("=(F",A18,"/D",A18,")") -> =(F18/D18) | F18: =CONCATENATE("=SUMAR.SI(",IF(C18="FACT_EMITIDA","SIGGE_E",C18),"!B:B;Reliquidacion!B",A18,";",IF(C18="FACT_EMITIDA","SIGGE_E",C18),"!H:H)") -> =SUMAR.SI(FACT_EST_EFACT!B:B;Reliquidacion!B18;FACT_EST_EFACT!H:H) | G18: =CONCATENATE("=SUMAR.SI(",IF(C18="FACT_EMITIDA","SIGGE_P",C18),"!B:B;Reliquidacion!B",A18,";",IF(C18="FACT_EMITIDA","SIGGE_P",C18),"!F:F)") -> =SUMAR.SI(FACT_EST_EFACT!B:B;Reliquidacion!B18;FACT_EST_EFACT!F:F) | H18: =CONCATENATE("=(I",A18,"/G",A18,")") -> =(I18/G18) | I18: =CONCATENATE("=SUMAR.SI(",IF(C18="FACT_EMITIDA","SIGGE_P",C18),"!B:B;Reliquidacion!B",A18,";",IF(C18="FACT_EMITIDA","SIGGE_P",C18),"!H:H)") -> =SUMAR.SI(FACT_EST_EFACT!B:B;Reliquidacion!B18;FACT_EST_EFACT!H:H) | J18: =CONCATENATE("=(F",A18,"+I",A18,")") -> =(F18+I18) | L18: =IF(VLOOKUP(B18,'MAPA DATA'!C:H,5,0)=1,"EFACT_CNE",IF(VLOOKUP(B18,'MAPA DATA'!C:H,6,0)=1,"EFACT_EST_CNE","SIN DATA")) -> EFACT_CNE | M18: =CONCATENATE("=SUMAR.SI(",L18,"!B:B;Reliquidacion!B",A18,";",L18,"!S:S)") -> =SUMAR.SI(EFACT_CNE!B:B;Reliquidacion!B18;EFACT_CNE!S:S) | N18: =CONCATENATE("=(O",A18,"/M",A18,")") -> =(O18/M18) | O18: =CONCATENATE("=SUMAR.SI(",L18,"!B:B;Reliquidacion!B",A18,";",L18,"!W:W)") -> =SUMAR.SI(EFACT_CNE!B:B;Reliquidacion!B18;EFACT_CNE!W:W) | P18: =CONCATENATE("=SUMAR.SI(",L18,"!B:B;Reliquidacion!B",A18,";",L18,"!X:X)") -> =SUMAR.SI(EFACT_CNE!B:B;Reliquidacion!B18;EFACT_CNE!X:X) | Q18: =CONCATENATE("=(R",A18,"/P",A18,")") -> =(R18/P18) | R18: =CONCATENATE("=SUMAR.SI(",L18,"!B:B;Reliquidacion!B",A18,";",L18,"!AB:AB)") -> =SUMAR.SI(EFACT_CNE!B:B;Reliquidacion!B18;EFACT_CNE!AB:AB) | S18: =CONCATENATE("=(O",A18,"+R",A18,")") -> =(O18+R18) | U18: =CONCATENATE("=(S",A18,"-J",A18,")") -> =(S18-J18) | V18: PNP 7T/2027 | W18: =VLOOKUP(V18,#REF!,2,0) -> #REF! | X18: =VLOOKUP(V18,#REF!,6,0) -> #REF! | Y18: 43156 | Z18: 44377 | AA18: =Z18-Y18 -> 1221 | AB18: =+(1+X18)^(AA18/360)-1 -> #REF! | AC18: =AB18*U18 -> #REF! | AD18: =+U18+AC18 -> #VALUE!
A19: =A18+1 -> 19 | B19: 42675 | C19: =IF(VLOOKUP(B19,'MAPA DATA'!C:F,2,0)=1,"FACT_EMITIDA",IF(VLOOKUP(B19,'MAPA DATA'!C:F,3,0)=1,"FACT_EST_EFACT",(IF(VLOOKUP(B19,'MAPA DATA'!C:F,4,0)=1,"FACT_EST_CEN","SIN DATA")))) -> FACT_EST_EFACT | D19: =CONCATENATE("=SUMAR.SI(",IF(C19="FACT_EMITIDA","SIGGE_E",C19),"!B:B;Reliquidacion!B",A19,";",IF(C19="FACT_EMITIDA","SIGGE_E",C19),"!F:F)") -> =SUMAR.SI(FACT_EST_EFACT!B:B;Reliquidacion!B19;FACT_EST_EFACT!F:F) | E19: =CONCATENATE("=(F",A19,"/D",A19,")") -> =(F19/D19) | F19: =CONCATENATE("=SUMAR.SI(",IF(C19="FACT_EMITIDA","SIGGE_E",C19),"!B:B;Reliquidacion!B",A19,";",IF(C19="FACT_EMITIDA","SIGGE_E",C19),"!H:H)") -> =SUMAR.SI(FACT_EST_EFACT!B:B;Reliquidacion!B19;FACT_EST_EFACT!H:H) | G19: =CONCATENATE("=SUMAR.SI(",IF(C19="FACT_EMITIDA","SIGGE_P",C19),"!B:B;Reliquidacion!B",A19,";",IF(C19="FACT_EMITIDA","SIGGE_P",C19),"!F:F)") -> =SUMAR.SI(FACT_EST_EFACT!B:B;Reliquidacion!B19;FACT_EST_EFACT!F:F) | H19: =CONCATENATE("=(I",A19,"/G",A19,")") -> =(I19/G19) | I19: =CONCATENATE("=SUMAR.SI(",IF(C19="FACT_EMITIDA","SIGGE_P",C19),"!B:B;Reliquidacion!B",A19,";",IF(C19="FACT_EMITIDA","SIGGE_P",C19),"!H:H)") -> =SUMAR.SI(FACT_EST_EFACT!B:B;Reliquidacion!B19;FACT_EST_EFACT!H:H) | J19: =CONCATENATE("=(F",A19,"+I",A19,")") -> =(F19+I19) | L19: =IF(VLOOKUP(B19,'MAPA DATA'!C:H,5,0)=1,"EFACT_CNE",IF(VLOOKUP(B19,'MAPA DATA'!C:H,6,0)=1,"EFACT_EST_CNE","SIN DATA")) -> EFACT_CNE | M19: =CONCATENATE("=SUMAR.SI(",L19,"!B:B;Reliquidacion!B",A19,";",L19,"!S:S)") -> =SUMAR.SI(EFACT_CNE!B:B;Reliquidacion!B19;EFACT_CNE!S:S) | N19: =CONCATENATE("=(O",A19,"/M",A19,")") -> =(O19/M19) | O19: =CONCATENATE("=SUMAR.SI(",L19,"!B:B;Reliquidacion!B",A19,";",L19,"!W:W)") -> =SUMAR.SI(EFACT_CNE!B:B;Reliquidacion!B19;EFACT_CNE!W:W) | P19: =CONCATENATE("=SUMAR.SI(",L19,"!B:B;Reliquidacion!B",A19,";",L19,"!X:X)") -> =SUMAR.SI(EFACT_CNE!B:B;Reliquidacion!B19;EFACT_CNE!X:X) | Q19: =CONCATENATE("=(R",A19,"/P",A19,")") -> =(R19/P19) | R19: =CONCATENATE("=SUMAR.SI(",L19,"!B:B;Reliquidacion!B",A19,";",L19,"!AB:AB)") -> =SUMAR.SI(EFACT_CNE!B:B;Reliquidacion!B19;EFACT_CNE!AB:AB) | S19: =CONCATENATE("=(O",A19,"+R",A19,")") -> =(O19+R19) | U19: =CONCATENATE("=(S",A19,"-J",A19,")") -> =(S19-J19) | V19: PNP 7T/2028 | W19: =VLOOKUP(V19,#REF!,2,0) -> #REF! | X19: =VLOOKUP(V19,#REF!,6,0) -> #REF! | Y19: 43156 | Z19: 44377 | AA19: =Z19-Y19 -> 1221 | AB19: =+(1+X19)^(AA19/360)-1 -> #REF! | AC19: =AB19*U19 -> #REF! | AD19: =+U19+AC19 -> #VALUE!
A20: =A19+1 -> 20 | B20: 42705 | C20: =IF(VLOOKUP(B20,'MAPA DATA'!C:F,2,0)=1,"FACT_EMITIDA",IF(VLOOKUP(B20,'MAPA DATA'!C:F,3,0)=1,"FACT_EST_EFACT",(IF(VLOOKUP(B20,'MAPA DATA'!C:F,4,0)=1,"FACT_EST_CEN","SIN DATA")))) -> FACT_EST_EFACT | D20: =CONCATENATE("=SUMAR.SI(",IF(C20="FACT_EMITIDA","SIGGE_E",C20),"!B:B;Reliquidacion!B",A20,";",IF(C20="FACT_EMITIDA","SIGGE_E",C20),"!F:F)") -> =SUMAR.SI(FACT_EST_EFACT!B:B;Reliquidacion!B20;FACT_EST_EFACT!F:F) | E20: =CONCATENATE("=(F",A20,"/D",A20,")") -> =(F20/D20) | F20: =CONCATENATE("=SUMAR.SI(",IF(C20="FACT_EMITIDA","SIGGE_E",C20),"!B:B;Reliquidacion!B",A20,";",IF(C20="FACT_EMITIDA","SIGGE_E",C20),"!H:H)") -> =SUMAR.SI(FACT_EST_EFACT!B:B;Reliquidacion!B20;FACT_EST_EFACT!H:H) | G20: =CONCATENATE("=SUMAR.SI(",IF(C20="FACT_EMITIDA","SIGGE_P",C20),"!B:B;Reliquidacion!B",A20,";",IF(C20="FACT_EMITIDA","SIGGE_P",C20),"!F:F)") -> =SUMAR.SI(FACT_EST_EFACT!B:B;Reliquidacion!B20;FACT_EST_EFACT!F:F) | H20: =CONCATENATE("=(I",A20,"/G",A20,")") -> =(I20/G20) | I20: =CONCATENATE("=SUMAR.SI(",IF(C20="FACT_EMITIDA","SIGGE_P",C20),"!B:B;Reliquidacion!B",A20,";",IF(C20="FACT_EMITIDA","SIGGE_P",C20),"!H:H)") -> =SUMAR.SI(FACT_EST_EFACT!B:B;Reliquidacion!B20;FACT_EST_EFACT!H:H) | J20: =CONCATENATE("=(F",A20,"+I",A20,")") -> =(F20+I20) | L20: =IF(VLOOKUP(B20,'MAPA DATA'!C:H,5,0)=1,"EFACT_CNE",IF(VLOOKUP(B20,'MAPA DATA'!C:H,6,0)=1,"EFACT_EST_CNE","SIN DATA")) -> EFACT_CNE | M20: =CONCATENATE("=SUMAR.SI(",L20,"!B:B;Reliquidacion!B",A20,";",L20,"!S:S)") -> =SUMAR.SI(EFACT_CNE!B:B;Reliquidacion!B20;EFACT_CNE!S:S) | N20: =CONCATENATE("=(O",A20,"/M",A20,")") -> =(O20/M20) | O20: =CONCATENATE("=SUMAR.SI(",L20,"!B:B;Reliquidacion!B",A20,";",L20,"!W:W)") -> =SUMAR.SI(EFACT_CNE!B:B;Reliquidacion!B20;EFACT_CNE!W:W) | P20: =CONCATENATE("=SUMAR.SI(",L20,"!B:B;Reliquidacion!B",A20,";",L20,"!X:X)") -> =SUMAR.SI(EFACT_CNE!B:B;Reliquidacion!B20;EFACT_CNE!X:X) | Q20: =CONCATENATE("=(R",A20,"/P",A20,")") -> =(R20/P20) | R20: =CONCATENATE("=SUMAR.SI(",L20,"!B:B;Reliquidacion!B",A20,";",L20,"!AB:AB)") -> =SUMAR.SI(EFACT_CNE!B:B;Reliquidacion!B20;EFACT_CNE!AB:AB) | S20: =CONCATENATE("=(O",A20,"+R",A20,")") -> =(O20+R20) | U20: =CONCATENATE("=(S",A20,"-J",A20,")") -> =(S20-J20) | V20: PNP 7T/2029 | W20: =VLOOKUP(V20,#REF!,2,0) -> #REF! | X20: =VLOOKUP(V20,#REF!,6,0) -> #REF! | Y20: 43156 | Z20: 44377 | AA20: =Z20-Y20 -> 1221 | AB20: =+(1+X20)^(AA20/360)-1 -> #REF! | AC20: =AB20*U20 -> #REF! | AD20: =+U20+AC20 -> #VALUE!
A21: =A20+1 -> 21 | B21: 42736 | C21: =IF(VLOOKUP(B21,'MAPA DATA'!C:F,2,0)=1,"FACT_EMITIDA",IF(VLOOKUP(B21,'MAPA DATA'!C:F,3,0)=1,"FACT_EST_EFACT",(IF(VLOOKUP(B21,'MAPA DATA'!C:F,4,0)=1,"FACT_EST_CEN","SIN DATA")))) -> SIN DATA | D21: =CONCATENATE("=SUMAR.SI(",IF(C21="FACT_EMITIDA","SIGGE_E",C21),"!B:B;Reliquidacion!B",A21,";",IF(C21="FACT_EMITIDA","SIGGE_E",C21),"!F:F)") -> =SUMAR.SI(SIN DATA!B:B;Reliquidacion!B21;SIN DATA!F:F) | E21: =CONCATENATE("=(F",A21,"/D",A21,")") -> =(F21/D21) | F21: =CONCATENATE("=SUMAR.SI(",IF(C21="FACT_EMITIDA","SIGGE_E",C21),"!B:B;Reliquidacion!B",A21,";",IF(C21="FACT_EMITIDA","SIGGE_E",C21),"!H:H)") -> =SUMAR.SI(SIN DATA!B:B;Reliquidacion!B21;SIN DATA!H:H) | G21: =CONCATENATE("=SUMAR.SI(",IF(C21="FACT_EMITIDA","SIGGE_P",C21),"!B:B;Reliquidacion!B",A21,";",IF(C21="FACT_EMITIDA","SIGGE_P",C21),"!F:F)") -> =SUMAR.SI(SIN DATA!B:B;Reliquidacion!B21;SIN DATA!F:F) | H21: =CONCATENATE("=(I",A21,"/G",A21,")") -> =(I21/G21) | I21: =CONCATENATE("=SUMAR.SI(",IF(C21="FACT_EMITIDA","SIGGE_P",C21),"!B:B;Reliquidacion!B",A21,";",IF(C21="FACT_EMITIDA","SIGGE_P",C21),"!H:H)") -> =SUMAR.SI(SIN DATA!B:B;Reliquidacion!B21;SIN DATA!H:H) | J21: =CONCATENATE("=(F",A21,"+I",A21,")") -> =(F21+I21) | L21: =IF(VLOOKUP(B21,'MAPA DATA'!C:H,5,0)=1,"EFACT_CNE",IF(VLOOKUP(B21,'MAPA DATA'!C:H,6,0)=1,"EFACT_EST_CNE","SIN DATA")) -> EFACT_CNE | M21: =CONCATENATE("=SUMAR.SI(",L21,"!B:B;Reliquidacion!B",A21,";",L21,"!S:S)") -> =SUMAR.SI(EFACT_CNE!B:B;Reliquidacion!B21;EFACT_CNE!S:S) | N21: =CONCATENATE("=(O",A21,"/M",A21,")") -> =(O21/M21) | O21: =CONCATENATE("=SUMAR.SI(",L21,"!B:B;Reliquidacion!B",A21,";",L21,"!W:W)") -> =SUMAR.SI(EFACT_CNE!B:B;Reliquidacion!B21;EFACT_CNE!W:W) | P21: =CONCATENATE("=SUMAR.SI(",L21,"!B:B;Reliquidacion!B",A21,";",L21,"!X:X)") -> =SUMAR.SI(EFACT_CNE!B:B;Reliquidacion!B21;EFACT_CNE!X:X) | Q21: =CONCATENATE("=(R",A21,"/P",A21,")") -> =(R21/P21) | R21: =CONCATENATE("=SUMAR.SI(",L21,"!B:B;Reliquidacion!B",A21,";",L21,"!AB:AB)") -> =SUMAR.SI(EFACT_CNE!B:B;Reliquidacion!B21;EFACT_CNE!AB:AB) | S21: =CONCATENATE("=(O",A21,"+R",A21,")") -> =(O21+R21) | U21: =CONCATENATE("=(S",A21,"-J",A21,")") -> =(S21-J21) | V21: PNP 7T/2030 | W21: =VLOOKUP(V21,#REF!,2,0) -> #REF! | X21: =VLOOKUP(V21,#REF!,6,0) -> #REF! | Y21: 43156 | Z21: 44377 | AA21: =Z21-Y21 -> 1221 | AB21: =+(1+X21)^(AA21/360)-1 -> #REF! | AC21: =AB21*U21 -> #REF! | AD21: =+U21+AC21 -> #VALUE!
A22: =A21+1 -> 22 | B22: 42767 | C22: =IF(VLOOKUP(B22,'MAPA DATA'!C:F,2,0)=1,"FACT_EMITIDA",IF(VLOOKUP(B22,'MAPA DATA'!C:F,3,0)=1,"FACT_EST_EFACT",(IF(VLOOKUP(B22,'MAPA DATA'!C:F,4,0)=1,"FACT_EST_CEN","SIN DATA")))) -> FACT_EST_EFACT | D22: =CONCATENATE("=SUMAR.SI(",IF(C22="FACT_EMITIDA","SIGGE_E",C22),"!B:B;Reliquidacion!B",A22,";",IF(C22="FACT_EMITIDA","SIGGE_E",C22),"!F:F)") -> =SUMAR.SI(FACT_EST_EFACT!B:B;Reliquidacion!B22;FACT_EST_EFACT!F:F) | E22: =CONCATENATE("=(F",A22,"/D",A22,")") -> =(F22/D22) | F22: =CONCATENATE("=SUMAR.SI(",IF(C22="FACT_EMITIDA","SIGGE_E",C22),"!B:B;Reliquidacion!B",A22,";",IF(C22="FACT_EMITIDA","SIGGE_E",C22),"!H:H)") -> =SUMAR.SI(FACT_EST_EFACT!B:B;Reliquidacion!B22;FACT_EST_EFACT!H:H) | G22: =CONCATENATE("=SUMAR.SI(",IF(C22="FACT_EMITIDA","SIGGE_P",C22),"!B:B;Reliquidacion!B",A22,";",IF(C22="FACT_EMITIDA","SIGGE_P",C22),"!F:F)") -> =SUMAR.SI(FACT_EST_EFACT!B:B;Reliquidacion!B22;FACT_EST_EFACT!F:F) | H22: =CONCATENATE("=(I",A22,"/G",A22,")") -> =(I22/G22) | I22: =CONCATENATE("=SUMAR.SI(",IF(C22="FACT_EMITIDA","SIGGE_P",C22),"!B:B;Reliquidacion!B",A22,";",IF(C22="FACT_EMITIDA","SIGGE_P",C22),"!H:H)") -> =SUMAR.SI(FACT_EST_EFACT!B:B;Reliquidacion!B22;FACT_EST_EFACT!H:H) | J22: =CONCATENATE("=(F",A22,"+I",A22,")") -> =(F22+I22) | L22: =IF(VLOOKUP(B22,'MAPA DATA'!C:H,5,0)=1,"EFACT_CNE",IF(VLOOKUP(B22,'MAPA DATA'!C:H,6,0)=1,"EFACT_EST_CNE","SIN DATA")) -> EFACT_CNE | M22: =CONCATENATE("=SUMAR.SI(",L22,"!B:B;Reliquidacion!B",A22,";",L22,"!S:S)") -> =SUMAR.SI(EFACT_CNE!B:B;Reliquidacion!B22;EFACT_CNE!S:S) | N22: =CONCATENATE("=(O",A22,"/M",A22,")") -> =(O22/M22) | O22: =CONCATENATE("=SUMAR.SI(",L22,"!B:B;Reliquidacion!B",A22,";",L22,"!W:W)") -> =SUMAR.SI(EFACT_CNE!B:B;Reliquidacion!B22;EFACT_CNE!W:W) | P22: =CONCATENATE("=SUMAR.SI(",L22,"!B:B;Reliquidacion!B",A22,";",L22,"!X:X)") -> =SUMAR.SI(EFACT_CNE!B:B;Reliquidacion!B22;EFACT_CNE!X:X) | Q22: =CONCATENATE("=(R",A22,"/P",A22,")") -> =(R22/P22) | R22: =CONCATENATE("=SUMAR.SI(",L22,"!B:B;Reliquidacion!B",A22,";",L22,"!AB:AB)") -> =SUMAR.SI(EFACT_CNE!B:B;Reliquidacion!B22;EFACT_CNE!AB:AB) | S22: =CONCATENATE("=(O",A22,"+R",A22,")") -> =(O22+R22) | U22: =CONCATENATE("=(S",A22,"-J",A22,")") -> =(S22-J22) | V22: PNP 7T/2031 | W22: =VLOOKUP(V22,#REF!,2,0) -> #REF! | X22: =VLOOKUP(V22,#REF!,6,0) -> #REF! | Y22: 43156 | Z22: 44377 | AA22: =Z22-Y22 -> 1221 | AB22: =+(1+X22)^(AA22/360)-1 -> #REF! | AC22: =AB22*U22 -> #REF! | AD22: =+U22+AC22 -> #VALUE!
A23: =A22+1 -> 23 | B23: 42795 | C23: =IF(VLOOKUP(B23,'MAPA DATA'!C:F,2,0)=1,"FACT_EMITIDA",IF(VLOOKUP(B23,'MAPA DATA'!C:F,3,0)=1,"FACT_EST_EFACT",(IF(VLOOKUP(B23,'MAPA DATA'!C:F,4,0)=1,"FACT_EST_CEN","SIN DATA")))) -> FACT_EST_EFACT | D23: =CONCATENATE("=SUMAR.SI(",IF(C23="FACT_EMITIDA","SIGGE_E",C23),"!B:B;Reliquidacion!B",A23,";",IF(C23="FACT_EMITIDA","SIGGE_E",C23),"!F:F)") -> =SUMAR.SI(FACT_EST_EFACT!B:B;Reliquidacion!B23;FACT_EST_EFACT!F:F) | E23: =CONCATENATE("=(F",A23,"/D",A23,")") -> =(F23/D23) | F23: =CONCATENATE("=SUMAR.SI(",IF(C23="FACT_EMITIDA","SIGGE_E",C23),"!B:B;Reliquidacion!B",A23,";",IF(C23="FACT_EMITIDA","SIGGE_E",C23),"!H:H)") -> =SUMAR.SI(FACT_EST_EFACT!B:B;Reliquidacion!B23;FACT_EST_EFACT!H:H) | G23: =CONCATENATE("=SUMAR.SI(",IF(C23="FACT_EMITIDA","SIGGE_P",C23),"!B:B;Reliquidacion!B",A23,";",IF(C23="FACT_EMITIDA","SIGGE_P",C23),"!F:F)") -> =SUMAR.SI(FACT_EST_EFACT!B:B;Reliquidacion!B23;FACT_EST_EFACT!F:F) | H23: =CONCATENATE("=(I",A23,"/G",A23,")") -> =(I23/G23) | I23: =CONCATENATE("=SUMAR.SI(",IF(C23="FACT_EMITIDA","SIGGE_P",C23),"!B:B;Reliquidacion!B",A23,";",IF(C23="FACT_EMITIDA","SIGGE_P",C23),"!H:H)") -> =SUMAR.SI(FACT_EST_EFACT!B:B;Reliquidacion!B23;FACT_EST_EFACT!H:H) | J23: =CONCATENATE("=(F",A23,"+I",A23,")") -> =(F23+I23) | L23: =IF(VLOOKUP(B23,'MAPA DATA'!C:H,5,0)=1,"EFACT_CNE",IF(VLOOKUP(B23,'MAPA DATA'!C:H,6,0)=1,"EFACT_EST_CNE","SIN DATA")) -> EFACT_CNE | M23: =CONCATENATE("=SUMAR.SI(",L23,"!B:B;Reliquidacion!B",A23,";",L23,"!S:S)") -> =SUMAR.SI(EFACT_CNE!B:B;Reliquidacion!B23;EFACT_CNE!S:S) | N23: =CONCATENATE("=(O",A23,"/M",A23,")") -> =(O23/M23) | O23: =CONCATENATE("=SUMAR.SI(",L23,"!B:B;Reliquidacion!B",A23,";",L23,"!W:W)") -> =SUMAR.SI(EFACT_CNE!B:B;Reliquidacion!B23;EFACT_CNE!W:W) | P23: =CONCATENATE("=SUMAR.SI(",L23,"!B:B;Reliquidacion!B",A23,";",L23,"!X:X)") -> =SUMAR.SI(EFACT_CNE!B:B;Reliquidacion!B23;EFACT_CNE!X:X) | Q23: =CONCATENATE("=(R",A23,"/P",A23,")") -> =(R23/P23) | R23: =CONCATENATE("=SUMAR.SI(",L23,"!B:B;Reliquidacion!B",A23,";",L23,"!AB:AB)") -> =SUMAR.SI(EFACT_CNE!B:B;Reliquidacion!B23;EFACT_CNE!AB:AB) | S23: =CONCATENATE("=(O",A23,"+R",A23,")") -> =(O23+R23) | U23: =CONCATENATE("=(S",A23,"-J",A23,")") -> =(S23-J23)
A24: =A23+1 -> 24 | B24: 42826 | C24: =IF(VLOOKUP(B24,'MAPA DATA'!C:F,2,0)=1,"FACT_EMITIDA",IF(VLOOKUP(B24,'MAPA DATA'!C:F,3,0)=1,"FACT_EST_EFACT",(IF(VLOOKUP(B24,'MAPA DATA'!C:F,4,0)=1,"FACT_EST_CEN","SIN DATA")))) -> FACT_EST_EFACT | D24: =CONCATENATE("=SUMAR.SI(",IF(C24="FACT_EMITIDA","SIGGE_E",C24),"!B:B;Reliquidacion!B",A24,";",IF(C24="FACT_EMITIDA","SIGGE_E",C24),"!F:F)") -> =SUMAR.SI(FACT_EST_EFACT!B:B;Reliquidacion!B24;FACT_EST_EFACT!F:F) | E24: =CONCATENATE("=(F",A24,"/D",A24,")") -> =(F24/D24) | F24: =CONCATENATE("=SUMAR.SI(",IF(C24="FACT_EMITIDA","SIGGE_E",C24),"!B:B;Reliquidacion!B",A24,";",IF(C24="FACT_EMITIDA","SIGGE_E",C24),"!H:H)") -> =SUMAR.SI(FACT_EST_EFACT!B:B;Reliquidacion!B24;FACT_EST_EFACT!H:H) | G24: =CONCATENATE("=SUMAR.SI(",IF(C24="FACT_EMITIDA","SIGGE_P",C24),"!B:B;Reliquidacion!B",A24,";",IF(C24="FACT_EMITIDA","SIGGE_P",C24),"!F:F)") -> =SUMAR.SI(FACT_EST_EFACT!B:B;Reliquidacion!B24;FACT_EST_EFACT!F:F) | H24: =CONCATENATE("=(I",A24,"/G",A24,")") -> =(I24/G24) | I24: =CONCATENATE("=SUMAR.SI(",IF(C24="FACT_EMITIDA","SIGGE_P",C24),"!B:B;Reliquidacion!B",A24,";",IF(C24="FACT_EMITIDA","SIGGE_P",C24),"!H:H)") -> =SUMAR.SI(FACT_EST_EFACT!B:B;Reliquidacion!B24;FACT_EST_EFACT!H:H) | J24: =CONCATENATE("=(F",A24,"+I",A24,")") -> =(F24+I24) | L24: =IF(VLOOKUP(B24,'MAPA DATA'!C:H,5,0)=1,"EFACT_CNE",IF(VLOOKUP(B24,'MAPA DATA'!C:H,6,0)=1,"EFACT_EST_CNE","SIN DATA")) -> EFACT_CNE | M24: =CONCATENATE("=SUMAR.SI(",L24,"!B:B;Reliquidacion!B",A24,";",L24,"!S:S)") -> =SUMAR.SI(EFACT_CNE!B:B;Reliquidacion!B24;EFACT_CNE!S:S) | N24: =CONCATENATE("=(O",A24,"/M",A24,")") -> =(O24/M24) | O24: =CONCATENATE("=SUMAR.SI(",L24,"!B:B;Reliquidacion!B",A24,";",L24,"!W:W)") -> =SUMAR.SI(EFACT_CNE!B:B;Reliquidacion!B24;EFACT_CNE!W:W) | P24: =CONCATENATE("=SUMAR.SI(",L24,"!B:B;Reliquidacion!B",A24,";",L24,"!X:X)") -> =SUMAR.SI(EFACT_CNE!B:B;Reliquidacion!B24;EFACT_CNE!X:X) | Q24: =CONCATENATE("=(R",A24,"/P",A24,")") -> =(R24/P24) | R24: =CONCATENATE("=SUMAR.SI(",L24,"!B:B;Reliquidacion!B",A24,";",L24,"!AB:AB)") -> =SUMAR.SI(EFACT_CNE!B:B;Reliquidacion!B24;EFACT_CNE!AB:AB) | S24: =CONCATENATE("=(O",A24,"+R",A24,")") -> =(O24+R24) | U24: =CONCATENATE("=(S",A24,"-J",A24,")") -> =(S24-J24)
A25: =A24+1 -> 25 | B25: 42856 | C25: =IF(VLOOKUP(B25,'MAPA DATA'!C:F,2,0)=1,"FACT_EMITIDA",IF(VLOOKUP(B25,'MAPA DATA'!C:F,3,0)=1,"FACT_EST_EFACT",(IF(VLOOKUP(B25,'MAPA DATA'!C:F,4,0)=1,"FACT_EST_CEN","SIN DATA")))) -> FACT_EST_EFACT | D25: =CONCATENATE("=SUMAR.SI(",IF(C25="FACT_EMITIDA","SIGGE_E",C25),"!B:B;Reliquidacion!B",A25,";",IF(C25="FACT_EMITIDA","SIGGE_E",C25),"!F:F)") -> =SUMAR.SI(FACT_EST_EFACT!B:B;Reliquidacion!B25;FACT_EST_EFACT!F:F) | E25: =CONCATENATE("=(F",A25,"/D",A25,")") -> =(F25/D25) | F25: =CONCATENATE("=SUMAR.SI(",IF(C25="FACT_EMITIDA","SIGGE_E",C25),"!B:B;Reliquidacion!B",A25,";",IF(C25="FACT_EMITIDA","SIGGE_E",C25),"!H:H)") -> =SUMAR.SI(FACT_EST_EFACT!B:B;Reliquidacion!B25;FACT_EST_EFACT!H:H) | G25: =CONCATENATE("=SUMAR.SI(",IF(C25="FACT_EMITIDA","SIGGE_P",C25),"!B:B;Reliquidacion!B",A25,";",IF(C25="FACT_EMITIDA","SIGGE_P",C25),"!F:F)") -> =SUMAR.SI(FACT_EST_EFACT!B:B;Reliquidacion!B25;FACT_EST_EFACT!F:F) | H25: =CONCATENATE("=(I",A25,"/G",A25,")") -> =(I25/G25) | I25: =CONCATENATE("=SUMAR.SI(",IF(C25="FACT_EMITIDA","SIGGE_P",C25),"!B:B;Reliquidacion!B",A25,";",IF(C25="FACT_EMITIDA","SIGGE_P",C25),"!H:H)") -> =SUMAR.SI(FACT_EST_EFACT!B:B;Reliquidacion!B25;FACT_EST_EFACT!H:H) | J25: =CONCATENATE("=(F",A25,"+I",A25,")") -> =(F25+I25) | L25: =IF(VLOOKUP(B25,'MAPA DATA'!C:H,5,0)=1,"EFACT_CNE",IF(VLOOKUP(B25,'MAPA DATA'!C:H,6,0)=1,"EFACT_EST_CNE","SIN DATA")) -> EFACT_CNE | M25: =CONCATENATE("=SUMAR.SI(",L25,"!B:B;Reliquidacion!B",A25,";",L25,"!S:S)") -> =SUMAR.SI(EFACT_CNE!B:B;Reliquidacion!B25;EFACT_CNE!S:S) | N25: =CONCATENATE("=(O",A25,"/M",A25,")") -> =(O25/M25) | O25: =CONCATENATE("=SUMAR.SI(",L25,"!B:B;Reliquidacion!B",A25,";",L25,"!W:W)") -> =SUMAR.SI(EFACT_CNE!B:B;Reliquidacion!B25;EFACT_CNE!W:W) | P25: =CONCATENATE("=SUMAR.SI(",L25,"!B:B;Reliquidacion!B",A25,";",L25,"!X:X)") -> =SUMAR.SI(EFACT_CNE!B:B;Reliquidacion!B25;EFACT_CNE!X:X) | Q25: =CONCATENATE("=(R",A25,"/P",A25,")") -> =(R25/P25) | R25: =CONCATENATE("=SUMAR.SI(",L25,"!B:B;Reliquidacion!B",A25,";",L25,"!AB:AB)") -> =SUMAR.SI(EFACT_CNE!B:B;Reliquidacion!B25;EFACT_CNE!AB:AB) | S25: =CONCATENATE("=(O",A25,"+R",A25,")") -> =(O25+R25) | U25: =CONCATENATE("=(S",A25,"-J",A25,")") -> =(S25-J25)
A26: =A25+1 -> 26 | B26: 42887 | C26: =IF(VLOOKUP(B26,'MAPA DATA'!C:F,2,0)=1,"FACT_EMITIDA",IF(VLOOKUP(B26,'MAPA DATA'!C:F,3,0)=1,"FACT_EST_EFACT",(IF(VLOOKUP(B26,'MAPA DATA'!C:F,4,0)=1,"FACT_EST_CEN","SIN DATA")))) -> FACT_EST_EFACT | D26: =CONCATENATE("=SUMAR.SI(",IF(C26="FACT_EMITIDA","SIGGE_E",C26),"!B:B;Reliquidacion!B",A26,";",IF(C26="FACT_EMITIDA","SIGGE_E",C26),"!F:F)") -> =SUMAR.SI(FACT_EST_EFACT!B:B;Reliquidacion!B26;FACT_EST_EFACT!F:F) | E26: =CONCATENATE("=(F",A26,"/D",A26,")") -> =(F26/D26) | F26: =CONCATENATE("=SUMAR.SI(",IF(C26="FACT_EMITIDA","SIGGE_E",C26),"!B:B;Reliquidacion!B",A26,";",IF(C26="FACT_EMITIDA","SIGGE_E",C26),"!H:H)") -> =SUMAR.SI(FACT_EST_EFACT!B:B;Reliquidacion!B26;FACT_EST_EFACT!H:H) | G26: =CONCATENATE("=SUMAR.SI(",IF(C26="FACT_EMITIDA","SIGGE_P",C26),"!B:B;Reliquidacion!B",A26,";",IF(C26="FACT_EMITIDA","SIGGE_P",C26),"!F:F)") -> =SUMAR.SI(FACT_EST_EFACT!B:B;Reliquidacion!B26;FACT_EST_EFACT!F:F) | H26: =CONCATENATE("=(I",A26,"/G",A26,")") -> =(I26/G26) | I26: =CONCATENATE("=SUMAR.SI(",IF(C26="FACT_EMITIDA","SIGGE_P",C26),"!B:B;Reliquidacion!B",A26,";",IF(C26="FACT_EMITIDA","SIGGE_P",C26),"!H:H)") -> =SUMAR.SI(FACT_EST_EFACT!B:B;Reliquidacion!B26;FACT_EST_EFACT!H:H) | J26: =CONCATENATE("=(F",A26,"+I",A26,")") -> =(F26+I26) | L26: =IF(VLOOKUP(B26,'MAPA DATA'!C:H,5,0)=1,"EFACT_CNE",IF(VLOOKUP(B26,'MAPA DATA'!C:H,6,0)=1,"EFACT_EST_CNE","SIN DATA")) -> EFACT_CNE | M26: =CONCATENATE("=SUMAR.SI(",L26,"!B:B;Reliquidacion!B",A26,";",L26,"!S:S)") -> =SUMAR.SI(EFACT_CNE!B:B;Reliquidacion!B26;EFACT_CNE!S:S) | N26: =CONCATENATE("=(O",A26,"/M",A26,")") -> =(O26/M26) | O26: =CONCATENATE("=SUMAR.SI(",L26,"!B:B;Reliquidacion!B",A26,";",L26,"!W:W)") -> =SUMAR.SI(EFACT_CNE!B:B;Reliquidacion!B26;EFACT_CNE!W:W) | P26: =CONCATENATE("=SUMAR.SI(",L26,"!B:B;Reliquidacion!B",A26,";",L26,"!X:X)") -> =SUMAR.SI(EFACT_CNE!B:B;Reliquidacion!B26;EFACT_CNE!X:X) | Q26: =CONCATENATE("=(R",A26,"/P",A26,")") -> =(R26/P26) | R26: =CONCATENATE("=SUMAR.SI(",L26,"!B:B;Reliquidacion!B",A26,";",L26,"!AB:AB)") -> =SUMAR.SI(EFACT_CNE!B:B;Reliquidacion!B26;EFACT_CNE!AB:AB) | S26: =CONCATENATE("=(O",A26,"+R",A26,")") -> =(O26+R26) | U26: =CONCATENATE("=(S",A26,"-J",A26,")") -> =(S26-J26)
A27: =A26+1 -> 27 | B27: 42917 | C27: =IF(VLOOKUP(B27,'MAPA DATA'!C:F,2,0)=1,"FACT_EMITIDA",IF(VLOOKUP(B27,'MAPA DATA'!C:F,3,0)=1,"FACT_EST_EFACT",(IF(VLOOKUP(B27,'MAPA DATA'!C:F,4,0)=1,"FACT_EST_CEN","SIN DATA")))) -> FACT_EST_EFACT | D27: =CONCATENATE("=SUMAR.SI(",IF(C27="FACT_EMITIDA","SIGGE_E",C27),"!B:B;Reliquidacion!B",A27,";",IF(C27="FACT_EMITIDA","SIGGE_E",C27),"!F:F)") -> =SUMAR.SI(FACT_EST_EFACT!B:B;Reliquidacion!B27;FACT_EST_EFACT!F:F) | E27: =CONCATENATE("=(F",A27,"/D",A27,")") -> =(F27/D27) | F27: =CONCATENATE("=SUMAR.SI(",IF(C27="FACT_EMITIDA","SIGGE_E",C27),"!B:B;Reliquidacion!B",A27,";",IF(C27="FACT_EMITIDA","SIGGE_E",C27),"!H:H)") -> =SUMAR.SI(FACT_EST_EFACT!B:B;Reliquidacion!B27;FACT_EST_EFACT!H:H) | G27: =CONCATENATE("=SUMAR.SI(",IF(C27="FACT_EMITIDA","SIGGE_P",C27),"!B:B;Reliquidacion!B",A27,";",IF(C27="FACT_EMITIDA","SIGGE_P",C27),"!F:F)") -> =SUMAR.SI(FACT_EST_EFACT!B:B;Reliquidacion!B27;FACT_EST_EFACT!F:F) | H27: =CONCATENATE("=(I",A27,"/G",A27,")") -> =(I27/G27) | I27: =CONCATENATE("=SUMAR.SI(",IF(C27="FACT_EMITIDA","SIGGE_P",C27),"!B:B;Reliquidacion!B",A27,";",IF(C27="FACT_EMITIDA","SIGGE_P",C27),"!H:H)") -> =SUMAR.SI(FACT_EST_EFACT!B:B;Reliquidacion!B27;FACT_EST_EFACT!H:H) | J27: =CONCATENATE("=(F",A27,"+I",A27,")") -> =(F27+I27) | L27: =IF(VLOOKUP(B27,'MAPA DATA'!C:H,5,0)=1,"EFACT_CNE",IF(VLOOKUP(B27,'MAPA DATA'!C:H,6,0)=1,"EFACT_EST_CNE","SIN DATA")) -> EFACT_CNE | M27: =CONCATENATE("=SUMAR.SI(",L27,"!B:B;Reliquidacion!B",A27,";",L27,"!S:S)") -> =SUMAR.SI(EFACT_CNE!B:B;Reliquidacion!B27;EFACT_CNE!S:S) | N27: =CONCATENATE("=(O",A27,"/M",A27,")") -> =(O27/M27) | O27: =CONCATENATE("=SUMAR.SI(",L27,"!B:B;Reliquidacion!B",A27,";",L27,"!W:W)") -> =SUMAR.SI(EFACT_CNE!B:B;Reliquidacion!B27;EFACT_CNE!W:W) | P27: =CONCATENATE("=SUMAR.SI(",L27,"!B:B;Reliquidacion!B",A27,";",L27,"!X:X)") -> =SUMAR.SI(EFACT_CNE!B:B;Reliquidacion!B27;EFACT_CNE!X:X) | Q27: =CONCATENATE("=(R",A27,"/P",A27,")") -> =(R27/P27) | R27: =CONCATENATE("=SUMAR.SI(",L27,"!B:B;Reliquidacion!B",A27,";",L27,"!AB:AB)") -> =SUMAR.SI(EFACT_CNE!B:B;Reliquidacion!B27;EFACT_CNE!AB:AB) | S27: =CONCATENATE("=(O",A27,"+R",A27,")") -> =(O27+R27) | U27: =CONCATENATE("=(S",A27,"-J",A27,")") -> =(S27-J27)
A28: =A27+1 -> 28 | B28: 42948 | C28: =IF(VLOOKUP(B28,'MAPA DATA'!C:F,2,0)=1,"FACT_EMITIDA",IF(VLOOKUP(B28,'MAPA DATA'!C:F,3,0)=1,"FACT_EST_EFACT",(IF(VLOOKUP(B28,'MAPA DATA'!C:F,4,0)=1,"FACT_EST_CEN","SIN DATA")))) -> FACT_EST_EFACT | D28: =CONCATENATE("=SUMAR.SI(",IF(C28="FACT_EMITIDA","SIGGE_E",C28),"!B:B;Reliquidacion!B",A28,";",IF(C28="FACT_EMITIDA","SIGGE_E",C28),"!F:F)") -> =SUMAR.SI(FACT_EST_EFACT!B:B;Reliquidacion!B28;FACT_EST_EFACT!F:F) | E28: =CONCATENATE("=(F",A28,"/D",A28,")") -> =(F28/D28) | F28: =CONCATENATE("=SUMAR.SI(",IF(C28="FACT_EMITIDA","SIGGE_E",C28),"!B:B;Reliquidacion!B",A28,";",IF(C28="FACT_EMITIDA","SIGGE_E",C28),"!H:H)") -> =SUMAR.SI(FACT_EST_EFACT!B:B;Reliquidacion!B28;FACT_EST_EFACT!H:H) | G28: =CONCATENATE("=SUMAR.SI(",IF(C28="FACT_EMITIDA","SIGGE_P",C28),"!B:B;Reliquidacion!B",A28,";",IF(C28="FACT_EMITIDA","SIGGE_P",C28),"!F:F)") -> =SUMAR.SI(FACT_EST_EFACT!B:B;Reliquidacion!B28;FACT_EST_EFACT!F:F) | H28: =CONCATENATE("=(I",A28,"/G",A28,")") -> =(I28/G28) | I28: =CONCATENATE("=SUMAR.SI(",IF(C28="FACT_EMITIDA","SIGGE_P",C28),"!B:B;Reliquidacion!B",A28,";",IF(C28="FACT_EMITIDA","SIGGE_P",C28),"!H:H)") -> =SUMAR.SI(FACT_EST_EFACT!B:B;Reliquidacion!B28;FACT_EST_EFACT!H:H) | J28: =CONCATENATE("=(F",A28,"+I",A28,")") -> =(F28+I28) | L28: =IF(VLOOKUP(B28,'MAPA DATA'!C:H,5,0)=1,"EFACT_CNE",IF(VLOOKUP(B28,'MAPA DATA'!C:H,6,0)=1,"EFACT_EST_CNE","SIN DATA")) -> EFACT_CNE | M28: =CONCATENATE("=SUMAR.SI(",L28,"!B:B;Reliquidacion!B",A28,";",L28,"!S:S)") -> =SUMAR.SI(EFACT_CNE!B:B;Reliquidacion!B28;EFACT_CNE!S:S) | N28: =CONCATENATE("=(O",A28,"/M",A28,")") -> =(O28/M28) | O28: =CONCATENATE("=SUMAR.SI(",L28,"!B:B;Reliquidacion!B",A28,";",L28,"!W:W)") -> =SUMAR.SI(EFACT_CNE!B:B;Reliquidacion!B28;EFACT_CNE!W:W) | P28: =CONCATENATE("=SUMAR.SI(",L28,"!B:B;Reliquidacion!B",A28,";",L28,"!X:X)") -> =SUMAR.SI(EFACT_CNE!B:B;Reliquidacion!B28;EFACT_CNE!X:X) | Q28: =CONCATENATE("=(R",A28,"/P",A28,")") -> =(R28/P28) | R28: =CONCATENATE("=SUMAR.SI(",L28,"!B:B;Reliquidacion!B",A28,";",L28,"!AB:AB)") -> =SUMAR.SI(EFACT_CNE!B:B;Reliquidacion!B28;EFACT_CNE!AB:AB) | S28: =CONCATENATE("=(O",A28,"+R",A28,")") -> =(O28+R28) | U28: =CONCATENATE("=(S",A28,"-J",A28,")") -> =(S28-J28)
A29: =A28+1 -> 29 | B29: 42979 | C29: =IF(VLOOKUP(B29,'MAPA DATA'!C:F,2,0)=1,"FACT_EMITIDA",IF(VLOOKUP(B29,'MAPA DATA'!C:F,3,0)=1,"FACT_EST_EFACT",(IF(VLOOKUP(B29,'MAPA DATA'!C:F,4,0)=1,"FACT_EST_CEN","SIN DATA")))) -> FACT_EST_EFACT | D29: =CONCATENATE("=SUMAR.SI(",IF(C29="FACT_EMITIDA","SIGGE_E",C29),"!B:B;Reliquidacion!B",A29,";",IF(C29="FACT_EMITIDA","SIGGE_E",C29),"!F:F)") -> =SUMAR.SI(FACT_EST_EFACT!B:B;Reliquidacion!B29;FACT_EST_EFACT!F:F) | E29: =CONCATENATE("=(F",A29,"/D",A29,")") -> =(F29/D29) | F29: =CONCATENATE("=SUMAR.SI(",IF(C29="FACT_EMITIDA","SIGGE_E",C29),"!B:B;Reliquidacion!B",A29,";",IF(C29="FACT_EMITIDA","SIGGE_E",C29),"!H:H)") -> =SUMAR.SI(FACT_EST_EFACT!B:B;Reliquidacion!B29;FACT_EST_EFACT!H:H) | G29: =CONCATENATE("=SUMAR.SI(",IF(C29="FACT_EMITIDA","SIGGE_P",C29),"!B:B;Reliquidacion!B",A29,";",IF(C29="FACT_EMITIDA","SIGGE_P",C29),"!F:F)") -> =SUMAR.SI(FACT_EST_EFACT!B:B;Reliquidacion!B29;FACT_EST_EFACT!F:F) | H29: =CONCATENATE("=(I",A29,"/G",A29,")") -> =(I29/G29) | I29: =CONCATENATE("=SUMAR.SI(",IF(C29="FACT_EMITIDA","SIGGE_P",C29),"!B:B;Reliquidacion!B",A29,";",IF(C29="FACT_EMITIDA","SIGGE_P",C29),"!H:H)") -> =SUMAR.SI(FACT_EST_EFACT!B:B;Reliquidacion!B29;FACT_EST_EFACT!H:H) | J29: =CONCATENATE("=(F",A29,"+I",A29,")") -> =(F29+I29) | L29: =IF(VLOOKUP(B29,'MAPA DATA'!C:H,5,0)=1,"EFACT_CNE",IF(VLOOKUP(B29,'MAPA DATA'!C:H,6,0)=1,"EFACT_EST_CNE","SIN DATA")) -> EFACT_CNE | M29: =CONCATENATE("=SUMAR.SI(",L29,"!B:B;Reliquidacion!B",A29,";",L29,"!S:S)") -> =SUMAR.SI(EFACT_CNE!B:B;Reliquidacion!B29;EFACT_CNE!S:S) | N29: =CONCATENATE("=(O",A29,"/M",A29,")") -> =(O29/M29) | O29: =CONCATENATE("=SUMAR.SI(",L29,"!B:B;Reliquidacion!B",A29,";",L29,"!W:W)") -> =SUMAR.SI(EFACT_CNE!B:B;Reliquidacion!B29;EFACT_CNE!W:W) | P29: =CONCATENATE("=SUMAR.SI(",L29,"!B:B;Reliquidacion!B",A29,";",L29,"!X:X)") -> =SUMAR.SI(EFACT_CNE!B:B;Reliquidacion!B29;EFACT_CNE!X:X) | Q29: =CONCATENATE("=(R",A29,"/P",A29,")") -> =(R29/P29) | R29: =CONCATENATE("=SUMAR.SI(",L29,"!B:B;Reliquidacion!B",A29,";",L29,"!AB:AB)") -> =SUMAR.SI(EFACT_CNE!B:B;Reliquidacion!B29;EFACT_CNE!AB:AB) | S29: =CONCATENATE("=(O",A29,"+R",A29,")") -> =(O29+R29) | U29: =CONCATENATE("=(S",A29,"-J",A29,")") -> =(S29-J29)
A30: =A29+1 -> 30 | B30: 43009 | C30: =IF(VLOOKUP(B30,'MAPA DATA'!C:F,2,0)=1,"FACT_EMITIDA",IF(VLOOKUP(B30,'MAPA DATA'!C:F,3,0)=1,"FACT_EST_EFACT",(IF(VLOOKUP(B30,'MAPA DATA'!C:F,4,0)=1,"FACT_EST_CEN","SIN DATA")))) -> FACT_EST_EFACT | D30: =CONCATENATE("=SUMAR.SI(",IF(C30="FACT_EMITIDA","SIGGE_E",C30),"!B:B;Reliquidacion!B",A30,";",IF(C30="FACT_EMITIDA","SIGGE_E",C30),"!F:F)") -> =SUMAR.SI(FACT_EST_EFACT!B:B;Reliquidacion!B30;FACT_EST_EFACT!F:F) | E30: =CONCATENATE("=(F",A30,"/D",A30,")") -> =(F30/D30) | F30: =CONCATENATE("=SUMAR.SI(",IF(C30="FACT_EMITIDA","SIGGE_E",C30),"!B:B;Reliquidacion!B",A30,";",IF(C30="FACT_EMITIDA","SIGGE_E",C30),"!H:H)") -> =SUMAR.SI(FACT_EST_EFACT!B:B;Reliquidacion!B30;FACT_EST_EFACT!H:H) | G30: =CONCATENATE("=SUMAR.SI(",IF(C30="FACT_EMITIDA","SIGGE_P",C30),"!B:B;Reliquidacion!B",A30,";",IF(C30="FACT_EMITIDA","SIGGE_P",C30),"!F:F)") -> =SUMAR.SI(FACT_EST_EFACT!B:B;Reliquidacion!B30;FACT_EST_EFACT!F:F) | H30: =CONCATENATE("=(I",A30,"/G",A30,")") -> =(I30/G30) | I30: =CONCATENATE("=SUMAR.SI(",IF(C30="FACT_EMITIDA","SIGGE_P",C30),"!B:B;Reliquidacion!B",A30,";",IF(C30="FACT_EMITIDA","SIGGE_P",C30),"!H:H)") -> =SUMAR.SI(FACT_EST_EFACT!B:B;Reliquidacion!B30;FACT_EST_EFACT!H:H) | J30: =CONCATENATE("=(F",A30,"+I",A30,")") -> =(F30+I30) | L30: =IF(VLOOKUP(B30,'MAPA DATA'!C:H,5,0)=1,"EFACT_CNE",IF(VLOOKUP(B30,'MAPA DATA'!C:H,6,0)=1,"EFACT_EST_CNE","SIN DATA")) -> EFACT_CNE | M30: =CONCATENATE("=SUMAR.SI(",L30,"!B:B;Reliquidacion!B",A30,";",L30,"!S:S)") -> =SUMAR.SI(EFACT_CNE!B:B;Reliquidacion!B30;EFACT_CNE!S:S) | N30: =CONCATENATE("=(O",A30,"/M",A30,")") -> =(O30/M30) | O30: =CONCATENATE("=SUMAR.SI(",L30,"!B:B;Reliquidacion!B",A30,";",L30,"!W:W)") -> =SUMAR.SI(EFACT_CNE!B:B;Reliquidacion!B30;EFACT_CNE!W:W) | P30: =CONCATENATE("=SUMAR.SI(",L30,"!B:B;Reliquidacion!B",A30,";",L30,"!X:X)") -> =SUMAR.SI(EFACT_CNE!B:B;Reliquidacion!B30;EFACT_CNE!X:X) | Q30: =CONCATENATE("=(R",A30,"/P",A30,")") -> =(R30/P30) | R30: =CONCATENATE("=SUMAR.SI(",L30,"!B:B;Reliquidacion!B",A30,";",L30,"!AB:AB)") -> =SUMAR.SI(EFACT_CNE!B:B;Reliquidacion!B30;EFACT_CNE!AB:AB) | S30: =CONCATENATE("=(O",A30,"+R",A30,")") -> =(O30+R30) | U30: =CONCATENATE("=(S",A30,"-J",A30,")") -> =(S30-J30)
A31: =A30+1 -> 31 | B31: 43040 | C31: =IF(VLOOKUP(B31,'MAPA DATA'!C:F,2,0)=1,"FACT_EMITIDA",IF(VLOOKUP(B31,'MAPA DATA'!C:F,3,0)=1,"FACT_EST_EFACT",(IF(VLOOKUP(B31,'MAPA DATA'!C:F,4,0)=1,"FACT_EST_CEN","SIN DATA")))) -> FACT_EST_EFACT | D31: =CONCATENATE("=SUMAR.SI(",IF(C31="FACT_EMITIDA","SIGGE_E",C31),"!B:B;Reliquidacion!B",A31,";",IF(C31="FACT_EMITIDA","SIGGE_E",C31),"!F:F)") -> =SUMAR.SI(FACT_EST_EFACT!B:B;Reliquidacion!B31;FACT_EST_EFACT!F:F) | E31: =CONCATENATE("=(F",A31,"/D",A31,")") -> =(F31/D31) | F31: =CONCATENATE("=SUMAR.SI(",IF(C31="FACT_EMITIDA","SIGGE_E",C31),"!B:B;Reliquidacion!B",A31,";",IF(C31="FACT_EMITIDA","SIGGE_E",C31),"!H:H)") -> =SUMAR.SI(FACT_EST_EFACT!B:B;Reliquidacion!B31;FACT_EST_EFACT!H:H) | G31: =CONCATENATE("=SUMAR.SI(",IF(C31="FACT_EMITIDA","SIGGE_P",C31),"!B:B;Reliquidacion!B",A31,";",IF(C31="FACT_EMITIDA","SIGGE_P",C31),"!F:F)") -> =SUMAR.SI(FACT_EST_EFACT!B:B;Reliquidacion!B31;FACT_EST_EFACT!F:F) | H31: =CONCATENATE("=(I",A31,"/G",A31,")") -> =(I31/G31) | I31: =CONCATENATE("=SUMAR.SI(",IF(C31="FACT_EMITIDA","SIGGE_P",C31),"!B:B;Reliquidacion!B",A31,";",IF(C31="FACT_EMITIDA","SIGGE_P",C31),"!H:H)") -> =SUMAR.SI(FACT_EST_EFACT!B:B;Reliquidacion!B31;FACT_EST_EFACT!H:H) | J31: =CONCATENATE("=(F",A31,"+I",A31,")") -> =(F31+I31) | L31: =IF(VLOOKUP(B31,'MAPA DATA'!C:H,5,0)=1,"EFACT_CNE",IF(VLOOKUP(B31,'MAPA DATA'!C:H,6,0)=1,"EFACT_EST_CNE","SIN DATA")) -> EFACT_CNE | M31: =CONCATENATE("=SUMAR.SI(",L31,"!B:B;Reliquidacion!B",A31,";",L31,"!S:S)") -> =SUMAR.SI(EFACT_CNE!B:B;Reliquidacion!B31;EFACT_CNE!S:S) | N31: =CONCATENATE("=(O",A31,"/M",A31,")") -> =(O31/M31) | O31: =CONCATENATE("=SUMAR.SI(",L31,"!B:B;Reliquidacion!B",A31,";",L31,"!W:W)") -> =SUMAR.SI(EFACT_CNE!B:B;Reliquidacion!B31;EFACT_CNE!W:W) | P31: =CONCATENATE("=SUMAR.SI(",L31,"!B:B;Reliquidacion!B",A31,";",L31,"!X:X)") -> =SUMAR.SI(EFACT_CNE!B:B;Reliquidacion!B31;EFACT_CNE!X:X) | Q31: =CONCATENATE("=(R",A31,"/P",A31,")") -> =(R31/P31) | R31: =CONCATENATE("=SUMAR.SI(",L31,"!B:B;Reliquidacion!B",A31,";",L31,"!AB:AB)") -> =SUMAR.SI(EFACT_CNE!B:B;Reliquidacion!B31;EFACT_CNE!AB:AB) | S31: =CONCATENATE("=(O",A31,"+R",A31,")") -> =(O31+R31) | U31: =CONCATENATE("=(S",A31,"-J",A31,")") -> =(S31-J31)
A32: =A31+1 -> 32 | B32: 43070 | C32: =IF(VLOOKUP(B32,'MAPA DATA'!C:F,2,0)=1,"FACT_EMITIDA",IF(VLOOKUP(B32,'MAPA DATA'!C:F,3,0)=1,"FACT_EST_EFACT",(IF(VLOOKUP(B32,'MAPA DATA'!C:F,4,0)=1,"FACT_EST_CEN","SIN DATA")))) -> FACT_EST_EFACT | D32: =CONCATENATE("=SUMAR.SI(",IF(C32="FACT_EMITIDA","SIGGE_E",C32),"!B:B;Reliquidacion!B",A32,";",IF(C32="FACT_EMITIDA","SIGGE_E",C32),"!F:F)") -> =SUMAR.SI(FACT_EST_EFACT!B:B;Reliquidacion!B32;FACT_EST_EFACT!F:F) | E32: =CONCATENATE("=(F",A32,"/D",A32,")") -> =(F32/D32) | F32: =CONCATENATE("=SUMAR.SI(",IF(C32="FACT_EMITIDA","SIGGE_E",C32),"!B:B;Reliquidacion!B",A32,";",IF(C32="FACT_EMITIDA","SIGGE_E",C32),"!H:H)") -> =SUMAR.SI(FACT_EST_EFACT!B:B;Reliquidacion!B32;FACT_EST_EFACT!H:H) | G32: =CONCATENATE("=SUMAR.SI(",IF(C32="FACT_EMITIDA","SIGGE_P",C32),"!B:B;Reliquidacion!B",A32,";",IF(C32="FACT_EMITIDA","SIGGE_P",C32),"!F:F)") -> =SUMAR.SI(FACT_EST_EFACT!B:B;Reliquidacion!B32;FACT_EST_EFACT!F:F) | H32: =CONCATENATE("=(I",A32,"/G",A32,")") -> =(I32/G32) | I32: =CONCATENATE("=SUMAR.SI(",IF(C32="FACT_EMITIDA","SIGGE_P",C32),"!B:B;Reliquidacion!B",A32,";",IF(C32="FACT_EMITIDA","SIGGE_P",C32),"!H:H)") -> =SUMAR.SI(FACT_EST_EFACT!B:B;Reliquidacion!B32;FACT_EST_EFACT!H:H) | J32: =CONCATENATE("=(F",A32,"+I",A32,")") -> =(F32+I32) | L32: =IF(VLOOKUP(B32,'MAPA DATA'!C:H,5,0)=1,"EFACT_CNE",IF(VLOOKUP(B32,'MAPA DATA'!C:H,6,0)=1,"EFACT_EST_CNE","SIN DATA")) -> EFACT_CNE | M32: =CONCATENATE("=SUMAR.SI(",L32,"!B:B;Reliquidacion!B",A32,";",L32,"!S:S)") -> =SUMAR.SI(EFACT_CNE!B:B;Reliquidacion!B32;EFACT_CNE!S:S) | N32: =CONCATENATE("=(O",A32,"/M",A32,")") -> =(O32/M32) | O32: =CONCATENATE("=SUMAR.SI(",L32,"!B:B;Reliquidacion!B",A32,";",L32,"!W:W)") -> =SUMAR.SI(EFACT_CNE!B:B;Reliquidacion!B32;EFACT_CNE!W:W) | P32: =CONCATENATE("=SUMAR.SI(",L32,"!B:B;Reliquidacion!B",A32,";",L32,"!X:X)") -> =SUMAR.SI(EFACT_CNE!B:B;Reliquidacion!B32;EFACT_CNE!X:X) | Q32: =CONCATENATE("=(R",A32,"/P",A32,")") -> =(R32/P32) | R32: =CONCATENATE("=SUMAR.SI(",L32,"!B:B;Reliquidacion!B",A32,";",L32,"!AB:AB)") -> =SUMAR.SI(EFACT_CNE!B:B;Reliquidacion!B32;EFACT_CNE!AB:AB) | S32: =CONCATENATE("=(O",A32,"+R",A32,")") -> =(O32+R32) | U32: =CONCATENATE("=(S",A32,"-J",A32,")") -> =(S32-J32)
A33: =A32+1 -> 33 | B33: 43101 | C33: =IF(VLOOKUP(B33,'MAPA DATA'!C:F,2,0)=1,"FACT_EMITIDA",IF(VLOOKUP(B33,'MAPA DATA'!C:F,3,0)=1,"FACT_EST_EFACT",(IF(VLOOKUP(B33,'MAPA DATA'!C:F,4,0)=1,"FACT_EST_CEN","SIN DATA")))) -> FACT_EST_EFACT | D33: =CONCATENATE("=SUMAR.SI(",IF(C33="FACT_EMITIDA","SIGGE_E",C33),"!B:B;Reliquidacion!B",A33,";",IF(C33="FACT_EMITIDA","SIGGE_E",C33),"!F:F)") -> =SUMAR.SI(FACT_EST_EFACT!B:B;Reliquidacion!B33;FACT_EST_EFACT!F:F) | E33: =CONCATENATE("=(F",A33,"/D",A33,")") -> =(F33/D33) | F33: =CONCATENATE("=SUMAR.SI(",IF(C33="FACT_EMITIDA","SIGGE_E",C33),"!B:B;Reliquidacion!B",A33,";",IF(C33="FACT_EMITIDA","SIGGE_E",C33),"!H:H)") -> =SUMAR.SI(FACT_EST_EFACT!B:B;Reliquidacion!B33;FACT_EST_EFACT!H:H) | G33: =CONCATENATE("=SUMAR.SI(",IF(C33="FACT_EMITIDA","SIGGE_P",C33),"!B:B;Reliquidacion!B",A33,";",IF(C33="FACT_EMITIDA","SIGGE_P",C33),"!F:F)") -> =SUMAR.SI(FACT_EST_EFACT!B:B;Reliquidacion!B33;FACT_EST_EFACT!F:F) | H33: =CONCATENATE("=(I",A33,"/G",A33,")") -> =(I33/G33) | I33: =CONCATENATE("=SUMAR.SI(",IF(C33="FACT_EMITIDA","SIGGE_P",C33),"!B:B;Reliquidacion!B",A33,";",IF(C33="FACT_EMITIDA","SIGGE_P",C33),"!H:H)") -> =SUMAR.SI(FACT_EST_EFACT!B:B;Reliquidacion!B33;FACT_EST_EFACT!H:H) | J33: =CONCATENATE("=(F",A33,"+I",A33,")") -> =(F33+I33) | L33: =IF(VLOOKUP(B33,'MAPA DATA'!C:H,5,0)=1,"EFACT_CNE",IF(VLOOKUP(B33,'MAPA DATA'!C:H,6,0)=1,"EFACT_EST_CNE","SIN DATA")) -> EFACT_CNE | M33: =CONCATENATE("=SUMAR.SI(",L33,"!B:B;Reliquidacion!B",A33,";",L33,"!S:S)") -> =SUMAR.SI(EFACT_CNE!B:B;Reliquidacion!B33;EFACT_CNE!S:S) | N33: =CONCATENATE("=(O",A33,"/M",A33,")") -> =(O33/M33) | O33: =CONCATENATE("=SUMAR.SI(",L33,"!B:B;Reliquidacion!B",A33,";",L33,"!W:W)") -> =SUMAR.SI(EFACT_CNE!B:B;Reliquidacion!B33;EFACT_CNE!W:W) | P33: =CONCATENATE("=SUMAR.SI(",L33,"!B:B;Reliquidacion!B",A33,";",L33,"!X:X)") -> =SUMAR.SI(EFACT_CNE!B:B;Reliquidacion!B33;EFACT_CNE!X:X) | Q33: =CONCATENATE("=(R",A33,"/P",A33,")") -> =(R33/P33) | R33: =CONCATENATE("=SUMAR.SI(",L33,"!B:B;Reliquidacion!B",A33,";",L33,"!AB:AB)") -> =SUMAR.SI(EFACT_CNE!B:B;Reliquidacion!B33;EFACT_CNE!AB:AB) | S33: =CONCATENATE("=(O",A33,"+R",A33,")") -> =(O33+R33) | U33: =CONCATENATE("=(S",A33,"-J",A33,")") -> =(S33-J33) | V33: PNP 7T/2018 | W33: =VLOOKUP(V33,#REF!,2,0) -> #REF! | X33: =VLOOKUP(V33,#REF!,6,0) -> #REF! | Y33: 43156 | Z33: 44377 | AA33: =Z33-Y33 -> 1221 | AB33: =+(1+X33)^(AA33/360)-1 -> #REF! | AC33: =AB33*U33 -> #REF! | AD33: =+U33+AC33 -> #VALUE!
