Workbook

Sheet Reliquidacion
A2: Generador | B2: [GX]
A3: Distribuidor | B3: [EEDD]
A4: Licitacion | B4: 2013/03-2° Llamado
A5: Bloque | B5: [BLOQUE]
C7: LO QUE SE FACTURÓ | L7: LO QUE SE DEBIÓ HABER FACTURADO | U7: RELQUIDACIÓN Y CÁLCULO INTERESES
A8: ID | B8: MES | C8: ORIGEN DATA | D8: Energía (kWh) | E8: $/kWh | F8: Monto Energía ($) | G8: Potencia (kW) | H8: $/kW-mes | I8: Monto Potencia ($) | J8: Monto Total ($) | L8: ORIGEN DATA | M8: Energía (kWh) | N8: $/kWh | O8: Monto Energía ($) | P8: Potencia (kW) | Q8: $/kW-mes | R8: Monto Potencia ($) | S8: Monto Total ($) | U8: Mes | V8: Reliquidación mensual ($) | W8: Decreto PNP Reliquidación | X8: Fecha publicación Diario Oficial | Y8: Interés Anual | Z8: Fecha Facturación | AA8: Fecha Reliquidación | AB8: N° de días de intereses | AC8: Interés total según n° de días | AD8: Intereses ($) | AE8: Reliquidación Total ($)
A9: 9 | B9: 42370 | C9: =CONCATENATE("IF(VLOOKUP(B9,MAPA_DATA!D:G,2,0)=1,'FACT_EMITIDA',IF(VLOOKUP(B",A9,",MAPA_DATA!D:G,3,0)=1,'FACT_EST_EFACT',(IF(VLOOKUP(B",A9,",MAPA_DATA!D:G,4,0)=1,'FACT_EST_CEN','SIN_DATA')))") -> IF(VLOOKUP(B9,MAPA_DATA!D:G,2,0)=1,'FACT_EMITIDA',IF(VLOOKUP(B9,MAPA_DATA!D:G,3,0)=1,'FACT_EST_EFACT',(IF(VLOOKUP(B9,MAPA_DATA!D:G,4,0)=1,'FACT_EST_CEN','SIN_DATA'))) | D9: =CONCATENATE("SUMIF(",IF(C9="FACT_EMITIDA","SIGGE_E",C9),"!B:B,Reliquidacion!B",A9,",",IF(C9="FACT_EMITIDA","SIGGE_E",C9),"!F:F)") -> SUMIF(IF(VLOOKUP(B9,MAPA_DATA!D:G,2,0)=1,'FACT_EMITIDA',IF(VLOOKUP(B9,MAPA_DATA!D:G,3,0)=1,'FACT_EST_EFACT',(IF(VLOOKUP(B9,MAPA_DATA!D:G,4,0)=1,'FACT_EST_CEN','SIN_DATA')))!B:B,Reliquidacion!B9,IF(VLOOKUP(B9,MAPA_DATA!D:G,2,0)=1,'FACT_EMITIDA',IF(VLOOKUP(B9,MAPA_DATA!D:G,3,0)=1,'FACT_EST_EFACT',(IF(VLOOKUP(B9,MAPA_DATA!D:G,4,0)=1,'FACT_EST_CEN','SIN_DATA')))!F:F) | E9: =CONCATENATE("(F",A9,"/D",A9,")") -> (F9/D9) | F9: =CONCATENATE("SUMIF(",IF(C9="FACT_EMITIDA","SIGGE_E",C9),"!B:B,Reliquidacion!B",A9,",",IF(C9="FACT_EMITIDA","SIGGE_E",C9),"!H:H)") -> SUMIF(IF(VLOOKUP(B9,MAPA_DATA!D:G,2,0)=1,'FACT_EMITIDA',IF(VLOOKUP(B9,MAPA_DATA!D:G,3,0)=1,'FACT_EST_EFACT',(IF(VLOOKUP(B9,MAPA_DATA!D:G,4,0)=1,'FACT_EST_CEN','SIN_DATA')))!B:B,Reliquidacion!B9,IF(VLOOKUP(B9,MAPA_DATA!D:G,2,0)=1,'FACT_EMITIDA',IF(VLOOKUP(B9,MAPA_DATA!D:G,3,0)=1,'FACT_EST_EFACT',(IF(VLOOKUP(B9,MAPA_DATA!D:G,4,0)=1,'FACT_EST_CEN','SIN_DATA')))!H:H) | G9: =CONCATENATE("SUMIF(",IF(C9="FACT_EMITIDA","SIGGE_P",C9),"!B:B,Reliquidacion!B",A9,",",IF(C9="FACT_EMITIDA","SIGGE_P",C9),"!F:F)") -> SUMIF(IF(VLOOKUP(B9,MAPA_DATA!D:G,2,0)=1,'FACT_EMITIDA',IF(VLOOKUP(B9,MAPA_DATA!D:G,3,0)=1,'FACT_EST_EFACT',(IF(VLOOKUP(B9,MAPA_DATA!D:G,4,0)=1,'FACT_EST_CEN','SIN_DATA')))!B:B,Reliquidacion!B9,IF(VLOOKUP(B9,MAPA_DATA!D:G,2,0)=1,'FACT_EMITIDA',IF(VLOOKUP(B9,MAPA_DATA!D:G,3,0)=1,'FACT_EST_EFACT',(IF(VLOOKUP(B9,MAPA_DATA!D:G,4,0)=1,'FACT_EST_CEN','SIN_DATA')))!F:F) | H9: =CONCATENATE("(I",A9,"/G",A9,")") -> (I9/G9) | I9: =CONCATENATE("SUMIF(",IF(C9="FACT_EMITIDA","SIGGE_P",C9),"!B:B,Reliquidacion!B",A9,",",IF(C9="FACT_EMITIDA","SIGGE_P",C9),"!H:H)") -> SUMIF(IF(VLOOKUP(B9,MAPA_DATA!D:G,2,0)=1,'FACT_EMITIDA',IF(VLOOKUP(B9,MAPA_DATA!D:G,3,0)=1,'FACT_EST_EFACT',(IF(VLOOKUP(B9,MAPA_DATA!D:G,4,0)=1,'FACT_EST_CEN','SIN_DATA')))!B:B,Reliquidacion!B9,IF(VLOOKUP(B9,MAPA_DATA!D:G,2,0)=1,'FACT_EMITIDA',IF(VLOOKUP(B9,MAPA_DATA!D:G,3,0)=1,'FACT_EST_EFACT',(IF(VLOOKUP(B9,MAPA_DATA!D:G,4,0)=1,'FACT_EST_CEN','SIN_DATA')))!H:H) | J9: =CONCATENATE("(F",A9,"+I",A9,")") -> (F9+I9) | L9: =IF(VLOOKUP(B9,MAPA_DATA!D:I,5,0)=1,"EFACT_CNE",IF(VLOOKUP(B9,MAPA_DATA!D:I,6,0)=1,"EFACT_EST_CNE","SIN_DATA")) -> SIN_DATA | M9: =CONCATENATE("SUMIF(",L9,"!B:B;Reliquidacion!B",A9,";",L9,"!S:S)") -> SUMIF(SIN_DATA!B:B;Reliquidacion!B9;SIN_DATA!S:S) | N9: =CONCATENATE("(O",A9,"/M",A9,")") -> (O9/M9) | O9: =CONCATENATE("SUMIF(",L9,"!B:B;Reliquidacion!B",A9,";",L9,"!W:W)") -> SUMIF(SIN_DATA!B:B;Reliquidacion!B9;SIN_DATA!W:W) | P9: =CONCATENATE("SUMIF(",L9,"!B:B;Reliquidacion!B",A9,";",L9,"!X:X)") -> SUMIF(SIN_DATA!B:B;Reliquidacion!B9;SIN_DATA!X:X) | Q9: =CONCATENATE("(R",A9,"/P",A9,")") -> (R9/P9) | R9: =CONCATENATE("SUMIF(",L9,"!B:B;Reliquidacion!B",A9,";",L9,"!AB:AB)") -> SUMIF(SIN_DATA!B:B;Reliquidacion!B9;SIN_DATA!AB:AB) | S9: =CONCATENATE("(O",A9,"+R",A9,")") -> (O9+R9) | U9: 42370 | V9: =CONCATENATE("=(S",A9,"-J",A9,")") -> =(S9-J9) | W9: 8T/11-07-2016 | X9: =VLOOKUP(W9,[1]INTERESES!A:B,2,0) -> 0 | Y9: =VLOOKUP(W9,#REF!,6,0) -> #REF! | Z9: 43156 | AA9: 44377 | AB9: =AA9-Z9 -> 1221 | AC9: =+(1+Y9)^(AB9/360)-1 -> #REF! | AD9: =AC9*V9 -> #REF! | AE9: =+V9+AD9 -> #VALUE!
A10: =A9+1 -> 10 | B10: 42401 | C10: =CONCATENATE("IF(VLOOKUP(B9,MAPA_DATA!D:G,2,0)=1,'FACT_EMITIDA',IF(VLOOKUP(B",A10,",MAPA_DATA!D:G,3,0)=1,'FACT_EST_EFACT',(IF(VLOOKUP(B",A10,",MAPA_DATA!D:G,4,0)=1,'FACT_EST_CEN','SIN_DATA')))") -> IF(VLOOKUP(B9,MAPA_DATA!D:G,2,0)=1,'FACT_EMITIDA',IF(VLOOKUP(B10,MAPA_DATA!D:G,3,0)=1,'FACT_EST_EFACT',(IF(VLOOKUP(B10,MAPA_DATA!D:G,4,0)=1,'FACT_EST_CEN','SIN_DATA'))) | D10: =CONCATENATE("SUMIF(",IF(C10="FACT_EMITIDA","SIGGE_E",C10),"!B:B,Reliquidacion!B",A10,",",IF(C10="FACT_EMITIDA","SIGGE_E",C10),"!F:F)") -> SUMIF(IF(VLOOKUP(B9,MAPA_DATA!D:G,2,0)=1,'FACT_EMITIDA',IF(VLOOKUP(B10,MAPA_DATA!D:G,3,0)=1,'FACT_EST_EFACT',(IF(VLOOKUP(B10,MAPA_DATA!D:G,4,0)=1,'FACT_EST_CEN','SIN_DATA')))!B:B,Reliquidacion!B10,IF(VLOOKUP(B9,MAPA_DATA!D:G,2,0)=1,'FACT_EMITIDA',IF(VLOOKUP(B10,MAPA_DATA!D:G,3,0)=1,'FACT_EST_EFACT',(IF(VLOOKUP(B10,MAPA_DATA!D:G,4,0)=1,'FACT_EST_CEN','SIN_DATA')))!F:F) | E10: =CONCATENATE("(F",A10,"/D",A10,")") -> (F10/D10) | F10: =CONCATENATE("SUMIF(",IF(C10="FACT_EMITIDA","SIGGE_E",C10),"!B:B,Reliquidacion!B",A10,",",IF(C10="FACT_EMITIDA","SIGGE_E",C10),"!H:H)") -> SUMIF(IF(VLOOKUP(B9,MAPA_DATA!D:G,2,0)=1,'FACT_EMITIDA',IF(VLOOKUP(B10,MAPA_DATA!D:G,3,0)=1,'FACT_EST_EFACT',(IF(VLOOKUP(B10,MAPA_DATA!D:G,4,0)=1,'FACT_EST_CEN','SIN_DATA')))!B:B,Reliquidacion!B10,IF(VLOOKUP(B9,MAPA_DATA!D:G,2,0)=1,'FACT_EMITIDA',IF(VLOOKUP(B10,MAPA_DATA!D:G,3,0)=1,'FACT_EST_EFACT',(IF(VLOOKUP(B10,MAPA_DATA!D:G,4,0)=1,'FACT_EST_CEN','SIN_DATA')))!H:H) | G10: =CONCATENATE("SUMIF(",IF(C10="FACT_EMITIDA","SIGGE_P",C10),"!B:B,Reliquidacion!B",A10,",",IF(C10="FACT_EMITIDA","SIGGE_P",C10),"!F:F)") -> SUMIF(IF(VLOOKUP(B9,MAPA_DATA!D:G,2,0)=1,'FACT_EMITIDA',IF(VLOOKUP(B10,MAPA_DATA!D:G,3,0)=1,'FACT_EST_EFACT',(IF(VLOOKUP(B10,MAPA_DATA!D:G,4,0)=1,'FACT_EST_CEN','SIN_DATA')))!B:B,Reliquidacion!B10,IF(VLOOKUP(B9,MAPA_DATA!D:G,2,0)=1,'FACT_EMITIDA',IF(VLOOKUP(B10,MAPA_DATA!D:G,3,0)=1,'FACT_EST_EFACT',(IF(VLOOKUP(B10,MAPA_DATA!D:G,4,0)=1,'FACT_EST_CEN','SIN_DATA')))!F:F) | H10: =CONCATENATE("(I",A10,"/G",A10,")") -> (I10/G10) | I10: =CONCATENATE("SUMIF(",IF(C10="FACT_EMITIDA","SIGGE_P",C10),"!B:B,Reliquidacion!B",A10,",",IF(C10="FACT_EMITIDA","SIGGE_P",C10),"!H:H)") -> SUMIF(IF(VLOOKUP(B9,MAPA_DATA!D:G,2,0)=1,'FACT_EMITIDA',IF(VLOOKUP(B10,MAPA_DATA!D:G,3,0)=1,'FACT_EST_EFACT',(IF(VLOOKUP(B10,MAPA_DATA!D:G,4,0)=1,'FACT_EST_CEN','SIN_DATA')))!B:B,Reliquidacion!B10,IF(VLOOKUP(B9,MAPA_DATA!D:G,2,0)=1,'FACT_EMITIDA',IF(VLOOKUP(B10,MAPA_DATA!D:G,3,0)=1,'FACT_EST_EFACT',(IF(VLOOKUP(B10,MAPA_DATA!D:G,4,0)=1,'FACT_EST_CEN','SIN_DATA')))!H:H) | J10: =CONCATENATE("(F",A10,"+I",A10,")") -> (F10+I10) | L10: =IF(VLOOKUP(B10,MAPA_DATA!D:I,5,0)=1,"EFACT_CNE",IF(VLOOKUP(B10,MAPA_DATA!D:I,6,0)=1,"EFACT_EST_CNE","SIN_DATA")) -> SIN_DATA | M10: =CONCATENATE("SUMIF(",L10,"!B:B;Reliquidacion!B",A10,";",L10,"!S:S)") -> SUMIF(SIN_DATA!B:B;Reliquidacion!B10;SIN_DATA!S:S) | N10: =CONCATENATE("(O",A10,"/M",A10,")") -> (O10/M10) | O10: =CONCATENATE("SUMIF(",L10,"!B:B;Reliquidacion!B",A10,";",L10,"!W:W)") -> SUMIF(SIN_DATA!B:B;Reliquidacion!B10;SIN_DATA!W:W) | P10: =CONCATENATE("SUMIF(",L10,"!B:B;Reliquidacion!B",A10,";",L10,"!X:X)") -> SUMIF(SIN_DATA!B:B;Reliquidacion!B10;SIN_DATA!X:X) | Q10: =CONCATENATE("(R",A10,"/P",A10,")") -> (R10/P10) | R10: =CONCATENATE("SUMIF(",L10,"!B:B;Reliquidacion!B",A10,";",L10,"!AB:AB)") -> SUMIF(SIN_DATA!B:B;Reliquidacion!B10;SIN_DATA!AB:AB) | S10: =CONCATENATE("(O",A10,"+R",A10,")") -> (O10+R10) | U10: 42401 | V10: =CONCATENATE("=(S",A10,"-J",A10,")") -> =(S10-J10) | W10: 8T/11-07-2016 | X10: =VLOOKUP(W10,[1]INTERESES!A:B,2,0) -> 0 | Y10: =VLOOKUP(W10,#REF!,6,0) -> #REF! | Z10: 43156 | AA10: 44377 | AB10: =AA10-Z10 -> 1221 | AC10: =+(1+Y10)^(AB10/360)-1 -> #REF! | AD10: =AC10*V10 -> #REF! | AE10: =+V10+AD10 -> #VALUE!
A11: =A10+1 -> 11 | B11: 42430 | C11: =CONCATENATE("IF(VLOOKUP(B9,MAPA_DATA!D:G,2,0)=1,'FACT_EMITIDA',IF(VLOOKUP(B",A11,",MAPA_DATA!D:G,3,0)=1,'FACT_EST_EFACT',(IF(VLOOKUP(B",A11,",MAPA_DATA!D:G,4,0)=1,'FACT_EST_CEN','SIN_DATA')))") -> IF(VLOOKUP(B9,MAPA_DATA!D:G,2,0)=1,'FACT_EMITIDA',IF(VLOOKUP(B11,MAPA_DATA!D:G,3,0)=1,'FACT_EST_EFACT',(IF(VLOOKUP(B11,MAPA_DATA!D:G,4,0)=1,'FACT_EST_CEN','SIN_DATA'))) | D11: =CONCATENATE("SUMIF(",IF(C11="FACT_EMITIDA","SIGGE_E",C11),"!B:B,Reliquidacion!B",A11,",",IF(C11="FACT_EMITIDA","SIGGE_E",C11),"!F:F)") -> SUMIF(IF(VLOOKUP(B9,MAPA_DATA!D:G,2,0)=1,'FACT_EMITIDA',IF(VLOOKUP(B11,MAPA_DATA!D:G,3,0)=1,'FACT_EST_EFACT',(IF(VLOOKUP(B11,MAPA_DATA!D:G,4,0)=1,'FACT_EST_CEN','SIN_DATA')))!B:B,Reliquidacion!B11,IF(VLOOKUP(B9,MAPA_DATA!D:G,2,0)=1,'FACT_EMITIDA',IF(VLOOKUP(B11,MAPA_DATA!D:G,3,0)=1,'FACT_EST_EFACT',(IF(VLOOKUP(B11,MAPA_DATA!D:G,4,0)=1,'FACT_EST_CEN','SIN_DATA')))!F:F) | E11: =CONCATENATE("(F",A11,"/D",A11,")") -> (F11/D11) | F11: =CONCATENATE("SUMIF(",IF(C11="FACT_EMITIDA","SIGGE_E",C11),"!B:B,Reliquidacion!B",A11,",",IF(C11="FACT_EMITIDA","SIGGE_E",C11),"!H:H)") -> SUMIF(IF(VLOOKUP(B9,MAPA_DATA!D:G,2,0)=1,'FACT_EMITIDA',IF(VLOOKUP(B11,MAPA_DATA!D:G,3,0)=1,'FACT_EST_EFACT',(IF(VLOOKUP(B11,MAPA_DATA!D:G,4,0)=1,'FACT_EST_CEN','SIN_DATA')))!B:B,Reliquidacion!B11,IF(VLOOKUP(B9,MAPA_DATA!D:G,2,0)=1,'FACT_EMITIDA',IF(VLOOKUP(B11,MAPA_DATA!D:G,3,0)=1,'FACT_EST_EFACT',(IF(VLOOKUP(B11,MAPA_DATA!D:G,4,0)=1,'FACT_EST_CEN','SIN_DATA')))!H:H) | G11: =CONCATENATE("SUMIF(",IF(C11="FACT_EMITIDA","SIGGE_P",C11),"!B:B,Reliquidacion!B",A11,",",IF(C11="FACT_EMITIDA","SIGGE_P",C11),"!F:F)") -> SUMIF(IF(VLOOKUP(B9,MAPA_DATA!D:G,2,0)=1,'FACT_EMITIDA',IF(VLOOKUP(B11,MAPA_DATA!D:G,3,0)=1,'FACT_EST_EFACT',(IF(VLOOKUP(B11,MAPA_DATA!D:G,4,0)=1,'FACT_EST_CEN','SIN_DATA')))!B:B,Reliquidacion!B11,IF(VLOOKUP(B9,MAPA_DATA!D:G,2,0)=1,'FACT_EMITIDA',IF(VLOOKUP(B11,MAPA_DATA!D:G,3,0)=1,'FACT_EST_EFACT',(IF(VLOOKUP(B11,MAPA_DATA!D:G,4,0)=1,'FACT_EST_CEN','SIN_DATA')))!F:F) | H11: =CONCATENATE("(I",A11,"/G",A11,")") -> (I11/G11) | I11: =CONCATENATE("SUMIF(",IF(C11="FACT_EMITIDA","SIGGE_P",C11),"!B:B,Reliquidacion!B",A11,",",IF(C11="FACT_EMITIDA","SIGGE_P",C11),"!H:H)") -> SUMIF(IF(VLOOKUP(B9,MAPA_DATA!D:G,2,0)=1,'FACT_EMITIDA',IF(VLOOKUP(B11,MAPA_DATA!D:G,3,0)=1,'FACT_EST_EFACT',(IF(VLOOKUP(B11,MAPA_DATA!D:G,4,0)=1,'FACT_EST_CEN','SIN_DATA')))!B:B,Reliquidacion!B11,IF(VLOOKUP(B9,MAPA_DATA!D:G,2,0)=1,'FACT_EMITIDA',IF(VLOOKUP(B11,MAPA_DATA!D:G,3,0)=1,'FACT_EST_EFACT',(IF(VLOOKUP(B11,MAPA_DATA!D:G,4,0)=1,'FACT_EST_CEN','SIN_DATA')))!H:H) | J11: =CONCATENATE("(F",A11,"+I",A11,")") -> (F11+I11) | L11: =IF(VLOOKUP(B11,MAPA_DATA!D:I,5,0)=1,"EFACT_CNE",IF(VLOOKUP(B11,MAPA_DATA!D:I,6,0)=1,"EFACT_EST_CNE","SIN_DATA")) -> SIN_DATA | M11: =CONCATENATE("SUMIF(",L11,"!B:B;Reliquidacion!B",A11,";",L11,"!S:S)") -> SUMIF(SIN_DATA!B:B;Reliquidacion!B11;SIN_DATA!S:S) | N11: =CONCATENATE("(O",A11,"/M",A11,")") -> (O11/M11) | O11: =CONCATENATE("SUMIF(",L11,"!B:B;Reliquidacion!B",A11,";",L11,"!W:W)") -> SUMIF(SIN_DATA!B:B;Reliquidacion!B11;SIN_DATA!W:W) | P11: =CONCATENATE("SUMIF(",L11,"!B:B;Reliquidacion!B",A11,";",L11,"!X:X)") -> SUMIF(SIN_DATA!B:B;Reliquidacion!B11;SIN_DATA!X:X) | Q11: =CONCATENATE("(R",A11,"/P",A11,")") -> (R11/P11) | R11: =CONCATENATE("SUMIF(",L11,"!B:B;Reliquidacion!B",A11,";",L11,"!AB:AB)") -> SUMIF(SIN_DATA!B:B;Reliquidacion!B11;SIN_DATA!AB:AB) | S11: =CONCATENATE("(O",A11,"+R",A11,")") -> (O11+R11) | U11: 42430 | V11: =CONCATENATE("=(S",A11,"-J",A11,")") -> =(S11-J11) | W11: 12T/20-12-2016 | X11: =VLOOKUP(W11,[1]INTERESES!A:B,2,0) -> 0 | Y11: =VLOOKUP(W11,#REF!,6,0) -> #REF! | Z11: 43156 | AA11: 44377 | AB11: =AA11-Z11 -> 1221 | AC11: =+(1+Y11)^(AB11/360)-1 -> #REF! | AD11: =AC11*V11 -> #REF! | AE11: =+V11+AD11 -> #VALUE!
A12: =A11+1 -> 12 | B12: 42461 | C12: =CONCATENATE("IF(VLOOKUP(B9,MAPA_DATA!D:G,2,0)=1,'FACT_EMITIDA',IF(VLOOKUP(B",A12,",MAPA_DATA!D:G,3,0)=1,'FACT_EST_EFACT',(IF(VLOOKUP(B",A12,",MAPA_DATA!D:G,4,0)=1,'FACT_EST_CEN','SIN_DATA')))") -> IF(VLOOKUP(B9,MAPA_DATA!D:G,2,0)=1,'FACT_EMITIDA',IF(VLOOKUP(B12,MAPA_DATA!D:G,3,0)=1,'FACT_EST_EFACT',(IF(VLOOKUP(B12,MAPA_DATA!D:G,4,0)=1,'FACT_EST_CEN','SIN_DATA'))) | D12: =CONCATENATE("SUMIF(",IF(C12="FACT_EMITIDA","SIGGE_E",C12),"!B:B,Reliquidacion!B",A12,",",IF(C12="FACT_EMITIDA","SIGGE_E",C12),"!F:F)") -> SUMIF(IF(VLOOKUP(B9,MAPA_DATA!D:G,2,0)=1,'FACT_EMITIDA',IF(VLOOKUP(B12,MAPA_DATA!D:G,3,0)=1,'FACT_EST_EFACT',(IF(VLOOKUP(B12,MAPA_DATA!D:G,4,0)=1,'FACT_EST_CEN','SIN_DATA')))!B:B,Reliquidacion!B12,IF(VLOOKUP(B9,MAPA_DATA!D:G,2,0)=1,'FACT_EMITIDA',IF(VLOOKUP(B12,MAPA_DATA!D:G,3,0)=1,'FACT_EST_EFACT',(IF(VLOOKUP(B12,MAPA_DATA!D:G,4,0)=1,'FACT_EST_CEN','SIN_DATA')))!F:F) | E12: =CONCATENATE("(F",A12,"/D",A12,")") -> (F12/D12) | F12: =CONCATENATE("SUMIF(",IF(C12="FACT_EMITIDA","SIGGE_E",C12),"!B:B,Reliquidacion!B",A12,",",IF(C12="FACT_EMITIDA","SIGGE_E",C12),"!H:H)") -> SUMIF(IF(VLOOKUP(B9,MAPA_DATA!D:G,2,0)=1,'FACT_EMITIDA',IF(VLOOKUP(B12,MAPA_DATA!D:G,3,0)=1,'FACT_EST_EFACT',(IF(VLOOKUP(B12,MAPA_DATA!D:G,4,0)=1,'FACT_EST_CEN','SIN_DATA')))!B:B,Reliquidacion!B12,IF(VLOOKUP(B9,MAPA_DATA!D:G,2,0)=1,'FACT_EMITIDA',IF(VLOOKUP(B12,MAPA_DATA!D:G,3,0)=1,'FACT_EST_EFACT',(IF(VLOOKUP(B12,MAPA_DATA!D:G,4,0)=1,'FACT_EST_CEN','SIN_DATA')))!H:H) | G12: =CONCATENATE("SUMIF(",IF(C12="FACT_EMITIDA","SIGGE_P",C12),"!B:B,Reliquidacion!B",A12,",",IF(C12="FACT_EMITIDA","SIGGE_P",C12),"!F:F)") -> SUMIF(IF(VLOOKUP(B9,MAPA_DATA!D:G,2,0)=1,'FACT_EMITIDA',IF(VLOOKUP(B12,MAPA_DATA!D:G,3,0)=1,'FACT_EST_EFACT',(IF(VLOOKUP(B12,MAPA_DATA!D:G,4,0)=1,'FACT_EST_CEN','SIN_DATA')))!B:B,Reliquidacion!B12,IF(VLOOKUP(B9,MAPA_DATA!D:G,2,0)=1,'FACT_EMITIDA',IF(VLOOKUP(B12,MAPA_DATA!D:G,3,0)=1,'FACT_EST_EFACT',(IF(VLOOKUP(B12,MAPA_DATA!D:G,4,0)=1,'FACT_EST_CEN','SIN_DATA')))!F:F) | H12: =CONCATENATE("(I",A12,"/G",A12,")") -> (I12/G12) | I12: =CONCATENATE("SUMIF(",IF(C12="FACT_EMITIDA","SIGGE_P",C12),"!B:B,Reliquidacion!B",A12,",",IF(C12="FACT_EMITIDA","SIGGE_P",C12),"!H:H)") -> SUMIF(IF(VLOOKUP(B9,MAPA_DATA!D:G,2,0)=1,'FACT_EMITIDA',IF(VLOOKUP(B12,MAPA_DATA!D:G,3,0)=1,'FACT_EST_EFACT',(IF(VLOOKUP(B12,MAPA_DATA!D:G,4,0)=1,'FACT_EST_CEN','SIN_DATA')))!B:B,Reliquidacion!B12,IF(VLOOKUP(B9,MAPA_DATA!D:G,2,0)=1,'FACT_EMITIDA',IF(VLOOKUP(B12,MAPA_DATA!D:G,3,0)=1,'FACT_EST_EFACT',(IF(VLOOKUP(B12,MAPA_DATA!D:G,4,0)=1,'FACT_EST_CEN','SIN_DATA')))!H:H) | J12: =CONCATENATE("(F",A12,"+I",A12,")") -> (F12+I12) | L12: =IF(VLOOKUP(B12,MAPA_DATA!D:I,5,0)=1,"EFACT_CNE",IF(VLOOKUP(B12,MAPA_DATA!D:I,6,0)=1,"EFACT_EST_CNE","SIN_DATA")) -> SIN_DATA | M12: =CONCATENATE("SUMIF(",L12,"!B:B;Reliquidacion!B",A12,";",L12,"!S:S)") -> SUMIF(SIN_DATA!B:B;Reliquidacion!B12;SIN_DATA!S:S) | N12: =CONCATENATE("(O",A12,"/M",A12,")") -> (O12/M12) | O12: =CONCATENATE("SUMIF(",L12,"!B:B;Reliquidacion!B",A12,";",L12,"!W:W)") -> SUMIF(SIN_DATA!B:B;Reliquidacion!B12;SIN_DATA!W:W) | P12: =CONCATENATE("SUMIF(",L12,"!B:B;Reliquidacion!B",A12,";",L12,"!X:X)") -> SUMIF(SIN_DATA!B:B;Reliquidacion!B12;SIN_DATA!X:X) | Q12: =CONCATENATE("(R",A12,"/P",A12,")") -> (R12/P12) | R12: =CONCATENATE("SUMIF(",L12,"!B:B;Reliquidacion!B",A12,";",L12,"!AB:AB)") -> SUMIF(SIN_DATA!B:B;Reliquidacion!B12;SIN_DATA!AB:AB) | S12: =CONCATENATE("(O",A12,"+R",A12,")") -> (O12+R12) | U12: 42461 | V12: =CONCATENATE("=(S",A12,"-J",A12,")") -> =(S12-J12) | W12: 12T/20-12-2016 | X12: =VLOOKUP(W12,[1]INTERESES!A:B,2,0) -> 0 | Y12: =VLOOKUP(W12,#REF!,6,0) -> #REF! | Z12: 43156 | AA12: 44377 | AB12: =AA12-Z12 -> 1221 | AC12: =+(1+Y12)^(AB12/360)-1 -> #REF! | AD12: =AC12*V12 -> #REF! | AE12: =+V12+AD12 -> #VALUE!
A13: =A12+1 -> 13 | B13: 42491 | C13: =CONCATENATE("IF(VLOOKUP(B9,MAPA_DATA!D:G,2,0)=1,'FACT_EMITIDA',IF(VLOOKUP(B",A13,",MAPA_DATA!D:G,3,0)=1,'FACT_EST_EFACT',(IF(VLOOKUP(B",A13,",MAPA_DATA!D:G,4,0)=1,'FACT_EST_CEN','SIN_DATA')))") -> IF(VLOOKUP(B9,MAPA_DATA!D:G,2,0)=1,'FACT_EMITIDA',IF(VLOOKUP(B13,MAPA_DATA!D:G,3,0)=1,'FACT_EST_EFACT',(IF(VLOOKUP(B13,MAPA_DATA!D:G,4,0)=1,'FACT_EST_CEN','SIN_DATA'))) | D13: =CONCATENATE("SUMIF(",IF(C13="FACT_EMITIDA","SIGGE_E",C13),"!B:B,Reliquidacion!B",A13,",",IF(C13="FACT_EMITIDA","SIGGE_E",C13),"!F:F)") -> SUMIF(IF(VLOOKUP(B9,MAPA_DATA!D:G,2,0)=1,'FACT_EMITIDA',IF(VLOOKUP(B13,MAPA_DATA!D:G,3,0)=1,'FACT_EST_EFACT',(IF(VLOOKUP(B13,MAPA_DATA!D:G,4,0)=1,'FACT_EST_CEN','SIN_DATA')))!B:B,Reliquidacion!B13,IF(VLOOKUP(B9,MAPA_DATA!D:G,2,0)=1,'FACT_EMITIDA',IF(VLOOKUP(B13,MAPA_DATA!D:G,3,0)=1,'FACT_EST_EFACT',(IF(VLOOKUP(B13,MAPA_DATA!D:G,4,0)=1,'FACT_EST_CEN','SIN_DATA')))!F:F) | E13: =CONCATENATE("(F",A13,"/D",A13,")") -> (F13/D13) | F13: =CONCATENATE("SUMIF(",IF(C13="FACT_EMITIDA","SIGGE_E",C13),"!B:B,Reliquidacion!B",A13,",",IF(C13="FACT_EMITIDA","SIGGE_E",C13),"!H:H)") -> SUMIF(IF(VLOOKUP(B9,MAPA_DATA!D:G,2,0)=1,'FACT_EMITIDA',IF(VLOOKUP(B13,MAPA_DATA!D:G,3,0)=1,'FACT_EST_EFACT',(IF(VLOOKUP(B13,MAPA_DATA!D:G,4,0)=1,'FACT_EST_CEN','SIN_DATA')))!B:B,Reliquidacion!B13,IF(VLOOKUP(B9,MAPA_DATA!D:G,2,0)=1,'FACT_EMITIDA',IF(VLOOKUP(B13,MAPA_DATA!D:G,3,0)=1,'FACT_EST_EFACT',(IF(VLOOKUP(B13,MAPA_DATA!D:G,4,0)=1,'FACT_EST_CEN','SIN_DATA')))!H:H) | G13: =CONCATENATE("SUMIF(",IF(C13="FACT_EMITIDA","SIGGE_P",C13),"!B:B,Reliquidacion!B",A13,",",IF(C13="FACT_EMITIDA","SIGGE_P",C13),"!F:F)") -> SUMIF(IF(VLOOKUP(B9,MAPA_DATA!D:G,2,0)=1,'FACT_EMITIDA',IF(VLOOKUP(B13,MAPA_DATA!D:G,3,0)=1,'FACT_EST_EFACT',(IF(VLOOKUP(B13,MAPA_DATA!D:G,4,0)=1,'FACT_EST_CEN','SIN_DATA')))!B:B,Reliquidacion!B13,IF(VLOOKUP(B9,MAPA_DATA!D:G,2,0)=1,'FACT_EMITIDA',IF(VLOOKUP(B13,MAPA_DATA!D:G,3,0)=1,'FACT_EST_EFACT',(IF(VLOOKUP(B13,MAPA_DATA!D:G,4,0)=1,'FACT_EST_CEN','SIN_DATA')))!F:F) | H13: =CONCATENATE("(I",A13,"/G",A13,")") -> (I13/G13) | I13: =CONCATENATE("SUMIF(",IF(C13="FACT_EMITIDA","SIGGE_P",C13),"!B:B,Reliquidacion!B",A13,",",IF(C13="FACT_EMITIDA","SIGGE_P",C13),"!H:H)") -> SUMIF(IF(VLOOKUP(B9,MAPA_DATA!D:G,2,0)=1,'FACT_EMITIDA',IF(VLOOKUP(B13,MAPA_DATA!D:G,3,0)=1,'FACT_EST_EFACT',(IF(VLOOKUP(B13,MAPA_DATA!D:G,4,0)=1,'FACT_EST_CEN','SIN_DATA')))!B:B,Reliquidacion!B13,IF(VLOOKUP(B9,MAPA_DATA!D:G,2,0)=1,'FACT_EMITIDA',IF(VLOOKUP(B13,MAPA_DATA!D:G,3,0)=1,'FACT_EST_EFACT',(IF(VLOOKUP(B13,MAPA_DATA!D:G,4,0)=1,'FACT_EST_CEN','SIN_DATA')))!H:H) | J13: =CONCATENATE("(F",A13,"+I",A13,")") -> (F13+I13) | L13: =IF(VLOOKUP(B13,MAPA_DATA!D:I,5,0)=1,"EFACT_CNE",IF(VLOOKUP(B13,MAPA_DATA!D:I,6,0)=1,"EFACT_EST_CNE","SIN_DATA")) -> SIN_DATA | M13: =CONCATENATE("SUMIF(",L13,"!B:B;Reliquidacion!B",A13,";",L13,"!S:S)") -> SUMIF(SIN_DATA!B:B;Reliquidacion!B13;SIN_DATA!S:S) | N13: =CONCATENATE("(O",A13,"/M",A13,")") -> (O13/M13) | O13: =CONCATENATE("SUMIF(",L13,"!B:B;Reliquidacion!B",A13,";",L13,"!W:W)") -> SUMIF(SIN_DATA!B:B;Reliquidacion!B13;SIN_DATA!W:W) | P13: =CONCATENATE("SUMIF(",L13,"!B:B;Reliquidacion!B",A13,";",L13,"!X:X)") -> SUMIF(SIN_DATA!B:B;Reliquidacion!B13;SIN_DATA!X:X) | Q13: =CONCATENATE("(R",A13,"/P",A13,")") -> (R13/P13) | R13: =CONCATENATE("SUMIF(",L13,"!B:B;Reliquidacion!B",A13,";",L13,"!AB:AB)") -> SUMIF(SIN_DATA!B:B;Reliquidacion!B13;SIN_DATA!AB:AB) | S13: =CONCATENATE("(O",A13,"+R",A13,")") -> (O13+R13) | U13: 42491 | V13: =CONCATENATE("=(S",A13,"-J",A13,")") -> =(S13-J13) | W13: 3T/15-05-2017 | X13: =VLOOKUP(W13,[1]INTERESES!A:B,2,0) -> 0 | Y13: =VLOOKUP(W13,#REF!,6,0) -> #REF! | Z13: 43156 | AA13: 44377 | AB13: =AA13-Z13 -> 1221 | AC13: =+(1+Y13)^(AB13/360)-1 -> #REF! | AD13: =AC13*V13 -> #REF! | AE13: =+V13+AD13 -> #VALUE!
A14: =A13+1 -> 14 | B14: 42522 | C14: =CONCATENATE("IF(VLOOKUP(B9,MAPA_DATA!D:G,2,0)=1,'FACT_EMITIDA',IF(VLOOKUP(B",A14,",MAPA_DATA!D:G,3,0)=1,'FACT_EST_EFACT',(IF(VLOOKUP(B",A14,",MAPA_DATA!D:G,4,0)=1,'FACT_EST_CEN','SIN_DATA')))") -> IF(VLOOKUP(B9,MAPA_DATA!D:G,2,0)=1,'FACT_EMITIDA',IF(VLOOKUP(B14,MAPA_DATA!D:G,3,0)=1,'FACT_EST_EFACT',(IF(VLOOKUP(B14,MAPA_DATA!D:G,4,0)=1,'FACT_EST_CEN','SIN_DATA'))) | D14: =CONCATENATE("SUMIF(",IF(C14="FACT_EMITIDA","SIGGE_E",C14),"!B:B,Reliquidacion!B",A14,",",IF(C14="FACT_EMITIDA","SIGGE_E",C14),"!F:F)") -> SUMIF(IF(VLOOKUP(B9,MAPA_DATA!D:G,2,0)=1,'FACT_EMITIDA',IF(VLOOKUP(B14,MAPA_DATA!D:G,3,0)=1,'FACT_EST_EFACT',(IF(VLOOKUP(B14,MAPA_DATA!D:G,4,0)=1,'FACT_EST_CEN','SIN_DATA')))!B:B,Reliquidacion!B14,IF(VLOOKUP(B9,MAPA_DATA!D:G,2,0)=1,'FACT_EMITIDA',IF(VLOOKUP(B14,MAPA_DATA!D:G,3,0)=1,'FACT_EST_EFACT',(IF(VLOOKUP(B14,MAPA_DATA!D:G,4,0)=1,'FACT_EST_CEN','SIN_DATA')))!F:F) | E14: =CONCATENATE("(F",A14,"/D",A14,")") -> (F14/D14) | F14: =CONCATENATE("SUMIF(",IF(C14="FACT_EMITIDA","SIGGE_E",C14),"!B:B,Reliquidacion!B",A14,",",IF(C14="FACT_EMITIDA","SIGGE_E",C14),"!H:H)") -> SUMIF(IF(VLOOKUP(B9,MAPA_DATA!D:G,2,0)=1,'FACT_EMITIDA',IF(VLOOKUP(B14,MAPA_DATA!D:G,3,0)=1,'FACT_EST_EFACT',(IF(VLOOKUP(B14,MAPA_DATA!D:G,4,0)=1,'FACT_EST_CEN','SIN_DATA')))!B:B,Reliquidacion!B14,IF(VLOOKUP(B9,MAPA_DATA!D:G,2,0)=1,'FACT_EMITIDA',IF(VLOOKUP(B14,MAPA_DATA!D:G,3,0)=1,'FACT_EST_EFACT',(IF(VLOOKUP(B14,MAPA_DATA!D:G,4,0)=1,'FACT_EST_CEN','SIN_DATA')))!H:H) | G14: =CONCATENATE("SUMIF(",IF(C14="FACT_EMITIDA","SIGGE_P",C14),"!B:B,Reliquidacion!B",A14,",",IF(C14="FACT_EMITIDA","SIGGE_P",C14),"!F:F)") -> SUMIF(IF(VLOOKUP(B9,MAPA_DATA!D:G,2,0)=1,'FACT_EMITIDA',IF(VLOOKUP(B14,MAPA_DATA!D:G,3,0)=1,'FACT_EST_EFACT',(IF(VLOOKUP(B14,MAPA_DATA!D:G,4,0)=1,'FACT_EST_CEN','SIN_DATA')))!B:B,Reliquidacion!B14,IF(VLOOKUP(B9,MAPA_DATA!D:G,2,0)=1,'FACT_EMITIDA',IF(VLOOKUP(B14,MAPA_DATA!D:G,3,0)=1,'FACT_EST_EFACT',(IF(VLOOKUP(B14,MAPA_DATA!D:G,4,0)=1,'FACT_EST_CEN','SIN_DATA')))!F:F) | H14: =CONCATENATE("(I",A14,"/G",A14,")") -> (I14/G14) | I14: =CONCATENATE("SUMIF(",IF(C14="FACT_EMITIDA","SIGGE_P",C14),"!B:B,Reliquidacion!B",A14,",",IF(C14="FACT_EMITIDA","SIGGE_P",C14),"!H:H)") -> SUMIF(IF(VLOOKUP(B9,MAPA_DATA!D:G,2,0)=1,'FACT_EMITIDA',IF(VLOOKUP(B14,MAPA_DATA!D:G,3,0)=1,'FACT_EST_EFACT',(IF(VLOOKUP(B14,MAPA_DATA!D:G,4,0)=1,'FACT_EST_CEN','SIN_DATA')))!B:B,Reliquidacion!B14,IF(VLOOKUP(B9,MAPA_DATA!D:G,2,0)=1,'FACT_EMITIDA',IF(VLOOKUP(B14,MAPA_DATA!D:G,3,0)=1,'FACT_EST_EFACT',(IF(VLOOKUP(B14,MAPA_DATA!D:G,4,0)=1,'FACT_EST_CEN','SIN_DATA')))!H:H) | J14: =CONCATENATE("(F",A14,"+I",A14,")") -> (F14+I14) | L14: =IF(VLOOKUP(B14,MAPA_DATA!D:I,5,0)=1,"EFACT_CNE",IF(VLOOKUP(B14,MAPA_DATA!D:I,6,0)=1,"EFACT_EST_CNE","SIN_DATA")) -> SIN_DATA | M14: =CONCATENATE("SUMIF(",L14,"!B:B;Reliquidacion!B",A14,";",L14,"!S:S)") -> SUMIF(SIN_DATA!B:B;Reliquidacion!B14;SIN_DATA!S:S) | N14: =CONCATENATE("(O",A14,"/M",A14,")") -> (O14/M14) | O14: =CONCATENATE("SUMIF(",L14,"!B:B;Reliquidacion!B",A14,";",L14,"!W:W)") -> SUMIF(SIN_DATA!B:B;Reliquidacion!B14;SIN_DATA!W:W) | P14: =CONCATENATE("SUMIF(",L14,"!B:B;Reliquidacion!B",A14,";",L14,"!X:X)") -> SUMIF(SIN_DATA!B:B;Reliquidacion!B14;SIN_DATA!X:X) | Q14: =CONCATENATE("(R",A14,"/P",A14,")") -> (R14/P14) | R14: =CONCATENATE("SUMIF(",L14,"!B:B;Reliquidacion!B",A14,";",L14,"!AB:AB)") -> SUMIF(SIN_DATA!B:B;Reliquidacion!B14;SIN_DATA!AB:AB) | S14: =CONCATENATE("(O",A14,"+R",A14,")") -> (O14+R14) | U14: 42522 | V14: =CONCATENATE("=(S",A14,"-J",A14,")") -> =(S14-J14) | W14: 3T/15-05-2017 | X14: =VLOOKUP(W14,[1]INTERESES!A:B,2,0) -> 0 | Y14: =VLOOKUP(W14,#REF!,6,0) -> #REF! | Z14: 43156 | AA14: 44377 | AB14: =AA14-Z14 -> 1221 | AC14: =+(1+Y14)^(AB14/360)-1 -> #REF! | AD14: =AC14*V14 -> #REF! | AE14: =+V14+AD14 -> #VALUE!
A15: =A14+1 -> 15 | B15: 42552 | C15: =CONCATENATE("IF(VLOOKUP(B9,MAPA_DATA!D:G,2,0)=1,'FACT_EMITIDA',IF(VLOOKUP(B",A15,",MAPA_DATA!D:G,3,0)=1,'FACT_EST_EFACT',(IF(VLOOKUP(B",A15,",MAPA_DATA!D:G,4,0)=1,'FACT_EST_CEN','SIN_DATA')))") -> IF(VLOOKUP(B9,MAPA_DATA!D:G,2,0)=1,'FACT_EMITIDA',IF(VLOOKUP(B15,MAPA_DATA!D:G,3,0)=1,'FACT_EST_EFACT',(IF(VLOOKUP(B15,MAPA_DATA!D:G,4,0)=1,'FACT_EST_CEN','SIN_DATA'))) | D15: =CONCATENATE("SUMIF(",IF(C15="FACT_EMITIDA","SIGGE_E",C15),"!B:B,Reliquidacion!B",A15,",",IF(C15="FACT_EMITIDA","SIGGE_E",C15),"!F:F)") -> SUMIF(IF(VLOOKUP(B9,MAPA_DATA!D:G,2,0)=1,'FACT_EMITIDA',IF(VLOOKUP(B15,MAPA_DATA!D:G,3,0)=1,'FACT_EST_EFACT',(IF(VLOOKUP(B15,MAPA_DATA!D:G,4,0)=1,'FACT_EST_CEN','SIN_DATA')))!B:B,Reliquidacion!B15,IF(VLOOKUP(B9,MAPA_DATA!D:G,2,0)=1,'FACT_EMITIDA',IF(VLOOKUP(B15,MAPA_DATA!D:G,3,0)=1,'FACT_EST_EFACT',(IF(VLOOKUP(B15,MAPA_DATA!D:G,4,0)=1,'FACT_EST_CEN','SIN_DATA')))!F:F) | E15: =CONCATENATE("(F",A15,"/D",A15,")") -> (F15/D15) | F15: =CONCATENATE("SUMIF(",IF(C15="FACT_EMITIDA","SIGGE_E",C15),"!B:B,Reliquidacion!B",A15,",",IF(C15="FACT_EMITIDA","SIGGE_E",C15),"!H:H)") -> SUMIF(IF(VLOOKUP(B9,MAPA_DATA!D:G,2,0)=1,'FACT_EMITIDA',IF(VLOOKUP(B15,MAPA_DATA!D:G,3,0)=1,'FACT_EST_EFACT',(IF(VLOOKUP(B15,MAPA_DATA!D:G,4,0)=1,'FACT_EST_CEN','SIN_DATA')))!B:B,Reliquidacion!B15,IF(VLOOKUP(B9,MAPA_DATA!D:G,2,0)=1,'FACT_EMITIDA',IF(VLOOKUP(B15,MAPA_DATA!D:G,3,0)=1,'FACT_EST_EFACT',(IF(VLOOKUP(B15,MAPA_DATA!D:G,4,0)=1,'FACT_EST_CEN','SIN_DATA')))!H:H) | G15: =CONCATENATE("SUMIF(",IF(C15="FACT_EMITIDA","SIGGE_P",C15),"!B:B,Reliquidacion!B",A15,",",IF(C15="FACT_EMITIDA","SIGGE_P",C15),"!F:F)") -> SUMIF(IF(VLOOKUP(B9,MAPA_DATA!D:G,2,0)=1,'FACT_EMITIDA',IF(VLOOKUP(B15,MAPA_DATA!D:G,3,0)=1,'FACT_EST_EFACT',(IF(VLOOKUP(B15,MAPA_DATA!D:G,4,0)=1,'FACT_EST_CEN','SIN_DATA')))!B:B,Reliquidacion!B15,IF(VLOOKUP(B9,MAPA_DATA!D:G,2,0)=1,'FACT_EMITIDA',IF(VLOOKUP(B15,MAPA_DATA!D:G,3,0)=1,'FACT_EST_EFACT',(IF(VLOOKUP(B15,MAPA_DATA!D:G,4,0)=1,'FACT_EST_CEN','SIN_DATA')))!F:F) | H15: =CONCATENATE("(I",A15,"/G",A15,")") -> (I15/G15) | I15: =CONCATENATE("SUMIF(",IF(C15="FACT_EMITIDA","SIGGE_P",C15),"!B:B,Reliquidacion!B",A15,",",IF(C15="FACT_EMITIDA","SIGGE_P",C15),"!H:H)") -> SUMIF(IF(VLOOKUP(B9,MAPA_DATA!D:G,2,0)=1,'FACT_EMITIDA',IF(VLOOKUP(B15,MAPA_DATA!D:G,3,0)=1,'FACT_EST_EFACT',(IF(VLOOKUP(B15,MAPA_DATA!D:G,4,0)=1,'FACT_EST_CEN','SIN_DATA')))!B:B,Reliquidacion!B15,IF(VLOOKUP(B9,MAPA_DATA!D:G,2,0)=1,'FACT_EMITIDA',IF(VLOOKUP(B15,MAPA_DATA!D:G,3,0)=1,'FACT_EST_EFACT',(IF(VLOOKUP(B15,MAPA_DATA!D:G,4,0)=1,'FACT_EST_CEN','SIN_DATA')))!H:H) | J15: =CONCATENATE("(F",A15,"+I",A15,")") -> (F15+I15) | L15: =IF(VLOOKUP(B15,MAPA_DATA!D:I,5,0)=1,"EFACT_CNE",IF(VLOOKUP(B15,MAPA_DATA!D:I,6,0)=1,"EFACT_EST_CNE","SIN_DATA")) -> SIN_DATA | M15: =CONCATENATE("SUMIF(",L15,"!B:B;Reliquidacion!B",A15,";",L15,"!S:S)") -> SUMIF(SIN_DATA!B:B;Reliquidacion!B15;SIN_DATA!S:S) | N15: =CONCATENATE("(O",A15,"/M",A15,")") -> (O15/M15) | O15: =CONCATENATE("SUMIF(",L15,"!B:B;Reliquidacion!B",A15,";",L15,"!W:W)") -> SUMIF(SIN_DATA!B:B;Reliquidacion!B15;SIN_DATA!W:W) | P15: =CONCATENATE("SUMIF(",L15,"!B:B;Reliquidacion!B",A15,";",L15,"!X:X)") -> SUMIF(SIN_DATA!B:B;Reliquidacion!B15;SIN_DATA!X:X) | Q15: =CONCATENATE("(R",A15,"/P",A15,")") -> (R15/P15) | R15: =CONCATENATE("SUMIF(",L15,"!B:B;Reliquidacion!B",A15,";",L15,"!AB:AB)") -> SUMIF(SIN_DATA!B:B;Reliquidacion!B15;SIN_DATA!AB:AB) | S15: =CONCATENATE("(O",A15,"+R",A15,")") -> (O15+R15) | U15: 42552 | V15: =CONCATENATE("=(S",A15,"-J",A15,")") -> =(S15-J15) | W15: 3T/15-05-2017 | X15: =VLOOKUP(W15,[1]INTERESES!A:B,2,0) -> 0 | Y15: =VLOOKUP(W15,#REF!,6,0) -> #REF! | Z15: 43156 | AA15: 44377 | AB15: =AA15-Z15 -> 1221 | AC15: =+(1+Y15)^(AB15/360)-1 -> #REF! | AD15: =AC15*V15 -> #REF! | AE15: =+V15+AD15 -> #VALUE!
A16: =A15+1 -> 16 | B16: 42583 | C16: =CONCATENATE("IF(VLOOKUP(B9,MAPA_DATA!D:G,2,0)=1,'FACT_EMITIDA',IF(VLOOKUP(B",A16,",MAPA_DATA!D:G,3,0)=1,'FACT_EST_EFACT',(IF(VLOOKUP(B",A16,",MAPA_DATA!D:G,4,0)=1,'FACT_EST_CEN','SIN_DATA')))") -> IF(VLOOKUP(B9,MAPA_DATA!D:G,2,0)=1,'FACT_EMITIDA',IF(VLOOKUP(B16,MAPA_DATA!D:G,3,0)=1,'FACT_EST_EFACT',(IF(VLOOKUP(B16,MAPA_DATA!D:G,4,0)=1,'FACT_EST_CEN','SIN_DATA'))) | D16: =CONCATENATE("SUMIF(",IF(C16="FACT_EMITIDA","SIGGE_E",C16),"!B:B,Reliquidacion!B",A16,",",IF(C16="FACT_EMITIDA","SIGGE_E",C16),"!F:F)") -> SUMIF(IF(VLOOKUP(B9,MAPA_DATA!D:G,2,0)=1,'FACT_EMITIDA',IF(VLOOKUP(B16,MAPA_DATA!D:G,3,0)=1,'FACT_EST_EFACT',(IF(VLOOKUP(B16,MAPA_DATA!D:G,4,0)=1,'FACT_EST_CEN','SIN_DATA')))!B:B,Reliquidacion!B16,IF(VLOOKUP(B9,MAPA_DATA!D:G,2,0)=1,'FACT_EMITIDA',IF(VLOOKUP(B16,MAPA_DATA!D:G,3,0)=1,'FACT_EST_EFACT',(IF(VLOOKUP(B16,MAPA_DATA!D:G,4,0)=1,'FACT_EST_CEN','SIN_DATA')))!F:F) | E16: =CONCATENATE("(F",A16,"/D",A16,")") -> (F16/D16) | F16: =CONCATENATE("SUMIF(",IF(C16="FACT_EMITIDA","SIGGE_E",C16),"!B:B,Reliquidacion!B",A16,",",IF(C16="FACT_EMITIDA","SIGGE_E",C16),"!H:H)") -> SUMIF(IF(VLOOKUP(B9,MAPA_DATA!D:G,2,0)=1,'FACT_EMITIDA',IF(VLOOKUP(B16,MAPA_DATA!D:G,3,0)=1,'FACT_EST_EFACT',(IF(VLOOKUP(B16,MAPA_DATA!D:G,4,0)=1,'FACT_EST_CEN','SIN_DATA')))!B:B,Reliquidacion!B16,IF(VLOOKUP(B9,MAPA_DATA!D:G,2,0)=1,'FACT_EMITIDA',IF(VLOOKUP(B16,MAPA_DATA!D:G,3,0)=1,'FACT_EST_EFACT',(IF(VLOOKUP(B16,MAPA_DATA!D:G,4,0)=1,'FACT_EST_CEN','SIN_DATA')))!H:H) | G16: =CONCATENATE("SUMIF(",IF(C16="FACT_EMITIDA","SIGGE_P",C16),"!B:B,Reliquidacion!B",A16,",",IF(C16="FACT_EMITIDA","SIGGE_P",C16),"!F:F)") -> SUMIF(IF(VLOOKUP(B9,MAPA_DATA!D:G,2,0)=1,'FACT_EMITIDA',IF(VLOOKUP(B16,MAPA_DATA!D:G,3,0)=1,'FACT_EST_EFACT',(IF(VLOOKUP(B16,MAPA_DATA!D:G,4,0)=1,'FACT_EST_CEN','SIN_DATA')))!B:B,Reliquidacion!B16,IF(VLOOKUP(B9,MAPA_DATA!D:G,2,0)=1,'FACT_EMITIDA',IF(VLOOKUP(B16,MAPA_DATA!D:G,3,0)=1,'FACT_EST_EFACT',(IF(VLOOKUP(B16,MAPA_DATA!D:G,4,0)=1,'FACT_EST_CEN','SIN_DATA')))!F:F) | H16: =CONCATENATE("(I",A16,"/G",A16,")") -> (I16/G16) | I16: =CONCATENATE("SUMIF(",IF(C16="FACT_EMITIDA","SIGGE_P",C16),"!B:B,Reliquidacion!B",A16,",",IF(C16="FACT_EMITIDA","SIGGE_P",C16),"!H:H)") -> SUMIF(IF(VLOOKUP(B9,MAPA_DATA!D:G,2,0)=1,'FACT_EMITIDA',IF(VLOOKUP(B16,MAPA_DATA!D:G,3,0)=1,'FACT_EST_EFACT',(IF(VLOOKUP(B16,MAPA_DATA!D:G,4,0)=1,'FACT_EST_CEN','SIN_DATA')))!B:B,Reliquidacion!B16,IF(VLOOKUP(B9,MAPA_DATA!D:G,2,0)=1,'FACT_EMITIDA',IF(VLOOKUP(B16,MAPA_DATA!D:G,3,0)=1,'FACT_EST_EFACT',(IF(VLOOKUP(B16,MAPA_DATA!D:G,4,0)=1,'FACT_EST_CEN','SIN_DATA')))!H:H) | J16: =CONCATENATE("(F",A16,"+I",A16,")") -> (F16+I16) | L16: =IF(VLOOKUP(B16,MAPA_DATA!D:I,5,0)=1,"EFACT_CNE",IF(VLOOKUP(B16,MAPA_DATA!D:I,6,0)=1,"EFACT_EST_CNE","SIN_DATA")) -> SIN_DATA | M16: =CONCATENATE("SUMIF(",L16,"!B:B;Reliquidacion!B",A16,";",L16,"!S:S)") -> SUMIF(SIN_DATA!B:B;Reliquidacion!B16;SIN_DATA!S:S) | N16: =CONCATENATE("(O",A16,"/M",A16,")") -> (O16/M16) | O16: =CONCATENATE("SUMIF(",L16,"!B:B;Reliquidacion!B",A16,";",L16,"!W:W)") -> SUMIF(SIN_DATA!B:B;Reliquidacion!B16;SIN_DATA!W:W) | P16: =CONCATENATE("SUMIF(",L16,"!B:B;Reliquidacion!B",A16,";",L16,"!X:X)") -> SUMIF(SIN_DATA!B:B;Reliquidacion!B16;SIN_DATA!X:X) | Q16: =CONCATENATE("(R",A16,"/P",A16,")") -> (R16/P16) | R16: =CONCATENATE("SUMIF(",L16,"!B:B;Reliquidacion!B",A16,";",L16,"!AB:AB)") -> SUMIF(SIN_DATA!B:B;Reliquidacion!B16;SIN_DATA!AB:AB) | S16: =CONCATENATE("(O",A16,"+R",A16,")") -> (O16+R16) | U16: 42583 | V16: =CONCATENATE("=(S",A16,"-J",A16,")") -> =(S16-J16) | W16: 3T/15-05-2017 | X16: =VLOOKUP(W16,[1]INTERESES!A:B,2,0) -> 0 | Y16: =VLOOKUP(W16,#REF!,6,0) -> #REF! | Z16: 43156 | AA16: 44377 | AB16: =AA16-Z16 -> 1221 | AC16: =+(1+Y16)^(AB16/360)-1 -> #REF! | AD16: =AC16*V16 -> #REF! | AE16: =+V16+AD16 -> #VALUE!
A17: =A16+1 -> 17 | B17: 42614 | C17: =CONCATENATE("IF(VLOOKUP(B9,MAPA_DATA!D:G,2,0)=1,'FACT_EMITIDA',IF(VLOOKUP(B",A17,",MAPA_DATA!D:G,3,0)=1,'FACT_EST_EFACT',(IF(VLOOKUP(B",A17,",MAPA_DATA!D:G,4,0)=1,'FACT_EST_CEN','SIN_DATA')))") -> IF(VLOOKUP(B9,MAPA_DATA!D:G,2,0)=1,'FACT_EMITIDA',IF(VLOOKUP(B17,MAPA_DATA!D:G,3,0)=1,'FACT_EST_EFACT',(IF(VLOOKUP(B17,MAPA_DATA!D:G,4,0)=1,'FACT_EST_CEN','SIN_DATA'))) | D17: =CONCATENATE("SUMIF(",IF(C17="FACT_EMITIDA","SIGGE_E",C17),"!B:B,Reliquidacion!B",A17,",",IF(C17="FACT_EMITIDA","SIGGE_E",C17),"!F:F)") -> SUMIF(IF(VLOOKUP(B9,MAPA_DATA!D:G,2,0)=1,'FACT_EMITIDA',IF(VLOOKUP(B17,MAPA_DATA!D:G,3,0)=1,'FACT_EST_EFACT',(IF(VLOOKUP(B17,MAPA_DATA!D:G,4,0)=1,'FACT_EST_CEN','SIN_DATA')))!B:B,Reliquidacion!B17,IF(VLOOKUP(B9,MAPA_DATA!D:G,2,0)=1,'FACT_EMITIDA',IF(VLOOKUP(B17,MAPA_DATA!D:G,3,0)=1,'FACT_EST_EFACT',(IF(VLOOKUP(B17,MAPA_DATA!D:G,4,0)=1,'FACT_EST_CEN','SIN_DATA')))!F:F) | E17: =CONCATENATE("(F",A17,"/D",A17,")") -> (F17/D17) | F17: =CONCATENATE("SUMIF(",IF(C17="FACT_EMITIDA","SIGGE_E",C17),"!B:B,Reliquidacion!B",A17,",",IF(C17="FACT_EMITIDA","SIGGE_E",C17),"!H:H)") -> SUMIF(IF(VLOOKUP(B9,MAPA_DATA!D:G,2,0)=1,'FACT_EMITIDA',IF(VLOOKUP(B17,MAPA_DATA!D:G,3,0)=1,'FACT_EST_EFACT',(IF(VLOOKUP(B17,MAPA_DATA!D:G,4,0)=1,'FACT_EST_CEN','SIN_DATA')))!B:B,Reliquidacion!B17,IF(VLOOKUP(B9,MAPA_DATA!D:G,2,0)=1,'FACT_EMITIDA',IF(VLOOKUP(B17,MAPA_DATA!D:G,3,0)=1,'FACT_EST_EFACT',(IF(VLOOKUP(B17,MAPA_DATA!D:G,4,0)=1,'FACT_EST_CEN','SIN_DATA')))!H:H) | G17: =CONCATENATE("SUMIF(",IF(C17="FACT_EMITIDA","SIGGE_P",C17),"!B:B,Reliquidacion!B",A17,",",IF(C17="FACT_EMITIDA","SIGGE_P",C17),"!F:F)") -> SUMIF(IF(VLOOKUP(B9,MAPA_DATA!D:G,2,0)=1,'FACT_EMITIDA',IF(VLOOKUP(B17,MAPA_DATA!D:G,3,0)=1,'FACT_EST_EFACT',(IF(VLOOKUP(B17,MAPA_DATA!D:G,4,0)=1,'FACT_EST_CEN','SIN_DATA')))!B:B,Reliquidacion!B17,IF(VLOOKUP(B9,MAPA_DATA!D:G,2,0)=1,'FACT_EMITIDA',IF(VLOOKUP(B17,MAPA_DATA!D:G,3,0)=1,'FACT_EST_EFACT',(IF(VLOOKUP(B17,MAPA_DATA!D:G,4,0)=1,'FACT_EST_CEN','SIN_DATA')))!F:F) | H17: =CONCATENATE("(I",A17,"/G",A17,")") -> (I17/G17) | I17: =CONCATENATE("SUMIF(",IF(C17="FACT_EMITIDA","SIGGE_P",C17),"!B:B,Reliquidacion!B",A17,",",IF(C17="FACT_EMITIDA","SIGGE_P",C17),"!H:H)") -> SUMIF(IF(VLOOKUP(B9,MAPA_DATA!D:G,2,0)=1,'FACT_EMITIDA',IF(VLOOKUP(B17,MAPA_DATA!D:G,3,0)=1,'FACT_EST_EFACT',(IF(VLOOKUP(B17,MAPA_DATA!D:G,4,0)=1,'FACT_EST_CEN','SIN_DATA')))!B:B,Reliquidacion!B17,IF(VLOOKUP(B9,MAPA_DATA!D:G,2,0)=1,'FACT_EMITIDA',IF(VLOOKUP(B17,MAPA_DATA!D:G,3,0)=1,'FACT_EST_EFACT',(IF(VLOOKUP(B17,MAPA_DATA!D:G,4,0)=1,'FACT_EST_CEN','SIN_DATA')))!H:H) | J17: =CONCATENATE("(F",A17,"+I",A17,")") -> (F17+I17) | L17: =IF(VLOOKUP(B17,MAPA_DATA!D:I,5,0)=1,"EFACT_CNE",IF(VLOOKUP(B17,MAPA_DATA!D:I,6,0)=1,"EFACT_EST_CNE","SIN_DATA")) -> SIN_DATA | M17: =CONCATENATE("SUMIF(",L17,"!B:B;Reliquidacion!B",A17,";",L17,"!S:S)") -> SUMIF(SIN_DATA!B:B;Reliquidacion!B17;SIN_DATA!S:S) | N17: =CONCATENATE("(O",A17,"/M",A17,")") -> (O17/M17) | O17: =CONCATENATE("SUMIF(",L17,"!B:B;Reliquidacion!B",A17,";",L17,"!W:W)") -> SUMIF(SIN_DATA!B:B;Reliquidacion!B17;SIN_DATA!W:W) | P17: =CONCATENATE("SUMIF(",L17,"!B:B;Reliquidacion!B",A17,";",L17,"!X:X)") -> SUMIF(SIN_DATA!B:B;Reliquidacion!B17;SIN_DATA!X:X) | Q17: =CONCATENATE("(R",A17,"/P",A17,")") -> (R17/P17) | R17: =CONCATENATE("SUMIF(",L17,"!B:B;Reliquidacion!B",A17,";",L17,"!AB:AB)") -> SUMIF(SIN_DATA!B:B;Reliquidacion!B17;SIN_DATA!AB:AB) | S17: =CONCATENATE("(O",A17,"+R",A17,")") -> (O17+R17) | U17: 42614 | V17: =CONCATENATE("=(S",A17,"-J",A17,")") -> =(S17-J17) | W17: 3T/15-05-2017 | X17: =VLOOKUP(W17,[1]INTERESES!A:B,2,0) -> 0 | Y17: =VLOOKUP(W17,#REF!,6,0) -> #REF! | Z17: 43156 | AA17: 44377 | AB17: =AA17-Z17 -> 1221 | AC17: =+(1+Y17)^(AB17/360)-1 -> #REF! | AD17: =AC17*V17 -> #REF! | AE17: =+V17+AD17 -> #VALUE!
A18: =A17+1 -> 18 | B18: 42644 | C18: =CONCATENATE("IF(VLOOKUP(B9,MAPA_DATA!D:G,2,0)=1,'FACT_EMITIDA',IF(VLOOKUP(B",A18,",MAPA_DATA!D:G,3,0)=1,'FACT_EST_EFACT',(IF(VLOOKUP(B",A18,",MAPA_DATA!D:G,4,0)=1,'FACT_EST_CEN','SIN_DATA')))") -> IF(VLOOKUP(B9,MAPA_DATA!D:G,2,0)=1,'FACT_EMITIDA',IF(VLOOKUP(B18,MAPA_DATA!D:G,3,0)=1,'FACT_EST_EFACT',(IF(VLOOKUP(B18,MAPA_DATA!D:G,4,0)=1,'FACT_EST_CEN','SIN_DATA'))) | D18: =CONCATENATE("SUMIF(",IF(C18="FACT_EMITIDA","SIGGE_E",C18),"!B:B,Reliquidacion!B",A18,",",IF(C18="FACT_EMITIDA","SIGGE_E",C18),"!F:F)") -> SUMIF(IF(VLOOKUP(B9,MAPA_DATA!D:G,2,0)=1,'FACT_EMITIDA',IF(VLOOKUP(B18,MAPA_DATA!D:G,3,0)=1,'FACT_EST_EFACT',(IF(VLOOKUP(B18,MAPA_DATA!D:G,4,0)=1,'FACT_EST_CEN','SIN_DATA')))!B:B,Reliquidacion!B18,IF(VLOOKUP(B9,MAPA_DATA!D:G,2,0)=1,'FACT_EMITIDA',IF(VLOOKUP(B18,MAPA_DATA!D:G,3,0)=1,'FACT_EST_EFACT',(IF(VLOOKUP(B18,MAPA_DATA!D:G,4,0)=1,'FACT_EST_CEN','SIN_DATA')))!F:F) | E18: =CONCATENATE("(F",A18,"/D",A18,")") -> (F18/D18) | F18: =CONCATENATE("SUMIF(",IF(C18="FACT_EMITIDA","SIGGE_E",C18),"!B:B,Reliquidacion!B",A18,",",IF(C18="FACT_EMITIDA","SIGGE_E",C18),"!H:H)") -> SUMIF(IF(VLOOKUP(B9,MAPA_DATA!D:G,2,0)=1,'FACT_EMITIDA',IF(VLOOKUP(B18,MAPA_DATA!D:G,3,0)=1,'FACT_EST_EFACT',(IF(VLOOKUP(B18,MAPA_DATA!D:G,4,0)=1,'FACT_EST_CEN','SIN_DATA')))!B:B,Reliquidacion!B18,IF(VLOOKUP(B9,MAPA_DATA!D:G,2,0)=1,'FACT_EMITIDA',IF(VLOOKUP(B18,MAPA_DATA!D:G,3,0)=1,'FACT_EST_EFACT',(IF(VLOOKUP(B18,MAPA_DATA!D:G,4,0)=1,'FACT_EST_CEN','SIN_DATA')))!H:H) | G18: =CONCATENATE("SUMIF(",IF(C18="FACT_EMITIDA","SIGGE_P",C18),"!B:B,Reliquidacion!B",A18,",",IF(C18="FACT_EMITIDA","SIGGE_P",C18),"!F:F)") -> SUMIF(IF(VLOOKUP(B9,MAPA_DATA!D:G,2,0)=1,'FACT_EMITIDA',IF(VLOOKUP(B18,MAPA_DATA!D:G,3,0)=1,'FACT_EST_EFACT',(IF(VLOOKUP(B18,MAPA_DATA!D:G,4,0)=1,'FACT_EST_CEN','SIN_DATA')))!B:B,Reliquidacion!B18,IF(VLOOKUP(B9,MAPA_DATA!D:G,2,0)=1,'FACT_EMITIDA',IF(VLOOKUP(B18,MAPA_DATA!D:G,3,0)=1,'FACT_EST_EFACT',(IF(VLOOKUP(B18,MAPA_DATA!D:G,4,0)=1,'FACT_EST_CEN','SIN_DATA')))!F:F) | H18: =CONCATENATE("(I",A18,"/G",A18,")") -> (I18/G18) | I18: =CONCATENATE("SUMIF(",IF(C18="FACT_EMITIDA","SIGGE_P",C18),"!B:B,Reliquidacion!B",A18,",",IF(C18="FACT_EMITIDA","SIGGE_P",C18),"!H:H)") -> SUMIF(IF(VLOOKUP(B9,MAPA_DATA!D:G,2,0)=1,'FACT_EMITIDA',IF(VLOOKUP(B18,MAPA_DATA!D:G,3,0)=1,'FACT_EST_EFACT',(IF(VLOOKUP(B18,MAPA_DATA!D:G,4,0)=1,'FACT_EST_CEN','SIN_DATA')))!B:B,Reliquidacion!B18,IF(VLOOKUP(B9,MAPA_DATA!D:G,2,0)=1,'FACT_EMITIDA',IF(VLOOKUP(B18,MAPA_DATA!D:G,3,0)=1,'FACT_EST_EFACT',(IF(VLOOKUP(B18,MAPA_DATA!D:G,4,0)=1,'FACT_EST_CEN','SIN_DATA')))!H:H) | J18: =CONCATENATE("(F",A18,"+I",A18,")") -> (F18+I18) | L18: =IF(VLOOKUP(B18,MAPA_DATA!D:I,5,0)=1,"EFACT_CNE",IF(VLOOKUP(B18,MAPA_DATA!D:I,6,0)=1,"EFACT_EST_CNE","SIN_DATA")) -> SIN_DATA | M18: =CONCATENATE("SUMIF(",L18,"!B:B;Reliquidacion!B",A18,";",L18,"!S:S)") -> SUMIF(SIN_DATA!B:B;Reliquidacion!B18;SIN_DATA!S:S) | N18: =CONCATENATE("(O",A18,"/M",A18,")") -> (O18/M18) | O18: =CONCATENATE("SUMIF(",L18,"!B:B;Reliquidacion!B",A18,";",L18,"!W:W)") -> SUMIF(SIN_DATA!B:B;Reliquidacion!B18;SIN_DATA!W:W) | P18: =CONCATENATE("SUMIF(",L18,"!B:B;Reliquidacion!B",A18,";",L18,"!X:X)") -> SUMIF(SIN_DATA!B:B;Reliquidacion!B18;SIN_DATA!X:X) | Q18: =CONCATENATE("(R",A18,"/P",A18,")") -> (R18/P18) | R18: =CONCATENATE("SUMIF(",L18,"!B:B;Reliquidacion!B",A18,";",L18,"!AB:AB)") -> SUMIF(SIN_DATA!B:B;Reliquidacion!B18;SIN_DATA!AB:AB) | S18: =CONCATENATE("(O",A18,"+R",A18,")") -> (O18+R18) | U18: 42644 | V18: =CONCATENATE("=(S",A18,"-J",A18,")") -> =(S18-J18) | W18: 3T/15-05-2017 | X18: =VLOOKUP(W18,[1]INTERESES!A:B,2,0) -> 0 | Y18: =VLOOKUP(W18,#REF!,6,0) -> #REF! | Z18: 43156 | AA18: 44377 | AB18: =AA18-Z18 -> 1221 | AC18: =+(1+Y18)^(AB18/360)-1 -> #REF! | AD18: =AC18*V18 -> #REF! | AE18: =+V18+AD18 -> #VALUE!
A19: =A18+1 -> 19 | B19: 42675 | C19: =CONCATENATE("IF(VLOOKUP(B9,MAPA_DATA!D:G,2,0)=1,'FACT_EMITIDA',IF(VLOOKUP(B",A19,",MAPA_DATA!D:G,3,0)=1,'FACT_EST_EFACT',(IF(VLOOKUP(B",A19,",MAPA_DATA!D:G,4,0)=1,'FACT_EST_CEN','SIN_DATA')))") -> IF(VLOOKUP(B9,MAPA_DATA!D:G,2,0)=1,'FACT_EMITIDA',IF(VLOOKUP(B19,MAPA_DATA!D:G,3,0)=1,'FACT_EST_EFACT',(IF(VLOOKUP(B19,MAPA_DATA!D:G,4,0)=1,'FACT_EST_CEN','SIN_DATA'))) | D19: =CONCATENATE("SUMIF(",IF(C19="FACT_EMITIDA","SIGGE_E",C19),"!B:B,Reliquidacion!B",A19,",",IF(C19="FACT_EMITIDA","SIGGE_E",C19),"!F:F)") -> SUMIF(IF(VLOOKUP(B9,MAPA_DATA!D:G,2,0)=1,'FACT_EMITIDA',IF(VLOOKUP(B19,MAPA_DATA!D:G,3,0)=1,'FACT_EST_EFACT',(IF(VLOOKUP(B19,MAPA_DATA!D:G,4,0)=1,'FACT_EST_CEN','SIN_DATA')))!B:B,Reliquidacion!B19,IF(VLOOKUP(B9,MAPA_DATA!D:G,2,0)=1,'FACT_EMITIDA',IF(VLOOKUP(B19,MAPA_DATA!D:G,3,0)=1,'FACT_EST_EFACT',(IF(VLOOKUP(B19,MAPA_DATA!D:G,4,0)=1,'FACT_EST_CEN','SIN_DATA')))!F:F) | E19: =CONCATENATE("(F",A19,"/D",A19,")") -> (F19/D19) | F19: =CONCATENATE("SUMIF(",IF(C19="FACT_EMITIDA","SIGGE_E",C19),"!B:B,Reliquidacion!B",A19,",",IF(C19="FACT_EMITIDA","SIGGE_E",C19),"!H:H)") -> SUMIF(IF(VLOOKUP(B9,MAPA_DATA!D:G,2,0)=1,'FACT_EMITIDA',IF(VLOOKUP(B19,MAPA_DATA!D:G,3,0)=1,'FACT_EST_EFACT',(IF(VLOOKUP(B19,MAPA_DATA!D:G,4,0)=1,'FACT_EST_CEN','SIN_DATA')))!B:B,Reliquidacion!B19,IF(VLOOKUP(B9,MAPA_DATA!D:G,2,0)=1,'FACT_EMITIDA',IF(VLOOKUP(B19,MAPA_DATA!D:G,3,0)=1,'FACT_EST_EFACT',(IF(VLOOKUP(B19,MAPA_DATA!D:G,4,0)=1,'FACT_EST_CEN','SIN_DATA')))!H:H) | G19: =CONCATENATE("SUMIF(",IF(C19="FACT_EMITIDA","SIGGE_P",C19),"!B:B,Reliquidacion!B",A19,",",IF(C19="FACT_EMITIDA","SIGGE_P",C19),"!F:F)") -> SUMIF(IF(VLOOKUP(B9,MAPA_DATA!D:G,2,0)=1,'FACT_EMITIDA',IF(VLOOKUP(B19,MAPA_DATA!D:G,3,0)=1,'FACT_EST_EFACT',(IF(VLOOKUP(B19,MAPA_DATA!D:G,4,0)=1,'FACT_EST_CEN','SIN_DATA')))!B:B,Reliquidacion!B19,IF(VLOOKUP(B9,MAPA_DATA!D:G,2,0)=1,'FACT_EMITIDA',IF(VLOOKUP(B19,MAPA_DATA!D:G,3,0)=1,'FACT_EST_EFACT',(IF(VLOOKUP(B19,MAPA_DATA!D:G,4,0)=1,'FACT_EST_CEN','SIN_DATA')))!F:F) | H19: =CONCATENATE("(I",A19,"/G",A19,")") -> (I19/G19) | I19: =CONCATENATE("SUMIF(",IF(C19="FACT_EMITIDA","SIGGE_P",C19),"!B:B,Reliquidacion!B",A19,",",IF(C19="FACT_EMITIDA","SIGGE_P",C19),"!H:H)") -> SUMIF(IF(VLOOKUP(B9,MAPA_DATA!D:G,2,0)=1,'FACT_EMITIDA',IF(VLOOKUP(B19,MAPA_DATA!D:G,3,0)=1,'FACT_EST_EFACT',(IF(VLOOKUP(B19,MAPA_DATA!D:G,4,0)=1,'FACT_EST_CEN','SIN_DATA')))!B:B,Reliquidacion!B19,IF(VLOOKUP(B9,MAPA_DATA!D:G,2,0)=1,'FACT_EMITIDA',IF(VLOOKUP(B19,MAPA_DATA!D:G,3,0)=1,'FACT_EST_EFACT',(IF(VLOOKUP(B19,MAPA_DATA!D:G,4,0)=1,'FACT_EST_CEN','SIN_DATA')))!H:H) | J19: =CONCATENATE("(F",A19,"+I",A19,")") -> (F19+I19) | L19: =IF(VLOOKUP(B19,MAPA_DATA!D:I,5,0)=1,"EFACT_CNE",IF(VLOOKUP(B19,MAPA_DATA!D:I,6,0)=1,"EFACT_EST_CNE","SIN_DATA")) -> SIN_DATA | M19: =CONCATENATE("SUMIF(",L19,"!B:B;Reliquidacion!B",A19,";",L19,"!S:S)") -> SUMIF(SIN_DATA!B:B;Reliquidacion!B19;SIN_DATA!S:S) | N19: =CONCATENATE("(O",A19,"/M",A19,")") -> (O19/M19) | O19: =CONCATENATE("SUMIF(",L19,"!B:B;Reliquidacion!B",A19,";",L19,"!W:W)") -> SUMIF(SIN_DATA!B:B;Reliquidacion!B19;SIN_DATA!W:W) | P19: =CONCATENATE("SUMIF(",L19,"!B:B;Reliquidacion!B",A19,";",L19,"!X:X)") -> SUMIF(SIN_DATA!B:B;Reliquidacion!B19;SIN_DATA!X:X) | Q19: =CONCATENATE("(R",A19,"/P",A19,")") -> (R19/P19) | R19: =CONCATENATE("SUMIF(",L19,"!B:B;Reliquidacion!B",A19,";",L19,"!AB:AB)") -> SUMIF(SIN_DATA!B:B;Reliquidacion!B19;SIN_DATA!AB:AB) | S19: =CONCATENATE("(O",A19,"+R",A19,")") -> (O19+R19) | U19: 42675 | V19: =CONCATENATE("=(S",A19,"-J",A19,")") -> =(S19-J19) | W19: 3T/15-05-2017 | X19: =VLOOKUP(W19,[1]INTERESES!A:B,2,0) -> 0 | Y19: =VLOOKUP(W19,#REF!,6,0) -> #REF! | Z19: 43156 | AA19: 44377 | AB19: =AA19-Z19 -> 1221 | AC19: =+(1+Y19)^(AB19/360)-1 -> #REF! | AD19: =AC19*V19 -> #REF! | AE19: =+V19+AD19 -> #VALUE!
A20: =A19+1 -> 20 | B20: 42705 | C20: =CONCATENATE("IF(VLOOKUP(B9,MAPA_DATA!D:G,2,0)=1,'FACT_EMITIDA',IF(VLOOKUP(B",A20,",MAPA_DATA!D:G,3,0)=1,'FACT_EST_EFACT',(IF(VLOOKUP(B",A20,",MAPA_DATA!D:G,4,0)=1,'FACT_EST_CEN','SIN_DATA')))") -> IF(VLOOKUP(B9,MAPA_DATA!D:G,2,0)=1,'FACT_EMITIDA',IF(VLOOKUP(B20,MAPA_DATA!D:G,3,0)=1,'FACT_EST_EFACT',(IF(VLOOKUP(B20,MAPA_DATA!D:G,4,0)=1,'FACT_EST_CEN','SIN_DATA'))) | D20: =CONCATENATE("SUMIF(",IF(C20="FACT_EMITIDA","SIGGE_E",C20),"!B:B,Reliquidacion!B",A20,",",IF(C20="FACT_EMITIDA","SIGGE_E",C20),"!F:F)") -> SUMIF(IF(VLOOKUP(B9,MAPA_DATA!D:G,2,0)=1,'FACT_EMITIDA',IF(VLOOKUP(B20,MAPA_DATA!D:G,3,0)=1,'FACT_EST_EFACT',(IF(VLOOKUP(B20,MAPA_DATA!D:G,4,0)=1,'FACT_EST_CEN','SIN_DATA')))!B:B,Reliquidacion!B20,IF(VLOOKUP(B9,MAPA_DATA!D:G,2,0)=1,'FACT_EMITIDA',IF(VLOOKUP(B20,MAPA_DATA!D:G,3,0)=1,'FACT_EST_EFACT',(IF(VLOOKUP(B20,MAPA_DATA!D:G,4,0)=1,'FACT_EST_CEN','SIN_DATA')))!F:F) | E20: =CONCATENATE("(F",A20,"/D",A20,")") -> (F20/D20) | F20: =CONCATENATE("SUMIF(",IF(C20="FACT_EMITIDA","SIGGE_E",C20),"!B:B,Reliquidacion!B",A20,",",IF(C20="FACT_EMITIDA","SIGGE_E",C20),"!H:H)") -> SUMIF(IF(VLOOKUP(B9,MAPA_DATA!D:G,2,0)=1,'FACT_EMITIDA',IF(VLOOKUP(B20,MAPA_DATA!D:G,3,0)=1,'FACT_EST_EFACT',(IF(VLOOKUP(B20,MAPA_DATA!D:G,4,0)=1,'FACT_EST_CEN','SIN_DATA')))!B:B,Reliquidacion!B20,IF(VLOOKUP(B9,MAPA_DATA!D:G,2,0)=1,'FACT_EMITIDA',IF(VLOOKUP(B20,MAPA_DATA!D:G,3,0)=1,'FACT_EST_EFACT',(IF(VLOOKUP(B20,MAPA_DATA!D:G,4,0)=1,'FACT_EST_CEN','SIN_DATA')))!H:H) | G20: =CONCATENATE("SUMIF(",IF(C20="FACT_EMITIDA","SIGGE_P",C20),"!B:B,Reliquidacion!B",A20,",",IF(C20="FACT_EMITIDA","SIGGE_P",C20),"!F:F)") -> SUMIF(IF(VLOOKUP(B9,MAPA_DATA!D:G,2,0)=1,'FACT_EMITIDA',IF(VLOOKUP(B20,MAPA_DATA!D:G,3,0)=1,'FACT_EST_EFACT',(IF(VLOOKUP(B20,MAPA_DATA!D:G,4,0)=1,'FACT_EST_CEN','SIN_DATA')))!B:B,Reliquidacion!B20,IF(VLOOKUP(B9,MAPA_DATA!D:G,2,0)=1,'FACT_EMITIDA',IF(VLOOKUP(B20,MAPA_DATA!D:G,3,0)=1,'FACT_EST_EFACT',(IF(VLOOKUP(B20,MAPA_DATA!D:G,4,0)=1,'FACT_EST_CEN','SIN_DATA')))!F:F) | H20: =CONCATENATE("(I",A20,"/G",A20,")") -> (I20/G20) | I20: =CONCATENATE("SUMIF(",IF(C20="FACT_EMITIDA","SIGGE_P",C20),"!B:B,Reliquidacion!B",A20,",",IF(C20="FACT_EMITIDA","SIGGE_P",C20),"!H:H)") -> SUMIF(IF(VLOOKUP(B9,MAPA_DATA!D:G,2,0)=1,'FACT_EMITIDA',IF(VLOOKUP(B20,MAPA_DATA!D:G,3,0)=1,'FACT_EST_EFACT',(IF(VLOOKUP(B20,MAPA_DATA!D:G,4,0)=1,'FACT_EST_CEN','SIN_DATA')))!B:B,Reliquidacion!B20,IF(VLOOKUP(B9,MAPA_DATA!D:G,2,0)=1,'FACT_EMITIDA',IF(VLOOKUP(B20,MAPA_DATA!D:G,3,0)=1,'FACT_EST_EFACT',(IF(VLOOKUP(B20,MAPA_DATA!D:G,4,0)=1,'FACT_EST_CEN','SIN_DATA')))!H:H) | J20: =CONCATENATE("(F",A20,"+I",A20,")") -> (F20+I20) | L20: =IF(VLOOKUP(B20,MAPA_DATA!D:I,5,0)=1,"EFACT_CNE",IF(VLOOKUP(B20,MAPA_DATA!D:I,6,0)=1,"EFACT_EST_CNE","SIN_DATA")) -> SIN_DATA | M20: =CONCATENATE("SUMIF(",L20,"!B:B;Reliquidacion!B",A20,";",L20,"!S:S)") -> SUMIF(SIN_DATA!B:B;Reliquidacion!B20;SIN_DATA!S:S) | N20: =CONCATENATE("(O",A20,"/M",A20,")") -> (O20/M20) | O20: =CONCATENATE("SUMIF(",L20,"!B:B;Reliquidacion!B",A20,";",L20,"!W:W)") -> SUMIF(SIN_DATA!B:B;Reliquidacion!B20;SIN_DATA!W:W) | P20: =CONCATENATE("SUMIF(",L20,"!B:B;Reliquidacion!B",A20,";",L20,"!X:X)") -> SUMIF(SIN_DATA!B:B;Reliquidacion!B20;SIN_DATA!X:X) | Q20: =CONCATENATE("(R",A20,"/P",A20,")") -> (R20/P20) | R20: =CONCATENATE("SUMIF(",L20,"!B:B;Reliquidacion!B",A20,";",L20,"!AB:AB)") -> SUMIF(SIN_DATA!B:B;Reliquidacion!B20;SIN_DATA!AB:AB) | S20: =CONCATENATE("(O",A20,"+R",A20,")") -> (O20+R20) | U20: 42705 | V20: =CONCATENATE("=(S",A20,"-J",A20,")") -> =(S20-J20) | W20: 3T/15-05-2017 | X20: =VLOOKUP(W20,[1]INTERESES!A:B,2,0) -> 0 | Y20: =VLOOKUP(W20,#REF!,6,0) -> #REF! | Z20: 43156 | AA20: 44377 | AB20: =AA20-Z20 -> 1221 | AC20: =+(1+Y20)^(AB20/360)-1 -> #REF! | AD20: =AC20*V20 -> #REF! | AE20: =+V20+AD20 -> #VALUE!
A21: =A20+1 -> 21 | B21: 42736 | C21: =CONCATENATE("IF(VLOOKUP(B9,MAPA_DATA!D:G,2,0)=1,'FACT_EMITIDA',IF(VLOOKUP(B",A21,",MAPA_DATA!D:G,3,0)=1,'FACT_EST_EFACT',(IF(VLOOKUP(B",A21,",MAPA_DATA!D:G,4,0)=1,'FACT_EST_CEN','SIN_DATA')))") -> IF(VLOOKUP(B9,MAPA_DATA!D:G,2,0)=1,'FACT_EMITIDA',IF(VLOOKUP(B21,MAPA_DATA!D:G,3,0)=1,'FACT_EST_EFACT',(IF(VLOOKUP(B21,MAPA_DATA!D:G,4,0)=1,'FACT_EST_CEN','SIN_DATA'))) | D21: =CONCATENATE("SUMIF(",IF(C21="FACT_EMITIDA","SIGGE_E",C21),"!B:B,Reliquidacion!B",A21,",",IF(C21="FACT_EMITIDA","SIGGE_E",C21),"!F:F)") -> SUMIF(IF(VLOOKUP(B9,MAPA_DATA!D:G,2,0)=1,'FACT_EMITIDA',IF(VLOOKUP(B21,MAPA_DATA!D:G,3,0)=1,'FACT_EST_EFACT',(IF(VLOOKUP(B21,MAPA_DATA!D:G,4,0)=1,'FACT_EST_CEN','SIN_DATA')))!B:B,Reliquidacion!B21,IF(VLOOKUP(B9,MAPA_DATA!D:G,2,0)=1,'FACT_EMITIDA',IF(VLOOKUP(B21,MAPA_DATA!D:G,3,0)=1,'FACT_EST_EFACT',(IF(VLOOKUP(B21,MAPA_DATA!D:G,4,0)=1,'FACT_EST_CEN','SIN_DATA')))!F:F) | E21: =CONCATENATE("(F",A21,"/D",A21,")") -> (F21/D21) | F21: =CONCATENATE("SUMIF(",IF(C21="FACT_EMITIDA","SIGGE_E",C21),"!B:B,Reliquidacion!B",A21,",",IF(C21="FACT_EMITIDA","SIGGE_E",C21),"!H:H)") -> SUMIF(IF(VLOOKUP(B9,MAPA_DATA!D:G,2,0)=1,'FACT_EMITIDA',IF(VLOOKUP(B21,MAPA_DATA!D:G,3,0)=1,'FACT_EST_EFACT',(IF(VLOOKUP(B21,MAPA_DATA!D:G,4,0)=1,'FACT_EST_CEN','SIN_DATA')))!B:B,Reliquidacion!B21,IF(VLOOKUP(B9,MAPA_DATA!D:G,2,0)=1,'FACT_EMITIDA',IF(VLOOKUP(B21,MAPA_DATA!D:G,3,0)=1,'FACT_EST_EFACT',(IF(VLOOKUP(B21,MAPA_DATA!D:G,4,0)=1,'FACT_EST_CEN','SIN_DATA')))!H:H) | G21: =CONCATENATE("SUMIF(",IF(C21="FACT_EMITIDA","SIGGE_P",C21),"!B:B,Reliquidacion!B",A21,",",IF(C21="FACT_EMITIDA","SIGGE_P",C21),"!F:F)") -> SUMIF(IF(VLOOKUP(B9,MAPA_DATA!D:G,2,0)=1,'FACT_EMITIDA',IF(VLOOKUP(B21,MAPA_DATA!D:G,3,0)=1,'FACT_EST_EFACT',(IF(VLOOKUP(B21,MAPA_DATA!D:G,4,0)=1,'FACT_EST_CEN','SIN_DATA')))!B:B,Reliquidacion!B21,IF(VLOOKUP(B9,MAPA_DATA!D:G,2,0)=1,'FACT_EMITIDA',IF(VLOOKUP(B21,MAPA_DATA!D:G,3,0)=1,'FACT_EST_EFACT',(IF(VLOOKUP(B21,MAPA_DATA!D:G,4,0)=1,'FACT_EST_CEN','SIN_DATA')))!F:F) | H21: =CONCATENATE("(I",A21,"/G",A21,")") -> (I21/G21) | I21: =CONCATENATE("SUMIF(",IF(C21="FACT_EMITIDA","SIGGE_P",C21),"!B:B,Reliquidacion!B",A21,",",IF(C21="FACT_EMITIDA","SIGGE_P",C21),"!H:H)") -> SUMIF(IF(VLOOKUP(B9,MAPA_DATA!D:G,2,0)=1,'FACT_EMITIDA',IF(VLOOKUP(B21,MAPA_DATA!D:G,3,0)=1,'FACT_EST_EFACT',(IF(VLOOKUP(B21,MAPA_DATA!D:G,4,0)=1,'FACT_EST_CEN','SIN_DATA')))!B:B,Reliquidacion!B21,IF(VLOOKUP(B9,MAPA_DATA!D:G,2,0)=1,'FACT_EMITIDA',IF(VLOOKUP(B21,MAPA_DATA!D:G,3,0)=1,'FACT_EST_EFACT',(IF(VLOOKUP(B21,MAPA_DATA!D:G,4,0)=1,'FACT_EST_CEN','SIN_DATA')))!H:H) | J21: =CONCATENATE("(F",A21,"+I",A21,")") -> (F21+I21) | L21: =IF(VLOOKUP(B21,MAPA_DATA!D:I,5,0)=1,"EFACT_CNE",IF(VLOOKUP(B21,MAPA_DATA!D:I,6,0)=1,"EFACT_EST_CNE","SIN_DATA")) -> SIN_DATA | M21: =CONCATENATE("SUMIF(",L21,"!B:B;Reliquidacion!B",A21,";",L21,"!S:S)") -> SUMIF(SIN_DATA!B:B;Reliquidacion!B21;SIN_DATA!S:S) | N21: =CONCATENATE("(O",A21,"/M",A21,")") -> (O21/M21) | O21: =CONCATENATE("SUMIF(",L21,"!B:B;Reliquidacion!B",A21,";",L21,"!W:W)") -> SUMIF(SIN_DATA!B:B;Reliquidacion!B21;SIN_DATA!W:W) | P21: =CONCATENATE("SUMIF(",L21,"!B:B;Reliquidacion!B",A21,";",L21,"!X:X)") -> SUMIF(SIN_DATA!B:B;Reliquidacion!B21;SIN_DATA!X:X) | Q21: =CONCATENATE("(R",A21,"/P",A21,")") -> (R21/P21) | R21: =CONCATENATE("SUMIF(",L21,"!B:B;Reliquidacion!B",A21,";",L21,"!AB:AB)") -> SUMIF(SIN_DATA!B:B;Reliquidacion!B21;SIN_DATA!AB:AB) | S21: =CONCATENATE("(O",A21,"+R",A21,")") -> (O21+R21) | U21: 42736 | V21: =CONCATENATE("=(S",A21,"-J",A21,")") -> =(S21-J21) | W21: 3T/15-05-2017 | X21: =VLOOKUP(W21,[1]INTERESES!A:B,2,0) -> 0 | Y21: =VLOOKUP(W21,#REF!,6,0) -> #REF! | Z21: 43156 | AA21: 44377 | AB21: =AA21-Z21 -> 1221 | AC21: =+(1+Y21)^(AB21/360)-1 -> #REF! | AD21: =AC21*V21 -> #REF! | AE21: =+V21+AD21 -> #VALUE!
A22: =A21+1 -> 22 | B22: 42767 | C22: =CONCATENATE("IF(VLOOKUP(B9,MAPA_DATA!D:G,2,0)=1,'FACT_EMITIDA',IF(VLOOKUP(B",A22,",MAPA_DATA!D:G,3,0)=1,'FACT_EST_EFACT',(IF(VLOOKUP(B",A22,",MAPA_DATA!D:G,4,0)=1,'FACT_EST_CEN','SIN_DATA')))") -> IF(VLOOKUP(B9,MAPA_DATA!D:G,2,0)=1,'FACT_EMITIDA',IF(VLOOKUP(B22,MAPA_DATA!D:G,3,0)=1,'FACT_EST_EFACT',(IF(VLOOKUP(B22,MAPA_DATA!D:G,4,0)=1,'FACT_EST_CEN','SIN_DATA'))) | D22: =CONCATENATE("SUMIF(",IF(C22="FACT_EMITIDA","SIGGE_E",C22),"!B:B,Reliquidacion!B",A22,",",IF(C22="FACT_EMITIDA","SIGGE_E",C22),"!F:F)") -> SUMIF(IF(VLOOKUP(B9,MAPA_DATA!D:G,2,0)=1,'FACT_EMITIDA',IF(VLOOKUP(B22,MAPA_DATA!D:G,3,0)=1,'FACT_EST_EFACT',(IF(VLOOKUP(B22,MAPA_DATA!D:G,4,0)=1,'FACT_EST_CEN','SIN_DATA')))!B:B,Reliquidacion!B22,IF(VLOOKUP(B9,MAPA_DATA!D:G,2,0)=1,'FACT_EMITIDA',IF(VLOOKUP(B22,MAPA_DATA!D:G,3,0)=1,'FACT_EST_EFACT',(IF(VLOOKUP(B22,MAPA_DATA!D:G,4,0)=1,'FACT_EST_CEN','SIN_DATA')))!F:F) | E22: =CONCATENATE("(F",A22,"/D",A22,")") -> (F22/D22) | F22: =CONCATENATE("SUMIF(",IF(C22="FACT_EMITIDA","SIGGE_E",C22),"!B:B,Reliquidacion!B",A22,",",IF(C22="FACT_EMITIDA","SIGGE_E",C22),"!H:H)") -> SUMIF(IF(VLOOKUP(B9,MAPA_DATA!D:G,2,0)=1,'FACT_EMITIDA',IF(VLOOKUP(B22,MAPA_DATA!D:G,3,0)=1,'FACT_EST_EFACT',(IF(VLOOKUP(B22,MAPA_DATA!D:G,4,0)=1,'FACT_EST_CEN','SIN_DATA')))!B:B,Reliquidacion!B22,IF(VLOOKUP(B9,MAPA_DATA!D:G,2,0)=1,'FACT_EMITIDA',IF(VLOOKUP(B22,MAPA_DATA!D:G,3,0)=1,'FACT_EST_EFACT',(IF(VLOOKUP(B22,MAPA_DATA!D:G,4,0)=1,'FACT_EST_CEN','SIN_DATA')))!H:H) | G22: =CONCATENATE("SUMIF(",IF(C22="FACT_EMITIDA","SIGGE_P",C22),"!B:B,Reliquidacion!B",A22,",",IF(C22="FACT_EMITIDA","SIGGE_P",C22),"!F:F)") -> SUMIF(IF(VLOOKUP(B9,MAPA_DATA!D:G,2,0)=1,'FACT_EMITIDA',IF(VLOOKUP(B22,MAPA_DATA!D:G,3,0)=1,'FACT_EST_EFACT',(IF(VLOOKUP(B22,MAPA_DATA!D:G,4,0)=1,'FACT_EST_CEN','SIN_DATA')))!B:B,Reliquidacion!B22,IF(VLOOKUP(B9,MAPA_DATA!D:G,2,0)=1,'FACT_EMITIDA',IF(VLOOKUP(B22,MAPA_DATA!D:G,3,0)=1,'FACT_EST_EFACT',(IF(VLOOKUP(B22,MAPA_DATA!D:G,4,0)=1,'FACT_EST_CEN','SIN_DATA')))!F:F) | H22: =CONCATENATE("(I",A22,"/G",A22,")") -> (I22/G22) | I22: =CONCATENATE("SUMIF(",IF(C22="FACT_EMITIDA","SIGGE_P",C22),"!B:B,Reliquidacion!B",A22,",",IF(C22="FACT_EMITIDA","SIGGE_P",C22),"!H:H)") -> SUMIF(IF(VLOOKUP(B9,MAPA_DATA!D:G,2,0)=1,'FACT_EMITIDA',IF(VLOOKUP(B22,MAPA_DATA!D:G,3,0)=1,'FACT_EST_EFACT',(IF(VLOOKUP(B22,MAPA_DATA!D:G,4,0)=1,'FACT_EST_CEN','SIN_DATA')))!B:B,Reliquidacion!B22,IF(VLOOKUP(B9,MAPA_DATA!D:G,2,0)=1,'FACT_EMITIDA',IF(VLOOKUP(B22,MAPA_DATA!D:G,3,0)=1,'FACT_EST_EFACT',(IF(VLOOKUP(B22,MAPA_DATA!D:G,4,0)=1,'FACT_EST_CEN','SIN_DATA')))!H:H) | J22: =CONCATENATE("(F",A22,"+I",A22,")") -> (F22+I22) | L22: =IF(VLOOKUP(B22,MAPA_DATA!D:I,5,0)=1,"EFACT_CNE",IF(VLOOKUP(B22,MAPA_DATA!D:I,6,0)=1,"EFACT_EST_CNE","SIN_DATA")) -> SIN_DATA | M22: =CONCATENATE("SUMIF(",L22,"!B:B;Reliquidacion!B",A22,";",L22,"!S:S)") -> SUMIF(SIN_DATA!B:B;Reliquidacion!B22;SIN_DATA!S:S) | N22: =CONCATENATE("(O",A22,"/M",A22,")") -> (O22/M22) | O22: =CONCATENATE("SUMIF(",L22,"!B:B;Reliquidacion!B",A22,";",L22,"!W:W)") -> SUMIF(SIN_DATA!B:B;Reliquidacion!B22;SIN_DATA!W:W) | P22: =CONCATENATE("SUMIF(",L22,"!B:B;Reliquidacion!B",A22,";",L22,"!X:X)") -> SUMIF(SIN_DATA!B:B;Reliquidacion!B22;SIN_DATA!X:X) | Q22: =CONCATENATE("(R",A22,"/P",A22,")") -> (R22/P22) | R22: =CONCATENATE("SUMIF(",L22,"!B:B;Reliquidacion!B",A22,";",L22,"!AB:AB)") -> SUMIF(SIN_DATA!B:B;Reliquidacion!B22;SIN_DATA!AB:AB) | S22: =CONCATENATE("(O",A22,"+R",A22,")") -> (O22+R22) | U22: 42767 | V22: =CONCATENATE("=(S",A22,"-J",A22,")") -> =(S22-J22) | W22: 12T/28-11-2017 | X22: =VLOOKUP(W22,[1]INTERESES!A:B,2,0) -> 0 | Y22: =VLOOKUP(W22,#REF!,6,0) -> #REF! | Z22: 43156 | AA22: 44377 | AB22: =AA22-Z22 -> 1221 | AC22: =+(1+Y22)^(AB22/360)-1 -> #REF! | AD22: =AC22*V22 -> #REF! | AE22: =+V22+AD22 -> #VALUE!
A23: =A22+1 -> 23 | B23: 42795 | C23: =CONCATENATE("IF(VLOOKUP(B9,MAPA_DATA!D:G,2,0)=1,'FACT_EMITIDA',IF(VLOOKUP(B",A23,",MAPA_DATA!D:G,3,0)=1,'FACT_EST_EFACT',(IF(VLOOKUP(B",A23,",MAPA_DATA!D:G,4,0)=1,'FACT_EST_CEN','SIN_DATA')))") -> IF(VLOOKUP(B9,MAPA_DATA!D:G,2,0)=1,'FACT_EMITIDA',IF(VLOOKUP(B23,MAPA_DATA!D:G,3,0)=1,'FACT_EST_EFACT',(IF(VLOOKUP(B23,MAPA_DATA!D:G,4,0)=1,'FACT_EST_CEN','SIN_DATA'))) | D23: =CONCATENATE("SUMIF(",IF(C23="FACT_EMITIDA","SIGGE_E",C23),"!B:B,Reliquidacion!B",A23,",",IF(C23="FACT_EMITIDA","SIGGE_E",C23),"!F:F)") -> SUMIF(IF(VLOOKUP(B9,MAPA_DATA!D:G,2,0)=1,'FACT_EMITIDA',IF(VLOOKUP(B23,MAPA_DATA!D:G,3,0)=1,'FACT_EST_EFACT',(IF(VLOOKUP(B23,MAPA_DATA!D:G,4,0)=1,'FACT_EST_CEN','SIN_DATA')))!B:B,Reliquidacion!B23,IF(VLOOKUP(B9,MAPA_DATA!D:G,2,0)=1,'FACT_EMITIDA',IF(VLOOKUP(B23,MAPA_DATA!D:G,3,0)=1,'FACT_EST_EFACT',(IF(VLOOKUP(B23,MAPA_DATA!D:G,4,0)=1,'FACT_EST_CEN','SIN_DATA')))!F:F) | E23: =CONCATENATE("(F",A23,"/D",A23,")") -> (F23/D23) | F23: =CONCATENATE("SUMIF(",IF(C23="FACT_EMITIDA","SIGGE_E",C23),"!B:B,Reliquidacion!B",A23,",",IF(C23="FACT_EMITIDA","SIGGE_E",C23),"!H:H)") -> SUMIF(IF(VLOOKUP(B9,MAPA_DATA!D:G,2,0)=1,'FACT_EMITIDA',IF(VLOOKUP(B23,MAPA_DATA!D:G,3,0)=1,'FACT_EST_EFACT',(IF(VLOOKUP(B23,MAPA_DATA!D:G,4,0)=1,'FACT_EST_CEN','SIN_DATA')))!B:B,Reliquidacion!B23,IF(VLOOKUP(B9,MAPA_DATA!D:G,2,0)=1,'FACT_EMITIDA',IF(VLOOKUP(B23,MAPA_DATA!D:G,3,0)=1,'FACT_EST_EFACT',(IF(VLOOKUP(B23,MAPA_DATA!D:G,4,0)=1,'FACT_EST_CEN','SIN_DATA')))!H:H) | G23: =CONCATENATE("SUMIF(",IF(C23="FACT_EMITIDA","SIGGE_P",C23),"!B:B,Reliquidacion!B",A23,",",IF(C23="FACT_EMITIDA","SIGGE_P",C23),"!F:F)") -> SUMIF(IF(VLOOKUP(B9,MAPA_DATA!D:G,2,0)=1,'FACT_EMITIDA',IF(VLOOKUP(B23,MAPA_DATA!D:G,3,0)=1,'FACT_EST_EFACT',(IF(VLOOKUP(B23,MAPA_DATA!D:G,4,0)=1,'FACT_EST_CEN','SIN_DATA')))!B:B,Reliquidacion!B23,IF(VLOOKUP(B9,MAPA_DATA!D:G,2,0)=1,'FACT_EMITIDA',IF(VLOOKUP(B23,MAPA_DATA!D:G,3,0)=1,'FACT_EST_EFACT',(IF(VLOOKUP(B23,MAPA_DATA!D:G,4,0)=1,'FACT_EST_CEN','SIN_DATA')))!F:F) | H23: =CONCATENATE("(I",A23,"/G",A23,")") -> (I23/G23) | I23: =CONCATENATE("SUMIF(",IF(C23="FACT_EMITIDA","SIGGE_P",C23),"!B:B,Reliquidacion!B",A23,",",IF(C23="FACT_EMITIDA","SIGGE_P",C23),"!H:H)") -> SUMIF(IF(VLOOKUP(B9,MAPA_DATA!D:G,2,0)=1,'FACT_EMITIDA',IF(VLOOKUP(B23,MAPA_DATA!D:G,3,0)=1,'FACT_EST_EFACT',(IF(VLOOKUP(B23,MAPA_DATA!D:G,4,0)=1,'FACT_EST_CEN','SIN_DATA')))!B:B,Reliquidacion!B23,IF(VLOOKUP(B9,MAPA_DATA!D:G,2,0)=1,'FACT_EMITIDA',IF(VLOOKUP(B23,MAPA_DATA!D:G,3,0)=1,'FACT_EST_EFACT',(IF(VLOOKUP(B23,MAPA_DATA!D:G,4,0)=1,'FACT_EST_CEN','SIN_DATA')))!H:H) | J23: =CONCATENATE("(F",A23,"+I",A23,")") -> (F23+I23) | L23: =IF(VLOOKUP(B23,MAPA_DATA!D:I,5,0)=1,"EFACT_CNE",IF(VLOOKUP(B23,MAPA_DATA!D:I,6,0)=1,"EFACT_EST_CNE","SIN_DATA")) -> SIN_DATA | M23: =CONCATENATE("SUMIF(",L23,"!B:B;Reliquidacion!B",A23,";",L23,"!S:S)") -> SUMIF(SIN_DATA!B:B;Reliquidacion!B23;SIN_DATA!S:S) | N23: =CONCATENATE("(O",A23,"/M",A23,")") -> (O23/M23) | O23: =CONCATENATE("SUMIF(",L23,"!B:B;Reliquidacion!B",A23,";",L23,"!W:W)") -> SUMIF(SIN_DATA!B:B;Reliquidacion!B23;SIN_DATA!W:W) | P23: =CONCATENATE("SUMIF(",L23,"!B:B;Reliquidacion!B",A23,";",L23,"!X:X)") -> SUMIF(SIN_DATA!B:B;Reliquidacion!B23;SIN_DATA!X:X) | Q23: =CONCATENATE("(R",A23,"/P",A23,")") -> (R23/P23) | R23: =CONCATENATE("SUMIF(",L23,"!B:B;Reliquidacion!B",A23,";",L23,"!AB:AB)") -> SUMIF(SIN_DATA!B:B;Reliquidacion!B23;SIN_DATA!AB:AB) | S23: =CONCATENATE("(O",A23,"+R",A23,")") -> (O23+R23) | U23: 42795 | V23: =CONCATENATE("=(S",A23,"-J",A23,")") -> =(S23-J23) | W23: 12T/28-11-2017 | X23: =VLOOKUP(W23,[1]INTERESES!A:B,2,0) -> 0
