Workbook

Sheet README
A1: Hoja | B1: Descripción
A2: EFACT_CNE | B2: Información de facturación definitiva proveniente de los archivos EFACT publicados por la CNE en los Decretos de Precio de Nudo
A3: FACT_EMITIDA | B3: Información de facturación real desde PDFs y sistema SIGGE (gestión facturación electrónica)

Sheet MAPA_DATA
A1: Num | B1: Anho | C1: Mes | D1: Fecha | E1: FACT_EMITIDA | F1: FACT_EST_EFACT | G1: FACT_EST_CEN | H1: EFACT_CNE | I1: EFACT_EST_CEN | J1: OrigenData1 | K1: OrigenData2
A2: 1 | B2: 2016 | C2: 1 | D2: 01-01-2016 | E2: 0 | F2: 1 | G2: 0 | H2: 1 | I2: 0 | J2: FACT_EST_EFACT | K2: EFACT_CNE
A3: 2 | B3: 2016 | C3: 2 | D3: 01-02-2016 | E3: 0 | F3: 1 | G3: 0 | H3: 1 | I3: 0 | J3: FACT_EST_EFACT | K3: EFACT_CNE
A4: 3 | B4: 2016 | C4: 3 | D4: 01-03-2016 | E4: 0 | F4: 1 | G4: 0 | H4: 1 | I4: 0 | J4: FACT_EST_EFACT | K4: EFACT_CNE
A5: 4 | B5: 2016 | C5: 4 | D5: 01-04-2016 | E5: 0 | F5: 1 | G5: 0 | H5: 1 | I5: 0 | J5: FACT_EST_EFACT | K5: EFACT_CNE
A6: 5 | B6: 2016 | C6: 5 | D6: 01-05-2016 | E6: 0 | F6: 1 | G6: 0 | H6: 1 | I6: 0 | J6: FACT_EST_EFACT | K6: EFACT_CNE
A7: 6 | B7: 2016 | C7: 6 | D7: 01-06-2016 | E7: 0 | F7: 1 | G7: 0 | H7: 1 | I7: 0 | J7: FACT_EST_EFACT | K7: EFACT_CNE
A8: 7 | B8: 2016 | C8: 7 | D8: 01-07-2016 | E8: 0 | F8: 1 | G8: 0 | H8: 1 | I8: 0 | J8: FACT_EST_EFACT | K8: EFACT_CNE
A9: 8 | B9: 2016 | C9: 8 | D9: 01-08-2016 | E9: 0 | F9: 1 | G9: 0 | H9: 1 | I9: 0 | J9: FACT_EST_EFACT | K9: EFACT_CNE
A10: 9 | B10: 2016 | C10: 9 | D10: 01-09-2016 | E10: 0 | F10: 1 | G10: 0 | H10: 1 | I10: 0 | J10: FACT_EST_EFACT | K10: EFACT_CNE
A11: 10 | B11: 2016 | C11: 10 | D11: 01-10-2016 | E11: 0 | F11: 1 | G11: 0 | H11: 1 | I11: 0 | J11: FACT_EST_EFACT | K11: EFACT_CNE
A12: 11 | B12: 2016 | C12: 11 | D12: 01-11-2016 | E12: 0 | F12: 1 | G12: 0 | H12: 1 | I12: 0 | J12: FACT_EST_EFACT | K12: EFACT_CNE
A13: 12 | B13: 2016 | C13: 12 | D13: 01-12-2016 | E13: 0 | F13: 1 | G13: 0 | H13: 1 | I13: 0 | J13: FACT_EST_EFACT | K13: EFACT_CNE
... A58: 57 | B58: 2020 | C58: 9 | D58: 01-09-2020 | E58: 1 | F58: 0 | G58: 0 | H58: 1 | I58: 0 | J58: FACT_EMITIDA | K58: EFACT_CNE

Sheet ReliquidacionEFACT
A2: Generador | B2: [GX]
A3: Distribuidor | B3: [EEDD]
A4: Licitacion | B4: 2013/03-2° Llamado
A5: Bloque | B5: [BLOQUE]
C7: LO QUE SE FACTURÓ | L7: LO QUE SE DEBIÓ HABER FACTURADO | U7: RELQUIDACIÓN Y CÁLCULO INTERESES
A8: ID | B8: MES | C8: ORIGEN DATA | D8: Energía (kWh) | E8: Monto Energía ($) | F8: $/kWh | G8: Potencia (kW) | H8: Monto Potencia ($) | I8: $/kW-mes | J8: Monto Total ($) | L8: ORIGEN DATA | M8: Energía (kWh) | N8: Monto Energía ($) | O8: $/kWh | P8: Potencia (kW) | Q8: Monto Potencia ($) | R8: $/kW-mes | S8: Monto Total ($) | U8: Mes | V8: Reliquidación mensual ($) | W8: Decreto PNP Reliquidación | X8: Fecha publicación Diario Oficial | Y8: Interés Anual | Z8: Fecha Facturación | AA8: Fecha Reliquidación | AB8: N° de días de intereses | AC8: Interés total según n° de días | AD8: Intereses ($) | AE8: Reliquidación Total ($)
A9: =9 -> 9 | B9: 43344 | C9: FACT_EMITIDA | D9: =CONCATENATE("SUMIF(",IF(C9="FACT_EMITIDA","SIGGE_E",C9),"!B:B,ReliquidacionEFACT!B",A9,",",IF(C9="FACT_EMITIDA","SIGGE_E",C9),"!S:S)") -> SUMIF(SIGGE_E!B:B,ReliquidacionEFACT!B9,SIGGE_E!S:S) | E9: =CONCATENATE("SUMIF(",IF(C9="FACT_EMITIDA","SIGGE_E",C9),"!B:B,ReliquidacionEFACT!B",A9,",",IF(C9="FACT_EMITIDA","SIGGE_E",C9),"!T:T)") -> SUMIF(SIGGE_E!B:B,ReliquidacionEFACT!B9,SIGGE_E!T:T) | F9: =CONCATENATE("IFERROR((E",A9,"/D",A9,"),0)") -> IFERROR((E9/D9),0) | G9: =CONCATENATE("SUMIF(",IF(C9="FACT_EMITIDA","SIGGE_P",C9),"!B:B,ReliquidacionEFACT!B",A9,",",IF(C9="FACT_EMITIDA","SIGGE_P",C9),"!U:U)") -> SUMIF(SIGGE_P!B:B,ReliquidacionEFACT!B9,SIGGE_P!U:U) | H9: =CONCATENATE("SUMIF(",IF(C9="FACT_EMITIDA","SIGGE_P",C9),"!B:B,ReliquidacionEFACT!B",A9,",",IF(C9="FACT_EMITIDA","SIGGE_P",C9),"!V:V)") -> SUMIF(SIGGE_P!B:B,ReliquidacionEFACT!B9,SIGGE_P!V:V) | I9: =CONCATENATE("IFERROR((H",A9,"/G",A9,"),0)") -> IFERROR((H9/G9),0) | J9: =CONCATENATE("(E",A9,"+H",A9,")") -> (E9+H9) | L9: =(MAPA_DATA!K34) -> EFACT_CNE | M9: =CONCATENATE("SUMIF(",L9,"!B:B,ReliquidacionEFACT!B",A9,",",L9,"!S:S)") -> SUMIF(EFACT_CNE!B:B,ReliquidacionEFACT!B9,EFACT_CNE!S:S) | N9: =CONCATENATE("SUMIF(",L9,"!B:B,ReliquidacionEFACT!B",A9,",",L9,"!T:T)") -> SUMIF(EFACT_CNE!B:B,ReliquidacionEFACT!B9,EFACT_CNE!T:T) | O9: =CONCATENATE("IFERROR((N",A9,"/M",A9,"),0)") -> IFERROR((N9/M9),0) | P9: =CONCATENATE("SUMIF(",L9,"!B:B,ReliquidacionEFACT!B",A9,",",L9,"!U:U)") -> SUMIF(EFACT_CNE!B:B,ReliquidacionEFACT!B9,EFACT_CNE!U:U) | Q9: =CONCATENATE("SUMIF(",L9,"!B:B,ReliquidacionEFACT!B",A9,",",L9,"!V:V)") -> SUMIF(EFACT_CNE!B:B,ReliquidacionEFACT!B9,EFACT_CNE!V:V) | R9: =CONCATENATE("IFERROR((Q",A9,"/P",A9,"),0)") -> IFERROR((Q9/P9),0) | S9: =CONCATENATE("(N",A9,"+Q",A9,")") -> (N9+Q9) | U9: 43344 | V9: =CONCATENATE("(S",A9,"-J",A9,")") -> (S9-J9) | W9: PNP_6T_08-05-2020 | X9: 44137 | Y9: 0.0361 | Z9: 43398 | AA9: 44377 | AB9: =CONCATENATE("(AA",A9,"-Z",A9,")") -> (AA9-Z9) | AC9: =CONCATENATE("(1+Y",A9,")^(AB",A9,"/360)-1") -> (1+Y9)^(AB9/360)-1 | AD9: =CONCATENATE("(AC",A9,"*V",A9,")") -> (AC9*V9) | AE9: =CONCATENATE("(V",A9,"+AD",A9,")") -> (V9+AD9)
A10: =A9+1 -> 10 | B10: 43374 | C10: FACT_EMITIDA | D10: =CONCATENATE("SUMIF(",IF(C10="FACT_EMITIDA","SIGGE_E",C10),"!B:B,ReliquidacionEFACT!B",A10,",",IF(C10="FACT_EMITIDA","SIGGE_E",C10),"!S:S)") -> SUMIF(SIGGE_E!B:B,ReliquidacionEFACT!B10,SIGGE_E!S:S) | E10: =CONCATENATE("SUMIF(",IF(C10="FACT_EMITIDA","SIGGE_E",C10),"!B:B,ReliquidacionEFACT!B",A10,",",IF(C10="FACT_EMITIDA","SIGGE_E",C10),"!T:T)") -> SUMIF(SIGGE_E!B:B,ReliquidacionEFACT!B10,SIGGE_E!T:T) | F10: =CONCATENATE("IFERROR((E",A10,"/D",A10,"),0)") -> IFERROR((E10/D10),0) | G10: =CONCATENATE("SUMIF(",IF(C10="FACT_EMITIDA","SIGGE_P",C10),"!B:B,ReliquidacionEFACT!B",A10,",",IF(C10="FACT_EMITIDA","SIGGE_P",C10),"!U:U)") -> SUMIF(SIGGE_P!B:B,ReliquidacionEFACT!B10,SIGGE_P!U:U) | H10: =CONCATENATE("SUMIF(",IF(C10="FACT_EMITIDA","SIGGE_P",C10),"!B:B,ReliquidacionEFACT!B",A10,",",IF(C10="FACT_EMITIDA","SIGGE_P",C10),"!V:V)") -> SUMIF(SIGGE_P!B:B,ReliquidacionEFACT!B10,SIGGE_P!V:V) | I10: =CONCATENATE("IFERROR((H",A10,"/G",A10,"),0)") -> IFERROR((H10/G10),0) | J10: =CONCATENATE("(E",A10,"+H",A10,")") -> (E10+H10) | L10: =(MAPA_DATA!K35) -> EFACT_CNE | M10: =CONCATENATE("SUMIF(",L10,"!B:B,ReliquidacionEFACT!B",A10,",",L10,"!S:S)") -> SUMIF(EFACT_CNE!B:B,ReliquidacionEFACT!B10,EFACT_CNE!S:S) | N10: =CONCATENATE("SUMIF(",L10,"!B:B,ReliquidacionEFACT!B",A10,",",L10,"!T:T)") -> SUMIF(EFACT_CNE!B:B,ReliquidacionEFACT!B10,EFACT_CNE!T:T) | O10: =CONCATENATE("IFERROR((N",A10,"/M",A10,"),0)") -> IFERROR((N10/M10),0) | P10: =CONCATENATE("SUMIF(",L10,"!B:B,ReliquidacionEFACT!B",A10,",",L10,"!U:U)") -> SUMIF(EFACT_CNE!B:B,ReliquidacionEFACT!B10,EFACT_CNE!U:U) | Q10: =CONCATENATE("SUMIF(",L10,"!B:B,ReliquidacionEFACT!B",A10,",",L10,"!V:V)") -> SUMIF(EFACT_CNE!B:B,ReliquidacionEFACT!B10,EFACT_CNE!V:V) | R10: =CONCATENATE("IFERROR((Q",A10,"/P",A10,"),0)") -> IFERROR((Q10/P10),0) | S10: =CONCATENATE("(N",A10,"+Q",A10,")") -> (N10+Q10) | U10: 43374 | V10: =CONCATENATE("(S",A10,"-J",A10,")") -> (S10-J10) | W10: PNP_6T_08-05-2020 | X10: 44137 | Y10: 0.0361 | Z10: 43429 | AA10: =AA9 -> 44377 | AB10: =CONCATENATE("(AA",A10,"-Z",A10,")") -> (AA10-Z10) | AC10: =CONCATENATE("(1+Y",A10,")^(AB",A10,"/360)-1") -> (1+Y10)^(AB10/360)-1 | AD10: =CONCATENATE("(AC",A10,"*V",A10,")") -> (AC10*V10) | AE10: =CONCATENATE("(V",A10,"+AD",A10,")") -> (V10+AD10)
A11: =A10+1 -> 11 | B11: 43405 | C11: FACT_EMITIDA | D11: =CONCATENATE("SUMIF(",IF(C11="FACT_EMITIDA","SIGGE_E",C11),"!B:B,ReliquidacionEFACT!B",A11,",",IF(C11="FACT_EMITIDA","SIGGE_E",C11),"!S:S)") -> SUMIF(SIGGE_E!B:B,ReliquidacionEFACT!B11,SIGGE_E!S:S) | E11: =CONCATENATE("SUMIF(",IF(C11="FACT_EMITIDA","SIGGE_E",C11),"!B:B,ReliquidacionEFACT!B",A11,",",IF(C11="FACT_EMITIDA","SIGGE_E",C11),"!T:T)") -> SUMIF(SIGGE_E!B:B,ReliquidacionEFACT!B11,SIGGE_E!T:T) | F11: =CONCATENATE("IFERROR((E",A11,"/D",A11,"),0)") -> IFERROR((E11/D11),0) | G11: =CONCATENATE("SUMIF(",IF(C11="FACT_EMITIDA","SIGGE_P",C11),"!B:B,ReliquidacionEFACT!B",A11,",",IF(C11="FACT_EMITIDA","SIGGE_P",C11),"!U:U)") -> SUMIF(SIGGE_P!B:B,ReliquidacionEFACT!B11,SIGGE_P!U:U) | H11: =CONCATENATE("SUMIF(",IF(C11="FACT_EMITIDA","SIGGE_P",C11),"!B:B,ReliquidacionEFACT!B",A11,",",IF(C11="FACT_EMITIDA","SIGGE_P",C11),"!V:V)") -> SUMIF(SIGGE_P!B:B,ReliquidacionEFACT!B11,SIGGE_P!V:V) | I11: =CONCATENATE("IFERROR((H",A11,"/G",A11,"),0)") -> IFERROR((H11/G11),0) | J11: =CONCATENATE("(E",A11,"+H",A11,")") -> (E11+H11) | L11: =(MAPA_DATA!K36) -> EFACT_CNE | M11: =CONCATENATE("SUMIF(",L11,"!B:B,ReliquidacionEFACT!B",A11,",",L11,"!S:S)") -> SUMIF(EFACT_CNE!B:B,ReliquidacionEFACT!B11,EFACT_CNE!S:S) | N11: =CONCATENATE("SUMIF(",L11,"!B:B,ReliquidacionEFACT!B",A11,",",L11,"!T:T)") -> SUMIF(EFACT_CNE!B:B,ReliquidacionEFACT!B11,EFACT_CNE!T:T) | O11: =CONCATENATE("IFERROR((N",A11,"/M",A11,"),0)") -> IFERROR((N11/M11),0) | P11: =CONCATENATE("SUMIF(",L11,"!B:B,ReliquidacionEFACT!B",A11,",",L11,"!U:U)") -> SUMIF(EFACT_CNE!B:B,ReliquidacionEFACT!B11,EFACT_CNE!U:U) | Q11: =CONCATENATE("SUMIF(",L11,"!B:B,ReliquidacionEFACT!B",A11,",",L11,"!V:V)") -> SUMIF(EFACT_CNE!B:B,ReliquidacionEFACT!B11,EFACT_CNE!V:V) | R11: =CONCATENATE("IFERROR((Q",A11,"/P",A11,"),0)") -> IFERROR((Q11/P11),0) | S11: =CONCATENATE("(N",A11,"+Q",A11,")") -> (N11+Q11) | U11: 43405 | V11: =CONCATENATE("(S",A11,"-J",A11,")") -> (S11-J11) | W11: PNP_6T_08-05-2020 | X11: 44137 | Y11: 0.0361 | Z11: 43459 | AA11: =AA10 -> 44377 | AB11: =CONCATENATE("(AA",A11,"-Z",A11,")") -> (AA11-Z11) | AC11: =CONCATENATE("(1+Y",A11,")^(AB",A11,"/360)-1") -> (1+Y11)^(AB11/360)-1 | AD11: =CONCATENATE("(AC",A11,"*V",A11,")") -> (AC11*V11) | AE11: =CONCATENATE("(V",A11,"+AD",A11,")") -> (V11+AD11)
A12: =A11+1 -> 12 | B12: 43435 | C12: FACT_EMITIDA | D12: =CONCATENATE("SUMIF(",IF(C12="FACT_EMITIDA","SIGGE_E",C12),"!B:B,ReliquidacionEFACT!B",A12,",",IF(C12="FACT_EMITIDA","SIGGE_E",C12),"!S:S)") -> SUMIF(SIGGE_E!B:B,ReliquidacionEFACT!B12,SIGGE_E!S:S) | E12: =CONCATENATE("SUMIF(",IF(C12="FACT_EMITIDA","SIGGE_E",C12),"!B:B,ReliquidacionEFACT!B",A12,",",IF(C12="FACT_EMITIDA","SIGGE_E",C12),"!T:T)") -> SUMIF(SIGGE_E!B:B,ReliquidacionEFACT!B12,SIGGE_E!T:T) | F12: =CONCATENATE("IFERROR((E",A12,"/D",A12,"),0)") -> IFERROR((E12/D12),0) | G12: =CONCATENATE("SUMIF(",IF(C12="FACT_EMITIDA","SIGGE_P",C12),"!B:B,ReliquidacionEFACT!B",A12,",",IF(C12="FACT_EMITIDA","SIGGE_P",C12),"!U:U)") -> SUMIF(SIGGE_P!B:B,ReliquidacionEFACT!B12,SIGGE_P!U:U) | H12: =CONCATENATE("SUMIF(",IF(C12="FACT_EMITIDA","SIGGE_P",C12),"!B:B,ReliquidacionEFACT!B",A12,",",IF(C12="FACT_EMITIDA","SIGGE_P",C12),"!V:V)") -> SUMIF(SIGGE_P!B:B,ReliquidacionEFACT!B12,SIGGE_P!V:V) | I12: =CONCATENATE("IFERROR((H",A12,"/G",A12,"),0)") -> IFERROR((H12/G12),0) | J12: =CONCATENATE("(E",A12,"+H",A12,")") -> (E12+H12) | L12: =(MAPA_DATA!K37) -> EFACT_CNE | M12: =CONCATENATE("SUMIF(",L12,"!B:B,ReliquidacionEFACT!B",A12,",",L12,"!S:S)") -> SUMIF(EFACT_CNE!B:B,ReliquidacionEFACT!B12,EFACT_CNE!S:S) | N12: =CONCATENATE("SUMIF(",L12,"!B:B,ReliquidacionEFACT!B",A12,",",L12,"!T:T)") -> SUMIF(EFACT_CNE!B:B,ReliquidacionEFACT!B12,EFACT_CNE!T:T) | O12: =CONCATENATE("IFERROR((N",A12,"/M",A12,"),0)") -> IFERROR((N12/M12),0) | P12: =CONCATENATE("SUMIF(",L12,"!B:B,ReliquidacionEFACT!B",A12,",",L12,"!U:U)") -> SUMIF(EFACT_CNE!B:B,ReliquidacionEFACT!B12,EFACT_CNE!U:U) | Q12: =CONCATENATE("SUMIF(",L12,"!B:B,ReliquidacionEFACT!B",A12,",",L12,"!V:V)") -> SUMIF(EFACT_CNE!B:B,ReliquidacionEFACT!B12,EFACT_CNE!V:V) | R12: =CONCATENATE("IFERROR((Q",A12,"/P",A12,"),0)") -> IFERROR((Q12/P12),0) | S12: =CONCATENATE("(N",A12,"+Q",A12,")") -> (N12+Q12) | U12: 43435 | V12: =CONCATENATE("(S",A12,"-J",A12,")") -> (S12-J12) | W12: PNP_6T_08-05-2020 | X12: 44137 | Y12: 0.0361 | Z12: 43490 | AA12: =AA11 -> 44377 | AB12: =CONCATENATE("(AA",A12,"-Z",A12,")") -> (AA12-Z12) | AC12: =CONCATENATE("(1+Y",A12,")^(AB",A12,"/360)-1") -> (1+Y12)^(AB12/360)-1 | AD12: =CONCATENATE("(AC",A12,"*V",A12,")") -> (AC12*V12) | AE12: =CONCATENATE("(V",A12,"+AD",A12,")") -> (V12+AD12)
A13: =A12+1 -> 13 | B13: 43466 | C13: FACT_EMITIDA | D13: =CONCATENATE("SUMIF(",IF(C13="FACT_EMITIDA","SIGGE_E",C13),"!B:B,ReliquidacionEFACT!B",A13,",",IF(C13="FACT_EMITIDA","SIGGE_E",C13),"!S:S)") -> SUMIF(SIGGE_E!B:B,ReliquidacionEFACT!B13,SIGGE_E!S:S) | E13: =CONCATENATE("SUMIF(",IF(C13="FACT_EMITIDA","SIGGE_E",C13),"!B:B,ReliquidacionEFACT!B",A13,",",IF(C13="FACT_EMITIDA","SIGGE_E",C13),"!T:T)") -> SUMIF(SIGGE_E!B:B,ReliquidacionEFACT!B13,SIGGE_E!T:T) | F13: =CONCATENATE("IFERROR((E",A13,"/D",A13,"),0)") -> IFERROR((E13/D13),0) | G13: =CONCATENATE("SUMIF(",IF(C13="FACT_EMITIDA","SIGGE_P",C13),"!B:B,ReliquidacionEFACT!B",A13,",",IF(C13="FACT_EMITIDA","SIGGE_P",C13),"!U:U)") -> SUMIF(SIGGE_P!B:B,ReliquidacionEFACT!B13,SIGGE_P!U:U) | H13: =CONCATENATE("SUMIF(",IF(C13="FACT_EMITIDA","SIGGE_P",C13),"!B:B,ReliquidacionEFACT!B",A13,",",IF(C13="FACT_EMITIDA","SIGGE_P",C13),"!V:V)") -> SUMIF(SIGGE_P!B:B,ReliquidacionEFACT!B13,SIGGE_P!V:V) | I13: =CONCATENATE("IFERROR((H",A13,"/G",A13,"),0)") -> IFERROR((H13/G13),0) | J13: =CONCATENATE("(E",A13,"+H",A13,")") -> (E13+H13) | L13: =(MAPA_DATA!K38) -> EFACT_CNE | M13: =CONCATENATE("SUMIF(",L13,"!B:B,ReliquidacionEFACT!B",A13,",",L13,"!S:S)") -> SUMIF(EFACT_CNE!B:B,ReliquidacionEFACT!B13,EFACT_CNE!S:S) | N13: =CONCATENATE("SUMIF(",L13,"!B:B,ReliquidacionEFACT!B",A13,",",L13,"!T:T)") -> SUMIF(EFACT_CNE!B:B,ReliquidacionEFACT!B13,EFACT_CNE!T:T) | O13: =CONCATENATE("IFERROR((N",A13,"/M",A13,"),0)") -> IFERROR((N13/M13),0) | P13: =CONCATENATE("SUMIF(",L13,"!B:B,ReliquidacionEFACT!B",A13,",",L13,"!U:U)") -> SUMIF(EFACT_CNE!B:B,ReliquidacionEFACT!B13,EFACT_CNE!U:U) | Q13: =CONCATENATE("SUMIF(",L13,"!B:B,ReliquidacionEFACT!B",A13,",",L13,"!V:V)") -> SUMIF(EFACT_CNE!B:B,ReliquidacionEFACT!B13,EFACT_CNE!V:V) | R13: =CONCATENATE("IFERROR((Q",A13,"/P",A13,"),0)") -> IFERROR((Q13/P13),0) | S13: =CONCATENATE("(N",A13,"+Q",A13,")") -> (N13+Q13) | U13: 43466 | V13: =CONCATENATE("(S",A13,"-J",A13,")") -> (S13-J13) | W13: PNP_6T_08-05-2020 | X13: 44137 | Y13: 0.0361 | Z13: 43521 | AA13: =AA12 -> 44377 | AB13: =CONCATENATE("(AA",A13,"-Z",A13,")") -> (AA13-Z13) | AC13: =CONCATENATE("(1+Y",A13,")^(AB",A13,"/360)-1") -> (1+Y13)^(AB13/360)-1 | AD13: =CONCATENATE("(AC",A13,"*V",A13,")") -> (AC13*V13) | AE13: =CONCATENATE("(V",A13,"+AD",A13,")") -> (V13+AD13)
A14: =A13+1 -> 14 | B14: 43497 | C14: FACT_EMITIDA | D14: =CONCATENATE("SUMIF(",IF(C14="FACT_EMITIDA","SIGGE_E",C14),"!B:B,ReliquidacionEFACT!B",A14,",",IF(C14="FACT_EMITIDA","SIGGE_E",C14),"!S:S)") -> SUMIF(SIGGE_E!B:B,ReliquidacionEFACT!B14,SIGGE_E!S:S) | E14: =CONCATENATE("SUMIF(",IF(C14="FACT_EMITIDA","SIGGE_E",C14),"!B:B,ReliquidacionEFACT!B",A14,",",IF(C14="FACT_EMITIDA","SIGGE_E",C14),"!T:T)") -> SUMIF(SIGGE_E!B:B,ReliquidacionEFACT!B14,SIGGE_E!T:T) | F14: =CONCATENATE("IFERROR((E",A14,"/D",A14,"),0)") -> IFERROR((E14/D14),0) | G14: =CONCATENATE("SUMIF(",IF(C14="FACT_EMITIDA","SIGGE_P",C14),"!B:B,ReliquidacionEFACT!B",A14,",",IF(C14="FACT_EMITIDA","SIGGE_P",C14),"!U:U)") -> SUMIF(SIGGE_P!B:B,ReliquidacionEFACT!B14,SIGGE_P!U:U) | H14: =CONCATENATE("SUMIF(",IF(C14="FACT_EMITIDA","SIGGE_P",C14),"!B:B,ReliquidacionEFACT!B",A14,",",IF(C14="FACT_EMITIDA","SIGGE_P",C14),"!V:V)") -> SUMIF(SIGGE_P!B:B,ReliquidacionEFACT!B14,SIGGE_P!V:V) | I14: =CONCATENATE("IFERROR((H",A14,"/G",A14,"),0)") -> IFERROR((H14/G14),0) | J14: =CONCATENATE("(E",A14,"+H",A14,")") -> (E14+H14) | L14: =(MAPA_DATA!K39) -> EFACT_CNE | M14: =CONCATENATE("SUMIF(",L14,"!B:B,ReliquidacionEFACT!B",A14,",",L14,"!S:S)") -> SUMIF(EFACT_CNE!B:B,ReliquidacionEFACT!B14,EFACT_CNE!S:S) | N14: =CONCATENATE("SUMIF(",L14,"!B:B,ReliquidacionEFACT!B",A14,",",L14,"!T:T)") -> SUMIF(EFACT_CNE!B:B,ReliquidacionEFACT!B14,EFACT_CNE!T:T) | O14: =CONCATENATE("IFERROR((N",A14,"/M",A14,"),0)") -> IFERROR((N14/M14),0) | P14: =CONCATENATE("SUMIF(",L14,"!B:B,ReliquidacionEFACT!B",A14,",",L14,"!U:U)") -> SUMIF(EFACT_CNE!B:B,ReliquidacionEFACT!B14,EFACT_CNE!U:U) | Q14: =CONCATENATE("SUMIF(",L14,"!B:B,ReliquidacionEFACT!B",A14,",",L14,"!V:V)") -> SUMIF(EFACT_CNE!B:B,ReliquidacionEFACT!B14,EFACT_CNE!V:V) | R14: =CONCATENATE("IFERROR((Q",A14,"/P",A14,"),0)") -> IFERROR((Q14/P14),0) | S14: =CONCATENATE("(N",A14,"+Q",A14,")") -> (N14+Q14) | U14: 43497 | V14: =CONCATENATE("(S",A14,"-J",A14,")") -> (S14-J14) | W14: PNP_6T_08-05-2020 | X14: 44137 | Y14: 0.0361 | Z14: 43549 | AA14: =AA13 -> 44377 | AB14: =CONCATENATE("(AA",A14,"-Z",A14,")") -> (AA14-Z14) | AC14: =CONCATENATE("(1+Y",A14,")^(AB",A14,"/360)-1") -> (1+Y14)^(AB14/360)-1 | AD14: =CONCATENATE("(AC",A14,"*V",A14,")") -> (AC14*V14) | AE14: =CONCATENATE("(V",A14,"+AD",A14,")") -> (V14+AD14)
A15: =A14+1 -> 15 | B15: 43525 | C15: FACT_EMITIDA | D15: =CONCATENATE("SUMIF(",IF(C15="FACT_EMITIDA","SIGGE_E",C15),"!B:B,ReliquidacionEFACT!B",A15,",",IF(C15="FACT_EMITIDA","SIGGE_E",C15),"!S:S)") -> SUMIF(SIGGE_E!B:B,ReliquidacionEFACT!B15,SIGGE_E!S:S) | E15: =CONCATENATE("SUMIF(",IF(C15="FACT_EMITIDA","SIGGE_E",C15),"!B:B,ReliquidacionEFACT!B",A15,",",IF(C15="FACT_EMITIDA","SIGGE_E",C15),"!T:T)") -> SUMIF(SIGGE_E!B:B,ReliquidacionEFACT!B15,SIGGE_E!T:T) | F15: =CONCATENATE("IFERROR((E",A15,"/D",A15,"),0)") -> IFERROR((E15/D15),0) | G15: =CONCATENATE("SUMIF(",IF(C15="FACT_EMITIDA","SIGGE_P",C15),"!B:B,ReliquidacionEFACT!B",A15,",",IF(C15="FACT_EMITIDA","SIGGE_P",C15),"!U:U)") -> SUMIF(SIGGE_P!B:B,ReliquidacionEFACT!B15,SIGGE_P!U:U) | H15: =CONCATENATE("SUMIF(",IF(C15="FACT_EMITIDA","SIGGE_P",C15),"!B:B,ReliquidacionEFACT!B",A15,",",IF(C15="FACT_EMITIDA","SIGGE_P",C15),"!V:V)") -> SUMIF(SIGGE_P!B:B,ReliquidacionEFACT!B15,SIGGE_P!V:V) | I15: =CONCATENATE("IFERROR((H",A15,"/G",A15,"),0)") -> IFERROR((H15/G15),0) | J15: =CONCATENATE("(E",A15,"+H",A15,")") -> (E15+H15) | L15: =(MAPA_DATA!K40) -> EFACT_CNE | M15: =CONCATENATE("SUMIF(",L15,"!B:B,ReliquidacionEFACT!B",A15,",",L15,"!S:S)") -> SUMIF(EFACT_CNE!B:B,ReliquidacionEFACT!B15,EFACT_CNE!S:S) | N15: =CONCATENATE("SUMIF(",L15,"!B:B,ReliquidacionEFACT!B",A15,",",L15,"!T:T)") -> SUMIF(EFACT_CNE!B:B,ReliquidacionEFACT!B15,EFACT_CNE!T:T) | O15: =CONCATENATE("IFERROR((N",A15,"/M",A15,"),0)") -> IFERROR((N15/M15),0) | P15: =CONCATENATE("SUMIF(",L15,"!B:B,ReliquidacionEFACT!B",A15,",",L15,"!U:U)") -> SUMIF(EFACT_CNE!B:B,ReliquidacionEFACT!B15,EFACT_CNE!U:U) | Q15: =CONCATENATE("SUMIF(",L15,"!B:B,ReliquidacionEFACT!B",A15,",",L15,"!V:V)") -> SUMIF(EFACT_CNE!B:B,ReliquidacionEFACT!B15,EFACT_CNE!V:V) | R15: =CONCATENATE("IFERROR((Q",A15,"/P",A15,"),0)") -> IFERROR((Q15/P15),0) | S15: =CONCATENATE("(N",A15,"+Q",A15,")") -> (N15+Q15) | U15: 43525 | V15: =CONCATENATE("(S",A15,"-J",A15,")") -> (S15-J15) | W15: PNP_6T_08-05-2020 | X15: 44137 | Y15: 0.0361 | Z15: 43580 | AA15: =AA14 -> 44377 | AB15: =CONCATENATE("(AA",A15,"-Z",A15,")") -> (AA15-Z15) | AC15: =CONCATENATE("(1+Y",A15,")^(AB",A15,"/360)-1") -> (1+Y15)^(AB15/360)-1 | AD15: =CONCATENATE("(AC",A15,"*V",A15,")") -> (AC15*V15) | AE15: =CONCATENATE("(V",A15,"+AD",A15,")") -> (V15+AD15)
A16: =A15+1 -> 16 | B16: 43556 | C16: FACT_EMITIDA | D16: =CONCATENATE("SUMIF(",IF(C16="FACT_EMITIDA","SIGGE_E",C16),"!B:B,ReliquidacionEFACT!B",A16,",",IF(C16="FACT_EMITIDA","SIGGE_E",C16),"!S:S)") -> SUMIF(SIGGE_E!B:B,ReliquidacionEFACT!B16,SIGGE_E!S:S) | E16: =CONCATENATE("SUMIF(",IF(C16="FACT_EMITIDA","SIGGE_E",C16),"!B:B,ReliquidacionEFACT!B",A16,",",IF(C16="FACT_EMITIDA","SIGGE_E",C16),"!T:T)") -> SUMIF(SIGGE_E!B:B,ReliquidacionEFACT!B16,SIGGE_E!T:T) | F16: =CONCATENATE("IFERROR((E",A16,"/D",A16,"),0)") -> IFERROR((E16/D16),0) | G16: =CONCATENATE("SUMIF(",IF(C16="FACT_EMITIDA","SIGGE_P",C16),"!B:B,ReliquidacionEFACT!B",A16,",",IF(C16="FACT_EMITIDA","SIGGE_P",C16),"!U:U)") -> SUMIF(SIGGE_P!B:B,ReliquidacionEFACT!B16,SIGGE_P!U:U) | H16: =CONCATENATE("SUMIF(",IF(C16="FACT_EMITIDA","SIGGE_P",C16),"!B:B,ReliquidacionEFACT!B",A16,",",IF(C16="FACT_EMITIDA","SIGGE_P",C16),"!V:V)") -> SUMIF(SIGGE_P!B:B,ReliquidacionEFACT!B16,SIGGE_P!V:V) | I16: =CONCATENATE("IFERROR((H",A16,"/G",A16,"),0)") -> IFERROR((H16/G16),0) | J16: =CONCATENATE("(E",A16,"+H",A16,")") -> (E16+H16) | L16: =(MAPA_DATA!K41) -> EFACT_CNE | M16: =CONCATENATE("SUMIF(",L16,"!B:B,ReliquidacionEFACT!B",A16,",",L16,"!S:S)") -> SUMIF(EFACT_CNE!B:B,ReliquidacionEFACT!B16,EFACT_CNE!S:S) | N16: =CONCATENATE("SUMIF(",L16,"!B:B,ReliquidacionEFACT!B",A16,",",L16,"!T:T)") -> SUMIF(EFACT_CNE!B:B,ReliquidacionEFACT!B16,EFACT_CNE!T:T) | O16: =CONCATENATE("IFERROR((N",A16,"/M",A16,"),0)") -> IFERROR((N16/M16),0) | P16: =CONCATENATE("SUMIF(",L16,"!B:B,ReliquidacionEFACT!B",A16,",",L16,"!U:U)") -> SUMIF(EFACT_CNE!B:B,ReliquidacionEFACT!B16,EFACT_CNE!U:U) | Q16: =CONCATENATE("SUMIF(",L16,"!B:B,ReliquidacionEFACT!B",A16,",",L16,"!V:V)") -> SUMIF(EFACT_CNE!B:B,ReliquidacionEFACT!B16,EFACT_CNE!V:V) | R16: =CONCATENATE("IFERROR((Q",A16,"/P",A16,"),0)") -> IFERROR((Q16/P16),0) | S16: =CONCATENATE("(N",A16,"+Q",A16,")") -> (N16+Q16) | U16: 43556 | V16: =CONCATENATE("(S",A16,"-J",A16,")") -> (S16-J16) | W16: PNP_6T_08-05-2020 | X16: 44137 | Y16: 0.0361 | Z16: 43610 | AA16: =AA15 -> 44377 | AB16: =CONCATENATE("(AA",A16,"-Z",A16,")") -> (AA16-Z16) | AC16: =CONCATENATE("(1+Y",A16,")^(AB",A16,"/360)-1") -> (1+Y16)^(AB16/360)-1 | AD16: =CONCATENATE("(AC",A16,"*V",A16,")") -> (AC16*V16) | AE16: =CONCATENATE("(V",A16,"+AD",A16,")") -> (V16+AD16)
A17: =A16+1 -> 17 | B17: 43586 | C17: FACT_EMITIDA | D17: =CONCATENATE("SUMIF(",IF(C17="FACT_EMITIDA","SIGGE_E",C17),"!B:B,ReliquidacionEFACT!B",A17,",",IF(C17="FACT_EMITIDA","SIGGE_E",C17),"!S:S)") -> SUMIF(SIGGE_E!B:B,ReliquidacionEFACT!B17,SIGGE_E!S:S) | E17: =CONCATENATE("SUMIF(",IF(C17="FACT_EMITIDA","SIGGE_E",C17),"!B:B,ReliquidacionEFACT!B",A17,",",IF(C17="FACT_EMITIDA","SIGGE_E",C17),"!T:T)") -> SUMIF(SIGGE_E!B:B,ReliquidacionEFACT!B17,SIGGE_E!T:T) | F17: =CONCATENATE("IFERROR((E",A17,"/D",A17,"),0)") -> IFERROR((E17/D17),0) | G17: =CONCATENATE("SUMIF(",IF(C17="FACT_EMITIDA","SIGGE_P",C17),"!B:B,ReliquidacionEFACT!B",A17,",",IF(C17="FACT_EMITIDA","SIGGE_P",C17),"!U:U)") -> SUMIF(SIGGE_P!B:B,ReliquidacionEFACT!B17,SIGGE_P!U:U) | H17: =CONCATENATE("SUMIF(",IF(C17="FACT_EMITIDA","SIGGE_P",C17),"!B:B,ReliquidacionEFACT!B",A17,",",IF(C17="FACT_EMITIDA","SIGGE_P",C17),"!V:V)") -> SUMIF(SIGGE_P!B:B,ReliquidacionEFACT!B17,SIGGE_P!V:V) | I17: =CONCATENATE("IFERROR((H",A17,"/G",A17,"),0)") -> IFERROR((H17/G17),0) | J17: =CONCATENATE("(E",A17,"+H",A17,")") -> (E17+H17) | L17: =(MAPA_DATA!K42) -> EFACT_CNE | M17: =CONCATENATE("SUMIF(",L17,"!B:B,ReliquidacionEFACT!B",A17,",",L17,"!S:S)") -> SUMIF(EFACT_CNE!B:B,ReliquidacionEFACT!B17,EFACT_CNE!S:S) | N17: =CONCATENATE("SUMIF(",L17,"!B:B,ReliquidacionEFACT!B",A17,",",L17,"!T:T)") -> SUMIF(EFACT_CNE!B:B,ReliquidacionEFACT!B17,EFACT_CNE!T:T) | O17: =CONCATENATE("IFERROR((N",A17,"/M",A17,"),0)") -> IFERROR((N17/M17),0) | P17: =CONCATENATE("SUMIF(",L17,"!B:B,ReliquidacionEFACT!B",A17,",",L17,"!U:U)") -> SUMIF(EFACT_CNE!B:B,ReliquidacionEFACT!B17,EFACT_CNE!U:U) | Q17: =CONCATENATE("SUMIF(",L17,"!B:B,ReliquidacionEFACT!B",A17,",",L17,"!V:V)") -> SUMIF(EFACT_CNE!B:B,ReliquidacionEFACT!B17,EFACT_CNE!V:V) | R17: =CONCATENATE("IFERROR((Q",A17,"/P",A17,"),0)") -> IFERROR((Q17/P17),0) | S17: =CONCATENATE("(N",A17,"+Q",A17,")") -> (N17+Q17) | U17: 43586 | V17: =CONCATENATE("(S",A17,"-J",A17,")") -> (S17-J17) | W17: PNP_6T_08-05-2020 | X17: 44137 | Y17: 0.0361 | Z17: 43641 | AA17: =AA16 -> 44377 | AB17: =CONCATENATE("(AA",A17,"-Z",A17,")") -> (AA17-Z17) | AC17: =CONCATENATE("(1+Y",A17,")^(AB",A17,"/360)-1") -> (1+Y17)^(AB17/360)-1 | AD17: =CONCATENATE("(AC",A17,"*V",A17,")") -> (AC17*V17) | AE17: =CONCATENATE("(V",A17,"+AD",A17,")") -> (V17+AD17)
A18: =A17+1 -> 18 | B18: 43617 | C18: FACT_EMITIDA | D18: =CONCATENATE("SUMIF(",IF(C18="FACT_EMITIDA","SIGGE_E",C18),"!B:B,ReliquidacionEFACT!B",A18,",",IF(C18="FACT_EMITIDA","SIGGE_E",C18),"!S:S)") -> SUMIF(SIGGE_E!B:B,ReliquidacionEFACT!B18,SIGGE_E!S:S) | E18: =CONCATENATE("SUMIF(",IF(C18="FACT_EMITIDA","SIGGE_E",C18),"!B:B,ReliquidacionEFACT!B",A18,",",IF(C18="FACT_EMITIDA","SIGGE_E",C18),"!T:T)") -> SUMIF(SIGGE_E!B:B,ReliquidacionEFACT!B18,SIGGE_E!T:T) | F18: =CONCATENATE("IFERROR((E",A18,"/D",A18,"),0)") -> IFERROR((E18/D18),0) | G18: =CONCATENATE("SUMIF(",IF(C18="FACT_EMITIDA","SIGGE_P",C18),"!B:B,ReliquidacionEFACT!B",A18,",",IF(C18="FACT_EMITIDA","SIGGE_P",C18),"!U:U)") -> SUMIF(SIGGE_P!B:B,ReliquidacionEFACT!B18,SIGGE_P!U:U) | H18: =CONCATENATE("SUMIF(",IF(C18="FACT_EMITIDA","SIGGE_P",C18),"!B:B,ReliquidacionEFACT!B",A18,",",IF(C18="FACT_EMITIDA","SIGGE_P",C18),"!V:V)") -> SUMIF(SIGGE_P!B:B,ReliquidacionEFACT!B18,SIGGE_P!V:V) | I18: =CONCATENATE("IFERROR((H",A18,"/G",A18,"),0)") -> IFERROR((H18/G18),0) | J18: =CONCATENATE("(E",A18,"+H",A18,")") -> (E18+H18) | L18: =(MAPA_DATA!K43) -> EFACT_CNE | M18: =CONCATENATE("SUMIF(",L18,"!B:B,ReliquidacionEFACT!B",A18,",",L18,"!S:S)") -> SUMIF(EFACT_CNE!B:B,ReliquidacionEFACT!B18,EFACT_CNE!S:S) | N18: =CONCATENATE("SUMIF(",L18,"!B:B,ReliquidacionEFACT!B",A18,",",L18,"!T:T)") -> SUMIF(EFACT_CNE!B:B,ReliquidacionEFACT!B18,EFACT_CNE!T:T) | O18: =CONCATENATE("IFERROR((N",A18,"/M",A18,"),0)") -> IFERROR((N18/M18),0) | P18: =CONCATENATE("SUMIF(",L18,"!B:B,ReliquidacionEFACT!B",A18,",",L18,"!U:U)") -> SUMIF(EFACT_CNE!B:B,ReliquidacionEFACT!B18,EFACT_CNE!U:U) | Q18: =CONCATENATE("SUMIF(",L18,"!B:B,ReliquidacionEFACT!B",A18,",",L18,"!V:V)") -> SUMIF(EFACT_CNE!B:B,ReliquidacionEFACT!B18,EFACT_CNE!V:V) | R18: =CONCATENATE("IFERROR((Q",A18,"/P",A18,"),0)") -> IFERROR((Q18/P18),0) | S18: =CONCATENATE("(N",A18,"+Q",A18,")") -> (N18+Q18) | U18: 43617 | V18: =CONCATENATE("(S",A18,"-J",A18,")") -> (S18-J18) | W18: PNP_6T_08-05-2020 | X18: 44137 | Y18: 0.0361 | Z18: 43671 | AA18: =AA17 -> 44377 | AB18: =CONCATENATE("(AA",A18,"-Z",A18,")") -> (AA18-Z18) | AC18: =CONCATENATE("(1+Y",A18,")^(AB",A18,"/360)-1") -> (1+Y18)^(AB18/360)-1 | AD18: =CONCATENATE("(AC",A18,"*V",A18,")") -> (AC18*V18) | AE18: =CONCATENATE("(V",A18,"+AD",A18,")") -> (V18+AD18)
A19: =A18+1 -> 19 | B19: 43647 | C19: FACT_EMITIDA | D19: =CONCATENATE("SUMIF(",IF(C19="FACT_EMITIDA","SIGGE_E",C19),"!B:B,ReliquidacionEFACT!B",A19,",",IF(C19="FACT_EMITIDA","SIGGE_E",C19),"!S:S)") -> SUMIF(SIGGE_E!B:B,ReliquidacionEFACT!B19,SIGGE_E!S:S) | E19: =CONCATENATE("SUMIF(",IF(C19="FACT_EMITIDA","SIGGE_E",C19),"!B:B,ReliquidacionEFACT!B",A19,",",IF(C19="FACT_EMITIDA","SIGGE_E",C19),"!T:T)") -> SUMIF(SIGGE_E!B:B,ReliquidacionEFACT!B19,SIGGE_E!T:T) | F19: =CONCATENATE("IFERROR((E",A19,"/D",A19,"),0)") -> IFERROR((E19/D19),0) | G19: =CONCATENATE("SUMIF(",IF(C19="FACT_EMITIDA","SIGGE_P",C19),"!B:B,ReliquidacionEFACT!B",A19,",",IF(C19="FACT_EMITIDA","SIGGE_P",C19),"!U:U)") -> SUMIF(SIGGE_P!B:B,ReliquidacionEFACT!B19,SIGGE_P!U:U) | H19: =CONCATENATE("SUMIF(",IF(C19="FACT_EMITIDA","SIGGE_P",C19),"!B:B,ReliquidacionEFACT!B",A19,",",IF(C19="FACT_EMITIDA","SIGGE_P",C19),"!V:V)") -> SUMIF(SIGGE_P!B:B,ReliquidacionEFACT!B19,SIGGE_P!V:V) | I19: =CONCATENATE("IFERROR((H",A19,"/G",A19,"),0)") -> IFERROR((H19/G19),0) | J19: =CONCATENATE("(E",A19,"+H",A19,")") -> (E19+H19) | L19: =(MAPA_DATA!K44) -> EFACT_CNE | M19: =CONCATENATE("SUMIF(",L19,"!B:B,ReliquidacionEFACT!B",A19,",",L19,"!S:S)") -> SUMIF(EFACT_CNE!B:B,ReliquidacionEFACT!B19,EFACT_CNE!S:S) | N19: =CONCATENATE("SUMIF(",L19,"!B:B,ReliquidacionEFACT!B",A19,",",L19,"!T:T)") -> SUMIF(EFACT_CNE!B:B,ReliquidacionEFACT!B19,EFACT_CNE!T:T) | O19: =CONCATENATE("IFERROR((N",A19,"/M",A19,"),0)") -> IFERROR((N19/M19),0) | P19: =CONCATENATE("SUMIF(",L19,"!B:B,ReliquidacionEFACT!B",A19,",",L19,"!U:U)") -> SUMIF(EFACT_CNE!B:B,ReliquidacionEFACT!B19,EFACT_CNE!U:U) | Q19: =CONCATENATE("SUMIF(",L19,"!B:B,ReliquidacionEFACT!B",A19,",",L19,"!V:V)") -> SUMIF(EFACT_CNE!B:B,ReliquidacionEFACT!B19,EFACT_CNE!V:V) | R19: =CONCATENATE("IFERROR((Q",A19,"/P",A19,"),0)") -> IFERROR((Q19/P19),0) | S19: =CONCATENATE("(N",A19,"+Q",A19,")") -> (N19+Q19) | U19: 43647 | V19: =CONCATENATE("(S",A19,"-J",A19,")") -> (S19-J19) | W19: PNP_6T_08-05-2020 | X19: 44137 | Y19: 0.0361 | Z19: 43702 | AA19: =AA18 -> 44377 | AB19: =CONCATENATE("(AA",A19,"-Z",A19,")") -> (AA19-Z19) | AC19: =CONCATENATE("(1+Y",A19,")^(AB",A19,"/360)-1") -> (1+Y19)^(AB19/360)-1 | AD19: =CONCATENATE("(AC",A19,"*V",A19,")") -> (AC19*V19) | AE19: =CONCATENATE("(V",A19,"+AD",A19,")") -> (V19+AD19)
A20: =A19+1 -> 20 | B20: 43678 | C20: FACT_EMITIDA | D20: =CONCATENATE("SUMIF(",IF(C20="FACT_EMITIDA","SIGGE_E",C20),"!B:B,ReliquidacionEFACT!B",A20,",",IF(C20="FACT_EMITIDA","SIGGE_E",C20),"!S:S)") -> SUMIF(SIGGE_E!B:B,ReliquidacionEFACT!B20,SIGGE_E!S:S) | E20: =CONCATENATE("SUMIF(",IF(C20="FACT_EMITIDA","SIGGE_E",C20),"!B:B,ReliquidacionEFACT!B",A20,",",IF(C20="FACT_EMITIDA","SIGGE_E",C20),"!T:T)") -> SUMIF(SIGGE_E!B:B,ReliquidacionEFACT!B20,SIGGE_E!T:T) | F20: =CONCATENATE("IFERROR((E",A20,"/D",A20,"),0)") -> IFERROR((E20/D20),0) | G20: =CONCATENATE("SUMIF(",IF(C20="FACT_EMITIDA","SIGGE_P",C20),"!B:B,ReliquidacionEFACT!B",A20,",",IF(C20="FACT_EMITIDA","SIGGE_P",C20),"!U:U)") -> SUMIF(SIGGE_P!B:B,ReliquidacionEFACT!B20,SIGGE_P!U:U) | H20: =CONCATENATE("SUMIF(",IF(C20="FACT_EMITIDA","SIGGE_P",C20),"!B:B,ReliquidacionEFACT!B",A20,",",IF(C20="FACT_EMITIDA","SIGGE_P",C20),"!V:V)") -> SUMIF(SIGGE_P!B:B,ReliquidacionEFACT!B20,SIGGE_P!V:V) | I20: =CONCATENATE("IFERROR((H",A20,"/G",A20,"),0)") -> IFERROR((H20/G20),0) | J20: =CONCATENATE("(E",A20,"+H",A20,")") -> (E20+H20) | L20: =(MAPA_DATA!K45) -> EFACT_CNE | M20: =CONCATENATE("SUMIF(",L20,"!B:B,ReliquidacionEFACT!B",A20,",",L20,"!S:S)") -> SUMIF(EFACT_CNE!B:B,ReliquidacionEFACT!B20,EFACT_CNE!S:S) | N20: =CONCATENATE("SUMIF(",L20,"!B:B,ReliquidacionEFACT!B",A20,",",L20,"!T:T)") -> SUMIF(EFACT_CNE!B:B,ReliquidacionEFACT!B20,EFACT_CNE!T:T) | O20: =CONCATENATE("IFERROR((N",A20,"/M",A20,"),0)") -> IFERROR((N20/M20),0) | P20: =CONCATENATE("SUMIF(",L20,"!B:B,ReliquidacionEFACT!B",A20,",",L20,"!U:U)") -> SUMIF(EFACT_CNE!B:B,ReliquidacionEFACT!B20,EFACT_CNE!U:U) | Q20: =CONCATENATE("SUMIF(",L20,"!B:B,ReliquidacionEFACT!B",A20,",",L20,"!V:V)") -> SUMIF(EFACT_CNE!B:B,ReliquidacionEFACT!B20,EFACT_CNE!V:V) | R20: =CONCATENATE("IFERROR((Q",A20,"/P",A20,"),0)") -> IFERROR((Q20/P20),0) | S20: =CONCATENATE("(N",A20,"+Q",A20,")") -> (N20+Q20) | U20: 43678 | V20: =CONCATENATE("(S",A20,"-J",A20,")") -> (S20-J20) | W20: PNP_6T_08-05-2020 | X20: 44137 | Y20: 0.0361 | Z20: 43733 | AA20: =AA19 -> 44377 | AB20: =CONCATENATE("(AA",A20,"-Z",A20,")") -> (AA20-Z20) | AC20: =CONCATENATE("(1+Y",A20,")^(AB",A20,"/360)-1") -> (1+Y20)^(AB20/360)-1 | AD20: =CONCATENATE("(AC",A20,"*V",A20,")") -> (AC20*V20) | AE20: =CONCATENATE("(V",A20,"+AD",A20,")") -> (V20+AD20)
A21: =A20+1 -> 21 | B21: 43709 | C21: FACT_EMITIDA | D21: =CONCATENATE("SUMIF(",IF(C21="FACT_EMITIDA","SIGGE_E",C21),"!B:B,ReliquidacionEFACT!B",A21,",",IF(C21="FACT_EMITIDA","SIGGE_E",C21),"!S:S)") -> SUMIF(SIGGE_E!B:B,ReliquidacionEFACT!B21,SIGGE_E!S:S) | E21: =CONCATENATE("SUMIF(",IF(C21="FACT_EMITIDA","SIGGE_E",C21),"!B:B,ReliquidacionEFACT!B",A21,",",IF(C21="FACT_EMITIDA","SIGGE_E",C21),"!T:T)") -> SUMIF(SIGGE_E!B:B,ReliquidacionEFACT!B21,SIGGE_E!T:T) | F21: =CONCATENATE("IFERROR((E",A21,"/D",A21,"),0)") -> IFERROR((E21/D21),0) | G21: =CONCATENATE("SUMIF(",IF(C21="FACT_EMITIDA","SIGGE_P",C21),"!B:B,ReliquidacionEFACT!B",A21,",",IF(C21="FACT_EMITIDA","SIGGE_P",C21),"!U:U)") -> SUMIF(SIGGE_P!B:B,ReliquidacionEFACT!B21,SIGGE_P!U:U) | H21: =CONCATENATE("SUMIF(",IF(C21="FACT_EMITIDA","SIGGE_P",C21),"!B:B,ReliquidacionEFACT!B",A21,",",IF(C21="FACT_EMITIDA","SIGGE_P",C21),"!V:V)") -> SUMIF(SIGGE_P!B:B,ReliquidacionEFACT!B21,SIGGE_P!V:V) | I21: =CONCATENATE("IFERROR((H",A21,"/G",A21,"),0)") -> IFERROR((H21/G21),0) | J21: =CONCATENATE("(E",A21,"+H",A21,")") -> (E21+H21) | L21: =(MAPA_DATA!K46) -> EFACT_CNE | M21: =CONCATENATE("SUMIF(",L21,"!B:B,ReliquidacionEFACT!B",A21,",",L21,"!S:S)") -> SUMIF(EFACT_CNE!B:B,ReliquidacionEFACT!B21,EFACT_CNE!S:S) | N21: =CONCATENATE("SUMIF(",L21,"!B:B,ReliquidacionEFACT!B",A21,",",L21,"!T:T)") -> SUMIF(EFACT_CNE!B:B,ReliquidacionEFACT!B21,EFACT_CNE!T:T) | O21: =CONCATENATE("IFERROR((N",A21,"/M",A21,"),0)") -> IFERROR((N21/M21),0) | P21: =CONCATENATE("SUMIF(",L21,"!B:B,ReliquidacionEFACT!B",A21,",",L21,"!U:U)") -> SUMIF(EFACT_CNE!B:B,ReliquidacionEFACT!B21,EFACT_CNE!U:U) | Q21: =CONCATENATE("SUMIF(",L21,"!B:B,ReliquidacionEFACT!B",A21,",",L21,"!V:V)") -> SUMIF(EFACT_CNE!B:B,ReliquidacionEFACT!B21,EFACT_CNE!V:V) | R21: =CONCATENATE("IFERROR((Q",A21,"/P",A21,"),0)") -> IFERROR((Q21/P21),0) | S21: =CONCATENATE("(N",A21,"+Q",A21,")") -> (N21+Q21) | U21: 43709 | V21: =CONCATENATE("(S",A21,"-J",A21,")") -> (S21-J21) | W21: PNP_6T_08-05-2020 | X21: 44137 | Y21: 0.0361 | Z21: 43763 | AA21: =AA20 -> 44377 | AB21: =CONCATENATE("(AA",A21,"-Z",A21,")") -> (AA21-Z21) | AC21: =CONCATENATE("(1+Y",A21,")^(AB",A21,"/360)-1") -> (1+Y21)^(AB21/360)-1 | AD21: =CONCATENATE("(AC",A21,"*V",A21,")") -> (AC21*V21) | AE21: =CONCATENATE("(V",A21,"+AD",A21,")") -> (V21+AD21)
... A33: =A32+1 -> 33 | B33: 44075 | C33: FACT_EMITIDA | D33: =CONCATENATE("SUMIF(",IF(C33="FACT_EMITIDA","SIGGE_E",C33),"!B:B,ReliquidacionEFACT!B",A33,",",IF(C33="FACT_EMITIDA","SIGGE_E",C33),"!S:S)") -> SUMIF(SIGGE_E!B:B,ReliquidacionEFACT!B33,SIGGE_E!S:S) | E33: =CONCATENATE("SUMIF(",IF(C33="FACT_EMITIDA","SIGGE_E",C33),"!B:B,ReliquidacionEFACT!B",A33,",",IF(C33="FACT_EMITIDA","SIGGE_E",C33),"!T:T)") -> SUMIF(SIGGE_E!B:B,ReliquidacionEFACT!B33,SIGGE_E!T:T) | F33: =CONCATENATE("IFERROR((E",A33,"/D",A33,"),0)") -> IFERROR((E33/D33),0) | G33: =CONCATENATE("SUMIF(",IF(C33="FACT_EMITIDA","SIGGE_P",C33),"!B:B,ReliquidacionEFACT!B",A33,",",IF(C33="FACT_EMITIDA","SIGGE_P",C33),"!U:U)") -> SUMIF(SIGGE_P!B:B,ReliquidacionEFACT!B33,SIGGE_P!U:U) | H33: =CONCATENATE("SUMIF(",IF(C33="FACT_EMITIDA","SIGGE_P",C33),"!B:B,ReliquidacionEFACT!B",A33,",",IF(C33="FACT_EMITIDA","SIGGE_P",C33),"!V:V)") -> SUMIF(SIGGE_P!B:B,ReliquidacionEFACT!B33,SIGGE_P!V:V) | I33: =CONCATENATE("IFERROR((H",A33,"/G",A33,"),0)") -> IFERROR((H33/G33),0) | J33: =CONCATENATE("(E",A33,"+H",A33,")") -> (E33+H33) | L33: =(MAPA_DATA!K58) -> EFACT_CNE | M33: =CONCATENATE("SUMIF(",L33,"!B:B,ReliquidacionEFACT!B",A33,",",L33,"!S:S)") -> SUMIF(EFACT_CNE!B:B,ReliquidacionEFACT!B33,EFACT_CNE!S:S) | N33: =CONCATENATE("SUMIF(",L33,"!B:B,ReliquidacionEFACT!B",A33,",",L33,"!T:T)") -> SUMIF(EFACT_CNE!B:B,ReliquidacionEFACT!B33,EFACT_CNE!T:T) | O33: =CONCATENATE("IFERROR((N",A33,"/M",A33,"),0)") -> IFERROR((N33/M33),0) | P33: =CONCATENATE("SUMIF(",L33,"!B:B,ReliquidacionEFACT!B",A33,",",L33,"!U:U)") -> SUMIF(EFACT_CNE!B:B,ReliquidacionEFACT!B33,EFACT_CNE!U:U) | Q33: =CONCATENATE("SUMIF(",L33,"!B:B,ReliquidacionEFACT!B",A33,",",L33,"!V:V)") -> SUMIF(EFACT_CNE!B:B,ReliquidacionEFACT!B33,EFACT_CNE!V:V) | R33: =CONCATENATE("IFERROR((Q",A33,"/P",A33,"),0)") -> IFERROR((Q33/P33),0) | S33: =CONCATENATE("(N",A33,"+Q",A33,")") -> (N33+Q33) | U33: 44075 | V33: =CONCATENATE("(S",A33,"-J",A33,")") -> (S33-J33) | W33: PNP_19T_30-12-2020 | X33: 44336 | Y33: 0.0328 | Z33: 44129 | AA33: =AA32 -> 44377 | AB33: =CONCATENATE("(AA",A33,"-Z",A33,")") -> (AA33-Z33) | AC33: =CONCATENATE("(1+Y",A33,")^(AB",A33,"/360)-1") -> (1+Y33)^(AB33/360)-1 | AD33: =CONCATENATE("(AC",A33,"*V",A33,")") -> (AC33*V33) | AE33: =CONCATENATE("(V",A33,"+AD",A33,")") -> (V33+AD33)
AD34: Reliquidación | AE34: =CONCATENATE("SUM(AE9:AE33)") -> SUM(AE9:AE33)
AC36: Montos a favor | AD36: ACCIONA emite factura
AC37: Montos en contra | AD37: ACCIONA emite nota de crédito

Sheet ReliquidacionCEN
A2: Generador | B2: [GX]
A3: Distribuidor | B3: [EEDD]
A4: Licitacion | B4: 2013/03-2° Llamado
A5: Bloque | B5: [BLOQUE]
C7: LO QUE SE FACTURÓ | L7: LO QUE SE DEBIÓ HABER FACTURADO | U7: RELQUIDACIÓN Y CÁLCULO INTERESES
A8: ID | B8: MES | C8: ORIGEN DATA | D8: Energía (kWh) | E8: Monto Energía ($) | F8: $/kWh | G8: Potencia (kW) | H8: Monto Potencia ($) | I8: $/kW-mes | J8: Monto Total ($) | L8: ORIGEN DATA | M8: Energía (kWh) | N8: Monto Energía ($) | O8: $/kWh | P8: Potencia (kW) | Q8: Monto Potencia ($) | R8: $/kW-mes | S8: Monto Total ($) | U8: Mes | V8: Reliquidación mensual ($) | W8: Decreto PNP Reliquidación | X8: Fecha publicación Diario Oficial | Y8: Interés Anual | Z8: Fecha Facturación | AA8: Fecha Reliquidación | AB8: N° de días de intereses | AC8: Interés total según n° de días | AD8: Intereses ($) | AE8: Reliquidación Total ($)
A9: =9 -> 9 | B9: 43344 | C9: FACT_EMITIDA | D9: =CONCATENATE("SUMIF(",IF(C9="FACT_EMITIDA","SIGGE_E",C9),"!B:B,ReliquidacionEFACT!B",A9,",",IF(C9="FACT_EMITIDA","SIGGE_E",C9),"!S:S)") -> SUMIF(SIGGE_E!B:B,ReliquidacionEFACT!B9,SIGGE_E!S:S) | E9: =CONCATENATE("SUMIF(",IF(C9="FACT_EMITIDA","SIGGE_E",C9),"!B:B,ReliquidacionEFACT!B",A9,",",IF(C9="FACT_EMITIDA","SIGGE_E",C9),"!T:T)") -> SUMIF(SIGGE_E!B:B,ReliquidacionEFACT!B9,SIGGE_E!T:T) | F9: =CONCATENATE("IFERROR((E",A9,"/D",A9,"),0)") -> IFERROR((E9/D9),0) | G9: =CONCATENATE("SUMIF(",IF(C9="FACT_EMITIDA","SIGGE_P",C9),"!B:B,ReliquidacionEFACT!B",A9,",",IF(C9="FACT_EMITIDA","SIGGE_P",C9),"!U:U)") -> SUMIF(SIGGE_P!B:B,ReliquidacionEFACT!B9,SIGGE_P!U:U) | H9: =CONCATENATE("SUMIF(",IF(C9="FACT_EMITIDA","SIGGE_P",C9),"!B:B,ReliquidacionEFACT!B",A9,",",IF(C9="FACT_EMITIDA","SIGGE_P",C9),"!V:V)") -> SUMIF(SIGGE_P!B:B,ReliquidacionEFACT!B9,SIGGE_P!V:V) | I9: =CONCATENATE("IFERROR((H",A9,"/G",A9,"),0)") -> IFERROR((H9/G9),0) | J9: =CONCATENATE("(E",A9,"+H",A9,")") -> (E9+H9) | L9: FACT_EST_CEN | M9: =CONCATENATE("SUMIF(",L9,"!B:B,ReliquidacionEFACT!B",A9,",",L9,"!S:S)") -> SUMIF(FACT_EST_CEN!B:B,ReliquidacionEFACT!B9,FACT_EST_CEN!S:S) | N9: =CONCATENATE("SUMIF(",L9,"!B:B,ReliquidacionEFACT!B",A9,",",L9,"!T:T)") -> SUMIF(FACT_EST_CEN!B:B,ReliquidacionEFACT!B9,FACT_EST_CEN!T:T) | O9: =CONCATENATE("IFERROR((N",A9,"/M",A9,"),0)") -> IFERROR((N9/M9),0) | P9: =CONCATENATE("SUMIF(",L9,"!B:B,ReliquidacionEFACT!B",A9,",",L9,"!U:U)") -> SUMIF(FACT_EST_CEN!B:B,ReliquidacionEFACT!B9,FACT_EST_CEN!U:U) | Q9: =CONCATENATE("SUMIF(",L9,"!B:B,ReliquidacionEFACT!B",A9,",",L9,"!V:V)") -> SUMIF(FACT_EST_CEN!B:B,ReliquidacionEFACT!B9,FACT_EST_CEN!V:V) | R9: =CONCATENATE("IFERROR((Q",A9,"/P",A9,"),0)") -> IFERROR((Q9/P9),0) | S9: =CONCATENATE("(N",A9,"+Q",A9,")") -> (N9+Q9) | U9: 43344 | V9: =CONCATENATE("(S",A9,"-J",A9,")") -> (S9-J9) | W9: PNP_6T_08-05-2020 | X9: 44137 | Y9: 0.0361 | Z9: 43398 | AA9: 44377 | AB9: =CONCATENATE("(AA",A9,"-Z",A9,")") -> (AA9-Z9) | AC9: =CONCATENATE("(1+Y",A9,")^(AB",A9,"/360)-1") -> (1+Y9)^(AB9/360)-1 | AD9: =CONCATENATE("(AC",A9,"*V",A9,")") -> (AC9*V9) | AE9: =CONCATENATE("(V",A9,"+AD",A9,")") -> (V9+AD9)
A10: =A9+1 -> 10 | B10: 43374 | C10: FACT_EMITIDA | D10: =CONCATENATE("SUMIF(",IF(C10="FACT_EMITIDA","SIGGE_E",C10),"!B:B,ReliquidacionEFACT!B",A10,",",IF(C10="FACT_EMITIDA","SIGGE_E",C10),"!S:S)") -> SUMIF(SIGGE_E!B:B,ReliquidacionEFACT!B10,SIGGE_E!S:S) | E10: =CONCATENATE("SUMIF(",IF(C10="FACT_EMITIDA","SIGGE_E",C10),"!B:B,ReliquidacionEFACT!B",A10,",",IF(C10="FACT_EMITIDA","SIGGE_E",C10),"!T:T)") -> SUMIF(SIGGE_E!B:B,ReliquidacionEFACT!B10,SIGGE_E!T:T) | F10: =CONCATENATE("IFERROR((E",A10,"/D",A10,"),0)") -> IFERROR((E10/D10),0) | G10: =CONCATENATE("SUMIF(",IF(C10="FACT_EMITIDA","SIGGE_P",C10),"!B:B,ReliquidacionEFACT!B",A10,",",IF(C10="FACT_EMITIDA","SIGGE_P",C10),"!U:U)") -> SUMIF(SIGGE_P!B:B,ReliquidacionEFACT!B10,SIGGE_P!U:U) | H10: =CONCATENATE("SUMIF(",IF(C10="FACT_EMITIDA","SIGGE_P",C10),"!B:B,ReliquidacionEFACT!B",A10,",",IF(C10="FACT_EMITIDA","SIGGE_P",C10),"!V:V)") -> SUMIF(SIGGE_P!B:B,ReliquidacionEFACT!B10,SIGGE_P!V:V) | I10: =CONCATENATE("IFERROR((H",A10,"/G",A10,"),0)") -> IFERROR((H10/G10),0) | J10: =CONCATENATE("(E",A10,"+H",A10,")") -> (E10+H10) | L10: FACT_EST_CEN | M10: =CONCATENATE("SUMIF(",L10,"!B:B,ReliquidacionEFACT!B",A10,",",L10,"!S:S)") -> SUMIF(FACT_EST_CEN!B:B,ReliquidacionEFACT!B10,FACT_EST_CEN!S:S) | N10: =CONCATENATE("SUMIF(",L10,"!B:B,ReliquidacionEFACT!B",A10,",",L10,"!T:T)") -> SUMIF(FACT_EST_CEN!B:B,ReliquidacionEFACT!B10,FACT_EST_CEN!T:T) | O10: =CONCATENATE("IFERROR((N",A10,"/M",A10,"),0)") -> IFERROR((N10/M10),0) | P10: =CONCATENATE("SUMIF(",L10,"!B:B,ReliquidacionEFACT!B",A10,",",L10,"!U:U)") -> SUMIF(FACT_EST_CEN!B:B,ReliquidacionEFACT!B10,FACT_EST_CEN!U:U) | Q10: =CONCATENATE("SUMIF(",L10,"!B:B,ReliquidacionEFACT!B",A10,",",L10,"!V:V)") -> SUMIF(FACT_EST_CEN!B:B,ReliquidacionEFACT!B10,FACT_EST_CEN!V:V) | R10: =CONCATENATE("IFERROR((Q",A10,"/P",A10,"),0)") -> IFERROR((Q10/P10),0) | S10: =CONCATENATE("(N",A10,"+Q",A10,")") -> (N10+Q10) | U10: 43374 | V10: =CONCATENATE("(S",A10,"-J",A10,")") -> (S10-J10) | W10: PNP_6T_08-05-2020 | X10: 44137 | Y10: 0.0361 | Z10: 43429 | AA10: =AA9 -> 44377 | AB10: =CONCATENATE("(AA",A10,"-Z",A10,")") -> (AA10-Z10) | AC10: =CONCATENATE("(1+Y",A10,")^(AB",A10,"/360)-1") -> (1+Y10)^(AB10/360)-1 | AD10: =CONCATENATE("(AC",A10,"*V",A10,")") -> (AC10*V10) | AE10: =CONCATENATE("(V",A10,"+AD",A10,")") -> (V10+AD10)
A11: =A10+1 -> 11 | B11: 43405 | C11: FACT_EMITIDA | D11: =CONCATENATE("SUMIF(",IF(C11="FACT_EMITIDA","SIGGE_E",C11),"!B:B,ReliquidacionEFACT!B",A11,",",IF(C11="FACT_EMITIDA","SIGGE_E",C11),"!S:S)") -> SUMIF(SIGGE_E!B:B,ReliquidacionEFACT!B11,SIGGE_E!S:S) | E11: =CONCATENATE("SUMIF(",IF(C11="FACT_EMITIDA","SIGGE_E",C11),"!B:B,ReliquidacionEFACT!B",A11,",",IF(C11="FACT_EMITIDA","SIGGE_E",C11),"!T:T)") -> SUMIF(SIGGE_E!B:B,ReliquidacionEFACT!B11,SIGGE_E!T:T) | F11: =CONCATENATE("IFERROR((E",A11,"/D",A11,"),0)") -> IFERROR((E11/D11),0) | G11: =CONCATENATE("SUMIF(",IF(C11="FACT_EMITIDA","SIGGE_P",C11),"!B:B,ReliquidacionEFACT!B",A11,",",IF(C11="FACT_EMITIDA","SIGGE_P",C11),"!U:U)") -> SUMIF(SIGGE_P!B:B,ReliquidacionEFACT!B11,SIGGE_P!U:U) | H11: =CONCATENATE("SUMIF(",IF(C11="FACT_EMITIDA","SIGGE_P",C11),"!B:B,ReliquidacionEFACT!B",A11,",",IF(C11="FACT_EMITIDA","SIGGE_P",C11),"!V:V)") -> SUMIF(SIGGE_P!B:B,ReliquidacionEFACT!B11,SIGGE_P!V:V) | I11: =CONCATENATE("IFERROR((H",A11,"/G",A11,"),0)") -> IFERROR((H11/G11),0) | J11: =CONCATENATE("(E",A11,"+H",A11,")") -> (E11+H11) | L11: FACT_EST_CEN | M11: =CONCATENATE("SUMIF(",L11,"!B:B,ReliquidacionEFACT!B",A11,",",L11,"!S:S)") -> SUMIF(FACT_EST_CEN!B:B,ReliquidacionEFACT!B11,FACT_EST_CEN!S:S) | N11: =CONCATENATE("SUMIF(",L11,"!B:B,ReliquidacionEFACT!B",A11,",",L11,"!T:T)") -> SUMIF(FACT_EST_CEN!B:B,ReliquidacionEFACT!B11,FACT_EST_CEN!T:T) | O11: =CONCATENATE("IFERROR((N",A11,"/M",A11,"),0)") -> IFERROR((N11/M11),0) | P11: =CONCATENATE("SUMIF(",L11,"!B:B,ReliquidacionEFACT!B",A11,",",L11,"!U:U)") -> SUMIF(FACT_EST_CEN!B:B,ReliquidacionEFACT!B11,FACT_EST_CEN!U:U) | Q11: =CONCATENATE("SUMIF(",L11,"!B:B,ReliquidacionEFACT!B",A11,",",L11,"!V:V)") -> SUMIF(FACT_EST_CEN!B:B,ReliquidacionEFACT!B11,FACT_EST_CEN!V:V) | R11: =CONCATENATE("IFERROR((Q",A11,"/P",A11,"),0)") -> IFERROR((Q11/P11),0) | S11: =CONCATENATE("(N",A11,"+Q",A11,")") -> (N11+Q11) | U11: 43405 | V11: =CONCATENATE("(S",A11,"-J",A11,")") -> (S11-J11) | W11: PNP_6T_08-05-2020 | X11: 44137 | Y11: 0.0361 | Z11: 43459 | AA11: =AA10 -> 44377 | AB11: =CONCATENATE("(AA",A11,"-Z",A11,")") -> (AA11-Z11) | AC11: =CONCATENATE("(1+Y",A11,")^(AB",A11,"/360)-1") -> (1+Y11)^(AB11/360)-1 | AD11: =CONCATENATE("(AC",A11,"*V",A11,")") -> (AC11*V11) | AE11: =CONCATENATE("(V",A11,"+AD",A11,")") -> (V11+AD11)
A12: =A11+1 -> 12 | B12: 43435 | C12: FACT_EMITIDA | D12: =CONCATENATE("SUMIF(",IF(C12="FACT_EMITIDA","SIGGE_E",C12),"!B:B,ReliquidacionEFACT!B",A12,",",IF(C12="FACT_EMITIDA","SIGGE_E",C12),"!S:S)") -> SUMIF(SIGGE_E!B:B,ReliquidacionEFACT!B12,SIGGE_E!S:S) | E12: =CONCATENATE("SUMIF(",IF(C12="FACT_EMITIDA","SIGGE_E",C12),"!B:B,ReliquidacionEFACT!B",A12,",",IF(C12="FACT_EMITIDA","SIGGE_E",C12),"!T:T)") -> SUMIF(SIGGE_E!B:B,ReliquidacionEFACT!B12,SIGGE_E!T:T) | F12: =CONCATENATE("IFERROR((E",A12,"/D",A12,"),0)") -> IFERROR((E12/D12),0) | G12: =CONCATENATE("SUMIF(",IF(C12="FACT_EMITIDA","SIGGE_P",C12),"!B:B,ReliquidacionEFACT!B",A12,",",IF(C12="FACT_EMITIDA","SIGGE_P",C12),"!U:U)") -> SUMIF(SIGGE_P!B:B,ReliquidacionEFACT!B12,SIGGE_P!U:U) | H12: =CONCATENATE("SUMIF(",IF(C12="FACT_EMITIDA","SIGGE_P",C12),"!B:B,ReliquidacionEFACT!B",A12,",",IF(C12="FACT_EMITIDA","SIGGE_P",C12),"!V:V)") -> SUMIF(SIGGE_P!B:B,ReliquidacionEFACT!B12,SIGGE_P!V:V) | I12: =CONCATENATE("IFERROR((H",A12,"/G",A12,"),0)") -> IFERROR((H12/G12),0) | J12: =CONCATENATE("(E",A12,"+H",A12,")") -> (E12+H12) | L12: FACT_EST_CEN | M12: =CONCATENATE("SUMIF(",L12,"!B:B,ReliquidacionEFACT!B",A12,",",L12,"!S:S)") -> SUMIF(FACT_EST_CEN!B:B,ReliquidacionEFACT!B12,FACT_EST_CEN!S:S) | N12: =CONCATENATE("SUMIF(",L12,"!B:B,ReliquidacionEFACT!B",A12,",",L12,"!T:T)") -> SUMIF(FACT_EST_CEN!B:B,ReliquidacionEFACT!B12,FACT_EST_CEN!T:T) | O12: =CONCATENATE("IFERROR((N",A12,"/M",A12,"),0)") -> IFERROR((N12/M12),0) | P12: =CONCATENATE("SUMIF(",L12,"!B:B,ReliquidacionEFACT!B",A12,",",L12,"!U:U)") -> SUMIF(FACT_EST_CEN!B:B,ReliquidacionEFACT!B12,FACT_EST_CEN!U:U) | Q12: =CONCATENATE("SUMIF(",L12,"!B:B,ReliquidacionEFACT!B",A12,",",L12,"!V:V)") -> SUMIF(FACT_EST_CEN!B:B,ReliquidacionEFACT!B12,FACT_EST_CEN!V:V) | R12: =CONCATENATE("IFERROR((Q",A12,"/P",A12,"),0)") -> IFERROR((Q12/P12),0) | S12: =CONCATENATE("(N",A12,"+Q",A12,")") -> (N12+Q12) | U12: 43435 | V12: =CONCATENATE("(S",A12,"-J",A12,")") -> (S12-J12) | W12: PNP_6T_08-05-2020 | X12: 44137 | Y12: 0.0361 | Z12: 43490 | AA12: =AA11 -> 44377 | AB12: =CONCATENATE("(AA",A12,"-Z",A12,")") -> (AA12-Z12) | AC12: =CONCATENATE("(1+Y",A12,")^(AB",A12,"/360)-1") -> (1+Y12)^(AB12/360)-1 | AD12: =CONCATENATE("(AC",A12,"*V",A12,")") -> (AC12*V12) | AE12: =CONCATENATE("(V",A12,"+AD",A12,")") -> (V12+AD12)
A13: =A12+1 -> 13 | B13: 43466 | C13: FACT_EMITIDA | D13: =CONCATENATE("SUMIF(",IF(C13="FACT_EMITIDA","SIGGE_E",C13),"!B:B,ReliquidacionEFACT!B",A13,",",IF(C13="FACT_EMITIDA","SIGGE_E",C13),"!S:S)") -> SUMIF(SIGGE_E!B:B,ReliquidacionEFACT!B13,SIGGE_E!S:S) | E13: =CONCATENATE("SUMIF(",IF(C13="FACT_EMITIDA","SIGGE_E",C13),"!B:B,ReliquidacionEFACT!B",A13,",",IF(C13="FACT_EMITIDA","SIGGE_E",C13),"!T:T)") -> SUMIF(SIGGE_E!B:B,ReliquidacionEFACT!B13,SIGGE_E!T:T) | F13: =CONCATENATE("IFERROR((E",A13,"/D",A13,"),0)") -> IFERROR((E13/D13),0) | G13: =CONCATENATE("SUMIF(",IF(C13="FACT_EMITIDA","SIGGE_P",C13),"!B:B,ReliquidacionEFACT!B",A13,",",IF(C13="FACT_EMITIDA","SIGGE_P",C13),"!U:U)") -> SUMIF(SIGGE_P!B:B,ReliquidacionEFACT!B13,SIGGE_P!U:U) | H13: =CONCATENATE("SUMIF(",IF(C13="FACT_EMITIDA","SIGGE_P",C13),"!B:B,ReliquidacionEFACT!B",A13,",",IF(C13="FACT_EMITIDA","SIGGE_P",C13),"!V:V)") -> SUMIF(SIGGE_P!B:B,ReliquidacionEFACT!B13,SIGGE_P!V:V) | I13: =CONCATENATE("IFERROR((H",A13,"/G",A13,"),0)") -> IFERROR((H13/G13),0) | J13: =CONCATENATE("(E",A13,"+H",A13,")") -> (E13+H13) | L13: FACT_EST_CEN | M13: =CONCATENATE("SUMIF(",L13,"!B:B,ReliquidacionEFACT!B",A13,",",L13,"!S:S)") -> SUMIF(FACT_EST_CEN!B:B,ReliquidacionEFACT!B13,FACT_EST_CEN!S:S) | N13: =CONCATENATE("SUMIF(",L13,"!B:B,ReliquidacionEFACT!B",A13,",",L13,"!T:T)") -> SUMIF(FACT_EST_CEN!B:B,ReliquidacionEFACT!B13,FACT_EST_CEN!T:T) | O13: =CONCATENATE("IFERROR((N",A13,"/M",A13,"),0)") -> IFERROR((N13/M13),0) | P13: =CONCATENATE("SUMIF(",L13,"!B:B,ReliquidacionEFACT!B",A13,",",L13,"!U:U)") -> SUMIF(FACT_EST_CEN!B:B,ReliquidacionEFACT!B13,FACT_EST_CEN!U:U) | Q13: =CONCATENATE("SUMIF(",L13,"!B:B,ReliquidacionEFACT!B",A13,",",L13,"!V:V)") -> SUMIF(FACT_EST_CEN!B:B,ReliquidacionEFACT!B13,FACT_EST_CEN!V:V) | R13: =CONCATENATE("IFERROR((Q",A13,"/P",A13,"),0)") -> IFERROR((Q13/P13),0) | S13: =CONCATENATE("(N",A13,"+Q",A13,")") -> (N13+Q13) | U13: 43466 | V13: =CONCATENATE("(S",A13,"-J",A13,")") -> (S13-J13) | W13: PNP_6T_08-05-2020 | X13: 44137 | Y13: 0.0361 | Z13: 43521 | AA13: =AA12 -> 44377 | AB13: =CONCATENATE("(AA",A13,"-Z",A13,")") -> (AA13-Z13) | AC13: =CONCATENATE("(1+Y",A13,")^(AB",A13,"/360)-1") -> (1+Y13)^(AB13/360)-1 | AD13: =CONCATENATE("(AC",A13,"*V",A13,")") -> (AC13*V13) | AE13: =CONCATENATE("(V",A13,"+AD",A13,")") -> (V13+AD13)
A14: =A13+1 -> 14 | B14: 43497 | C14: FACT_EMITIDA | D14: =CONCATENATE("SUMIF(",IF(C14="FACT_EMITIDA","SIGGE_E",C14),"!B:B,ReliquidacionEFACT!B",A14,",",IF(C14="FACT_EMITIDA","SIGGE_E",C14),"!S:S)") -> SUMIF(SIGGE_E!B:B,ReliquidacionEFACT!B14,SIGGE_E!S:S) | E14: =CONCATENATE("SUMIF(",IF(C14="FACT_EMITIDA","SIGGE_E",C14),"!B:B,ReliquidacionEFACT!B",A14,",",IF(C14="FACT_EMITIDA","SIGGE_E",C14),"!T:T)") -> SUMIF(SIGGE_E!B:B,ReliquidacionEFACT!B14,SIGGE_E!T:T) | F14: =CONCATENATE("IFERROR((E",A14,"/D",A14,"),0)") -> IFERROR((E14/D14),0) | G14: =CONCATENATE("SUMIF(",IF(C14="FACT_EMITIDA","SIGGE_P",C14),"!B:B,ReliquidacionEFACT!B",A14,",",IF(C14="FACT_EMITIDA","SIGGE_P",C14),"!U:U)") -> SUMIF(SIGGE_P!B:B,ReliquidacionEFACT!B14,SIGGE_P!U:U) | H14: =CONCATENATE("SUMIF(",IF(C14="FACT_EMITIDA","SIGGE_P",C14),"!B:B,ReliquidacionEFACT!B",A14,",",IF(C14="FACT_EMITIDA","SIGGE_P",C14),"!V:V)") -> SUMIF(SIGGE_P!B:B,ReliquidacionEFACT!B14,SIGGE_P!V:V) | I14: =CONCATENATE("IFERROR((H",A14,"/G",A14,"),0)") -> IFERROR((H14/G14),0) | J14: =CONCATENATE("(E",A14,"+H",A14,")") -> (E14+H14) | L14: FACT_EST_CEN | M14: =CONCATENATE("SUMIF(",L14,"!B:B,ReliquidacionEFACT!B",A14,",",L14,"!S:S)") -> SUMIF(FACT_EST_CEN!B:B,ReliquidacionEFACT!B14,FACT_EST_CEN!S:S) | N14: =CONCATENATE("SUMIF(",L14,"!B:B,ReliquidacionEFACT!B",A14,",",L14,"!T:T)") -> SUMIF(FACT_EST_CEN!B:B,ReliquidacionEFACT!B14,FACT_EST_CEN!T:T) | O14: =CONCATENATE("IFERROR((N",A14,"/M",A14,"),0)") -> IFERROR((N14/M14),0) | P14: =CONCATENATE("SUMIF(",L14,"!B:B,ReliquidacionEFACT!B",A14,",",L14,"!U:U)") -> SUMIF(FACT_EST_CEN!B:B,ReliquidacionEFACT!B14,FACT_EST_CEN!U:U) | Q14: =CONCATENATE("SUMIF(",L14,"!B:B,ReliquidacionEFACT!B",A14,",",L14,"!V:V)") -> SUMIF(FACT_EST_CEN!B:B,ReliquidacionEFACT!B14,FACT_EST_CEN!V:V) | R14: =CONCATENATE("IFERROR((Q",A14,"/P",A14,"),0)") -> IFERROR((Q14/P14),0) | S14: =CONCATENATE("(N",A14,"+Q",A14,")") -> (N14+Q14) | U14: 43497 | V14: =CONCATENATE("(S",A14,"-J",A14,")") -> (S14-J14) | W14: PNP_6T_08-05-2020 | X14: 44137 | Y14: 0.0361 | Z14: 43549 | AA14: =AA13 -> 44377 | AB14: =CONCATENATE("(AA",A14,"-Z",A14,")") -> (AA14-Z14) | AC14: =CONCATENATE("(1+Y",A14,")^(AB",A14,"/360)-1") -> (1+Y14)^(AB14/360)-1 | AD14: =CONCATENATE("(AC",A14,"*V",A14,")") -> (AC14*V14) | AE14: =CONCATENATE("(V",A14,"+AD",A14,")") -> (V14+AD14)
A15: =A14+1 -> 15 | B15: 43525 | C15: FACT_EMITIDA | D15: =CONCATENATE("SUMIF(",IF(C15="FACT_EMITIDA","SIGGE_E",C15),"!B:B,ReliquidacionEFACT!B",A15,",",IF(C15="FACT_EMITIDA","SIGGE_E",C15),"!S:S)") -> SUMIF(SIGGE_E!B:B,ReliquidacionEFACT!B15,SIGGE_E!S:S) | E15: =CONCATENATE("SUMIF(",IF(C15="FACT_EMITIDA","SIGGE_E",C15),"!B:B,ReliquidacionEFACT!B",A15,",",IF(C15="FACT_EMITIDA","SIGGE_E",C15),"!T:T)") -> SUMIF(SIGGE_E!B:B,ReliquidacionEFACT!B15,SIGGE_E!T:T) | F15: =CONCATENATE("IFERROR((E",A15,"/D",A15,"),0)") -> IFERROR((E15/D15),0) | G15: =CONCATENATE("SUMIF(",IF(C15="FACT_EMITIDA","SIGGE_P",C15),"!B:B,ReliquidacionEFACT!B",A15,",",IF(C15="FACT_EMITIDA","SIGGE_P",C15),"!U:U)") -> SUMIF(SIGGE_P!B:B,ReliquidacionEFACT!B15,SIGGE_P!U:U) | H15: =CONCATENATE("SUMIF(",IF(C15="FACT_EMITIDA","SIGGE_P",C15),"!B:B,ReliquidacionEFACT!B",A15,",",IF(C15="FACT_EMITIDA","SIGGE_P",C15),"!V:V)") -> SUMIF(SIGGE_P!B:B,ReliquidacionEFACT!B15,SIGGE_P!V:V) | I15: =CONCATENATE("IFERROR((H",A15,"/G",A15,"),0)") -> IFERROR((H15/G15),0) | J15: =CONCATENATE("(E",A15,"+H",A15,")") -> (E15+H15) | L15: FACT_EST_CEN | M15: =CONCATENATE("SUMIF(",L15,"!B:B,ReliquidacionEFACT!B",A15,",",L15,"!S:S)") -> SUMIF(FACT_EST_CEN!B:B,ReliquidacionEFACT!B15,FACT_EST_CEN!S:S) | N15: =CONCATENATE("SUMIF(",L15,"!B:B,ReliquidacionEFACT!B",A15,",",L15,"!T:T)") -> SUMIF(FACT_EST_CEN!B:B,ReliquidacionEFACT!B15,FACT_EST_CEN!T:T) | O15: =CONCATENATE("IFERROR((N",A15,"/M",A15,"),0)") -> IFERROR((N15/M15),0) | P15: =CONCATENATE("SUMIF(",L15,"!B:B,ReliquidacionEFACT!B",A15,",",L15,"!U:U)") -> SUMIF(FACT_EST_CEN!B:B,ReliquidacionEFACT!B15,FACT_EST_CEN!U:U) | Q15: =CONCATENATE("SUMIF(",L15,"!B:B,ReliquidacionEFACT!B",A15,",",L15,"!V:V)") -> SUMIF(FACT_EST_CEN!B:B,ReliquidacionEFACT!B15,FACT_EST_CEN!V:V) | R15: =CONCATENATE("IFERROR((Q",A15,"/P",A15,"),0)") -> IFERROR((Q15/P15),0) | S15: =CONCATENATE("(N",A15,"+Q",A15,")") -> (N15+Q15) | U15: 43525 | V15: =CONCATENATE("(S",A15,"-J",A15,")") -> (S15-J15) | W15: PNP_6T_08-05-2020 | X15: 44137 | Y15: 0.0361 | Z15: 43580 | AA15: =AA14 -> 44377 | AB15: =CONCATENATE("(AA",A15,"-Z",A15,")") -> (AA15-Z15) | AC15: =CONCATENATE("(1+Y",A15,")^(AB",A15,"/360)-1") -> (1+Y15)^(AB15/360)-1 | AD15: =CONCATENATE("(AC",A15,"*V",A15,")") -> (AC15*V15) | AE15: =CONCATENATE("(V",A15,"+AD",A15,")") -> (V15+AD15)
A16: =A15+1 -> 16 | B16: 43556 | C16: FACT_EMITIDA | D16: =CONCATENATE("SUMIF(",IF(C16="FACT_EMITIDA","SIGGE_E",C16),"!B:B,ReliquidacionEFACT!B",A16,",",IF(C16="FACT_EMITIDA","SIGGE_E",C16),"!S:S)") -> SUMIF(SIGGE_E!B:B,ReliquidacionEFACT!B16,SIGGE_E!S:S) | E16: =CONCATENATE("SUMIF(",IF(C16="FACT_EMITIDA","SIGGE_E",C16),"!B:B,ReliquidacionEFACT!B",A16,",",IF(C16="FACT_EMITIDA","SIGGE_E",C16),"!T:T)") -> SUMIF(SIGGE_E!B:B,ReliquidacionEFACT!B16,SIGGE_E!T:T) | F16: =CONCATENATE("IFERROR((E",A16,"/D",A16,"),0)") -> IFERROR((E16/D16),0) | G16: =CONCATENATE("SUMIF(",IF(C16="FACT_EMITIDA","SIGGE_P",C16),"!B:B,ReliquidacionEFACT!B",A16,",",IF(C16="FACT_EMITIDA","SIGGE_P",C16),"!U:U)") -> SUMIF(SIGGE_P!B:B,ReliquidacionEFACT!B16,SIGGE_P!U:U) | H16: =CONCATENATE("SUMIF(",IF(C16="FACT_EMITIDA","SIGGE_P",C16),"!B:B,ReliquidacionEFACT!B",A16,",",IF(C16="FACT_EMITIDA","SIGGE_P",C16),"!V:V)") -> SUMIF(SIGGE_P!B:B,ReliquidacionEFACT!B16,SIGGE_P!V:V) | I16: =CONCATENATE("IFERROR((H",A16,"/G",A16,"),0)") -> IFERROR((H16/G16),0) | J16: =CONCATENATE("(E",A16,"+H",A16,")") -> (E16+H16) | L16: FACT_EST_CEN | M16: =CONCATENATE("SUMIF(",L16,"!B:B,ReliquidacionEFACT!B",A16,",",L16,"!S:S)") -> SUMIF(FACT_EST_CEN!B:B,ReliquidacionEFACT!B16,FACT_EST_CEN!S:S) | N16: =CONCATENATE("SUMIF(",L16,"!B:B,ReliquidacionEFACT!B",A16,",",L16,"!T:T)") -> SUMIF(FACT_EST_CEN!B:B,ReliquidacionEFACT!B16,FACT_EST_CEN!T:T) | O16: =CONCATENATE("IFERROR((N",A16,"/M",A16,"),0)") -> IFERROR((N16/M16),0) | P16: =CONCATENATE("SUMIF(",L16,"!B:B,ReliquidacionEFACT!B",A16,",",L16,"!U:U)") -> SUMIF(FACT_EST_CEN!B:B,ReliquidacionEFACT!B16,FACT_EST_CEN!U:U) | Q16: =CONCATENATE("SUMIF(",L16,"!B:B,ReliquidacionEFACT!B",A16,",",L16,"!V:V)") -> SUMIF(FACT_EST_CEN!B:B,ReliquidacionEFACT!B16,FACT_EST_CEN!V:V) | R16: =CONCATENATE("IFERROR((Q",A16,"/P",A16,"),0)") -> IFERROR((Q16/P16),0) | S16: =CONCATENATE("(N",A16,"+Q",A16,")") -> (N16+Q16) | U16: 43556 | V16: =CONCATENATE("(S",A16,"-J",A16,")") -> (S16-J16) | W16: PNP_6T_08-05-2020 | X16: 44137 | Y16: 0.0361 | Z16: 43610 | AA16: =AA15 -> 44377 | AB16: =CONCATENATE("(AA",A16,"-Z",A16,")") -> (AA16-Z16) | AC16: =CONCATENATE("(1+Y",A16,")^(AB",A16,"/360)-1") -> (1+Y16)^(AB16/360)-1 | AD16: =CONCATENATE("(AC",A16,"*V",A16,")") -> (AC16*V16) | AE16: =CONCATENATE("(V",A16,"+AD",A16,")") -> (V16+AD16)
A17: =A16+1 -> 17 | B17: 43586 | C17: FACT_EMITIDA | D17: =CONCATENATE("SUMIF(",IF(C17="FACT_EMITIDA","SIGGE_E",C17),"!B:B,ReliquidacionEFACT!B",A17,",",IF(C17="FACT_EMITIDA","SIGGE_E",C17),"!S:S)") -> SUMIF(SIGGE_E!B:B,ReliquidacionEFACT!B17,SIGGE_E!S:S) | E17: =CONCATENATE("SUMIF(",IF(C17="FACT_EMITIDA","SIGGE_E",C17),"!B:B,ReliquidacionEFACT!B",A17,",",IF(C17="FACT_EMITIDA","SIGGE_E",C17),"!T:T)") -> SUMIF(SIGGE_E!B:B,ReliquidacionEFACT!B17,SIGGE_E!T:T) | F17: =CONCATENATE("IFERROR((E",A17,"/D",A17,"),0)") -> IFERROR((E17/D17),0) | G17: =CONCATENATE("SUMIF(",IF(C17="FACT_EMITIDA","SIGGE_P",C17),"!B:B,ReliquidacionEFACT!B",A17,",",IF(C17="FACT_EMITIDA","SIGGE_P",C17),"!U:U)") -> SUMIF(SIGGE_P!B:B,ReliquidacionEFACT!B17,SIGGE_P!U:U) | H17: =CONCATENATE("SUMIF(",IF(C17="FACT_EMITIDA","SIGGE_P",C17),"!B:B,ReliquidacionEFACT!B",A17,",",IF(C17="FACT_EMITIDA","SIGGE_P",C17),"!V:V)") -> SUMIF(SIGGE_P!B:B,ReliquidacionEFACT!B17,SIGGE_P!V:V) | I17: =CONCATENATE("IFERROR((H",A17,"/G",A17,"),0)") -> IFERROR((H17/G17),0) | J17: =CONCATENATE("(E",A17,"+H",A17,")") -> (E17+H17) | L17: FACT_EST_CEN | M17: =CONCATENATE("SUMIF(",L17,"!B:B,ReliquidacionEFACT!B",A17,",",L17,"!S:S)") -> SUMIF(FACT_EST_CEN!B:B,ReliquidacionEFACT!B17,FACT_EST_CEN!S:S) | N17: =CONCATENATE("SUMIF(",L17,"!B:B,ReliquidacionEFACT!B",A17,",",L17,"!T:T)") -> SUMIF(FACT_EST_CEN!B:B,ReliquidacionEFACT!B17,FACT_EST_CEN!T:T) | O17: =CONCATENATE("IFERROR((N",A17,"/M",A17,"),0)") -> IFERROR((N17/M17),0) | P17: =CONCATENATE("SUMIF(",L17,"!B:B,ReliquidacionEFACT!B",A17,",",L17,"!U:U)") -> SUMIF(FACT_EST_CEN!B:B,ReliquidacionEFACT!B17,FACT_EST_CEN!U:U) | Q17: =CONCATENATE("SUMIF(",L17,"!B:B,ReliquidacionEFACT!B",A17,",",L17,"!V:V)") -> SUMIF(FACT_EST_CEN!B:B,ReliquidacionEFACT!B17,FACT_EST_CEN!V:V) | R17: =CONCATENATE("IFERROR((Q",A17,"/P",A17,"),0)") -> IFERROR((Q17/P17),0) | S17: =CONCATENATE("(N",A17,"+Q",A17,")") -> (N17+Q17) | U17: 43586 | V17: =CONCATENATE("(S",A17,"-J",A17,")") -> (S17-J17) | W17: PNP_6T_08-05-2020 | X17: 44137 | Y17: 0.0361 | Z17: 43641 | AA17: =AA16 -> 44377 | AB17: =CONCATENATE("(AA",A17,"-Z",A17,")") -> (AA17-Z17) | AC17: =CONCATENATE("(1+Y",A17,")^(AB",A17,"/360)-1") -> (1+Y17)^(AB17/360)-1 | AD17: =CONCATENATE("(AC",A17,"*V",A17,")") -> (AC17*V17) | AE17: =CONCATENATE("(V",A17,"+AD",A17,")") -> (V17+AD17)
A18: =A17+1 -> 18 | B18: 43617 | C18: FACT_EMITIDA | D18: =CONCATENATE("SUMIF(",IF(C18="FACT_EMITIDA","SIGGE_E",C18),"!B:B,ReliquidacionEFACT!B",A18,",",IF(C18="FACT_EMITIDA","SIGGE_E",C18),"!S:S)") -> SUMIF(SIGGE_E!B:B,ReliquidacionEFACT!B18,SIGGE_E!S:S) | E18: =CONCATENATE("SUMIF(",IF(C18="FACT_EMITIDA","SIGGE_E",C18),"!B:B,ReliquidacionEFACT!B",A18,",",IF(C18="FACT_EMITIDA","SIGGE_E",C18),"!T:T)") -> SUMIF(SIGGE_E!B:B,ReliquidacionEFACT!B18,SIGGE_E!T:T) | F18: =CONCATENATE("IFERROR((E",A18,"/D",A18,"),0)") -> IFERROR((E18/D18),0) | G18: =CONCATENATE("SUMIF(",IF(C18="FACT_EMITIDA","SIGGE_P",C18),"!B:B,ReliquidacionEFACT!B",A18,",",IF(C18="FACT_EMITIDA","SIGGE_P",C18),"!U:U)") -> SUMIF(SIGGE_P!B:B,ReliquidacionEFACT!B18,SIGGE_P!U:U) | H18: =CONCATENATE("SUMIF(",IF(C18="FACT_EMITIDA","SIGGE_P",C18),"!B:B,ReliquidacionEFACT!B",A18,",",IF(C18="FACT_EMITIDA","SIGGE_P",C18),"!V:V)") -> SUMIF(SIGGE_P!B:B,ReliquidacionEFACT!B18,SIGGE_P!V:V) | I18: =CONCATENATE("IFERROR((H",A18,"/G",A18,"),0)") -> IFERROR((H18/G18),0) | J18: =CONCATENATE("(E",A18,"+H",A18,")") -> (E18+H18) | L18: FACT_EST_CEN | M18: =CONCATENATE("SUMIF(",L18,"!B:B,ReliquidacionEFACT!B",A18,",",L18,"!S:S)") -> SUMIF(FACT_EST_CEN!B:B,ReliquidacionEFACT!B18,FACT_EST_CEN!S:S) | N18: =CONCATENATE("SUMIF(",L18,"!B:B,ReliquidacionEFACT!B",A18,",",L18,"!T:T)") -> SUMIF(FACT_EST_CEN!B:B,ReliquidacionEFACT!B18,FACT_EST_CEN!T:T) | O18: =CONCATENATE("IFERROR((N",A18,"/M",A18,"),0)") -> IFERROR((N18/M18),0) | P18: =CONCATENATE("SUMIF(",L18,"!B:B,ReliquidacionEFACT!B",A18,",",L18,"!U:U)") -> SUMIF(FACT_EST_CEN!B:B,ReliquidacionEFACT!B18,FACT_EST_CEN!U:U) | Q18: =CONCATENATE("SUMIF(",L18,"!B:B,ReliquidacionEFACT!B",A18,",",L18,"!V:V)") -> SUMIF(FACT_EST_CEN!B:B,ReliquidacionEFACT!B18,FACT_EST_CEN!V:V) | R18: =CONCATENATE("IFERROR((Q",A18,"/P",A18,"),0)") -> IFERROR((Q18/P18),0) | S18: =CONCATENATE("(N",A18,"+Q",A18,")") -> (N18+Q18) | U18: 43617 | V18: =CONCATENATE("(S",A18,"-J",A18,")") -> (S18-J18) | W18: PNP_6T_08-05-2020 | X18: 44137 | Y18: 0.0361 | Z18: 43671 | AA18: =AA17 -> 44377 | AB18: =CONCATENATE("(AA",A18,"-Z",A18,")") -> (AA18-Z18) | AC18: =CONCATENATE("(1+Y",A18,")^(AB",A18,"/360)-1") -> (1+Y18)^(AB18/360)-1 | AD18: =CONCATENATE("(AC",A18,"*V",A18,")") -> (AC18*V18) | AE18: =CONCATENATE("(V",A18,"+AD",A18,")") -> (V18+AD18)
