Workbook

Sheet README
A1: Hoja | B1: Descripción
A2: EFACT_CNE | B2: Información de facturación definitiva proveniente de los archivos EFACT publicados por la CNE en los Decretos de Precio de Nudo
A3: FACT_EMITIDA | B3: Información de facturación real desde PDFs y sistema SIGGE (gestión facturación electrónica)

Sheet MAPA_DATA
A1: Num | B1: Anho | C1: Mes | D1: Fecha | E1: FACT_EMITIDA | F1: FACT_EST_EFACT | G1: FACT_EST_CEN | H1: EFACT_CNE | I1: EFACT_EST_CEN | J1: OrigenData1 | K1: OrigenData2
A2: 1 | B2: 2016 | C2: 1 | D2: 01-01-2016 | E2: 0 | F2: 1 | G2: 0 | H2: 1 | I2: 0 | J2: FACT_EST_EFACT | K2: EFACT_CNE
A3: 2 | B3: 2016 | C3: 2 | D3: 01-02-2016 | E3: 0 | F3: 1 | G3: 0 | H3: 1 | I3: 0 | J3: FACT_EST_EFACT | K3: EFACT_CNE
A4: 3 | B4: 2016 | C4: 3 | D4: 01-03-2016 | E4: 0 | F4: 1 | G4: 0 | H4: 1 | I4: 0 | J4: FACT_EST_EFACT | K4: EFACT_CNE
A5: 4 | B5: 2016 | C5: 4 | D5: 01-04-2016 | E5: 0 | F5: 1 | G5: 0 | H5: 1 | I5: 0 | J5: FACT_EST_EFACT | K5: EFACT_CNE
A6: 5 | B6: 2016 | C6: 5 | D6: 01-05-2016 | E6: 0 | F6: 1 | G6: 0 | H6: 1 | I6: 0 | J6: FACT_EST_EFACT | K6: EFACT_CNE
A7: 6 | B7: 2016 | C7: 6 | D7: 01-06-2016 | E7: 0 | F7: 1 | G7: 0 | H7: 1 | I7: 0 | J7: FACT_EST_EFACT | K7: EFACT_CNE
A8: 7 | B8: 2016 | C8: 7 | D8: 01-07-2016 | E8: 0 | F8: 1 | G8: 0 | H8: 1 | I8: 0 | J8: FACT_EST_EFACT | K8: EFACT_CNE
A9: 8 | B9: 2016 | C9: 8 | D9: 01-08-2016 | E9: 0 | F9: 1 | G9: 0 | H9: 1 | I9: 0 | J9: FACT_EST_EFACT | K9: EFACT_CNE
A10: 9 | B10: 2016 | C10: 9 | D10: 01-09-2016 | E10: 0 | F10: 1 | G10: 0 | H10: 1 | I10: 0 | J10: FACT_EST_EFACT | K10: EFACT_CNE
A11: 10 | B11: 2016 | C11: 10 | D11: 01-10-2016 | E11: 0 | F11: 1 | G11: 0 | H11: 1 | I11: 0 | J11: FACT_EST_EFACT | K11: EFACT_CNE
A12: 11 | B12: 2016 | C12: 11 | D12: 01-11-2016 | E12: 0 | F12: 1 | G12: 0 | H12: 1 | I12: 0 | J12: FACT_EST_EFACT | K12: EFACT_CNE
A13: 12 | B13: 2016 | C13: 12 | D13: 01-12-2016 | E13: 0 | F13: 1 | G13: 0 | H13: 1 | I13: 0 | J13: FACT_EST_EFACT | K13: EFACT_CNE
... A58: 57 | B58: 2020 | C58: 9 | D58: 01-09-2020 | E58: 1 | F58: 0 | G58: 0 | H58: 1 | I58: 0 | J58: FACT_EMITIDA | K58: EFACT_CNE

Sheet Reliquidacion
A2: Generador | B2: [GX]
A3: Distribuidor | B3: [EEDD]
A4: Licitacion | B4: 2013/03-2° Llamado
A5: Bloque | B5: [BLOQUE]
C7: LO QUE SE FACTURÓ | L7: LO QUE SE DEBIÓ HABER FACTURADO | U7: RELQUIDACIÓN Y CÁLCULO INTERESES
A8: ID | B8: MES | C8: ORIGEN DATA | D8: Energía (kWh) | E8: Monto Energía ($) | F8: $/kWh | G8: Potencia (kW) | H8: Monto Potencia ($) | I8: $/kW-mes | J8: Monto Total ($) | L8: ORIGEN DATA | M8: Energía (kWh) | N8: Monto Energía ($) | O8: $/kWh | P8: Potencia (kW) | Q8: Monto Potencia ($) | R8: $/kW-mes | S8: Monto Total ($) | U8: Mes | V8: Reliquidación mensual ($) | W8: Decreto PNP Reliquidación | X8: Fecha publicación Diario Oficial | Y8: Interés Anual | Z8: Fecha Facturación | AA8: Fecha Reliquidación | AB8: N° de días de intereses | AC8: Interés total según n° de días | AD8: Intereses ($) | AE8: Reliquidación Total ($)
A9: =9 -> 9 | B9: 43344 | C9: FACT_EMITIDA | D9: =CONCATENATE("SUMIF(",IF(C9="FACT_EMITIDA","SIGGE_E",C9),"!B:B,Reliquidacion!B",A9,",",IF(C9="FACT_EMITIDA","SIGGE_E",C9),"!S:S)") -> SUMIF(SIGGE_E!B:B,Reliquidacion!B9,SIGGE_E!S:S) | E9: =CONCATENATE("SUMIF(",IF(C9="FACT_EMITIDA","SIGGE_E",C9),"!B:B,Reliquidacion!B",A9,",",IF(C9="FACT_EMITIDA","SIGGE_E",C9),"!T:T)") -> SUMIF(SIGGE_E!B:B,Reliquidacion!B9,SIGGE_E!T:T) | F9: =CONCATENATE("IFERROR((E",A9,"/D",A9,"),0)") -> IFERROR((E9/D9),0) | G9: =CONCATENATE("SUMIF(",IF(C9="FACT_EMITIDA","SIGGE_P",C9),"!B:B,Reliquidacion!B",A9,",",IF(C9="FACT_EMITIDA","SIGGE_P",C9),"!U:U)") -> SUMIF(SIGGE_P!B:B,Reliquidacion!B9,SIGGE_P!U:U) | H9: =CONCATENATE("SUMIF(",IF(C9="FACT_EMITIDA","SIGGE_P",C9),"!B:B,Reliquidacion!B",A9,",",IF(C9="FACT_EMITIDA","SIGGE_P",C9),"!V:V)") -> SUMIF(SIGGE_P!B:B,Reliquidacion!B9,SIGGE_P!V:V) | I9: =CONCATENATE("IFERROR((H",A9,"/G",A9,"),0)") -> IFERROR((H9/G9),0) | J9: =CONCATENATE("(E",A9,"+H",A9,")") -> (E9+H9) | L9: =(MAPA_DATA!K34) -> EFACT_CNE | M9: =CONCATENATE("SUMIF(",L9,"!B:B,Reliquidacion!B",A9,",",L9,"!S:S)") -> SUMIF(EFACT_CNE!B:B,Reliquidacion!B9,EFACT_CNE!S:S) | N9: =CONCATENATE("SUMIF(",L9,"!B:B,Reliquidacion!B",A9,",",L9,"!T:T)") -> SUMIF(EFACT_CNE!B:B,Reliquidacion!B9,EFACT_CNE!T:T) | O9: =CONCATENATE("IFERROR((N",A9,"/M",A9,"),0)") -> IFERROR((N9/M9),0) | P9: =CONCATENATE("SUMIF(",L9,"!B:B,Reliquidacion!B",A9,",",L9,"!U:U)") -> SUMIF(EFACT_CNE!B:B,Reliquidacion!B9,EFACT_CNE!U:U) | Q9: =CONCATENATE("SUMIF(",L9,"!B:B,Reliquidacion!B",A9,",",L9,"!V:V)") -> SUMIF(EFACT_CNE!B:B,Reliquidacion!B9,EFACT_CNE!V:V) | R9: =CONCATENATE("IFERROR((Q",A9,"/P",A9,"),0)") -> IFERROR((Q9/P9),0) | S9: =CONCATENATE("(N",A9,"+Q",A9,")") -> (N9+Q9) | U9: 43344 | V9: =CONCATENATE("(S",A9,"-J",A9,")") -> (S9-J9) | W9: PNP_6T_08-05-2020 | X9: 44137 | Y9: 0.0361 | Z9: 43398 | AA9: 44377 | AB9: =CONCATENATE("(AA",A9,"-Z",A9,")") -> (AA9-Z9) | AC9: =CONCATENATE("(1+Y",A9,")^(AB",A9,"/360)-1") -> (1+Y9)^(AB9/360)-1 | AD9: =CONCATENATE("(AC",A9,"*V",A9,")") -> (AC9*V9) | AE9: =CONCATENATE("(V",A9,"+AD",A9,")") -> (V9+AD9)
A10: =A9+1 -> 10 | B10: 43374 | C10: FACT_EMITIDA | D10: =CONCATENATE("SUMIF(",IF(C10="FACT_EMITIDA","SIGGE_E",C10),"!B:B,Reliquidacion!B",A10,",",IF(C10="FACT_EMITIDA","SIGGE_E",C10),"!S:S)") -> SUMIF(SIGGE_E!B:B,Reliquidacion!B10,SIGGE_E!S:S) | E10: =CONCATENATE("SUMIF(",IF(C10="FACT_EMITIDA","SIGGE_E",C10),"!B:B,Reliquidacion!B",A10,",",IF(C10="FACT_EMITIDA","SIGGE_E",C10),"!T:T)") -> SUMIF(SIGGE_E!B:B,Reliquidacion!B10,SIGGE_E!T:T) | F10: =CONCATENATE("IFERROR((E",A10,"/D",A10,"),0)") -> IFERROR((E10/D10),0) | G10: =CONCATENATE("SUMIF(",IF(C10="FACT_EMITIDA","SIGGE_P",C10),"!B:B,Reliquidacion!B",A10,",",IF(C10="FACT_EMITIDA","SIGGE_P",C10),"!U:U)") -> SUMIF(SIGGE_P!B:B,Reliquidacion!B10,SIGGE_P!U:U) | H10: =CONCATENATE("SUMIF(",IF(C10="FACT_EMITIDA","SIGGE_P",C10),"!B:B,Reliquidacion!B",A10,",",IF(C10="FACT_EMITIDA","SIGGE_P",C10),"!V:V)") -> SUMIF(SIGGE_P!B:B,Reliquidacion!B10,SIGGE_P!V:V) | I10: =CONCATENATE("IFERROR((H",A10,"/G",A10,"),0)") -> IFERROR((H10/G10),0) | J10: =CONCATENATE("(E",A10,"+H",A10,")") -> (E10+H10) | L10: =(MAPA_DATA!K35) -> EFACT_CNE | M10: =CONCATENATE("SUMIF(",L10,"!B:B,Reliquidacion!B",A10,",",L10,"!S:S)") -> SUMIF(EFACT_CNE!B:B,Reliquidacion!B10,EFACT_CNE!S:S) | N10: =CONCATENATE("SUMIF(",L10,"!B:B,Reliquidacion!B",A10,",",L10,"!T:T)") -> SUMIF(EFACT_CNE!B:B,Reliquidacion!B10,EFACT_CNE!T:T) | O10: =CONCATENATE("IFERROR((N",A10,"/M",A10,"),0)") -> IFERROR((N10/M10),0) | P10: =CONCATENATE("SUMIF(",L10,"!B:B,Reliquidacion!B",A10,",",L10,"!U:U)") -> SUMIF(EFACT_CNE!B:B,Reliquidacion!B10,EFACT_CNE!U:U) | Q10: =CONCATENATE("SUMIF(",L10,"!B:B,Reliquidacion!B",A10,",",L10,"!V:V)") -> SUMIF(EFACT_CNE!B:B,Reliquidacion!B10,EFACT_CNE!V:V) | R10: =CONCATENATE("IFERROR((Q",A10,"/P",A10,"),0)") -> IFERROR((Q10/P10),0) | S10: =CONCATENATE("(N",A10,"+Q",A10,")") -> (N10+Q10) | U10: 43374 | V10: =CONCATENATE("(S",A10,"-J",A10,")") -> (S10-J10) | W10: PNP_6T_08-05-2020 | X10: 44137 | Y10: 0.0361 | Z10: 43429 | AA10: =AA9 -> 44377 | AB10: =CONCATENATE("(AA",A10,"-Z",A10,")") -> (AA10-Z10) | AC10: =CONCATENATE("(1+Y",A10,")^(AB",A10,"/360)-1") -> (1+Y10)^(AB10/360)-1 | AD10: =CONCATENATE("(AC",A10,"*V",A10,")") -> (AC10*V10) | AE10: =CONCATENATE("(V",A10,"+AD",A10,")") -> (V10+AD10)
A11: =A10+1 -> 11 | B11: 43405 | C11: FACT_EMITIDA | D11: =CONCATENATE("SUMIF(",IF(C11="FACT_EMITIDA","SIGGE_E",C11),"!B:B,Reliquidacion!B",A11,",",IF(C11="FACT_EMITIDA","SIGGE_E",C11),"!S:S)") -> SUMIF(SIGGE_E!B:B,Reliquidacion!B11,SIGGE_E!S:S) | E11: =CONCATENATE("SUMIF(",IF(C11="FACT_EMITIDA","SIGGE_E",C11),"!B:B,Reliquidacion!B",A11,",",IF(C11="FACT_EMITIDA","SIGGE_E",C11),"!T:T)") -> SUMIF(SIGGE_E!B:B,Reliquidacion!B11,SIGGE_E!T:T) | F11: =CONCATENATE("IFERROR((E",A11,"/D",A11,"),0)") -> IFERROR((E11/D11),0) | G11: =CONCATENATE("SUMIF(",IF(C11="FACT_EMITIDA","SIGGE_P",C11),"!B:B,Reliquidacion!B",A11,",",IF(C11="FACT_EMITIDA","SIGGE_P",C11),"!U:U)") -> SUMIF(SIGGE_P!B:B,Reliquidacion!B11,SIGGE_P!U:U) | H11: =CONCATENATE("SUMIF(",IF(C11="FACT_EMITIDA","SIGGE_P",C11),"!B:B,Reliquidacion!B",A11,",",IF(C11="FACT_EMITIDA","SIGGE_P",C11),"!V:V)") -> SUMIF(SIGGE_P!B:B,Reliquidacion!B11,SIGGE_P!V:V) | I11: =CONCATENATE("IFERROR((H",A11,"/G",A11,"),0)") -> IFERROR((H11/G11),0) | J11: =CONCATENATE("(E",A11,"+H",A11,")") -> (E11+H11) | L11: =(MAPA_DATA!K36) -> EFACT_CNE | M11: =CONCATENATE("SUMIF(",L11,"!B:B,Reliquidacion!B",A11,",",L11,"!S:S)") -> SUMIF(EFACT_CNE!B:B,Reliquidacion!B11,EFACT_CNE!S:S) | N11: =CONCATENATE("SUMIF(",L11,"!B:B,Reliquidacion!B",A11,",",L11,"!T:T)") -> SUMIF(EFACT_CNE!B:B,Reliquidacion!B11,EFACT_CNE!T:T) | O11: =CONCATENATE("IFERROR((N",A11,"/M",A11,"),0)") -> IFERROR((N11/M11),0) | P11: =CONCATENATE("SUMIF(",L11,"!B:B,Reliquidacion!B",A11,",",L11,"!U:U)") -> SUMIF(EFACT_CNE!B:B,Reliquidacion!B11,EFACT_CNE!U:U) | Q11: =CONCATENATE("SUMIF(",L11,"!B:B,Reliquidacion!B",A11,",",L11,"!V:V)") -> SUMIF(EFACT_CNE!B:B,Reliquidacion!B11,EFACT_CNE!V:V) | R11: =CONCATENATE("IFERROR((Q",A11,"/P",A11,"),0)") -> IFERROR((Q11/P11),0) | S11: =CONCATENATE("(N",A11,"+Q",A11,")") -> (N11+Q11) | U11: 43405 | V11: =CONCATENATE("(S",A11,"-J",A11,")") -> (S11-J11) | W11: PNP_6T_08-05-2020 | X11: 44137 | Y11: 0.0361 | Z11: 43459 | AA11: =AA10 -> 44377 | AB11: =CONCATENATE("(AA",A11,"-Z",A11,")") -> (AA11-Z11) | AC11: =CONCATENATE("(1+Y",A11,")^(AB",A11,"/360)-1") -> (1+Y11)^(AB11/360)-1 | AD11: =CONCATENATE("(AC",A11,"*V",A11,")") -> (AC11*V11) | AE11: =CONCATENATE("(V",A11,"+AD",A11,")") -> (V11+AD11)
A12: =A11+1 -> 12 | B12: 43435 | C12: FACT_EMITIDA | D12: =CONCATENATE("SUMIF(",IF(C12="FACT_EMITIDA","SIGGE_E",C12),"!B:B,Reliquidacion!B",A12,",",IF(C12="FACT_EMITIDA","SIGGE_E",C12),"!S:S)") -> SUMIF(SIGGE_E!B:B,Reliquidacion!B12,SIGGE_E!S:S) | E12: =CONCATENATE("SUMIF(",IF(C12="FACT_EMITIDA","SIGGE_E",C12),"!B:B,Reliquidacion!B",A12,",",IF(C12="FACT_EMITIDA","SIGGE_E",C12),"!T:T)") -> SUMIF(SIGGE_E!B:B,Reliquidacion!B12,SIGGE_E!T:T) | F12: =CONCATENATE("IFERROR((E",A12,"/D",A12,"),0)") -> IFERROR((E12/D12),0) | G12: =CONCATENATE("SUMIF(",IF(C12="FACT_EMITIDA","SIGGE_P",C12),"!B:B,Reliquidacion!B",A12,",",IF(C12="FACT_EMITIDA","SIGGE_P",C12),"!U:U)") -> SUMIF(SIGGE_P!B:B,Reliquidacion!B12,SIGGE_P!U:U) | H12: =CONCATENATE("SUMIF(",IF(C12="FACT_EMITIDA","SIGGE_P",C12),"!B:B,Reliquidacion!B",A12,",",IF(C12="FACT_EMITIDA","SIGGE_P",C12),"!V:V)") -> SUMIF(SIGGE_P!B:B,Reliquidacion!B12,SIGGE_P!V:V) | I12: =CONCATENATE("IFERROR((H",A12,"/G",A12,"),0)") -> IFERROR((H12/G12),0) | J12: =CONCATENATE("(E",A12,"+H",A12,")") -> (E12+H12) | L12: =(MAPA_DATA!K37) -> EFACT_CNE | M12: =CONCATENATE("SUMIF(",L12,"!B:B,Reliquidacion!B",A12,",",L12,"!S:S)") -> SUMIF(EFACT_CNE!B:B,Reliquidacion!B12,EFACT_CNE!S:S) | N12: =CONCATENATE("SUMIF(",L12,"!B:B,Reliquidacion!B",A12,",",L12,"!T:T)") -> SUMIF(EFACT_CNE!B:B,Reliquidacion!B12,EFACT_CNE!T:T) | O12: =CONCATENATE("IFERROR((N",A12,"/M",A12,"),0)") -> IFERROR((N12/M12),0) | P12: =CONCATENATE("SUMIF(",L12,"!B:B,Reliquidacion!B",A12,",",L12,"!U:U)") -> SUMIF(EFACT_CNE!B:B,Reliquidacion!B12,EFACT_CNE!U:U) | Q12: =CONCATENATE("SUMIF(",L12,"!B:B,Reliquidacion!B",A12,",",L12,"!V:V)") -> SUMIF(EFACT_CNE!B:B,Reliquidacion!B12,EFACT_CNE!V:V) | R12: =CONCATENATE("IFERROR((Q",A12,"/P",A12,"),0)") -> IFERROR((Q12/P12),0) | S12: =CONCATENATE("(N",A12,"+Q",A12,")") -> (N12+Q12) | U12: 43435 | V12: =CONCATENATE("(S",A12,"-J",A12,")") -> (S12-J12) | W12: PNP_6T_08-05-2020 | X12: 44137 | Y12: 0.0361 | Z12: 43490 | AA12: =AA11 -> 44377 | AB12: =CONCATENATE("(AA",A12,"-Z",A12,")") -> (AA12-Z12) | AC12: =CONCATENATE("(1+Y",A12,")^(AB",A12,"/360)-1") -> (1+Y12)^(AB12/360)-1 | AD12: =CONCATENATE("(AC",A12,"*V",A12,")") -> (AC12*V12) | AE12: =CONCATENATE("(V",A12,"+AD",A12,")") -> (V12+AD12)
A13: =A12+1 -> 13 | B13: 43466 | C13: FACT_EMITIDA | D13: =CONCATENATE("SUMIF(",IF(C13="FACT_EMITIDA","SIGGE_E",C13),"!B:B,Reliquidacion!B",A13,",",IF(C13="FACT_EMITIDA","SIGGE_E",C13),"!S:S)") -> SUMIF(SIGGE_E!B:B,Reliquidacion!B13,SIGGE_E!S:S) | E13: =CONCATENATE("SUMIF(",IF(C13="FACT_EMITIDA","SIGGE_E",C13),"!B:B,Reliquidacion!B",A13,",",IF(C13="FACT_EMITIDA","SIGGE_E",C13),"!T:T)") -> SUMIF(SIGGE_E!B:B,Reliquidacion!B13,SIGGE_E!T:T) | F13: =CONCATENATE("IFERROR((E",A13,"/D",A13,"),0)") -> IFERROR((E13/D13),0) | G13: =CONCATENATE("SUMIF(",IF(C13="FACT_EMITIDA","SIGGE_P",C13),"!B:B,Reliquidacion!B",A13,",",IF(C13="FACT_EMITIDA","SIGGE_P",C13),"!U:U)") -> SUMIF(SIGGE_P!B:B,Reliquidacion!B13,SIGGE_P!U:U) | H13: =CONCATENATE("SUMIF(",IF(C13="FACT_EMITIDA","SIGGE_P",C13),"!B:B,Reliquidacion!B",A13,",",IF(C13="FACT_EMITIDA","SIGGE_P",C13),"!V:V)") -> SUMIF(SIGGE_P!B:B,Reliquidacion!B13,SIGGE_P!V:V) | I13: =CONCATENATE("IFERROR((H",A13,"/G",A13,"),0)") -> IFERROR((H13/G13),0) | J13: =CONCATENATE("(E",A13,"+H",A13,")") -> (E13+H13) | L13: =(MAPA_DATA!K38) -> EFACT_CNE | M13: =CONCATENATE("SUMIF(",L13,"!B:B,Reliquidacion!B",A13,",",L13,"!S:S)") -> SUMIF(EFACT_CNE!B:B,Reliquidacion!B13,EFACT_CNE!S:S) | N13: =CONCATENATE("SUMIF(",L13,"!B:B,Reliquidacion!B",A13,",",L13,"!T:T)") -> SUMIF(EFACT_CNE!B:B,Reliquidacion!B13,EFACT_CNE!T:T) | O13: =CONCATENATE("IFERROR((N",A13,"/M",A13,"),0)") -> IFERROR((N13/M13),0) | P13: =CONCATENATE("SUMIF(",L13,"!B:B,Reliquidacion!B",A13,",",L13,"!U:U)") -> SUMIF(EFACT_CNE!B:B,Reliquidacion!B13,EFACT_CNE!U:U) | Q13: =CONCATENATE("SUMIF(",L13,"!B:B,Reliquidacion!B",A13,",",L13,"!V:V)") -> SUMIF(EFACT_CNE!B:B,Reliquidacion!B13,EFACT_CNE!V:V) | R13: =CONCATENATE("IFERROR((Q",A13,"/P",A13,"),0)") -> IFERROR((Q13/P13),0) | S13: =CONCATENATE("(N",A13,"+Q",A13,")") -> (N13+Q13) | U13: 43466 | V13: =CONCATENATE("(S",A13,"-J",A13,")") -> (S13-J13) | W13: PNP_6T_08-05-2020 | X13: 44137 | Y13: 0.0361 | Z13: 43521 | AA13: =AA12 -> 44377 | AB13: =CONCATENATE("(AA",A13,"-Z",A13,")") -> (AA13-Z13) | AC13: =CONCATENATE("(1+Y",A13,")^(AB",A13,"/360)-1") -> (1+Y13)^(AB13/360)-1 | AD13: =CONCATENATE("(AC",A13,"*V",A13,")") -> (AC13*V13) | AE13: =CONCATENATE("(V",A13,"+AD",A13,")") -> (V13+AD13)
A14: =A13+1 -> 14 | B14: 43497 | C14: FACT_EMITIDA | D14: =CONCATENATE("SUMIF(",IF(C14="FACT_EMITIDA","SIGGE_E",C14),"!B:B,Reliquidacion!B",A14,",",IF(C14="FACT_EMITIDA","SIGGE_E",C14),"!S:S)") -> SUMIF(SIGGE_E!B:B,Reliquidacion!B14,SIGGE_E!S:S) | E14: =CONCATENATE("SUMIF(",IF(C14="FACT_EMITIDA","SIGGE_E",C14),"!B:B,Reliquidacion!B",A14,",",IF(C14="FACT_EMITIDA","SIGGE_E",C14),"!T:T)") -> SUMIF(SIGGE_E!B:B,Reliquidacion!B14,SIGGE_E!T:T) | F14: =CONCATENATE("IFERROR((E",A14,"/D",A14,"),0)") -> IFERROR((E14/D14),0) | G14: =CONCATENATE("SUMIF(",IF(C14="FACT_EMITIDA","SIGGE_P",C14),"!B:B,Reliquidacion!B",A14,",",IF(C14="FACT_EMITIDA","SIGGE_P",C14),"!U:U)") -> SUMIF(SIGGE_P!B:B,Reliquidacion!B14,SIGGE_P!U:U) | H14: =CONCATENATE("SUMIF(",IF(C14="FACT_EMITIDA","SIGGE_P",C14),"!B:B,Reliquidacion!B",A14,",",IF(C14="FACT_EMITIDA","SIGGE_P",C14),"!V:V)") -> SUMIF(SIGGE_P!B:B,Reliquidacion!B14,SIGGE_P!V:V) | I14: =CONCATENATE("IFERROR((H",A14,"/G",A14,"),0)") -> IFERROR((H14/G14),0) | J14: =CONCATENATE("(E",A14,"+H",A14,")") -> (E14+H14) | L14: =(MAPA_DATA!K39) -> EFACT_CNE | M14: =CONCATENATE("SUMIF(",L14,"!B:B,Reliquidacion!B",A14,",",L14,"!S:S)") -> SUMIF(EFACT_CNE!B:B,Reliquidacion!B14,EFACT_CNE!S:S) | N14: =CONCATENATE("SUMIF(",L14,"!B:B,Reliquidacion!B",A14,",",L14,"!T:T)") -> SUMIF(EFACT_CNE!B:B,Reliquidacion!B14,EFACT_CNE!T:T) | O14: =CONCATENATE("IFERROR((N",A14,"/M",A14,"),0)") -> IFERROR((N14/M14),0) | P14: =CONCATENATE("SUMIF(",L14,"!B:B,Reliquidacion!B",A14,",",L14,"!U:U)") -> SUMIF(EFACT_CNE!B:B,Reliquidacion!B14,EFACT_CNE!U:U) | Q14: =CONCATENATE("SUMIF(",L14,"!B:B,Reliquidacion!B",A14,",",L14,"!V:V)") -> SUMIF(EFACT_CNE!B:B,Reliquidacion!B14,EFACT_CNE!V:V) | R14: =CONCATENATE("IFERROR((Q",A14,"/P",A14,"),0)") -> IFERROR((Q14/P14),0) | S14: =CONCATENATE("(N",A14,"+Q",A14,")") -> (N14+Q14) | U14: 43497 | V14: =CONCATENATE("(S",A14,"-J",A14,")") -> (S14-J14) | W14: PNP_6T_08-05-2020 | X14: 44137 | Y14: 0.0361 | Z14: 43549 | AA14: =AA13 -> 44377 | AB14: =CONCATENATE("(AA",A14,"-Z",A14,")") -> (AA14-Z14) | AC14: =CONCATENATE("(1+Y",A14,")^(AB",A14,"/360)-1") -> (1+Y14)^(AB14/360)-1 | AD14: =CONCATENATE("(AC",A14,"*V",A14,")") -> (AC14*V14) | AE14: =CONCATENATE("(V",A14,"+AD",A14,")") -> (V14+AD14)
A15: =A14+1 -> 15 | B15: 43525 | C15: FACT_EMITIDA | D15: =CONCATENATE("SUMIF(",IF(C15="FACT_EMITIDA","SIGGE_E",C15),"!B:B,Reliquidacion!B",A15,",",IF(C15="FACT_EMITIDA","SIGGE_E",C15),"!S:S)") -> SUMIF(SIGGE_E!B:B,Reliquidacion!B15,SIGGE_E!S:S) | E15: =CONCATENATE("SUMIF(",IF(C15="FACT_EMITIDA","SIGGE_E",C15),"!B:B,Reliquidacion!B",A15,",",IF(C15="FACT_EMITIDA","SIGGE_E",C15),"!T:T)") -> SUMIF(SIGGE_E!B:B,Reliquidacion!B15,SIGGE_E!T:T) | F15: =CONCATENATE("IFERROR((E",A15,"/D",A15,"),0)") -> IFERROR((E15/D15),0) | G15: =CONCATENATE("SUMIF(",IF(C15="FACT_EMITIDA","SIGGE_P",C15),"!B:B,Reliquidacion!B",A15,",",IF(C15="FACT_EMITIDA","SIGGE_P",C15),"!U:U)") -> SUMIF(SIGGE_P!B:B,Reliquidacion!B15,SIGGE_P!U:U) | H15: =CONCATENATE("SUMIF(",IF(C15="FACT_EMITIDA","SIGGE_P",C15),"!B:B,Reliquidacion!B",A15,",",IF(C15="FACT_EMITIDA","SIGGE_P",C15),"!V:V)") -> SUMIF(SIGGE_P!B:B,Reliquidacion!B15,SIGGE_P!V:V) | I15: =CONCATENATE("IFERROR((H",A15,"/G",A15,"),0)") -> IFERROR((H15/G15),0) | J15: =CONCATENATE("(E",A15,"+H",A15,")") -> (E15+H15) | L15: =(MAPA_DATA!K40) -> EFACT_CNE | M15: =CONCATENATE("SUMIF(",L15,"!B:B,Reliquidacion!B",A15,",",L15,"!S:S)") -> SUMIF(EFACT_CNE!B:B,Reliquidacion!B15,EFACT_CNE!S:S) | N15: =CONCATENATE("SUMIF(",L15,"!B:B,Reliquidacion!B",A15,",",L15,"!T:T)") -> SUMIF(EFACT_CNE!B:B,Reliquidacion!B15,EFACT_CNE!T:T) | O15: =CONCATENATE("IFERROR((N",A15,"/M",A15,"),0)") -> IFERROR((N15/M15),0) | P15: =CONCATENATE("SUMIF(",L15,"!B:B,Reliquidacion!B",A15,",",L15,"!U:U)") -> SUMIF(EFACT_CNE!B:B,Reliquidacion!B15,EFACT_CNE!U:U) | Q15: =CONCATENATE("SUMIF(",L15,"!B:B,Reliquidacion!B",A15,",",L15,"!V:V)") -> SUMIF(EFACT_CNE!B:B,Reliquidacion!B15,EFACT_CNE!V:V) | R15: =CONCATENATE("IFERROR((Q",A15,"/P",A15,"),0)") -> IFERROR((Q15/P15),0) | S15: =CONCATENATE("(N",A15,"+Q",A15,")") -> (N15+Q15) | U15: 43525 | V15: =CONCATENATE("(S",A15,"-J",A15,")") -> (S15-J15) | W15: PNP_6T_08-05-2020 | X15: 44137 | Y15: 0.0361 | Z15: 43580 | AA15: =AA14 -> 44377 | AB15: =CONCATENATE("(AA",A15,"-Z",A15,")") -> (AA15-Z15) | AC15: =CONCATENATE("(1+Y",A15,")^(AB",A15,"/360)-1") -> (1+Y15)^(AB15/360)-1 | AD15: =CONCATENATE("(AC",A15,"*V",A15,")") -> (AC15*V15) | AE15: =CONCATENATE("(V",A15,"+AD",A15,")") -> (V15+AD15)
A16: =A15+1 -> 16 | B16: 43556 | C16: FACT_EMITIDA | D16: =CONCATENATE("SUMIF(",IF(C16="FACT_EMITIDA","SIGGE_E",C16),"!B:B,Reliquidacion!B",A16,",",IF(C16="FACT_EMITIDA","SIGGE_E",C16),"!S:S)") -> SUMIF(SIGGE_E!B:B,Reliquidacion!B16,SIGGE_E!S:S) | E16: =CONCATENATE("SUMIF(",IF(C16="FACT_EMITIDA","SIGGE_E",C16),"!B:B,Reliquidacion!B",A16,",",IF(C16="FACT_EMITIDA","SIGGE_E",C16),"!T:T)") -> SUMIF(SIGGE_E!B:B,Reliquidacion!B16,SIGGE_E!T:T) | F16: =CONCATENATE("IFERROR((E",A16,"/D",A16,"),0)") -> IFERROR((E16/D16),0) | G16: =CONCATENATE("SUMIF(",IF(C16="FACT_EMITIDA","SIGGE_P",C16),"!B:B,Reliquidacion!B",A16,",",IF(C16="FACT_EMITIDA","SIGGE_P",C16),"!U:U)") -> SUMIF(SIGGE_P!B:B,Reliquidacion!B16,SIGGE_P!U:U) | H16: =CONCATENATE("SUMIF(",IF(C16="FACT_EMITIDA","SIGGE_P",C16),"!B:B,Reliquidacion!B",A16,",",IF(C16="FACT_EMITIDA","SIGGE_P",C16),"!V:V)") -> SUMIF(SIGGE_P!B:B,Reliquidacion!B16,SIGGE_P!V:V) | I16: =CONCATENATE("IFERROR((H",A16,"/G",A16,"),0)") -> IFERROR((H16/G16),0) | J16: =CONCATENATE("(E",A16,"+H",A16,")") -> (E16+H16) | L16: =(MAPA_DATA!K41) -> EFACT_CNE | M16: =CONCATENATE("SUMIF(",L16,"!B:B,Reliquidacion!B",A16,",",L16,"!S:S)") -> SUMIF(EFACT_CNE!B:B,Reliquidacion!B16,EFACT_CNE!S:S) | N16: =CONCATENATE("SUMIF(",L16,"!B:B,Reliquidacion!B",A16,",",L16,"!T:T)") -> SUMIF(EFACT_CNE!B:B,Reliquidacion!B16,EFACT_CNE!T:T) | O16: =CONCATENATE("IFERROR((N",A16,"/M",A16,"),0)") -> IFERROR((N16/M16),0) | P16: =CONCATENATE("SUMIF(",L16,"!B:B,Reliquidacion!B",A16,",",L16,"!U:U)") -> SUMIF(EFACT_CNE!B:B,Reliquidacion!B16,EFACT_CNE!U:U) | Q16: =CONCATENATE("SUMIF(",L16,"!B:B,Reliquidacion!B",A16,",",L16,"!V:V)") -> SUMIF(EFACT_CNE!B:B,Reliquidacion!B16,EFACT_CNE!V:V) | R16: =CONCATENATE("IFERROR((Q",A16,"/P",A16,"),0)") -> IFERROR((Q16/P16),0) | S16: =CONCATENATE("(N",A16,"+Q",A16,")") -> (N16+Q16) | U16: 43556 | V16: =CONCATENATE("(S",A16,"-J",A16,")") -> (S16-J16) | W16: PNP_6T_08-05-2020 | X16: 44137 | Y16: 0.0361 | Z16: 43610 | AA16: =AA15 -> 44377 | AB16: =CONCATENATE("(AA",A16,"-Z",A16,")") -> (AA16-Z16) | AC16: =CONCATENATE("(1+Y",A16,")^(AB",A16,"/360)-1") -> (1+Y16)^(AB16/360)-1 | AD16: =CONCATENATE("(AC",A16,"*V",A16,")") -> (AC16*V16) | AE16: =CONCATENATE("(V",A16,"+AD",A16,")") -> (V16+AD16)
A17: =A16+1 -> 17 | B17: 43586 | C17: FACT_EMITIDA | D17: =CONCATENATE("SUMIF(",IF(C17="FACT_EMITIDA","SIGGE_E",C17),"!B:B,Reliquidacion!B",A17,",",IF(C17="FACT_EMITIDA","SIGGE_E",C17),"!S:S)") -> SUMIF(SIGGE_E!B:B,Reliquidacion!B17,SIGGE_E!S:S) | E17: =CONCATENATE("SUMIF(",IF(C17="FACT_EMITIDA","SIGGE_E",C17),"!B:B,Reliquidacion!B",A17,",",IF(C17="FACT_EMITIDA","SIGGE_E",C17),"!T:T)") -> SUMIF(SIGGE_E!B:B,Reliquidacion!B17,SIGGE_E!T:T) | F17: =CONCATENATE("IFERROR((E",A17,"/D",A17,"),0)") -> IFERROR((E17/D17),0) | G17: =CONCATENATE("SUMIF(",IF(C17="FACT_EMITIDA","SIGGE_P",C17),"!B:B,Reliquidacion!B",A17,",",IF(C17="FACT_EMITIDA","SIGGE_P",C17),"!U:U)") -> SUMIF(SIGGE_P!B:B,Reliquidacion!B17,SIGGE_P!U:U) | H17: =CONCATENATE("SUMIF(",IF(C17="FACT_EMITIDA","SIGGE_P",C17),"!B:B,Reliquidacion!B",A17,",",IF(C17="FACT_EMITIDA","SIGGE_P",C17),"!V:V)") -> SUMIF(SIGGE_P!B:B,Reliquidacion!B17,SIGGE_P!V:V) | I17: =CONCATENATE("IFERROR((H",A17,"/G",A17,"),0)") -> IFERROR((H17/G17),0) | J17: =CONCATENATE("(E",A17,"+H",A17,")") -> (E17+H17) | L17: =(MAPA_DATA!K42) -> EFACT_CNE | M17: =CONCATENATE("SUMIF(",L17,"!B:B,Reliquidacion!B",A17,",",L17,"!S:S)") -> SUMIF(EFACT_CNE!B:B,Reliquidacion!B17,EFACT_CNE!S:S) | N17: =CONCATENATE("SUMIF(",L17,"!B:B,Reliquidacion!B",A17,",",L17,"!T:T)") -> SUMIF(EFACT_CNE!B:B,Reliquidacion!B17,EFACT_CNE!T:T) | O17: =CONCATENATE("IFERROR((N",A17,"/M",A17,"),0)") -> IFERROR((N17/M17),0) | P17: =CONCATENATE("SUMIF(",L17,"!B:B,Reliquidacion!B",A17,",",L17,"!U:U)") -> SUMIF(EFACT_CNE!B:B,Reliquidacion!B17,EFACT_CNE!U:U) | Q17: =CONCATENATE("SUMIF(",L17,"!B:B,Reliquidacion!B",A17,",",L17,"!V:V)") -> SUMIF(EFACT_CNE!B:B,Reliquidacion!B17,EFACT_CNE!V:V) | R17: =CONCATENATE("IFERROR((Q",A17,"/P",A17,"),0)") -> IFERROR((Q17/P17),0) | S17: =CONCATENATE("(N",A17,"+Q",A17,")") -> (N17+Q17) | U17: 43586 | V17: =CONCATENATE("(S",A17,"-J",A17,")") -> (S17-J17) | W17: PNP_6T_08-05-2020 | X17: 44137 | Y17: 0.0361 | Z17: 43641 | AA17: =AA16 -> 44377 | AB17: =CONCATENATE("(AA",A17,"-Z",A17,")") -> (AA17-Z17) | AC17: =CONCATENATE("(1+Y",A17,")^(AB",A17,"/360)-1") -> (1+Y17)^(AB17/360)-1 | AD17: =CONCATENATE("(AC",A17,"*V",A17,")") -> (AC17*V17) | AE17: =CONCATENATE("(V",A17,"+AD",A17,")") -> (V17+AD17)
A18: =A17+1 -> 18 | B18: 43617 | C18: FACT_EMITIDA | D18: =CONCATENATE("SUMIF(",IF(C18="FACT_EMITIDA","SIGGE_E",C18),"!B:B,Reliquidacion!B",A18,",",IF(C18="FACT_EMITIDA","SIGGE_E",C18),"!S:S)") -> SUMIF(SIGGE_E!B:B,Reliquidacion!B18,SIGGE_E!S:S) | E18: =CONCATENATE("SUMIF(",IF(C18="FACT_EMITIDA","SIGGE_E",C18),"!B:B,Reliquidacion!B",A18,",",IF(C18="FACT_EMITIDA","SIGGE_E",C18),"!T:T)") -> SUMIF(SIGGE_E!B:B,Reliquidacion!B18,SIGGE_E!T:T) | F18: =CONCATENATE("IFERROR((E",A18,"/D",A18,"),0)") -> IFERROR((E18/D18),0) | G18: =CONCATENATE("SUMIF(",IF(C18="FACT_EMITIDA","SIGGE_P",C18),"!B:B,Reliquidacion!B",A18,",",IF(C18="FACT_EMITIDA","SIGGE_P",C18),"!U:U)") -> SUMIF(SIGGE_P!B:B,Reliquidacion!B18,SIGGE_P!U:U) | H18: =CONCATENATE("SUMIF(",IF(C18="FACT_EMITIDA","SIGGE_P",C18),"!B:B,Reliquidacion!B",A18,",",IF(C18="FACT_EMITIDA","SIGGE_P",C18),"!V:V)") -> SUMIF(SIGGE_P!B:B,Reliquidacion!B18,SIGGE_P!V:V) | I18: =CONCATENATE("IFERROR((H",A18,"/G",A18,"),0)") -> IFERROR((H18/G18),0) | J18: =CONCATENATE("(E",A18,"+H",A18,")") -> (E18+H18) | L18: =(MAPA_DATA!K43) -> EFACT_CNE | M18: =CONCATENATE("SUMIF(",L18,"!B:B,Reliquidacion!B",A18,",",L18,"!S:S)") -> SUMIF(EFACT_CNE!B:B,Reliquidacion!B18,EFACT_CNE!S:S) | N18: =CONCATENATE("SUMIF(",L18,"!B:B,Reliquidacion!B",A18,",",L18,"!T:T)") -> SUMIF(EFACT_CNE!B:B,Reliquidacion!B18,EFACT_CNE!T:T) | O18: =CONCATENATE("IFERROR((N",A18,"/M",A18,"),0)") -> IFERROR((N18/M18),0) | P18: =CONCATENATE("SUMIF(",L18,"!B:B,Reliquidacion!B",A18,",",L18,"!U:U)") -> SUMIF(EFACT_CNE!B:B,Reliquidacion!B18,EFACT_CNE!U:U) | Q18: =CONCATENATE("SUMIF(",L18,"!B:B,Reliquidacion!B",A18,",",L18,"!V:V)") -> SUMIF(EFACT_CNE!B:B,Reliquidacion!B18,EFACT_CNE!V:V) | R18: =CONCATENATE("IFERROR((Q",A18,"/P",A18,"),0)") -> IFERROR((Q18/P18),0) | S18: =CONCATENATE("(N",A18,"+Q",A18,")") -> (N18+Q18) | U18: 43617 | V18: =CONCATENATE("(S",A18,"-J",A18,")") -> (S18-J18) | W18: PNP_6T_08-05-2020 | X18: 44137 | Y18: 0.0361 | Z18: 43671 | AA18: =AA17 -> 44377 | AB18: =CONCATENATE("(AA",A18,"-Z",A18,")") -> (AA18-Z18) | AC18: =CONCATENATE("(1+Y",A18,")^(AB",A18,"/360)-1") -> (1+Y18)^(AB18/360)-1 | AD18: =CONCATENATE("(AC",A18,"*V",A18,")") -> (AC18*V18) | AE18: =CONCATENATE("(V",A18,"+AD",A18,")") -> (V18+AD18)
A19: =A18+1 -> 19 | B19: 43647 | C19: FACT_EMITIDA | D19: =CONCATENATE("SUMIF(",IF(C19="FACT_EMITIDA","SIGGE_E",C19),"!B:B,Reliquidacion!B",A19,",",IF(C19="FACT_EMITIDA","SIGGE_E",C19),"!S:S)") -> SUMIF(SIGGE_E!B:B,Reliquidacion!B19,SIGGE_E!S:S) | E19: =CONCATENATE("SUMIF(",IF(C19="FACT_EMITIDA","SIGGE_E",C19),"!B:B,Reliquidacion!B",A19,",",IF(C19="FACT_EMITIDA","SIGGE_E",C19),"!T:T)") -> SUMIF(SIGGE_E!B:B,Reliquidacion!B19,SIGGE_E!T:T) | F19: =CONCATENATE("IFERROR((E",A19,"/D",A19,"),0)") -> IFERROR((E19/D19),0) | G19: =CONCATENATE("SUMIF(",IF(C19="FACT_EMITIDA","SIGGE_P",C19),"!B:B,Reliquidacion!B",A19,",",IF(C19="FACT_EMITIDA","SIGGE_P",C19),"!U:U)") -> SUMIF(SIGGE_P!B:B,Reliquidacion!B19,SIGGE_P!U:U) | H19: =CONCATENATE("SUMIF(",IF(C19="FACT_EMITIDA","SIGGE_P",C19),"!B:B,Reliquidacion!B",A19,",",IF(C19="FACT_EMITIDA","SIGGE_P",C19),"!V:V)") -> SUMIF(SIGGE_P!B:B,Reliquidacion!B19,SIGGE_P!V:V) | I19: =CONCATENATE("IFERROR((H",A19,"/G",A19,"),0)") -> IFERROR((H19/G19),0) | J19: =CONCATENATE("(E",A19,"+H",A19,")") -> (E19+H19) | L19: =(MAPA_DATA!K44) -> EFACT_CNE | M19: =CONCATENATE("SUMIF(",L19,"!B:B,Reliquidacion!B",A19,",",L19,"!S:S)") -> SUMIF(EFACT_CNE!B:B,Reliquidacion!B19,EFACT_CNE!S:S) | N19: =CONCATENATE("SUMIF(",L19,"!B:B,Reliquidacion!B",A19,",",L19,"!T:T)") -> SUMIF(EFACT_CNE!B:B,Reliquidacion!B19,EFACT_CNE!T:T) | O19: =CONCATENATE("IFERROR((N",A19,"/M",A19,"),0)") -> IFERROR((N19/M19),0) | P19: =CONCATENATE("SUMIF(",L19,"!B:B,Reliquidacion!B",A19,",",L19,"!U:U)") -> SUMIF(EFACT_CNE!B:B,Reliquidacion!B19,EFACT_CNE!U:U) | Q19: =CONCATENATE("SUMIF(",L19,"!B:B,Reliquidacion!B",A19,",",L19,"!V:V)") -> SUMIF(EFACT_CNE!B:B,Reliquidacion!B19,EFACT_CNE!V:V) | R19: =CONCATENATE("IFERROR((Q",A19,"/P",A19,"),0)") -> IFERROR((Q19/P19),0) | S19: =CONCATENATE("(N",A19,"+Q",A19,")") -> (N19+Q19) | U19: 43647 | V19: =CONCATENATE("(S",A19,"-J",A19,")") -> (S19-J19) | W19: PNP_6T_08-05-2020 | X19: 44137 | Y19: 0.0361 | Z19: 43702 | AA19: =AA18 -> 44377 | AB19: =CONCATENATE("(AA",A19,"-Z",A19,")") -> (AA19-Z19) | AC19: =CONCATENATE("(1+Y",A19,")^(AB",A19,"/360)-1") -> (1+Y19)^(AB19/360)-1 | AD19: =CONCATENATE("(AC",A19,"*V",A19,")") -> (AC19*V19) | AE19: =CONCATENATE("(V",A19,"+AD",A19,")") -> (V19+AD19)
A20: =A19+1 -> 20 | B20: 43678 | C20: FACT_EMITIDA | D20: =CONCATENATE("SUMIF(",IF(C20="FACT_EMITIDA","SIGGE_E",C20),"!B:B,Reliquidacion!B",A20,",",IF(C20="FACT_EMITIDA","SIGGE_E",C20),"!S:S)") -> SUMIF(SIGGE_E!B:B,Reliquidacion!B20,SIGGE_E!S:S) | E20: =CONCATENATE("SUMIF(",IF(C20="FACT_EMITIDA","SIGGE_E",C20),"!B:B,Reliquidacion!B",A20,",",IF(C20="FACT_EMITIDA","SIGGE_E",C20),"!T:T)") -> SUMIF(SIGGE_E!B:B,Reliquidacion!B20,SIGGE_E!T:T) | F20: =CONCATENATE("IFERROR((E",A20,"/D",A20,"),0)") -> IFERROR((E20/D20),0) | G20: =CONCATENATE("SUMIF(",IF(C20="FACT_EMITIDA","SIGGE_P",C20),"!B:B,Reliquidacion!B",A20,",",IF(C20="FACT_EMITIDA","SIGGE_P",C20),"!U:U)") -> SUMIF(SIGGE_P!B:B,Reliquidacion!B20,SIGGE_P!U:U) | H20: =CONCATENATE("SUMIF(",IF(C20="FACT_EMITIDA","SIGGE_P",C20),"!B:B,Reliquidacion!B",A20,",",IF(C20="FACT_EMITIDA","SIGGE_P",C20),"!V:V)") -> SUMIF(SIGGE_P!B:B,Reliquidacion!B20,SIGGE_P!V:V) | I20: =CONCATENATE("IFERROR((H",A20,"/G",A20,"),0)") -> IFERROR((H20/G20),0) | J20: =CONCATENATE("(E",A20,"+H",A20,")") -> (E20+H20) | L20: =(MAPA_DATA!K45) -> EFACT_CNE | M20: =CONCATENATE("SUMIF(",L20,"!B:B,Reliquidacion!B",A20,",",L20,"!S:S)") -> SUMIF(EFACT_CNE!B:B,Reliquidacion!B20,EFACT_CNE!S:S) | N20: =CONCATENATE("SUMIF(",L20,"!B:B,Reliquidacion!B",A20,",",L20,"!T:T)") -> SUMIF(EFACT_CNE!B:B,Reliquidacion!B20,EFACT_CNE!T:T) | O20: =CONCATENATE("IFERROR((N",A20,"/M",A20,"),0)") -> IFERROR((N20/M20),0) | P20: =CONCATENATE("SUMIF(",L20,"!B:B,Reliquidacion!B",A20,",",L20,"!U:U)") -> SUMIF(EFACT_CNE!B:B,Reliquidacion!B20,EFACT_CNE!U:U) | Q20: =CONCATENATE("SUMIF(",L20,"!B:B,Reliquidacion!B",A20,",",L20,"!V:V)") -> SUMIF(EFACT_CNE!B:B,Reliquidacion!B20,EFACT_CNE!V:V) | R20: =CONCATENATE("IFERROR((Q",A20,"/P",A20,"),0)") -> IFERROR((Q20/P20),0) | S20: =CONCATENATE("(N",A20,"+Q",A20,")") -> (N20+Q20) | U20: 43678 | V20: =CONCATENATE("(S",A20,"-J",A20,")") -> (S20-J20) | W20: PNP_6T_08-05-2020 | X20: 44137 | Y20: 0.0361 | Z20: 43733 | AA20: =AA19 -> 44377 | AB20: =CONCATENATE("(AA",A20,"-Z",A20,")") -> (AA20-Z20) | AC20: =CONCATENATE("(1+Y",A20,")^(AB",A20,"/360)-1") -> (1+Y20)^(AB20/360)-1 | AD20: =CONCATENATE("(AC",A20,"*V",A20,")") -> (AC20*V20) | AE20: =CONCATENATE("(V",A20,"+AD",A20,")") -> (V20+AD20)
A21: =A20+1 -> 21 | B21: 43709 | C21: FACT_EMITIDA | D21: =CONCATENATE("SUMIF(",IF(C21="FACT_EMITIDA","SIGGE_E",C21),"!B:B,Reliquidacion!B",A21,",",IF(C21="FACT_EMITIDA","SIGGE_E",C21),"!S:S)") -> SUMIF(SIGGE_E!B:B,Reliquidacion!B21,SIGGE_E!S:S) | E21: =CONCATENATE("SUMIF(",IF(C21="FACT_EMITIDA","SIGGE_E",C21),"!B:B,Reliquidacion!B",A21,",",IF(C21="FACT_EMITIDA","SIGGE_E",C21),"!T:T)") -> SUMIF(SIGGE_E!B:B,Reliquidacion!B21,SIGGE_E!T:T) | F21: =CONCATENATE("IFERROR((E",A21,"/D",A21,"),0)") -> IFERROR((E21/D21),0) | G21: =CONCATENATE("SUMIF(",IF(C21="FACT_EMITIDA","SIGGE_P",C21),"!B:B,Reliquidacion!B",A21,",",IF(C21="FACT_EMITIDA","SIGGE_P",C21),"!U:U)") -> SUMIF(SIGGE_P!B:B,Reliquidacion!B21,SIGGE_P!U:U) | H21: =CONCATENATE("SUMIF(",IF(C21="FACT_EMITIDA","SIGGE_P",C21),"!B:B,Reliquidacion!B",A21,",",IF(C21="FACT_EMITIDA","SIGGE_P",C21),"!V:V)") -> SUMIF(SIGGE_P!B:B,Reliquidacion!B21,SIGGE_P!V:V) | I21: =CONCATENATE("IFERROR((H",A21,"/G",A21,"),0)") -> IFERROR((H21/G21),0) | J21: =CONCATENATE("(E",A21,"+H",A21,")") -> (E21+H21) | L21: =(MAPA_DATA!K46) -> EFACT_CNE | M21: =CONCATENATE("SUMIF(",L21,"!B:B,Reliquidacion!B",A21,",",L21,"!S:S)") -> SUMIF(EFACT_CNE!B:B,Reliquidacion!B21,EFACT_CNE!S:S) | N21: =CONCATENATE("SUMIF(",L21,"!B:B,Reliquidacion!B",A21,",",L21,"!T:T)") -> SUMIF(EFACT_CNE!B:B,Reliquidacion!B21,EFACT_CNE!T:T) | O21: =CONCATENATE("IFERROR((N",A21,"/M",A21,"),0)") -> IFERROR((N21/M21),0) | P21: =CONCATENATE("SUMIF(",L21,"!B:B,Reliquidacion!B",A21,",",L21,"!U:U)") -> SUMIF(EFACT_CNE!B:B,Reliquidacion!B21,EFACT_CNE!U:U) | Q21: =CONCATENATE("SUMIF(",L21,"!B:B,Reliquidacion!B",A21,",",L21,"!V:V)") -> SUMIF(EFACT_CNE!B:B,Reliquidacion!B21,EFACT_CNE!V:V) | R21: =CONCATENATE("IFERROR((Q",A21,"/P",A21,"),0)") -> IFERROR((Q21/P21),0) | S21: =CONCATENATE("(N",A21,"+Q",A21,")") -> (N21+Q21) | U21: 43709 | V21: =CONCATENATE("(S",A21,"-J",A21,")") -> (S21-J21) | W21: PNP_6T_08-05-2020 | X21: 44137 | Y21: 0.0361 | Z21: 43763 | AA21: =AA20 -> 44377 | AB21: =CONCATENATE("(AA",A21,"-Z",A21,")") -> (AA21-Z21) | AC21: =CONCATENATE("(1+Y",A21,")^(AB",A21,"/360)-1") -> (1+Y21)^(AB21/360)-1 | AD21: =CONCATENATE("(AC",A21,"*V",A21,")") -> (AC21*V21) | AE21: =CONCATENATE("(V",A21,"+AD",A21,")") -> (V21+AD21)
... A33: =A32+1 -> 33 | B33: 44075 | C33: FACT_EMITIDA | D33: =CONCATENATE("SUMIF(",IF(C33="FACT_EMITIDA","SIGGE_E",C33),"!B:B,Reliquidacion!B",A33,",",IF(C33="FACT_EMITIDA","SIGGE_E",C33),"!S:S)") -> SUMIF(SIGGE_E!B:B,Reliquidacion!B33,SIGGE_E!S:S) | E33: =CONCATENATE("SUMIF(",IF(C33="FACT_EMITIDA","SIGGE_E",C33),"!B:B,Reliquidacion!B",A33,",",IF(C33="FACT_EMITIDA","SIGGE_E",C33),"!T:T)") -> SUMIF(SIGGE_E!B:B,Reliquidacion!B33,SIGGE_E!T:T) | F33: =CONCATENATE("IFERROR((E",A33,"/D",A33,"),0)") -> IFERROR((E33/D33),0) | G33: =CONCATENATE("SUMIF(",IF(C33="FACT_EMITIDA","SIGGE_P",C33),"!B:B,Reliquidacion!B",A33,",",IF(C33="FACT_EMITIDA","SIGGE_P",C33),"!U:U)") -> SUMIF(SIGGE_P!B:B,Reliquidacion!B33,SIGGE_P!U:U) | H33: =CONCATENATE("SUMIF(",IF(C33="FACT_EMITIDA","SIGGE_P",C33),"!B:B,Reliquidacion!B",A33,",",IF(C33="FACT_EMITIDA","SIGGE_P",C33),"!V:V)") -> SUMIF(SIGGE_P!B:B,Reliquidacion!B33,SIGGE_P!V:V) | I33: =CONCATENATE("IFERROR((H",A33,"/G",A33,"),0)") -> IFERROR((H33/G33),0) | J33: =CONCATENATE("(E",A33,"+H",A33,")") -> (E33+H33) | L33: =(MAPA_DATA!K58) -> EFACT_CNE | M33: =CONCATENATE("SUMIF(",L33,"!B:B,Reliquidacion!B",A33,",",L33,"!S:S)") -> SUMIF(EFACT_CNE!B:B,Reliquidacion!B33,EFACT_CNE!S:S) | N33: =CONCATENATE("SUMIF(",L33,"!B:B,Reliquidacion!B",A33,",",L33,"!T:T)") -> SUMIF(EFACT_CNE!B:B,Reliquidacion!B33,EFACT_CNE!T:T) | O33: =CONCATENATE("IFERROR((N",A33,"/M",A33,"),0)") -> IFERROR((N33/M33),0) | P33: =CONCATENATE("SUMIF(",L33,"!B:B,Reliquidacion!B",A33,",",L33,"!U:U)") -> SUMIF(EFACT_CNE!B:B,Reliquidacion!B33,EFACT_CNE!U:U) | Q33: =CONCATENATE("SUMIF(",L33,"!B:B,Reliquidacion!B",A33,",",L33,"!V:V)") -> SUMIF(EFACT_CNE!B:B,Reliquidacion!B33,EFACT_CNE!V:V) | R33: =CONCATENATE("IFERROR((Q",A33,"/P",A33,"),0)") -> IFERROR((Q33/P33),0) | S33: =CONCATENATE("(N",A33,"+Q",A33,")") -> (N33+Q33) | U33: 44075 | V33: =CONCATENATE("(S",A33,"-J",A33,")") -> (S33-J33) | W33: PNP_19T_30-12-2020 | X33: 44336 | Y33: 0.0328 | Z33: 44129 | AA33: =AA32 -> 44377 | AB33: =CONCATENATE("(AA",A33,"-Z",A33,")") -> (AA33-Z33) | AC33: =CONCATENATE("(1+Y",A33,")^(AB",A33,"/360)-1") -> (1+Y33)^(AB33/360)-1 | AD33: =CONCATENATE("(AC",A33,"*V",A33,")") -> (AC33*V33) | AE33: =CONCATENATE("(V",A33,"+AD",A33,")") -> (V33+AD33)
AD34: Reliquidación | AE34: =CONCATENATE("SUM(AE9:AE65)") -> SUM(AE9:AE65)
AC36: Montos a favor | AD36: ACCIONA emite factura
AC37: Montos en contra | AD37: ACCIONA emite nota de crédito

Sheet FACT_EMITIDA
A1: Periodo | B1: MesDevengado | C1: Nombre | D1: Concepto | E1: Agrupacion | F1: Glosa | G1: FechaCarga | H1: TipoDocumento | I1: Folio | J1: Vendedor | K1: Comprador | L1: Bloque | M1: Empresa | N1: ClaveEEDD | O1: Licitacion | P1: NomAgrupacion | Q1: Num | R1: Barra | S1: Energia | T1: PrecioEnergia | U1: Potencia | V1: PrecioPotencia | W1: Monto
A2: 43344 | B2: 43344 | C2: Licitación Caren y Cec (SIC 2013/03-2) BS1A | D2: Energia Licitaciones | E2: Energía | F2: Lic. SIC 2013/03-2 bloques BS1A: Energía sep 2018 | G2: 43392 | H2: 33 | I2: 6305 | J2: s | K2: s | L2: BS1A | M2: Caren | N2: Cec | O2: 41335 | P2: CEC | Q2: 1 | R2: TotalBarras | S2: 3000 | T2: 58.085 | U2: NULL | V2: NULL | W2: 174255
A3: 43374 | B3: 43374 | C3: Licitación Caren y Cec (SIC 2013/03-2) BS1A | D3: Energia Licitaciones | E3: Energía | F3: Lic. SIC 2013/03-2 bloques BS1A: Energía oct 2018 | G3: 43431 | H3: 33 | I3: 6796 | J3: s | K3: s | L3: BS1A | M3: Caren | N3: Cec | O3: 41335 | P3: CEC | Q3: 1 | R3: TotalBarras | S3: 3000 | T3: 59.678 | U3: NULL | V3: NULL | W3: 179035
A4: 43405 | B4: 43405 | C4: Licitación Caren y Cec (SIC 2013/03-2) BS1A | D4: Energia Licitaciones | E4: Energía | F4: Lic. SIC 2013/03-2 bloques BS1A: Energía nov 2018 | G4: 43448 | H4: 33 | I4: 6939 | J4: s | K4: s | L4: BS1A | M4: Caren | N4: Cec | O4: 41335 | P4: CEC | Q4: 1 | R4: TotalBarras | S4: 4000 | T4: 59.635 | U4: NULL | V4: NULL | W4: 238540
A5: 43435 | B5: 43435 | C5: Licitación Caren y Cec (SIC 2013/03-2) BS1A | D5: Energia Licitaciones | E5: Energía | F5: Lic. SIC 2013/03-2 bloques BS1A: Energía dic 2018 | G5: 43486 | H5: 33 | I5: 7194 | J5: s | K5: s | L5: BS1A | M5: Caren | N5: Cec | O5: 41335 | P5: CEC | Q5: 1 | R5: TotalBarras | S5: 5000 | T5: 67.951 | U5: NULL | V5: NULL | W5: 339757
A6: 43466 | B6: 43466 | C6: Licitación Caren y Cec (SIC 2013/03-2) BS1A | D6: Reliq. Energia Licitaciones | E6: Energía | F6: Lic. SIC 2013/03-2 bloques BS1A: Reliq. Energía ene 2019 | G6: 43539 | H6: 33 | I6: NULL | J6: s | K6: s | L6: BS1A | M6: Caren | N6: Cec | O6: 41335 | P6: CEC | Q6: 1 | R6: A.JAHUEL 220 | S6: 1.46188 | T6: 66.9 | U6: NULL | V6: NULL | W6: 98
A7: 43466 | B7: 43466 | C7: Licitación Caren y Cec (SIC 2013/03-2) BS1A | D7: Energia Licitaciones | E7: Energía | F7: Lic. SIC 2013/03-2 bloques BS1A: Energía ene 2019 | G7: 43504 | H7: 33 | I7: 7513 | J7: s | K7: s | L7: BS1A | M7: Caren | N7: Cec | O7: 41335 | P7: CEC | Q7: 1 | R7: A.JAHUEL 220 | S7: 1371.306 | T7: 66.9 | U7: NULL | V7: NULL | W7: 91740
A8: 43466 | B8: 43466 | C8: Licitación Caren y Cec (SIC 2013/03-2) BS1A | D8: Reliq. Energia Licitaciones | E8: Energía | F8: Lic. SIC 2013/03-2 bloques BS1A: Reliq. Energía ene 2019 | G8: 43539 | H8: 33 | I8: NULL | J8: s | K8: s | L8: BS1A | M8: Caren | N8: Cec | O8: 41335 | P8: CEC | Q8: 2 | R8: A.MELIP 220 | S8: 0.009388 | T8: 69.014 | U8: NULL | V8: NULL | W8: 1
A9: 43466 | B9: 43466 | C9: Licitación Caren y Cec (SIC 2013/03-2) BS1A | D9: Energia Licitaciones | E9: Energía | F9: Lic. SIC 2013/03-2 bloques BS1A: Energía ene 2019 | G9: 43504 | H9: 33 | I9: 7513 | J9: s | K9: s | L9: BS1A | M9: Caren | N9: Cec | O9: 41335 | P9: CEC | Q9: 2 | R9: A.MELIP 220 | S9: 8.806166 | T9: 69.014 | U9: NULL | V9: NULL | W9: 608
A10: 43466 | B10: 43466 | C10: Licitación Caren y Cec (SIC 2013/03-2) BS1A | D10: Reliq. Energia Licitaciones | E10: Energía | F10: Lic. SIC 2013/03-2 bloques BS1A: Reliq. Energía ene 2019 | G10: 43539 | H10: 33 | I10: NULL | J10: s | K10: s | L10: BS1A | M10: Caren | N10: Cec | O10: 41335 | P10: CEC | Q10: 3 | R10: CHARRUA 220 | S10: 0.453721 | T10: 63.27 | U10: NULL | V10: NULL | W10: 29
A11: 43466 | B11: 43466 | C11: Licitación Caren y Cec (SIC 2013/03-2) BS1A | D11: Energia Licitaciones | E11: Energía | F11: Lic. SIC 2013/03-2 bloques BS1A: Energía ene 2019 | G11: 43504 | H11: 33 | I11: 7513 | J11: s | K11: s | L11: BS1A | M11: Caren | N11: Cec | O11: 41335 | P11: CEC | Q11: 3 | R11: CHARRUA 220 | S11: 425.60961 | T11: 63.27 | U11: NULL | V11: NULL | W11: 26928
A12: 43466 | B12: 43466 | C12: Licitación Caren y Cec (SIC 2013/03-2) BS1A | D12: Reliq. Energia Licitaciones | E12: Energía | F12: Lic. SIC 2013/03-2 bloques BS1A: Reliq. Energía ene 2019 | G12: 43539 | H12: 33 | I12: NULL | J12: s | K12: s | L12: BS1A | M12: Caren | N12: Cec | O12: 41335 | P12: CEC | Q12: 4 | R12: ITAHUE 220 | S12: 2.212452 | T12: 65.349 | U12: NULL | V12: NULL | W12: 145
A13: 43466 | B13: 43466 | C13: Licitación Caren y Cec (SIC 2013/03-2) BS1A | D13: Energia Licitaciones | E13: Energía | F13: Lic. SIC 2013/03-2 bloques BS1A: Energía ene 2019 | G13: 43504 | H13: 33 | I13: 7513 | J13: s | K13: s | L13: BS1A | M13: Caren | N13: Cec | O13: 41335 | P13: CEC | Q13: 4 | R13: ITAHUE 220 | S13: 2075.374 | T13: 65.349 | U13: NULL | V13: NULL | W13: 135624
A14: 43466 | B14: 43466 | C14: Licitación Caren y Cec (SIC 2013/03-2) BS1A | D14: Reliq. Energia Licitaciones | E14: Energía | F14: Lic. SIC 2013/03-2 bloques BS1A: Reliq. Energía ene 2019 | G14: 43539 | H14: 33 | I14: NULL | J14: s | K14: s | L14: BS1A | M14: Caren | N14: Cec | O14: 41335 | P14: CEC | Q14: 5 | R14: RAPEL 220 | S14: 0.008637 | T14: 69.368 | U14: NULL | V14: NULL | W14: 1
A15: 43466 | B15: 43466 | C15: Licitación Caren y Cec (SIC 2013/03-2) BS1A | D15: Energia Licitaciones | E15: Energía | F15: Lic. SIC 2013/03-2 bloques BS1A: Energía ene 2019 | G15: 43504 | H15: 33 | I15: 7513 | J15: s | K15: s | L15: BS1A | M15: Caren | N15: Cec | O15: 41335 | P15: CEC | Q15: 5 | R15: RAPEL 220 | S15: 8.102057 | T15: 69.368 | U15: NULL | V15: NULL | W15: 562
A16: 43497 | B16: 43497 | C16: Licitación Caren y Cec (SIC 2013/03-2) BS1A | D16: Reliq. Energia Licitaciones | E16: Energía | F16: Lic. SIC 2013/03-2 bloques BS1A: Reliq. Energía feb 2019 | G16: 43564 | H16: 61 | I16: NULL | J16: s | K16: s | L16: BS1A | M16: Caren | N16: Cec | O16: 41335 | P16: CEC | Q16: 1 | R16: A.JAHUEL 220 | S16: 0.23349 | T16: 66.9 | U16: NULL | V16: NULL | W16: 16
A17: 43497 | B17: 43497 | C17: Licitación Caren y Cec (SIC 2013/03-2) BS1A | D17: Energia Licitaciones | E17: Energía | F17: Lic. SIC 2013/03-2 bloques BS1A: Energía feb 2019 | G17: 43532 | H17: 33 | I17: 7798 | J17: s | K17: s | L17: BS1A | M17: Caren | N17: Cec | O17: 41335 | P17: CEC | Q17: 1 | R17: A.JAHUEL 220 | S17: 1368.5299 | T17: 66.9 | U17: NULL | V17: NULL | W17: 91555
A18: 43497 | B18: 43497 | C18: Licitación Caren y Cec (SIC 2013/03-2) BS1A | D18: Energia Licitaciones | E18: Energía | F18: Lic. SIC 2013/03-2 bloques BS1A: Energía feb 2019 | G18: 43532 | H18: 33 | I18: 7798 | J18: s | K18: s | L18: BS1A | M18: Caren | N18: Cec | O18: 41335 | P18: CEC | Q18: 2 | R18: A.MELIP 220 | S18: 8.816632 | T18: 69.014 | U18: NULL | V18: NULL | W18: 608
A19: 43497 | B19: 43497 | C19: Licitación Caren y Cec (SIC 2013/03-2) BS1A | D19: Reliq. Energia Licitaciones | E19: Energía | F19: Lic. SIC 2013/03-2 bloques BS1A: Reliq. Energía feb 2019 | G19: 43564 | H19: 61 | I19: NULL | J19: s | K19: s | L19: BS1A | M19: Caren | N19: Cec | O19: 41335 | P19: CEC | Q19: 3 | R19: CHARRUA 220 | S19: 0.072089 | T19: 63.27 | U19: NULL | V19: NULL | W19: 5
A20: 43497 | B20: 43497 | C20: Licitación Caren y Cec (SIC 2013/03-2) BS1A | D20: Energia Licitaciones | E20: Energía | F20: Lic. SIC 2013/03-2 bloques BS1A: Energía feb 2019 | G20: 43532 | H20: 33 | I20: 7798 | J20: s | K20: s | L20: BS1A | M20: Caren | N20: Cec | O20: 41335 | P20: CEC | Q20: 3 | R20: CHARRUA 220 | S20: 422.52678 | T20: 63.27 | U20: NULL | V20: NULL | W20: 26733
A21: 43497 | B21: 43497 | C21: Licitación Caren y Cec (SIC 2013/03-2) BS1A | D21: Reliq. Energia Licitaciones | E21: Energía | F21: Lic. SIC 2013/03-2 bloques BS1A: Reliq. Energía feb 2019 | G21: 43564 | H21: 61 | I21: NULL | J21: s | K21: s | L21: BS1A | M21: Caren | N21: Cec | O21: 41335 | P21: CEC | Q21: 4 | R21: ITAHUE 220 | S21: 0.353269 | T21: 65.349 | U21: NULL | V21: NULL | W21: 23
A22: 43497 | B22: 43497 | C22: Licitación Caren y Cec (SIC 2013/03-2) BS1A | D22: Energia Licitaciones | E22: Energía | F22: Lic. SIC 2013/03-2 bloques BS1A: Energía feb 2019 | G22: 43532 | H22: 33 | I22: 7798 | J22: s | K22: s | L22: BS1A | M22: Caren | N22: Cec | O22: 41335 | P22: CEC | Q22: 4 | R22: ITAHUE 220 | S22: 2070.5801 | T22: 65.349 | U22: NULL | V22: NULL | W22: 135310
A23: 43497 | B23: 43497 | C23: Licitación Caren y Cec (SIC 2013/03-2) BS1A | D23: Energia Licitaciones | E23: Energía | F23: Lic. SIC 2013/03-2 bloques BS1A: Energía feb 2019 | G23: 43532 | H23: 33 | I23: 7798 | J23: s | K23: s | L23: BS1A | M23: Caren | N23: Cec | O23: 41335 | P23: CEC | Q23: 5 | R23: RAPEL 220 | S23: 8.102328 | T23: 69.368 | U23: NULL | V23: NULL | W23: 562
A24: 43525 | B24: 43525 | C24: Licitación Caren y Cec (SIC 2013/03-2) BS1A | D24: Reliq. Energia Licitaciones | E24: Energía | F24: Lic. SIC 2013/03-2 bloques BS1A: Reliq. Energía mar 2019 | G24: 43598 | H24: 33 | I24: NULL | J24: s | K24: s | L24: BS1A | M24: Caren | N24: Cec | O24: 41335 | P24: CEC | Q24: 1 | R24: A.JAHUEL 220 | S24: 0.580609 | T24: 66.9 | U24: NULL | V24: NULL | W24: 39
A25: 43525 | B25: 43525 | C25: Licitación Caren y Cec (SIC 2013/03-2) BS1A | D25: Energia Licitaciones | E25: Energía | F25: Lic. SIC 2013/03-2 bloques BS1A: Energía mar 2019 | G25: 43563 | H25: 33 | I25: 8389 | J25: s | K25: s | L25: BS1A | M25: Caren | N25: Cec | O25: 41335 | P25: CEC | Q25: 1 | R25: A.JAHUEL 220 | S25: 1311.6233 | T25: 66.9 | U25: NULL | V25: NULL | W25: 87748
A26: 43525 | B26: 43525 | C26: Licitación Caren y Cec (SIC 2013/03-2) BS1A | D26: Energia Licitaciones | E26: Energía | F26: Lic. SIC 2013/03-2 bloques BS1A: Energía mar 2019 | G26: 43563 | H26: 33 | I26: 8389 | J26: s | K26: s | L26: BS1A | M26: Caren | N26: Cec | O26: 41335 | P26: CEC | Q26: 2 | R26: A.MELIP 220 | S26: 8.173697 | T26: 69.014 | U26: NULL | V26: NULL | W26: 564
A27: 43525 | B27: 43525 | C27: Licitación Caren y Cec (SIC 2013/03-2) BS1A | D27: Reliq. Energia Licitaciones | E27: Energía | F27: Lic. SIC 2013/03-2 bloques BS1A: Reliq. Energía mar 2019 | G27: 43598 | H27: 33 | I27: NULL | J27: s | K27: s | L27: BS1A | M27: Caren | N27: Cec | O27: 41335 | P27: CEC | Q27: 3 | R27: CHARRUA 220 | S27: 0.178218 | T27: 63.27 | U27: NULL | V27: NULL | W27: 11
A28: 43525 | B28: 43525 | C28: Licitación Caren y Cec (SIC 2013/03-2) BS1A | D28: Energia Licitaciones | E28: Energía | F28: Lic. SIC 2013/03-2 bloques BS1A: Energía mar 2019 | G28: 43563 | H28: 33 | I28: 8389 | J28: s | K28: s | L28: BS1A | M28: Caren | N28: Cec | O28: 41335 | P28: CEC | Q28: 3 | R28: CHARRUA 220 | S28: 402.60399 | T28: 63.27 | U28: NULL | V28: NULL | W28: 25473
A29: 43525 | B29: 43525 | C29: Licitación Caren y Cec (SIC 2013/03-2) BS1A | D29: Reliq. Energia Licitaciones | E29: Energía | F29: Lic. SIC 2013/03-2 bloques BS1A: Reliq. Energía mar 2019 | G29: 43598 | H29: 33 | I29: NULL | J29: s | K29: s | L29: BS1A | M29: Caren | N29: Cec | O29: 41335 | P29: CEC | Q29: 4 | R29: ITAHUE 220 | S29: 0.87116 | T29: 65.349 | U29: NULL | V29: NULL | W29: 57
A30: 43525 | B30: 43525 | C30: Licitación Caren y Cec (SIC 2013/03-2) BS1A | D30: Energia Licitaciones | E30: Energía | F30: Lic. SIC 2013/03-2 bloques BS1A: Energía mar 2019 | G30: 43563 | H30: 33 | I30: 8389 | J30: s | K30: s | L30: BS1A | M30: Caren | N30: Cec | O30: 41335 | P30: CEC | Q30: 4 | R30: ITAHUE 220 | S30: 1967.9945 | T30: 65.349 | U30: NULL | V30: NULL | W30: 128606
A31: 43525 | B31: 43525 | C31: Licitación Caren y Cec (SIC 2013/03-2) BS1A | D31: Energia Licitaciones | E31: Energía | F31: Lic. SIC 2013/03-2 bloques BS1A: Energía mar 2019 | G31: 43563 | H31: 33 | I31: 8389 | J31: s | K31: s | L31: BS1A | M31: Caren | N31: Cec | O31: 41335 | P31: CEC | Q31: 5 | R31: RAPEL 220 | S31: 7.514895 | T31: 69.368 | U31: NULL | V31: NULL | W31: 521
A32: 43556 | B32: 43556 | C32: Licitación Caren y Cec (SIC 2013/03-2) BS1A | D32: Potencia Licitaciones | E32: Potencia | F32: Lic. SIC 2013/03-2 bloques BS1A: Potencia abr 2019 | G32: 43598 | H32: 33 | I32: 8451 | J32: s | K32: s | L32: BS1A | M32: Caren | N32: Cec | O32: 41335 | P32: CEC | Q32: 1 | R32: A.JAHUEL 220 | S32: NULL | T32: NULL | U32: 0 | V32: 0 | W32: 0
A33: 43556 | B33: 43556 | C33: Licitación Caren y Cec (SIC 2013/03-2) BS1A | D33: Reliq. Energia Licitaciones | E33: Energía | F33: Lic. SIC 2013/03-2 bloques BS1A: Reliq. Energía abr 2019 | G33: 43913.498 | H33: 61 | I33: NULL | J33: s | K33: s | L33: BS1A | M33: Caren | N33: Cec | O33: 41335 | P33: CEC | Q33: 1 | R33: A.JAHUEL 220 | S33: 1 | T33: -1091 | U33: NULL | V33: NULL | W33: -1091
A34: 43556 | B34: 43556 | C34: Licitación Caren y Cec (SIC 2013/03-2) BS1A | D34: Energia Licitaciones | E34: Energía | F34: Lic. SIC 2013/03-2 bloques BS1A: Energía abr 2019 | G34: 43598 | H34: 33 | I34: 8451 | J34: s | K34: s | L34: BS1A | M34: Caren | N34: Cec | O34: 41335 | P34: CEC | Q34: 1 | R34: A.JAHUEL 220 | S34: 897.9651 | T34: 66.9 | U34: NULL | V34: NULL | W34: 60074
A35: 43556 | B35: 43556 | C35: Licitación Caren y Cec (SIC 2013/03-2) BS1A | D35: Potencia Licitaciones | E35: Potencia | F35: Lic. SIC 2013/03-2 bloques BS1A: Potencia abr 2019 | G35: 43598 | H35: 33 | I35: 8451 | J35: s | K35: s | L35: BS1A | M35: Caren | N35: Cec | O35: 41335 | P35: CEC | Q35: 2 | R35: A.MELIP 220 | S35: NULL | T35: NULL | U35: 0 | V35: 0 | W35: 0
A36: 43556 | B36: 43556 | C36: Licitación Caren y Cec (SIC 2013/03-2) BS1A | D36: Reliq. Energia Licitaciones | E36: Energía | F36: Lic. SIC 2013/03-2 bloques BS1A: Reliq. Energía abr 2019 | G36: 43913.498 | H36: 61 | I36: NULL | J36: s | K36: s | L36: BS1A | M36: Caren | N36: Cec | O36: 41335 | P36: CEC | Q36: 2 | R36: A.MELIP 220 | S36: 1 | T36: -8 | U36: NULL | V36: NULL | W36: -8
A37: 43556 | B37: 43556 | C37: Licitación Caren y Cec (SIC 2013/03-2) BS1A | D37: Energia Licitaciones | E37: Energía | F37: Lic. SIC 2013/03-2 bloques BS1A: Energía abr 2019 | G37: 43598 | H37: 33 | I37: 8451 | J37: s | K37: s | L37: BS1A | M37: Caren | N37: Cec | O37: 41335 | P37: CEC | Q37: 2 | R37: A.MELIP 220 | S37: 5.912451 | T37: 69.014 | U37: NULL | V37: NULL | W37: 408
A38: 43556 | B38: 43556 | C38: Licitación Caren y Cec (SIC 2013/03-2) BS1A | D38: Potencia Licitaciones | E38: Potencia | F38: Lic. SIC 2013/03-2 bloques BS1A: Potencia abr 2019 | G38: 43598 | H38: 33 | I38: 8451 | J38: s | K38: s | L38: BS1A | M38: Caren | N38: Cec | O38: 41335 | P38: CEC | Q38: 3 | R38: CHARRUA 220 | S38: NULL | T38: NULL | U38: 0 | V38: 0 | W38: 0
A39: 43556 | B39: 43556 | C39: Licitación Caren y Cec (SIC 2013/03-2) BS1A | D39: Reliq. Energia Licitaciones | E39: Energía | F39: Lic. SIC 2013/03-2 bloques BS1A: Reliq. Energía abr 2019 | G39: 43913.498 | H39: 61 | I39: NULL | J39: s | K39: s | L39: BS1A | M39: Caren | N39: Cec | O39: 41335 | P39: CEC | Q39: 3 | R39: CHARRUA 220 | S39: 1 | T39: -327 | U39: NULL | V39: NULL | W39: -327
A40: 43556 | B40: 43556 | C40: Licitación Caren y Cec (SIC 2013/03-2) BS1A | D40: Energia Licitaciones | E40: Energía | F40: Lic. SIC 2013/03-2 bloques BS1A: Energía abr 2019 | G40: 43598 | H40: 33 | I40: 8451 | J40: s | K40: s | L40: BS1A | M40: Caren | N40: Cec | O40: 41335 | P40: CEC | Q40: 3 | R40: CHARRUA 220 | S40: 278.37089 | T40: 63.27 | U40: NULL | V40: NULL | W40: 17613
...

Sheet SIGGE_E
A1: Periodo | B1: MesDevengado | C1: Nombre | D1: Concepto | E1: Agrupacion | F1: Glosa | G1: FechaCarga | H1: TipoDocumento | I1: Folio | J1: Vendedor | K1: Comprador | L1: Bloque | M1: Empresa | N1: ClaveEEDD | O1: Licitacion | P1: NomAgrupacion | Q1: Num | R1: Barra | S1: Energia | T1: PrecioEnergia | U1: Potencia | V1: PrecioPotencia | W1: Monto
A2: 43344 | B2: 43344 | C2: Licitación Caren y Cec (SIC 2013/03-2) BS1A | D2: Energia Licitaciones | E2: Energía | F2: Lic. SIC 2013/03-2 bloques BS1A: Energía sep 2018 | G2: 43392 | H2: 33 | I2: 6305 | J2: s | K2: s | L2: BS1A | M2: Caren | N2: Cec | O2: 41335 | P2: CEC | Q2: 1 | R2: TotalBarras | S2: 3000 | T2: 58.085 | U2: NULL | V2: NULL | W2: 174255
A3: 43374 | B3: 43374 | C3: Licitación Caren y Cec (SIC 2013/03-2) BS1A | D3: Energia Licitaciones | E3: Energía | F3: Lic. SIC 2013/03-2 bloques BS1A: Energía oct 2018 | G3: 43431 | H3: 33 | I3: 6796 | J3: s | K3: s | L3: BS1A | M3: Caren | N3: Cec | O3: 41335 | P3: CEC | Q3: 1 | R3: TotalBarras | S3: 3000 | T3: 59.678 | U3: NULL | V3: NULL | W3: 179035
A4: 43405 | B4: 43405 | C4: Licitación Caren y Cec (SIC 2013/03-2) BS1A | D4: Energia Licitaciones | E4: Energía | F4: Lic. SIC 2013/03-2 bloques BS1A: Energía nov 2018 | G4: 43448 | H4: 33 | I4: 6939 | J4: s | K4: s | L4: BS1A | M4: Caren | N4: Cec | O4: 41335 | P4: CEC | Q4: 1 | R4: TotalBarras | S4: 4000 | T4: 59.635 | U4: NULL | V4: NULL | W4: 238540
A5: 43435 | B5: 43435 | C5: Licitación Caren y Cec (SIC 2013/03-2) BS1A | D5: Energia Licitaciones | E5: Energía | F5: Lic. SIC 2013/03-2 bloques BS1A: Energía dic 2018 | G5: 43486 | H5: 33 | I5: 7194 | J5: s | K5: s | L5: BS1A | M5: Caren | N5: Cec | O5: 41335 | P5: CEC | Q5: 1 | R5: TotalBarras | S5: 5000 | T5: 67.951 | U5: NULL | V5: NULL | W5: 339757
A6: 43466 | B6: 43466 | C6: Licitación Caren y Cec (SIC 2013/03-2) BS1A | D6: Reliq. Energia Licitaciones | E6: Energía | F6: Lic. SIC 2013/03-2 bloques BS1A: Reliq. Energía ene 2019 | G6: 43539 | H6: 33 | I6: NULL | J6: s | K6: s | L6: BS1A | M6: Caren | N6: Cec | O6: 41335 | P6: CEC | Q6: 1 | R6: A.JAHUEL 220 | S6: 1.46188 | T6: 66.9 | U6: NULL | V6: NULL | W6: 98
A7: 43466 | B7: 43466 | C7: Licitación Caren y Cec (SIC 2013/03-2) BS1A | D7: Energia Licitaciones | E7: Energía | F7: Lic. SIC 2013/03-2 bloques BS1A: Energía ene 2019 | G7: 43504 | H7: 33 | I7: 7513 | J7: s | K7: s | L7: BS1A | M7: Caren | N7: Cec | O7: 41335 | P7: CEC | Q7: 1 | R7: A.JAHUEL 220 | S7: 1371.306 | T7: 66.9 | U7: NULL | V7: NULL | W7: 91740
A8: 43466 | B8: 43466 | C8: Licitación Caren y Cec (SIC 2013/03-2) BS1A | D8: Reliq. Energia Licitaciones | E8: Energía | F8: Lic. SIC 2013/03-2 bloques BS1A: Reliq. Energía ene 2019 | G8: 43539 | H8: 33 | I8: NULL | J8: s | K8: s | L8: BS1A | M8: Caren | N8: Cec | O8: 41335 | P8: CEC | Q8: 2 | R8: A.MELIP 220 | S8: 0.009388 | T8: 69.014 | U8: NULL | V8: NULL | W8: 1
A9: 43466 | B9: 43466 | C9: Licitación Caren y Cec (SIC 2013/03-2) BS1A | D9: Energia Licitaciones | E9: Energía | F9: Lic. SIC 2013/03-2 bloques BS1A: Energía ene 2019 | G9: 43504 | H9: 33 | I9: 7513 | J9: s | K9: s | L9: BS1A | M9: Caren | N9: Cec | O9: 41335 | P9: CEC | Q9: 2 | R9: A.MELIP 220 | S9: 8.806166 | T9: 69.014 | U9: NULL | V9: NULL | W9: 608
A10: 43466 | B10: 43466 | C10: Licitación Caren y Cec (SIC 2013/03-2) BS1A | D10: Reliq. Energia Licitaciones | E10: Energía | F10: Lic. SIC 2013/03-2 bloques BS1A: Reliq. Energía ene 2019 | G10: 43539 | H10: 33 | I10: NULL | J10: s | K10: s | L10: BS1A | M10: Caren | N10: Cec | O10: 41335 | P10: CEC | Q10: 3 | R10: CHARRUA 220 | S10: 0.453721 | T10: 63.27 | U10: NULL | V10: NULL | W10: 29
A11: 43466 | B11: 43466 | C11: Licitación Caren y Cec (SIC 2013/03-2) BS1A | D11: Energia Licitaciones | E11: Energía | F11: Lic. SIC 2013/03-2 bloques BS1A: Energía ene 2019 | G11: 43504 | H11: 33 | I11: 7513 | J11: s | K11: s | L11: BS1A | M11: Caren | N11: Cec | O11: 41335 | P11: CEC | Q11: 3 | R11: CHARRUA 220 | S11: 425.60961 | T11: 63.27 | U11: NULL | V11: NULL | W11: 26928
A12: 43466 | B12: 43466 | C12: Licitación Caren y Cec (SIC 2013/03-2) BS1A | D12: Reliq. Energia Licitaciones | E12: Energía | F12: Lic. SIC 2013/03-2 bloques BS1A: Reliq. Energía ene 2019 | G12: 43539 | H12: 33 | I12: NULL | J12: s | K12: s | L12: BS1A | M12: Caren | N12: Cec | O12: 41335 | P12: CEC | Q12: 4 | R12: ITAHUE 220 | S12: 2.212452 | T12: 65.349 | U12: NULL | V12: NULL | W12: 145
A13: 43466 | B13: 43466 | C13: Licitación Caren y Cec (SIC 2013/03-2) BS1A | D13: Energia Licitaciones | E13: Energía | F13: Lic. SIC 2013/03-2 bloques BS1A: Energía ene 2019 | G13: 43504 | H13: 33 | I13: 7513 | J13: s | K13: s | L13: BS1A | M13: Caren | N13: Cec | O13: 41335 | P13: CEC | Q13: 4 | R13: ITAHUE 220 | S13: 2075.374 | T13: 65.349 | U13: NULL | V13: NULL | W13: 135624
A14: 43466 | B14: 43466 | C14: Licitación Caren y Cec (SIC 2013/03-2) BS1A | D14: Reliq. Energia Licitaciones | E14: Energía | F14: Lic. SIC 2013/03-2 bloques BS1A: Reliq. Energía ene 2019 | G14: 43539 | H14: 33 | I14: NULL | J14: s | K14: s | L14: BS1A | M14: Caren | N14: Cec | O14: 41335 | P14: CEC | Q14: 5 | R14: RAPEL 220 | S14: 0.008637 | T14: 69.368 | U14: NULL | V14: NULL | W14: 1
A15: 43466 | B15: 43466 | C15: Licitación Caren y Cec (SIC 2013/03-2) BS1A | D15: Energia Licitaciones | E15: Energía | F15: Lic. SIC 2013/03-2 bloques BS1A: Energía ene 2019 | G15: 43504 | H15: 33 | I15: 7513 | J15: s | K15: s | L15: BS1A | M15: Caren | N15: Cec | O15: 41335 | P15: CEC | Q15: 5 | R15: RAPEL 220 | S15: 8.102057 | T15: 69.368 | U15: NULL | V15: NULL | W15: 562
A16: 43497 | B16: 43497 | C16: Licitación Caren y Cec (SIC 2013/03-2) BS1A | D16: Reliq. Energia Licitaciones | E16: Energía | F16: Lic. SIC 2013/03-2 bloques BS1A: Reliq. Energía feb 2019 | G16: 43564 | H16: 61 | I16: NULL | J16: s | K16: s | L16: BS1A | M16: Caren | N16: Cec | O16: 41335 | P16: CEC | Q16: 1 | R16: A.JAHUEL 220 | S16: 0.23349 | T16: 66.9 | U16: NULL | V16: NULL | W16: 16
A17: 43497 | B17: 43497 | C17: Licitación Caren y Cec (SIC 2013/03-2) BS1A | D17: Energia Licitaciones | E17: Energía | F17: Lic. SIC 2013/03-2 bloques BS1A: Energía feb 2019 | G17: 43532 | H17: 33 | I17: 7798 | J17: s | K17: s | L17: BS1A | M17: Caren | N17: Cec | O17: 41335 | P17: CEC | Q17: 1 | R17: A.JAHUEL 220 | S17: 1368.5299 | T17: 66.9 | U17: NULL | V17: NULL | W17: 91555
A18: 43497 | B18: 43497 | C18: Licitación Caren y Cec (SIC 2013/03-2) BS1A | D18: Energia Licitaciones | E18: Energía | F18: Lic. SIC 2013/03-2 bloques BS1A: Energía feb 2019 | G18: 43532 | H18: 33 | I18: 7798 | J18: s | K18: s | L18: BS1A | M18: Caren | N18: Cec | O18: 41335 | P18: CEC | Q18: 2 | R18: A.MELIP 220 | S18: 8.816632 | T18: 69.014 | U18: NULL | V18: NULL | W18: 608
A19: 43497 | B19: 43497 | C19: Licitación Caren y Cec (SIC 2013/03-2) BS1A | D19: Reliq. Energia Licitaciones | E19: Energía | F19: Lic. SIC 2013/03-2 bloques BS1A: Reliq. Energía feb 2019 | G19: 43564 | H19: 61 | I19: NULL | J19: s | K19: s | L19: BS1A | M19: Caren | N19: Cec | O19: 41335 | P19: CEC | Q19: 3 | R19: CHARRUA 220 | S19: 0.072089 | T19: 63.27 | U19: NULL | V19: NULL | W19: 5
A20: 43497 | B20: 43497 | C20: Licitación Caren y Cec (SIC 2013/03-2) BS1A | D20: Energia Licitaciones | E20: Energía | F20: Lic. SIC 2013/03-2 bloques BS1A: Energía feb 2019 | G20: 43532 | H20: 33 | I20: 7798 | J20: s | K20: s | L20: BS1A | M20: Caren | N20: Cec | O20: 41335 | P20: CEC | Q20: 3 | R20: CHARRUA 220 | S20: 422.52678 | T20: 63.27 | U20: NULL | V20: NULL | W20: 26733
A21: 43497 | B21: 43497 | C21: Licitación Caren y Cec (SIC 2013/03-2) BS1A | D21: Reliq. Energia Licitaciones | E21: Energía | F21: Lic. SIC 2013/03-2 bloques BS1A: Reliq. Energía feb 2019 | G21: 43564 | H21: 61 | I21: NULL | J21: s | K21: s | L21: BS1A | M21: Caren | N21: Cec | O21: 41335 | P21: CEC | Q21: 4 | R21: ITAHUE 220 | S21: 0.353269 | T21: 65.349 | U21: NULL | V21: NULL | W21: 23
A22: 43497 | B22: 43497 | C22: Licitación Caren y Cec (SIC 2013/03-2) BS1A | D22: Energia Licitaciones | E22: Energía | F22: Lic. SIC 2013/03-2 bloques BS1A: Energía feb 2019 | G22: 43532 | H22: 33 | I22: 7798 | J22: s | K22: s | L22: BS1A | M22: Caren | N22: Cec | O22: 41335 | P22: CEC | Q22: 4 | R22: ITAHUE 220 | S22: 2070.5801 | T22: 65.349 | U22: NULL | V22: NULL | W22: 135310
A23: 43497 | B23: 43497 | C23: Licitación Caren y Cec (SIC 2013/03-2) BS1A | D23: Energia Licitaciones | E23: Energía | F23: Lic. SIC 2013/03-2 bloques BS1A: Energía feb 2019 | G23: 43532 | H23: 33 | I23: 7798 | J23: s | K23: s | L23: BS1A | M23: Caren | N23: Cec | O23: 41335 | P23: CEC | Q23: 5 | R23: RAPEL 220 | S23: 8.102328 | T23: 69.368 | U23: NULL | V23: NULL | W23: 562
A24: 43525 | B24: 43525 | C24: Licitación Caren y Cec (SIC 2013/03-2) BS1A | D24: Reliq. Energia Licitaciones | E24: Energía | F24: Lic. SIC 2013/03-2 bloques BS1A: Reliq. Energía mar 2019 | G24: 43598 | H24: 33 | I24: NULL | J24: s | K24: s | L24: BS1A | M24: Caren | N24: Cec | O24: 41335 | P24: CEC | Q24: 1 | R24: A.JAHUEL 220 | S24: 0.580609 | T24: 66.9 | U24: NULL | V24: NULL | W24: 39
A25: 43525 | B25: 43525 | C25: Licitación Caren y Cec (SIC 2013/03-2) BS1A | D25: Energia Licitaciones | E25: Energía | F25: Lic. SIC 2013/03-2 bloques BS1A: Energía mar 2019 | G25: 43563 | H25: 33 | I25: 8389 | J25: s | K25: s | L25: BS1A | M25: Caren | N25: Cec | O25: 41335 | P25: CEC | Q25: 1 | R25: A.JAHUEL 220 | S25: 1311.6233 | T25: 66.9 | U25: NULL | V25: NULL | W25: 87748
A26: 43525 | B26: 43525 | C26: Licitación Caren y Cec (SIC 2013/03-2) BS1A | D26: Energia Licitaciones | E26: Energía | F26: Lic. SIC 2013/03-2 bloques BS1A: Energía mar 2019 | G26: 43563 | H26: 33 | I26: 8389 | J26: s | K26: s | L26: BS1A | M26: Caren | N26: Cec | O26: 41335 | P26: CEC | Q26: 2 | R26: A.MELIP 220 | S26: 8.173697 | T26: 69.014 | U26: NULL | V26: NULL | W26: 564
A27: 43525 | B27: 43525 | C27: Licitación Caren y Cec (SIC 2013/03-2) BS1A | D27: Reliq. Energia Licitaciones | E27: Energía | F27: Lic. SIC 2013/03-2 bloques BS1A: Reliq. Energía mar 2019 | G27: 43598 | H27: 33 | I27: NULL | J27: s | K27: s | L27: BS1A | M27: Caren | N27: Cec | O27: 41335 | P27: CEC | Q27: 3 | R27: CHARRUA 220 | S27: 0.178218 | T27: 63.27 | U27: NULL | V27: NULL | W27: 11
